File: lab10/data/S1_HDPE_1.csv
Results Table 1,,,,,,,,,,,,,
,Specimen label,Thickness,Width,Length,Rate 1,,,,,,,,
,,(mm),(mm),(mm),(mm/min),,,,,,,,
1,HDPE-1,3.3,12.83,100,25.4,,,,,,,,
2,HDPE-5,3.3,12.83,83.44,127,,,,,,,,
3,HDPE-20,3.3,12.73,91.19,508,,,,,,,,
,,,,,,,,,,,,,
Results Table 2,,,,,,,,,,,,,
,,,,,,,,,,,,,
,,,,,,,,,,,,,
1,Time,Displacement,Force,,2,Time,Displacement,Force,,3,Time,Displacement,Force
,(s),(mm),(kN),,,(s),(mm),(kN),,,(s),(mm),(kN)
,0,0,-0.0067,,,0,0,0.0039,,,0,0,0.0107
,0.173,0.036,0.0243,,,0.071,0.0392,0.0457,,,0.05,0.0472,0.0547
,0.264,0.0846,0.0647,,,0.093,0.0822,0.089,,,0.06,0.0982,0.0991
,0.395,0.1389,0.105,,,0.116,0.1254,0.1303,,,0.068,0.1534,0.145
,0.534,0.1983,0.1454,,,0.14,0.1717,0.1716,,,0.076,0.2172,0.1954
,0.69,0.2634,0.1857,,,0.163,0.222,0.214,,,0.084,0.2852,0.2463
,0.854,0.3331,0.226,,,0.185,0.2739,0.2562,,,0.092,0.3538,0.2952
,1.03,0.4076,0.2663,,,0.208,0.3279,0.2975,,,0.1,0.4212,0.341
,1.214,0.486,0.3066,,,0.233,0.3834,0.3382,,,0.108,0.4866,0.3835
,1.413,0.569,0.3464,,,0.262,0.4441,0.3797,,,0.117,0.5582,0.4283
,1.613,0.6539,0.3847,,,0.292,0.5063,0.4202,,,0.127,0.6366,0.475
,1.813,0.739,0.4222,,,0.324,0.574,0.4624,,,0.137,0.7154,0.5199
,2.013,0.8236,0.4571,,,0.356,0.6419,0.504,,,0.147,0.7961,0.5642
,2.213,0.9083,0.4897,,,0.39,0.7137,0.5463,,,0.157,0.8793,0.6086
,2.413,0.9932,0.5209,,,0.425,0.788,0.5878,,,0.167,0.9651,0.6523
,2.613,1.0782,0.5505,,,0.462,0.8664,0.6292,,,0.177,1.053,0.695
,2.813,1.1626,0.5774,,,0.5,0.9466,0.6697,,,0.187,1.1422,0.7361
,3.013,1.247,0.6034,,,0.541,1.0332,0.7102,,,0.199,1.2498,0.7828
,3.213,1.3313,0.6275,,,0.585,1.1267,0.7514,,,0.211,1.3568,0.8259
,3.413,1.4161,0.6501,,,0.632,1.2263,0.7917,,,0.224,1.4712,0.8682
,3.613,1.501,0.672,,,0.684,1.3364,0.8326,,,0.238,1.5922,0.9095
,3.813,1.5856,0.6924,,,0.741,1.457,0.8736,,,0.254,1.7279,0.9518
,4.013,1.6705,0.7113,,,0.804,1.5897,0.9144,,,0.272,1.8789,0.9946
,4.213,1.7551,0.7301,,,0.872,1.7344,0.9549,,,0.292,2.0463,1.038
,4.413,1.8402,0.7473,,,0.948,1.8951,0.9957,,,0.313,2.2231,1.0792
,4.613,1.9241,0.7627,,,1.034,2.077,1.0363,,,0.336,2.4176,1.1207
,4.813,2.0085,0.7787,,,1.128,2.2757,1.0769,,,0.362,2.6385,1.1625
,5.013,2.0934,0.7931,,,1.234,2.5005,1.1171,,,0.391,2.8849,1.2038
,5.213,2.1783,0.8074,,,1.356,2.7583,1.1573,,,0.424,3.1645,1.2447
,5.413,2.2629,0.8212,,,1.497,3.0571,1.1978,,,0.463,3.4946,1.286
,5.613,2.3477,0.8337,,,1.668,3.4187,1.2379,,,0.509,3.8836,1.3262
,5.813,2.433,0.8464,,,1.868,3.8426,1.2754,,,0.569,4.3919,1.3669
,6.013,2.5174,0.8584,,,2.068,4.2656,1.3042,,,0.656,5.1281,1.407
,6.213,2.6014,0.8689,,,2.268,4.6891,1.3271,,,0.825,6.5594,1.4408
,6.413,2.6858,0.8795,,,2.468,5.1122,1.3431,,,1.025,8.2525,1.4329
,6.613,2.7709,0.8905,,,2.668,5.5361,1.3552,,,1.177,9.5395,1.3925
,6.813,2.8556,0.8999,,,2.868,5.9588,1.3632,,,1.246,10.1239,1.3518
,7.013,2.9405,0.9098,,,3.068,6.3823,1.3679,,,1.29,10.4963,1.3109
,7.213,3.0254,0.9196,,,3.268,6.8056,1.3695,,,1.324,10.7842,1.2704
,7.413,3.1101,0.928,,,3.468,7.2292,1.3695,,,1.356,11.0552,1.229
,7.613,3.1947,0.9369,,,3.668,7.6519,1.366,,,1.389,11.3346,1.1889
,7.813,3.2789,0.9451,,,3.868,8.0756,1.3572,,,1.429,11.6733,1.148
,8.013,3.3632,0.9522,,,4.04,8.4401,1.327,,,1.478,12.088,1.1076
,8.213,3.4481,0.96,,,4.094,8.5542,1.2859,,,1.536,12.5791,1.067
,8.413,3.5329,0.9678,,,4.129,8.6282,1.2444,,,1.593,13.0616,1.0265
,8.613,3.6178,0.9742,,,4.164,8.7024,1.2032,,,1.643,13.4851,0.9856
,8.813,3.7025,0.9811,,,4.198,8.7744,1.1624,,,1.689,13.8747,0.9441
,9.013,3.7874,0.9884,,,4.232,8.846,1.1207,,,1.738,14.2896,0.9034
,9.213,3.872,0.9938,,,4.263,8.9113,1.0799,,,1.798,14.7973,0.8629
,9.413,3.9561,0.9997,,,4.293,8.9752,1.0391,,,1.87,15.4071,0.822
,9.613,4.0404,1.0053,,,4.323,9.0391,0.9976,,,1.958,16.1518,0.7819
,9.813,4.1254,1.011,,,4.354,9.1047,0.9567,,,2.07,17.1004,0.7413
,10.013,4.2105,1.0167,,,4.389,9.1787,0.9161,,,2.128,17.5913,0.6978
,10.213,4.2951,1.0219,,,4.43,9.2654,0.8751,,,2.133,17.6337,0.641
,10.413,4.3799,1.0265,,,4.477,9.3647,0.8339,,,2.137,17.6676,0.5768
,10.613,4.465,1.0316,,,4.528,9.4724,0.7933,,,2.141,17.7015,0.5013
,10.813,4.5495,1.0362,,,4.562,9.5448,0.7515,,,2.145,17.7354,0.4217
,11.013,4.6334,1.0399,,,4.593,9.6106,0.7108,,,2.149,17.7693,0.3435
,11.213,4.718,1.0442,,,4.656,9.7435,0.6697,,,2.153,17.8032,0.2704
,11.413,4.8032,1.0487,,,4.744,9.93,0.6292,,,2.157,17.8371,0.2048
,11.613,4.8877,1.052,,,4.843,10.1395,0.5887,,,2.161,17.871,0.1479
,11.813,4.9724,1.0561,,,4.957,10.3807,0.5487,,,2.165,17.9049,0.1001
,12.013,5.0572,1.0597,,,5.096,10.6749,0.5085,,,2.17,17.9473,0.0528
,12.213,5.1422,1.0629,,,5.269,11.0412,0.4683,,,2.177,18.0066,0.0075
,12.413,5.2265,1.0663,,,5.469,11.4646,0.4333,,,2.283,18.9035,-0.0006
,12.613,5.3106,1.0691,,,5.669,11.8879,0.4053,,,2.483,20.5971,-0.0014
,12.813,5.3952,1.0715,,,5.869,12.3109,0.3814,,,2.683,22.2904,-0.0015
,13.013,5.4801,1.0747,,,6.069,12.7349,0.36,,,2.883,23.9836,-0.0013
,13.213,5.565,1.0777,,,6.269,13.1577,0.3402,,,3.083,25.677,-0.0018
,13.413,5.6498,1.0797,,,6.469,13.581,0.3224,,,3.283,27.3703,-0.0017
,13.613,5.7347,1.0828,,,6.669,14.0047,0.3055,,,3.483,29.0638,-0.0014
,13.813,5.8195,1.0851,,,6.869,14.4277,0.2894,,,3.683,30.7571,-0.0015
,14.013,5.9041,1.0872,,,7.069,14.8513,0.2745,,,3.883,32.4503,-0.0014
,14.213,5.9883,1.0893,,,7.269,15.2741,0.2601,,,4.083,34.1436,-0.0017
,14.413,6.0728,1.0908,,,7.469,15.6983,0.2466,,,,,
,14.613,6.1576,1.0925,,,7.669,16.1208,0.2332,,,,,
,14.813,6.2425,1.0949,,,7.869,16.5443,0.2208,,,,,
,15.013,6.3271,1.0962,,,8.069,16.9679,0.2081,,,,,
,15.213,6.4118,1.0981,,,8.269,17.3915,0.1956,,,,,
,15.413,6.497,1.0999,,,8.469,17.8141,0.1842,,,,,
,15.613,6.5814,1.1008,,,8.669,18.2378,0.1727,,,,,
,15.813,6.6654,1.1021,,,8.869,18.6615,0.162,,,,,
,16.013,6.75,1.1033,,,9.069,19.0844,0.1515,,,,,
,16.213,6.8348,1.1042,,,9.269,19.508,0.1413,,,,,
,16.413,6.9197,1.1056,,,9.469,19.931,0.1306,,,,,
,16.613,7.0042,1.1063,,,9.669,20.3548,0.1204,,,,,
,16.813,7.0893,1.1074,,,9.869,20.7774,0.1092,,,,,
,17.013,7.1744,1.1089,,,10.069,21.2012,0.097,,,,,
,17.213,7.2587,1.1093,,,10.269,21.6245,0.0825,,,,,
,17.413,7.3429,1.1097,,,10.469,22.0478,0.0636,,,,,
,17.613,7.4273,1.1105,,,10.614,22.3549,0.0284,,,,,
,17.813,7.5122,1.1109,,,10.733,22.6063,-0.0009,,,,,
,18.013,7.5969,1.1115,,,10.933,23.0301,-0.0011,,,,,
,18.213,7.6818,1.1124,,,11.133,23.4534,-0.001,,,,,
,18.413,7.7667,1.1123,,,11.333,23.8767,-0.0009,,,,,
,18.613,7.8516,1.1133,,,11.486,24.2004,-0.0011,,,,,
,18.813,7.936,1.1136,,,,,,,,,,
,19.013,8.02,1.113,,,,,,,,,,
,19.213,8.1045,1.1135,,,,,,,,,,
,19.413,8.1894,1.1138,,,,,,,,,,
,19.613,8.2745,1.1137,,,,,,,,,,
,19.813,8.3589,1.1138,,,,,,,,,,
,20.013,8.4439,1.1141,,,,,,,,,,
,20.213,8.529,1.1141,,,,,,,,,,
,20.413,8.6131,1.1141,,,,,,,,,,
,20.613,8.6973,1.1137,,,,,,,,,,
,20.813,8.7817,1.1133,,,,,,,,,,
,21.013,8.867,1.1138,,,,,,,,,,
,21.213,8.9516,1.1133,,,,,,,,,,
,21.413,9.0364,1.1131,,,,,,,,,,
,21.613,9.1215,1.1132,,,,,,,,,,
,21.813,9.2062,1.1126,,,,,,,,,,
,22.013,9.2905,1.1126,,,,,,,,,,
,22.213,9.3746,1.1118,,,,,,,,,,
,22.413,9.4594,1.1109,,,,,,,,,,
,22.613,9.5441,1.111,,,,,,,,,,
,22.813,9.6292,1.1108,,,,,,,,,,
,23.013,9.7137,1.1098,,,,,,,,,,
,23.213,9.7985,1.1098,,,,,,,,,,
,23.413,9.8834,1.1089,,,,,,,,,,
,23.613,9.9676,1.1089,,,,,,,,,,
,23.813,10.0519,1.1081,,,,,,,,,,
,24.013,10.1362,1.1069,,,,,,,,,,
,24.213,10.2215,1.1069,,,,,,,,,,
,24.413,10.3063,1.106,,,,,,,,,,
,24.613,10.391,1.1054,,,,,,,,,,
,24.813,10.476,1.1054,,,,,,,,,,
,25.013,10.5609,1.1045,,,,,,,,,,
,25.213,10.6453,1.1036,,,,,,,,,,
,25.413,10.7293,1.103,,,,,,,,,,
,25.613,10.8141,1.1018,,,,,,,,,,
,25.813,10.899,1.1016,,,,,,,,,,
,26.013,10.9837,1.1007,,,,,,,,,,
,26.213,11.0684,1.0996,,,,,,,,,,
,26.413,11.1532,1.0995,,,,,,,,,,
,26.613,11.2383,1.0985,,,,,,,,,,
,26.813,11.3222,1.0973,,,,,,,,,,
,27.013,11.4067,1.0971,,,,,,,,,,
,27.213,11.4913,1.0956,,,,,,,,,,
,27.413,11.5761,1.095,,,,,,,,,,
,27.613,11.6609,1.0941,,,,,,,,,,
,27.813,11.7456,1.0931,,,,,,,,,,
,28.013,11.8305,1.0924,,,,,,,,,,
,28.213,11.9154,1.0918,,,,,,,,,,
,28.413,12,1.0907,,,,,,,,,,
,28.613,12.084,1.09,,,,,,,,,,
,28.813,12.1686,1.0885,,,,,,,,,,
,29.013,12.2535,1.0877,,,,,,,,,,
,29.213,12.3384,1.0872,,,,,,,,,,
,29.413,12.4231,1.0856,,,,,,,,,,
,29.613,12.5079,1.0853,,,,,,,,,,
,29.813,12.5932,1.0844,,,,,,,,,,
,30.013,12.6773,1.0831,,,,,,,,,,
,30.213,12.7613,1.0822,,,,,,,,,,
,30.413,12.8459,1.0807,,,,,,,,,,
,30.613,12.931,1.0801,,,,,,,,,,
,30.813,13.0156,1.0794,,,,,,,,,,
,31.013,13.1002,1.0776,,,,,,,,,,
,31.213,13.1854,1.0775,,,,,,,,,,
,31.413,13.2702,1.0764,,,,,,,,,,
,31.613,13.3544,1.0751,,,,,,,,,,
,31.813,13.4386,1.0742,,,,,,,,,,
,32.013,13.5234,1.073,,,,,,,,,,
,32.213,13.6082,1.072,,,,,,,,,,
,32.413,13.6931,1.0715,,,,,,,,,,
,32.613,13.7779,1.07,,,,,,,,,,
,32.813,13.8627,1.0691,,,,,,,,,,
,33.013,13.9477,1.0683,,,,,,,,,,
,33.213,14.0319,1.0668,,,,,,,,,,
,33.413,14.1161,1.0659,,,,,,,,,,
,33.613,14.2006,1.0647,,,,,,,,,,
,33.813,14.2856,1.0634,,,,,,,,,,
,34.013,14.3707,1.0627,,,,,,,,,,
,34.213,14.4552,1.0615,,,,,,,,,,
,34.413,14.54,1.0606,,,,,,,,,,
,34.613,14.6248,1.0599,,,,,,,,,,
,34.813,14.7091,1.0586,,,,,,,,,,
,35.013,14.7932,1.0573,,,,,,,,,,
,35.213,14.8778,1.0564,,,,,,,,,,
,35.413,14.963,1.0549,,,,,,,,,,
,35.613,15.0477,1.0543,,,,,,,,,,
,35.813,15.1324,1.0533,,,,,,,,,,
,36.013,15.2173,1.0519,,,,,,,,,,
,36.213,15.3024,1.0514,,,,,,,,,,
,36.413,15.3864,1.0498,,,,,,,,,,
,36.613,15.4708,1.0489,,,,,,,,,,
,36.813,15.5555,1.0478,,,,,,,,,,
,37.013,15.6404,1.0467,,,,,,,,,,
,37.213,15.7251,1.0455,,,,,,,,,,
,37.413,15.8098,1.0447,,,,,,,,,,
,37.613,15.8947,1.0435,,,,,,,,,,
,37.813,15.9794,1.0426,,,,,,,,,,
,38.013,16.0638,1.0418,,,,,,,,,,
,38.213,16.1481,1.04,,,,,,,,,,
,38.413,16.2326,1.0391,,,,,,,,,,
,38.613,16.3176,1.0382,,,,,,,,,,
,38.813,16.4025,1.0369,,,,,,,,,,
,39.013,16.4871,1.0359,,,,,,,,,,
,39.213,16.5717,1.0348,,,,,,,,,,
,39.413,16.657,1.0338,,,,,,,,,,
,39.613,16.7413,1.0328,,,,,,,,,,
,39.813,16.8253,1.0314,,,,,,,,,,
,40.013,16.91,1.0301,,,,,,,,,,
,40.213,16.9951,1.0294,,,,,,,,,,
,40.413,17.0796,1.0283,,,,,,,,,,
,40.613,17.1643,1.0269,,,,,,,,,,
,40.813,17.2495,1.0266,,,,,,,,,,
,41.013,17.3343,1.025,,,,,,,,,,
,41.213,17.4185,1.024,,,,,,,,,,
,41.413,17.5027,1.023,,,,,,,,,,
,41.613,17.5872,1.0214,,,,,,,,,,
,41.813,17.6723,1.0204,,,,,,,,,,
,42.013,17.757,1.0201,,,,,,,,,,
,42.213,17.8418,1.0184,,,,,,,,,,
,42.413,17.9266,1.0175,,,,,,,,,,
,42.613,18.0116,1.017,,,,,,,,,,
,42.813,18.0958,1.0155,,,,,,,,,,
,43.013,18.1798,1.0142,,,,,,,,,,
,43.213,18.2647,1.0135,,,,,,,,,,
,43.413,18.3494,1.0119,,,,,,,,,,
,43.613,18.4344,1.0114,,,,,,,,,,
,43.813,18.5191,1.0101,,,,,,,,,,
,44.013,18.6041,1.0088,,,,,,,,,,
,44.213,18.689,1.0085,,,,,,,,,,
,44.413,18.7731,1.0069,,,,,,,,,,
,44.613,18.8571,1.0054,,,,,,,,,,
,44.813,18.9419,1.0049,,,,,,,,,,
,45.013,19.0272,1.0036,,,,,,,,,,
,45.213,19.1117,1.0025,,,,,,,,,,
,45.413,19.1965,1.0018,,,,,,,,,,
,45.613,19.2815,1.0005,,,,,,,,,,
,45.813,19.3662,0.9993,,,,,,,,,,
,46.013,19.4503,0.9983,,,,,,,,,,
,46.213,19.5342,0.9966,,,,,,,,,,
,46.413,19.6195,0.9962,,,,,,,,,,
,46.613,19.7039,0.9948,,,,,,,,,,
,46.813,19.789,0.9941,,,,,,,,,,
,47.013,19.8738,0.9934,,,,,,,,,,
,47.213,19.9588,0.9917,,,,,,,,,,
,47.413,20.0434,0.9911,,,,,,,,,,
,47.613,20.1276,0.9898,,,,,,,,,,
,47.813,20.2119,0.9884,,,,,,,,,,
,48.013,20.2965,0.9877,,,,,,,,,,
,48.213,20.3818,0.9868,,,,,,,,,,
,48.413,20.4664,0.9852,,,,,,,,,,
,48.613,20.5511,0.9846,,,,,,,,,,
,48.813,20.636,0.9837,,,,,,,,,,
,49.013,20.7209,0.9825,,,,,,,,,,
,49.213,20.8051,0.9816,,,,,,,,,,
,49.413,20.8889,0.9797,,,,,,,,,,
,49.613,20.9742,0.979,,,,,,,,,,
,49.813,21.0587,0.9779,,,,,,,,,,
,50.013,21.1437,0.977,,,,,,,,,,
,50.213,21.2284,0.9765,,,,,,,,,,
,50.413,21.3133,0.9748,,,,,,,,,,
,50.613,21.3981,0.9739,,,,,,,,,,
,50.813,21.4823,0.9727,,,,,,,,,,
,51.013,21.5665,0.9714,,,,,,,,,,
,51.213,21.6513,0.9707,,,,,,,,,,
,51.413,21.7362,0.9692,,,,,,,,,,
,51.613,21.821,0.9685,,,,,,,,,,
,51.813,21.9056,0.9673,,,,,,,,,,
,52.013,21.9908,0.9664,,,,,,,,,,
,52.213,22.0754,0.9655,,,,,,,,,,
,52.413,22.1598,0.964,,,,,,,,,,
,52.613,22.2439,0.9626,,,,,,,,,,
,52.813,22.3286,0.9619,,,,,,,,,,
,53.013,22.4136,0.9605,,,,,,,,,,
,53.213,22.4985,0.9597,,,,,,,,,,
,53.413,22.5832,0.958,,,,,,,,,,
,53.613,22.668,0.9574,,,,,,,,,,
,53.813,22.753,0.9571,,,,,,,,,,
,54.013,22.837,0.9554,,,,,,,,,,
,54.213,22.9212,0.954,,,,,,,,,,
,54.413,23.0059,0.9534,,,,,,,,,,
,54.613,23.0911,0.9519,,,,,,,,,,
,54.813,23.1755,0.951,,,,,,,,,,
,55.013,23.2603,0.9502,,,,,,,,,,
,55.213,23.3456,0.9488,,,,,,,,,,
,55.413,23.4303,0.9482,,,,,,,,,,
,55.613,23.5143,0.9466,,,,,,,,,,
,55.813,23.5986,0.9454,,,,,,,,,,
,56.013,23.6835,0.9447,,,,,,,,,,
,56.213,23.7683,0.9432,,,,,,,,,,
,56.413,23.853,0.9427,,,,,,,,,,
,56.613,23.938,0.9415,,,,,,,,,,
,56.813,24.0229,0.9404,,,,,,,,,,
,57.013,24.1075,0.9397,,,,,,,,,,
,57.213,24.1915,0.9381,,,,,,,,,,
,57.413,24.2761,0.9371,,,,,,,,,,
,57.613,24.3607,0.936,,,,,,,,,,
,57.813,24.4457,0.9344,,,,,,,,,,
,58.013,24.5304,0.9339,,,,,,,,,,
,58.213,24.6153,0.9327,,,,,,,,,,
,58.413,24.7001,0.9315,,,,,,,,,,
,58.613,24.7847,0.9309,,,,,,,,,,
,58.813,24.8691,0.9292,,,,,,,,,,
,59.013,24.9531,0.9279,,,,,,,,,,
,59.213,25.038,0.9275,,,,,,,,,,
,59.413,25.1232,0.9257,,,,,,,,,,
,59.613,25.2079,0.9251,,,,,,,,,,
,59.813,25.2925,0.9239,,,,,,,,,,
,60.013,25.3775,0.9228,,,,,,,,,,
,60.213,25.4623,0.9221,,,,,,,,,,
,60.413,25.5462,0.9202,,,,,,,,,,
,60.613,25.6306,0.9193,,,,,,,,,,
,60.813,25.7156,0.9186,,,,,,,,,,
,61.013,25.8004,0.9169,,,,,,,,,,
,61.213,25.885,0.9161,,,,,,,,,,
,61.413,25.9699,0.9148,,,,,,,,,,
,61.613,26.0548,0.9136,,,,,,,,,,
,61.813,26.1392,0.913,,,,,,,,,,
,62.013,26.2237,0.9112,,,,,,,,,,
,62.213,26.3081,0.9102,,,,,,,,,,
,62.413,26.3928,0.9092,,,,,,,,,,
,62.613,26.4776,0.9077,,,,,,,,,,
,62.813,26.5623,0.9068,,,,,,,,,,
,63.013,26.6471,0.9054,,,,,,,,,,
,63.213,26.732,0.9044,,,,,,,,,,
,63.413,26.8168,0.9038,,,,,,,,,,
,63.613,26.9011,0.9022,,,,,,,,,,
,63.813,26.9853,0.9009,,,,,,,,,,
,64.013,27.0702,0.8999,,,,,,,,,,
,64.213,27.1551,0.8983,,,,,,,,,,
,64.413,27.2397,0.8975,,,,,,,,,,
,64.613,27.3245,0.8963,,,,,,,,,,
,64.813,27.4096,0.8951,,,,,,,,,,
,65.013,27.4941,0.894,,,,,,,,,,
,65.213,27.5784,0.8924,,,,,,,,,,
,65.413,27.6626,0.8912,,,,,,,,,,
,65.613,27.7474,0.8898,,,,,,,,,,
,65.813,27.8322,0.8886,,,,,,,,,,
,66.013,27.9167,0.8877,,,,,,,,,,
,66.213,28.0017,0.886,,,,,,,,,,
,66.413,28.0867,0.8851,,,,,,,,,,
,66.613,28.1715,0.884,,,,,,,,,,
,66.813,28.2555,0.8824,,,,,,,,,,
,67.013,28.3398,0.8813,,,,,,,,,,
,67.213,28.4248,0.88,,,,,,,,,,
,67.413,28.5095,0.8786,,,,,,,,,,
,67.613,28.5944,0.8776,,,,,,,,,,
,67.813,28.6791,0.876,,,,,,,,,,
,68.013,28.7642,0.8753,,,,,,,,,,
,68.213,28.8488,0.8738,,,,,,,,,,
,68.413,28.9329,0.8724,,,,,,,,,,
,68.613,29.0172,0.8711,,,,,,,,,,
,68.813,29.1019,0.8694,,,,,,,,,,
,69.013,29.1872,0.8686,,,,,,,,,,
,69.213,29.2714,0.8675,,,,,,,,,,
,69.413,29.3564,0.8659,,,,,,,,,,
,69.613,29.4416,0.8651,,,,,,,,,,
,69.813,29.526,0.8635,,,,,,,,,,
,70.013,29.61,0.862,,,,,,,,,,
,70.213,29.6944,0.8607,,,,,,,,,,
,70.413,29.7795,0.8594,,,,,,,,,,
,70.613,29.8641,0.8581,,,,,,,,,,
,70.813,29.949,0.8567,,,,,,,,,,
,71.013,30.0338,0.8556,,,,,,,,,,
,71.213,30.1188,0.8547,,,,,,,,,,
,71.413,30.2033,0.8528,,,,,,,,,,
,71.613,30.2875,0.8516,,,,,,,,,,
,71.813,30.3721,0.8503,,,,,,,,,,
,72.013,30.4565,0.8487,,,,,,,,,,
,72.213,30.5418,0.8482,,,,,,,,,,
,72.413,30.6264,0.8463,,,,,,,,,,
,72.613,30.7113,0.8451,,,,,,,,,,
,72.813,30.7961,0.8443,,,,,,,,,,
,73.013,30.8807,0.8426,,,,,,,,,,
,73.213,30.9648,0.8413,,,,,,,,,,
,73.413,31.0491,0.8398,,,,,,,,,,
,73.613,31.1342,0.8382,,,,,,,,,,
,73.813,31.219,0.8375,,,,,,,,,,
,74.013,31.3037,0.8359,,,,,,,,,,
,74.213,31.3883,0.8347,,,,,,,,,,
,74.413,31.4735,0.8336,,,,,,,,,,
,74.613,31.558,0.832,,,,,,,,,,
,74.813,31.6421,0.8309,,,,,,,,,,
,75.013,31.7266,0.8292,,,,,,,,,,
,75.213,31.8114,0.8279,,,,,,,,,,
,75.413,31.8964,0.827,,,,,,,,,,
,75.613,31.9811,0.8251,,,,,,,,,,
,75.813,32.0659,0.8244,,,,,,,,,,
,76.013,32.151,0.8229,,,,,,,,,,
,76.213,32.2354,0.8215,,,,,,,,,,
,76.413,32.3196,0.8204,,,,,,,,,,
,76.613,32.404,0.8185,,,,,,,,,,
,76.813,32.4888,0.8177,,,,,,,,,,
,77.013,32.5737,0.8163,,,,,,,,,,
,77.213,32.6583,0.8149,,,,,,,,,,
,77.413,32.7431,0.814,,,,,,,,,,
,77.613,32.828,0.8122,,,,,,,,,,
,77.813,32.9128,0.8112,,,,,,,,,,
,78.013,32.9969,0.81,,,,,,,,,,
,78.213,33.0812,0.8079,,,,,,,,,,
,78.413,33.1661,0.8072,,,,,,,,,,
,78.613,33.2512,0.8057,,,,,,,,,,
,78.813,33.3357,0.8043,,,,,,,,,,
,79.013,33.4205,0.8032,,,,,,,,,,
,79.213,33.5058,0.8018,,,,,,,,,,
,79.413,33.5902,0.8008,,,,,,,,,,
,79.613,33.6741,0.7988,,,,,,,,,,
,79.813,33.7586,0.7977,,,,,,,,,,
,80.013,33.8436,0.7968,,,,,,,,,,
,80.213,33.9283,0.795,,,,,,,,,,
,80.413,34.0129,0.7943,,,,,,,,,,
,80.613,34.098,0.7927,,,,,,,,,,
,80.813,34.183,0.7916,,,,,,,,,,
,81.013,34.2674,0.7906,,,,,,,,,,
,81.213,34.3514,0.7885,,,,,,,,,,
,81.413,34.4361,0.7874,,,,,,,,,,
,81.613,34.5208,0.7858,,,,,,,,,,
,81.813,34.6057,0.7847,,,,,,,,,,
,82.013,34.6905,0.7837,,,,,,,,,,
,82.213,34.7754,0.782,,,,,,,,,,
,82.413,34.8602,0.7809,,,,,,,,,,
,82.613,34.9446,0.7795,,,,,,,,,,
,82.813,35.0288,0.778,,,,,,,,,,
,83.013,35.1131,0.7769,,,,,,,,,,
,83.213,35.1982,0.7752,,,,,,,,,,
,83.413,35.2832,0.7742,,,,,,,,,,
,83.613,35.3679,0.7729,,,,,,,,,,
,83.813,35.4526,0.7712,,,,,,,,,,
,84.013,35.5375,0.7708,,,,,,,,,,
,84.213,35.6221,0.7686,,,,,,,,,,
,84.413,35.7059,0.7673,,,,,,,,,,
,84.613,35.7906,0.7664,,,,,,,,,,
,84.813,35.8758,0.7646,,,,,,,,,,
,85.013,35.9604,0.7635,,,,,,,,,,
,85.213,36.045,0.7618,,,,,,,,,,
,85.413,36.1299,0.7609,,,,,,,,,,
,85.613,36.2149,0.7598,,,,,,,,,,
,85.813,36.2991,0.7582,,,,,,,,,,
,86.013,36.3833,0.7568,,,,,,,,,,
,86.213,36.4681,0.7555,,,,,,,,,,
,86.413,36.5529,0.754,,,,,,,,,,
,86.613,36.6377,0.7534,,,,,,,,,,
,86.813,36.7223,0.7512,,,,,,,,,,
,87.013,36.8072,0.7507,,,,,,,,,,
,87.213,36.8921,0.7495,,,,,,,,,,
,87.413,36.9767,0.7483,,,,,,,,,,
,87.613,37.0608,0.7471,,,,,,,,,,
,87.813,37.1454,0.7455,,,,,,,,,,
,88.013,37.2303,0.7445,,,,,,,,,,
,88.213,37.315,0.7433,,,,,,,,,,
,88.413,37.3998,0.7416,,,,,,,,,,
,88.613,37.4843,0.7409,,,,,,,,,,
,88.813,37.5696,0.7395,,,,,,,,,,
,89.013,37.654,0.7382,,,,,,,,,,
,89.213,37.738,0.7369,,,,,,,,,,
,89.413,37.8227,0.7351,,,,,,,,,,
,89.613,37.9076,0.7341,,,,,,,,,,
,89.813,37.9922,0.7327,,,,,,,,,,
,90.013,38.0769,0.7311,,,,,,,,,,
,90.213,38.1619,0.7304,,,,,,,,,,
,90.413,38.2468,0.7285,,,,,,,,,,
,90.613,38.3314,0.7276,,,,,,,,,,
,90.813,38.4154,0.726,,,,,,,,,,
,91.013,38.5,0.7244,,,,,,,,,,
,91.213,38.5849,0.7235,,,,,,,,,,
,91.413,38.6695,0.7218,,,,,,,,,,
,91.613,38.7545,0.721,,,,,,,,,,
,91.813,38.8389,0.7196,,,,,,,,,,
,92.013,38.9243,0.718,,,,,,,,,,
,92.213,39.0085,0.7172,,,,,,,,,,
,92.413,39.0927,0.7157,,,,,,,,,,
,92.613,39.1774,0.7147,,,,,,,,,,
,92.813,39.262,0.7131,,,,,,,,,,
,93.013,39.3469,0.7122,,,,,,,,,,
,93.213,39.4315,0.7108,,,,,,,,,,
,93.413,39.5165,0.7096,,,,,,,,,,
,93.613,39.6014,0.7089,,,,,,,,,,
,93.813,39.6859,0.7074,,,,,,,,,,
,94.013,39.7699,0.7059,,,,,,,,,,
,94.213,39.8545,0.7049,,,,,,,,,,
,94.413,39.9398,0.7034,,,,,,,,,,
,94.613,40.0241,0.7025,,,,,,,,,,
,94.813,40.1092,0.7008,,,,,,,,,,
,95.013,40.194,0.7001,,,,,,,,,,
,95.213,40.2789,0.6986,,,,,,,,,,
,95.413,40.3631,0.6975,,,,,,,,,,
,95.613,40.4474,0.6961,,,,,,,,,,
,95.813,40.5321,0.6947,,,,,,,,,,
,96.013,40.6168,0.6941,,,,,,,,,,
,96.213,40.7017,0.6925,,,,,,,,,,
,96.413,40.7864,0.6918,,,,,,,,,,
,96.613,40.8713,0.6904,,,,,,,,,,
,96.813,40.956,0.6896,,,,,,,,,,
,97.013,41.0403,0.6884,,,,,,,,,,
,97.213,41.1247,0.6873,,,,,,,,,,
,97.413,41.2092,0.6864,,,,,,,,,,
,97.613,41.2943,0.6852,,,,,,,,,,
,97.813,41.379,0.6844,,,,,,,,,,
,98.013,41.4637,0.6831,,,,,,,,,,
,98.213,41.5485,0.6822,,,,,,,,,,
,98.413,41.6335,0.6819,,,,,,,,,,
,98.613,41.7181,0.6804,,,,,,,,,,
,98.813,41.8019,0.6798,,,,,,,,,,
,99.013,41.8868,0.6783,,,,,,,,,,
,99.213,41.9717,0.6777,,,,,,,,,,
,99.413,42.0564,0.6768,,,,,,,,,,
,99.613,42.1409,0.6754,,,,,,,,,,
,99.813,42.2261,0.6752,,,,,,,,,,
,100.013,42.3109,0.674,,,,,,,,,,
,100.213,42.3952,0.6733,,,,,,,,,,
,100.413,42.4794,0.6722,,,,,,,,,,
,100.613,42.5641,0.6713,,,,,,,,,,
,100.813,42.6489,0.6707,,,,,,,,,,
,101.013,42.7336,0.6697,,,,,,,,,,
,101.213,42.8184,0.6693,,,,,,,,,,
,101.413,42.9033,0.6683,,,,,,,,,,
,101.613,42.9881,0.6679,,,,,,,,,,
,101.813,43.0727,0.6673,,,,,,,,,,
,102.013,43.1567,0.6664,,,,,,,,,,
,102.213,43.2414,0.6663,,,,,,,,,,
,102.413,43.3261,0.665,,,,,,,,,,
,102.613,43.4111,0.6653,,,,,,,,,,
,102.813,43.4957,0.6649,,,,,,,,,,
,103.013,43.5806,0.6656,,,,,,,,,,
,103.213,43.6656,0.6668,,,,,,,,,,
,103.413,43.75,0.668,,,,,,,,,,
,103.613,43.834,0.6705,,,,,,,,,,
,103.813,43.9187,0.6716,,,,,,,,,,
,104.013,44.0039,0.6736,,,,,,,,,,
,104.213,44.0883,0.6741,,,,,,,,,,
,104.413,44.1731,0.6748,,,,,,,,,,
,104.613,44.2581,0.6757,,,,,,,,,,
,104.813,44.343,0.6755,,,,,,,,,,
,105.013,44.427,0.6757,,,,,,,,,,
,105.213,44.5113,0.6752,,,,,,,,,,
,105.413,44.5961,0.6752,,,,,,,,,,
,105.613,44.6808,0.6752,,,,,,,,,,
,105.813,44.7657,0.6746,,,,,,,,,,
,106.013,44.8505,0.6747,,,,,,,,,,
,106.213,44.9354,0.6737,,,,,,,,,,
,106.413,45.0202,0.6739,,,,,,,,,,
,106.613,45.1046,0.6732,,,,,,,,,,
,106.813,45.1888,0.6726,,,,,,,,,,
,107.013,45.2732,0.6724,,,,,,,,,,
,107.213,45.3584,0.6717,,,,,,,,,,
,107.413,45.4433,0.6717,,,,,,,,,,
,107.613,45.528,0.6706,,,,,,,,,,
,107.813,45.6126,0.6706,,,,,,,,,,
,108.013,45.6976,0.6706,,,,,,,,,,
,108.213,45.7818,0.67,,,,,,,,,,
,108.413,45.8657,0.6696,,,,,,,,,,
,108.613,45.9506,0.669,,,,,,,,,,
,108.813,46.0358,0.669,,,,,,,,,,
,109.013,46.1205,0.6685,,,,,,,,,,
,109.213,46.205,0.668,,,,,,,,,,
,109.413,46.2898,0.6677,,,,,,,,,,
,109.613,46.375,0.6673,,,,,,,,,,
,109.813,46.459,0.6671,,,,,,,,,,
,110.013,46.5432,0.666,,,,,,,,,,
,110.213,46.628,0.6661,,,,,,,,,,
,110.413,46.7132,0.6654,,,,,,,,,,
,110.613,46.7978,0.6652,,,,,,,,,,
,110.813,46.8824,0.6647,,,,,,,,,,
,111.013,46.9674,0.6641,,,,,,,,,,
,111.213,47.052,0.6643,,,,,,,,,,
,111.413,47.1363,0.6636,,,,,,,,,,
,111.613,47.2207,0.663,,,,,,,,,,
,111.813,47.3054,0.6628,,,,,,,,,,
,112.013,47.3903,0.6621,,,,,,,,,,
,112.213,47.475,0.6621,,,,,,,,,,
,112.413,47.5596,0.6608,,,,,,,,,,
,112.613,47.6444,0.6611,,,,,,,,,,
,112.813,47.7295,0.6609,,,,,,,,,,
,113.013,47.8137,0.6605,,,,,,,,,,
,113.213,47.8979,0.66,,,,,,,,,,
,113.413,47.9826,0.6593,,,,,,,,,,
,113.613,48.0678,0.6597,,,,,,,,,,
,113.813,48.1524,0.659,,,,,,,,,,
,114.013,48.2367,0.6589,,,,,,,,,,
,114.213,48.3222,0.6589,,,,,,,,,,
,114.413,48.4067,0.6583,,,,,,,,,,
,114.613,48.491,0.6585,,,,,,,,,,
,114.813,48.5754,0.6578,,,,,,,,,,
,115.013,48.6602,0.6579,,,,,,,,,,
,115.213,48.7449,0.6577,,,,,,,,,,
,115.413,48.8296,0.6573,,,,,,,,,,
,115.613,48.9144,0.6575,,,,,,,,,,
,115.813,48.9992,0.6567,,,,,,,,,,
,116.013,49.0842,0.6575,,,,,,,,,,
,116.213,49.1682,0.6568,,,,,,,,,,
,116.413,49.2525,0.6565,,,,,,,,,,
,116.613,49.3373,0.6565,,,,,,,,,,
,116.813,49.4222,0.6562,,,,,,,,,,
,117.013,49.507,0.6564,,,,,,,,,,
,117.213,49.5914,0.6558,,,,,,,,,,
,117.413,49.6767,0.656,,,,,,,,,,
,117.613,49.7612,0.6558,,,,,,,,,,
,117.813,49.8458,0.6553,,,,,,,,,,
,118.013,49.93,0.6554,,,,,,,,,,
,118.213,50.0146,0.6552,,,,,,,,,,
,118.413,50.0997,0.6554,,,,,,,,,,
,118.613,50.1844,0.6551,,,,,,,,,,
,118.813,50.269,0.6552,,,,,,,,,,
,119.013,50.354,0.6554,,,,,,,,,,
,119.213,50.4389,0.6553,,,,,,,,,,
,119.413,50.5229,0.6555,,,,,,,,,,
,119.613,50.6071,0.6548,,,,,,,,,,
,119.813,50.6922,0.6556,,,,,,,,,,
,120.013,50.7768,0.656,,,,,,,,,,
,120.213,50.8617,0.6571,,,,,,,,,,
,120.413,50.9464,0.6569,,,,,,,,,,
,120.613,51.0313,0.6574,,,,,,,,,,
,120.813,51.116,0.6579,,,,,,,,,,
,121.013,51.2004,0.6581,,,,,,,,,,
,121.213,51.2848,0.6587,,,,,,,,,,
,121.413,51.3694,0.6581,,,,,,,,,,
,121.613,51.4544,0.6589,,,,,,,,,,
,121.813,51.5392,0.6586,,,,,,,,,,
,122.013,51.6238,0.659,,,,,,,,,,
,122.213,51.7087,0.6589,,,,,,,,,,
,122.413,51.7935,0.659,,,,,,,,,,
,122.613,51.8777,0.6592,,,,,,,,,,
,122.813,51.9619,0.6587,,,,,,,,,,
,123.013,52.0469,0.6594,,,,,,,,,,
,123.213,52.1318,0.659,,,,,,,,,,
,123.413,52.2164,0.6592,,,,,,,,,,
,123.613,52.301,0.6591,,,,,,,,,,
,123.813,52.3861,0.6594,,,,,,,,,,
,124.013,52.4708,0.6595,,,,,,,,,,
,124.213,52.5548,0.6592,,,,,,,,,,
,124.413,52.6393,0.6598,,,,,,,,,,
,124.613,52.7242,0.6592,,,,,,,,,,
,124.813,52.809,0.6599,,,,,,,,,,
,125.013,52.8935,0.6593,,,,,,,,,,
,125.213,52.9786,0.6598,,,,,,,,,,
,125.413,53.0634,0.6598,,,,,,,,,,
,125.613,53.1481,0.66,,,,,,,,,,
,125.813,53.2323,0.6601,,,,,,,,,,
,126.013,53.3169,0.6597,,,,,,,,,,
,126.213,53.4015,0.6604,,,,,,,,,,
,126.413,53.4862,0.66,,,,,,,,,,
,126.613,53.5712,0.6606,,,,,,,,,,
,126.813,53.6558,0.6601,,,,,,,,,,
,127.013,53.7407,0.6606,,,,,,,,,,
,127.213,53.8256,0.6605,,,,,,,,,,
,127.413,53.9098,0.6606,,,,,,,,,,
,127.613,53.994,0.6606,,,,,,,,,,
,127.813,54.0787,0.6605,,,,,,,,,,
,128.013,54.1638,0.661,,,,,,,,,,
,128.213,54.2483,0.6608,,,,,,,,,,
,128.413,54.3329,0.6613,,,,,,,,,,
,128.613,54.4182,0.6613,,,,,,,,,,
,128.813,54.5029,0.6614,,,,,,,,,,
,129.013,54.5869,0.6613,,,,,,,,,,
,129.213,54.6714,0.6613,,,,,,,,,,
,129.413,54.7562,0.6616,,,,,,,,,,
,129.613,54.8408,0.6616,,,,,,,,,,
,129.813,54.9258,0.6624,,,,,,,,,,
,130.013,55.0108,0.662,,,,,,,,,,
,130.213,55.0956,0.6627,,,,,,,,,,
,130.413,55.1802,0.6627,,,,,,,,,,
,130.613,55.2643,0.6626,,,,,,,,,,
,130.813,55.3487,0.663,,,,,,,,,,
,131.013,55.4333,0.6628,,,,,,,,,,
,131.213,55.5183,0.6638,,,,,,,,,,
,131.413,55.6032,0.6634,,,,,,,,,,
,131.613,55.6878,0.6641,,,,,,,,,,
,131.813,55.7729,0.6638,,,,,,,,,,
,132.013,55.8574,0.6643,,,,,,,,,,
,132.213,55.9416,0.6642,,,,,,,,,,
,132.413,56.0259,0.6644,,,,,,,,,,
,132.613,56.1107,0.6649,,,,,,,,,,
,132.813,56.1957,0.6649,,,,,,,,,,
,133.013,56.2807,0.6656,,,,,,,,,,
,133.213,56.3651,0.6656,,,,,,,,,,
,133.413,56.4501,0.6661,,,,,,,,,,
,133.613,56.5349,0.6662,,,,,,,,,,
,133.813,56.6187,0.6662,,,,,,,,,,
,134.013,56.7032,0.6668,,,,,,,,,,
,134.213,56.7882,0.6666,,,,,,,,,,
,134.413,56.8731,0.6672,,,,,,,,,,
,134.613,56.9577,0.6668,,,,,,,,,,
,134.813,57.0424,0.6676,,,,,,,,,,
,135.013,57.1275,0.6676,,,,,,,,,,
,135.213,57.212,0.6679,,,,,,,,,,
,135.413,57.2961,0.6682,,,,,,,,,,
,135.613,57.3805,0.668,,,,,,,,,,
,135.813,57.4655,0.6686,,,,,,,,,,
,136.013,57.5503,0.6684,,,,,,,,,,
,136.213,57.635,0.6691,,,,,,,,,,
,136.413,57.7197,0.6689,,,,,,,,,,
,136.613,57.8045,0.669,,,,,,,,,,
,136.813,57.8895,0.6696,,,,,,,,,,
,137.013,57.9734,0.6696,,,,,,,,,,
,137.213,58.0579,0.6698,,,,,,,,,,
,137.413,58.1428,0.6695,,,,,,,,,,
,137.613,58.2278,0.6701,,,,,,,,,,
,137.813,58.3123,0.6695,,,,,,,,,,
,138.013,58.397,0.6701,,,,,,,,,,
,138.213,58.4822,0.6704,,,,,,,,,,
,138.413,58.5667,0.6703,,,,,,,,,,
,138.613,58.6508,0.6707,,,,,,,,,,
,138.813,58.7352,0.6698,,,,,,,,,,
,139.013,58.8202,0.6705,,,,,,,,,,
,139.213,58.905,0.6702,,,,,,,,,,
,139.413,58.9895,0.6703,,,,,,,,,,
,139.613,59.0746,0.6702,,,,,,,,,,
,139.813,59.1591,0.6702,,,,,,,,,,
,140.013,59.244,0.6703,,,,,,,,,,
,140.213,59.328,0.6698,,,,,,,,,,
,140.413,59.4126,0.6702,,,,,,,,,,
,140.613,59.4974,0.67,,,,,,,,,,
,140.813,59.5823,0.6707,,,,,,,,,,
,141.013,59.6671,0.6702,,,,,,,,,,
,141.213,59.7518,0.6705,,,,,,,,,,
,141.413,59.8368,0.6704,,,,,,,,,,
,141.613,59.9214,0.6706,,,,,,,,,,
,141.813,60.0057,0.6704,,,,,,,,,,
,142.013,60.0898,0.6704,,,,,,,,,,
,142.213,60.1748,0.6709,,,,,,,,,,
,142.413,60.2598,0.6705,,,,,,,,,,
,142.613,60.3444,0.671,,,,,,,,,,
,142.813,60.4291,0.6704,,,,,,,,,,
,143.013,60.5139,0.671,,,,,,,,,,
,143.213,60.5988,0.6708,,,,,,,,,,
,143.413,60.6827,0.671,,,,,,,,,,
,143.613,60.7671,0.6708,,,,,,,,,,
,143.813,60.8523,0.6708,,,,,,,,,,
,144.013,60.937,0.6712,,,,,,,,,,
,144.213,61.0217,0.6706,,,,,,,,,,
,144.413,61.1065,0.6711,,,,,,,,,,
,144.613,61.1915,0.671,,,,,,,,,,
,144.813,61.2759,0.6712,,,,,,,,,,
,145.013,61.3601,0.6709,,,,,,,,,,
,145.213,61.4446,0.6711,,,,,,,,,,
,145.413,61.5294,0.671,,,,,,,,,,
,145.613,61.6144,0.671,,,,,,,,,,
,145.813,61.6993,0.6717,,,,,,,,,,
,146.013,61.784,0.6714,,,,,,,,,,
,146.213,61.8688,0.6721,,,,,,,,,,
,146.413,61.9534,0.6717,,,,,,,,,,
,146.613,62.0376,0.6719,,,,,,,,,,
,146.813,62.1219,0.672,,,,,,,,,,
,147.013,62.207,0.6721,,,,,,,,,,
,147.213,62.2919,0.6724,,,,,,,,,,
,147.413,62.3763,0.672,,,,,,,,,,
,147.613,62.461,0.6729,,,,,,,,,,
,147.813,62.5461,0.6727,,,,,,,,,,
,148.013,62.6307,0.6732,,,,,,,,,,
,148.213,62.7146,0.6727,,,,,,,,,,
,148.413,62.7992,0.6732,,,,,,,,,,
,148.613,62.8844,0.6736,,,,,,,,,,
,148.813,62.969,0.6732,,,,,,,,,,
,149.013,63.0536,0.674,,,,,,,,,,
,149.213,63.1387,0.6732,,,,,,,,,,
,149.413,63.2236,0.6742,,,,,,,,,,
,149.613,63.308,0.6741,,,,,,,,,,
,149.813,63.3922,0.6738,,,,,,,,,,
,150.013,63.477,0.674,,,,,,,,,,
,150.213,63.5616,0.6739,,,,,,,,,,
,150.413,63.6463,0.6744,,,,,,,,,,
,150.613,63.7311,0.6741,,,,,,,,,,
,150.813,63.8158,0.6741,,,,,,,,,,
,151.013,63.9009,0.6741,,,,,,,,,,
,151.213,63.9853,0.6745,,,,,,,,,,
,151.413,64.0696,0.6746,,,,,,,,,,
,151.613,64.1539,0.6741,,,,,,,,,,
,151.813,64.2387,0.6748,,,,,,,,,,
,152.013,64.3238,0.6745,,,,,,,,,,
,152.213,64.4082,0.6744,,,,,,,,,,
,152.413,64.4931,0.6747,,,,,,,,,,
,152.613,64.5784,0.6748,,,,,,,,,,
,152.813,64.6629,0.6749,,,,,,,,,,
,153.013,64.7468,0.6744,,,,,,,,,,
,153.213,64.8314,0.6746,,,,,,,,,,
,153.413,64.9165,0.6747,,,,,,,,,,
,153.613,65.001,0.6747,,,,,,,,,,
,153.813,65.0856,0.6749,,,,,,,,,,
,154.013,65.1708,0.6748,,,,,,,,,,
,154.213,65.2557,0.6755,,,,,,,,,,
,154.413,65.3399,0.6749,,,,,,,,,,
,154.613,65.424,0.6751,,,,,,,,,,
,154.813,65.5086,0.6751,,,,,,,,,,
,155.013,65.5934,0.6747,,,,,,,,,,
,155.213,65.6783,0.6755,,,,,,,,,,
,155.413,65.7629,0.675,,,,,,,,,,
,155.613,65.8481,0.6751,,,,,,,,,,
,155.813,65.9329,0.6757,,,,,,,,,,
,156.013,66.0172,0.6753,,,,,,,,,,
,156.213,66.1015,0.6754,,,,,,,,,,
,156.413,66.1857,0.675,,,,,,,,,,
,156.613,66.2709,0.6755,,,,,,,,,,
,156.813,66.3558,0.6751,,,,,,,,,,
,157.013,66.4405,0.6755,,,,,,,,,,
,157.213,66.5254,0.6759,,,,,,,,,,
,157.413,66.6103,0.6758,,,,,,,,,,
,157.613,66.6946,0.6762,,,,,,,,,,
,157.813,66.7786,0.6757,,,,,,,,,,
,158.013,66.8632,0.6759,,,,,,,,,,
,158.213,66.9483,0.6758,,,,,,,,,,
,158.413,67.0332,0.6759,,,,,,,,,,
,158.613,67.1175,0.676,,,,,,,,,,
,158.813,67.2026,0.6757,,,,,,,,,,
,159.013,67.2876,0.6765,,,,,,,,,,
,159.213,67.3716,0.6758,,,,,,,,,,
,159.413,67.4559,0.6761,,,,,,,,,,
,159.613,67.5403,0.6758,,,,,,,,,,
,159.813,67.6256,0.6759,,,,,,,,,,
,160.013,67.7102,0.6761,,,,,,,,,,
,160.213,67.7951,0.6757,,,,,,,,,,
,160.413,67.8801,0.6762,,,,,,,,,,
,160.613,67.9648,0.6761,,,,,,,,,,
,160.813,68.0491,0.6763,,,,,,,,,,
,161.013,68.1334,0.676,,,,,,,,,,
,161.213,68.2181,0.6762,,,,,,,,,,
,161.413,68.3028,0.6764,,,,,,,,,,
,161.613,68.3878,0.6763,,,,,,,,,,
,161.813,68.4724,0.6767,,,,,,,,,,
,162.013,68.5571,0.6765,,,,,,,,,,
,162.213,68.6424,0.677,,,,,,,,,,
,162.413,68.7263,0.6768,,,,,,,,,,
,162.613,68.8106,0.6768,,,,,,,,,,
,162.813,68.8951,0.677,,,,,,,,,,
,163.013,68.9803,0.6767,,,,,,,,,,
,163.213,69.0649,0.6771,,,,,,,,,,
,163.413,69.1495,0.6771,,,,,,,,,,
,163.613,69.2346,0.6776,,,,,,,,,,
,163.813,69.3196,0.6773,,,,,,,,,,
,164.013,69.4039,0.6773,,,,,,,,,,
,164.213,69.488,0.6771,,,,,,,,,,
,164.413,69.5727,0.6772,,,,,,,,,,
,164.613,69.6575,0.6774,,,,,,,,,,
,164.813,69.7423,0.6773,,,,,,,,,,
,165.013,69.8272,0.6779,,,,,,,,,,
,165.213,69.912,0.6774,,,,,,,,,,
,165.413,69.997,0.6779,,,,,,,,,,
,165.613,70.0811,0.6773,,,,,,,,,,
,165.813,70.1654,0.6774,,,,,,,,,,
,166.013,70.2497,0.6773,,,,,,,,,,
,166.213,70.3348,0.6777,,,,,,,,,,
,166.413,70.4197,0.6777,,,,,,,,,,
,166.613,70.5042,0.6776,,,,,,,,,,
,166.813,70.5892,0.6774,,,,,,,,,,
,167.013,70.6742,0.6776,,,,,,,,,,
,167.213,70.7586,0.6776,,,,,,,,,,
,167.413,70.8425,0.6773,,,,,,,,,,
,167.613,70.9273,0.6776,,,,,,,,,,
,167.813,71.0123,0.6776,,,,,,,,,,
,168.013,71.0972,0.678,,,,,,,,,,
,168.213,71.1818,0.6777,,,,,,,,,,
,168.413,71.2668,0.6782,,,,,,,,,,
,168.613,71.3517,0.6779,,,,,,,,,,
,168.813,71.4358,0.6785,,,,,,,,,,
,169.013,71.52,0.6778,,,,,,,,,,
,169.213,71.6048,0.6784,,,,,,,,,,
,169.413,71.6896,0.678,,,,,,,,,,
,169.613,71.7745,0.6787,,,,,,,,,,
,169.813,71.8592,0.6786,,,,,,,,,,
,170.013,71.944,0.6791,,,,,,,,,,
,170.213,72.0287,0.6791,,,,,,,,,,
,170.413,72.1131,0.6796,,,,,,,,,,
,170.613,72.1973,0.6796,,,,,,,,,,
,170.813,72.2818,0.6792,,,,,,,,,,
,171.013,72.3669,0.6801,,,,,,,,,,
,171.213,72.452,0.68,,,,,,,,,,
,171.413,72.5364,0.6805,,,,,,,,,,
,171.613,72.6213,0.6805,,,,,,,,,,
,171.813,72.7064,0.6812,,,,,,,,,,
,172.013,72.7905,0.6807,,,,,,,,,,
,172.213,72.8747,0.6812,,,,,,,,,,
,172.413,72.9594,0.681,,,,,,,,,,
,172.613,73.0446,0.6815,,,,,,,,,,
,172.813,73.1291,0.6813,,,,,,,,,,
,173.013,73.2137,0.6817,,,,,,,,,,
,173.213,73.2988,0.6821,,,,,,,,,,
,173.413,73.3835,0.6821,,,,,,,,,,
,173.613,73.4677,0.6826,,,,,,,,,,
,173.813,73.552,0.6822,,,,,,,,,,
,174.013,73.6368,0.683,,,,,,,,,,
,174.213,73.7215,0.6826,,,,,,,,,,
,174.413,73.8063,0.6831,,,,,,,,,,
,174.613,73.8912,0.6829,,,,,,,,,,
,174.813,73.9758,0.6832,,,,,,,,,,
,175.013,74.0609,0.6837,,,,,,,,,,
,175.213,74.1453,0.6837,,,,,,,,,,
,175.413,74.2297,0.6842,,,,,,,,,,
,175.613,74.3139,0.6835,,,,,,,,,,
,175.813,74.3989,0.6842,,,,,,,,,,
,176.013,74.4838,0.6841,,,,,,,,,,
,176.213,74.5683,0.6844,,,,,,,,,,
,176.413,74.6533,0.6845,,,,,,,,,,
,176.613,74.7383,0.6849,,,,,,,,,,
,176.813,74.8227,0.6845,,,,,,,,,,
,177.013,74.9067,0.6846,,,,,,,,,,
,177.213,74.9911,0.6845,,,,,,,,,,
,177.413,75.0764,0.6845,,,,,,,,,,
,177.613,75.161,0.6848,,,,,,,,,,
,177.813,75.2456,0.6847,,,,,,,,,,
,178.013,75.3306,0.6848,,,,,,,,,,
,178.213,75.4159,0.6848,,,,,,,,,,
,178.413,75.4998,0.6848,,,,,,,,,,
,178.613,75.5839,0.6845,,,,,,,,,,
,178.813,75.6688,0.6845,,,,,,,,,,
,179.013,75.7534,0.6845,,,,,,,,,,
,179.213,75.8383,0.6848,,,,,,,,,,
,179.413,75.9232,0.6846,,,,,,,,,,
,179.613,76.0082,0.6849,,,,,,,,,,
,179.813,76.0929,0.6848,,,,,,,,,,
,180.013,76.1771,0.6849,,,,,,,,,,
,180.213,76.2613,0.6845,,,,,,,,,,
,180.413,76.3458,0.6848,,,,,,,,,,
,180.613,76.431,0.6845,,,,,,,,,,
,180.813,76.5158,0.6851,,,,,,,,,,
,181.013,76.6005,0.6845,,,,,,,,,,
,181.213,76.6853,0.6851,,,,,,,,,,
,181.413,76.7702,0.6849,,,,,,,,,,
,181.613,76.8544,0.685,,,,,,,,,,
,181.813,76.9383,0.6848,,,,,,,,,,
,182.013,77.0233,0.685,,,,,,,,,,
,182.213,77.1082,0.6852,,,,,,,,,,
,182.413,77.193,0.6854,,,,,,,,,,
,182.613,77.2776,0.6854,,,,,,,,,,
,182.813,77.3628,0.6853,,,,,,,,,,
,183.013,77.4476,0.6856,,,,,,,,,,
,183.213,77.5316,0.6851,,,,,,,,,,
,183.413,77.6158,0.6856,,,,,,,,,,
,183.613,77.7007,0.6851,,,,,,,,,,
,183.813,77.7857,0.6855,,,,,,,,,,
,184.013,77.8702,0.6849,,,,,,,,,,
,184.213,77.9552,0.6855,,,,,,,,,,
,184.413,78.04,0.6851,,,,,,,,,,
,184.613,78.1248,0.6853,,,,,,,,,,
,184.813,78.2089,0.6851,,,,,,,,,,
,185.013,78.293,0.6851,,,,,,,,,,
,185.213,78.378,0.6854,,,,,,,,,,
,185.413,78.4626,0.6852,,,,,,,,,,
,185.613,78.5477,0.6856,,,,,,,,,,
,185.813,78.6324,0.685,,,,,,,,,,
,186.013,78.7172,0.6854,,,,,,,,,,
,186.213,78.8021,0.6852,,,,,,,,,,
,186.413,78.8864,0.6854,,,,,,,,,,
,186.613,78.9705,0.6849,,,,,,,,,,
,186.813,79.0551,0.6851,,,,,,,,,,
,187.013,79.1404,0.6853,,,,,,,,,,
,187.213,79.225,0.6852,,,,,,,,,,
,187.413,79.3095,0.6853,,,,,,,,,,
,187.613,79.3949,0.6857,,,,,,,,,,
,187.813,79.4795,0.6858,,,,,,,,,,
,188.013,79.5636,0.6854,,,,,,,,,,
,188.213,79.6478,0.6859,,,,,,,,,,
,188.413,79.7328,0.6856,,,,,,,,,,
,188.613,79.8175,0.6859,,,,,,,,,,
,188.813,79.9024,0.6856,,,,,,,,,,
,189.013,79.9873,0.6859,,,,,,,,,,
,189.213,80.0721,0.6859,,,,,,,,,,
,189.413,80.1568,0.6862,,,,,,,,,,
,189.613,80.241,0.686,,,,,,,,,,
,189.813,80.3252,0.6862,,,,,,,,,,
,190.013,80.4099,0.6865,,,,,,,,,,
,190.213,80.4949,0.6862,,,,,,,,,,
,190.413,80.5797,0.6867,,,,,,,,,,
,190.613,80.6644,0.6864,,,,,,,,,,
,190.813,80.7494,0.687,,,,,,,,,,
,191.013,80.8342,0.6868,,,,,,,,,,
,191.213,80.9185,0.6869,,,,,,,,,,
,191.413,81.0024,0.6866,,,,,,,,,,
,191.613,81.0873,0.6869,,,,,,,,,,
,191.813,81.1725,0.6867,,,,,,,,,,
,192.013,81.2571,0.6872,,,,,,,,,,
,192.213,81.3419,0.6869,,,,,,,,,,
,192.413,81.427,0.6872,,,,,,,,,,
,192.613,81.5117,0.687,,,,,,,,,,
,192.813,81.5954,0.687,,,,,,,,,,
,193.013,81.6799,0.687,,,,,,,,,,
,193.213,81.7648,0.6869,,,,,,,,,,
,193.413,81.8497,0.6872,,,,,,,,,,
,193.613,81.9343,0.6871,,,,,,,,,,
,193.813,82.0192,0.6872,,,,,,,,,,
,194.013,82.1041,0.6874,,,,,,,,,,
,194.213,82.1886,0.6872,,,,,,,,,,
,194.413,82.273,0.687,,,,,,,,,,
,194.613,82.3573,0.6875,,,,,,,,,,
,194.813,82.442,0.6871,,,,,,,,,,
,195.013,82.5271,0.6876,,,,,,,,,,
,195.213,82.612,0.6872,,,,,,,,,,
,195.413,82.6966,0.6878,,,,,,,,,,
,195.613,82.7814,0.6871,,,,,,,,,,
,195.813,82.8662,0.6878,,,,,,,,,,
,196.013,82.9503,0.6872,,,,,,,,,,
,196.213,83.0346,0.6878,,,,,,,,,,
,196.413,83.1194,0.6872,,,,,,,,,,
,196.613,83.2046,0.688,,,,,,,,,,
,196.813,83.289,0.6873,,,,,,,,,,
,197.013,83.3738,0.6881,,,,,,,,,,
,197.213,83.4589,0.6875,,,,,,,,,,
,197.413,83.5433,0.688,,,,,,,,,,
,197.613,83.6276,0.6876,,,,,,,,,,
,197.813,83.712,0.6879,,,,,,,,,,
,198.013,83.797,0.6878,,,,,,,,,,
,198.213,83.8816,0.6879,,,,,,,,,,
,198.413,83.9663,0.6881,,,,,,,,,,
,198.613,84.0512,0.6884,,,,,,,,,,
,198.813,84.1361,0.6882,,,,,,,,,,
,199.013,84.2207,0.6886,,,,,,,,,,
,199.213,84.305,0.6883,,,,,,,,,,
,199.413,84.3895,0.6886,,,,,,,,,,
,199.613,84.4741,0.6884,,,,,,,,,,
,199.813,84.559,0.6887,,,,,,,,,,
,200.013,84.6438,0.6883,,,,,,,,,,
,200.213,84.7285,0.6883,,,,,,,,,,
,200.413,84.8135,0.6885,,,,,,,,,,
,200.613,84.898,0.6886,,,,,,,,,,
,200.813,84.9826,0.6886,,,,,,,,,,
,201.013,85.0666,0.6884,,,,,,,,,,
,201.213,85.1513,0.6884,,,,,,,,,,
,201.413,85.2364,0.6883,,,,,,,,,,
,201.613,85.3209,0.6883,,,,,,,,,,
,201.813,85.4056,0.6884,,,,,,,,,,
,202.013,85.4908,0.6887,,,,,,,,,,
,202.213,85.5757,0.6886,,,,,,,,,,
,202.413,85.6595,0.6883,,,,,,,,,,
,202.613,85.7437,0.6878,,,,,,,,,,
,202.813,85.8289,0.6881,,,,,,,,,,
,203.013,85.9136,0.6882,,,,,,,,,,
,203.213,85.9982,0.6881,,,,,,,,,,
,203.413,86.0832,0.6882,,,,,,,,,,
,203.613,86.1684,0.6882,,,,,,,,,,
,203.813,86.2526,0.6881,,,,,,,,,,
,204.013,86.3369,0.6882,,,,,,,,,,
,204.213,86.4214,0.6878,,,,,,,,,,
,204.413,86.5059,0.6879,,,,,,,,,,
,204.613,86.5911,0.6877,,,,,,,,,,
,204.813,86.6755,0.688,,,,,,,,,,
,205.013,86.7605,0.688,,,,,,,,,,
,205.213,86.8454,0.6882,,,,,,,,,,
,205.413,86.9301,0.6876,,,,,,,,,,
,205.613,87.0142,0.6882,,,,,,,,,,
,205.813,87.0984,0.6873,,,,,,,,,,
,206.013,87.1834,0.6882,,,,,,,,,,
,206.213,87.2683,0.6877,,,,,,,,,,
,206.413,87.3532,0.6882,,,,,,,,,,
,206.613,87.4377,0.6877,,,,,,,,,,
,206.813,87.5229,0.6882,,,,,,,,,,
,207.013,87.6074,0.6879,,,,,,,,,,
,207.213,87.6914,0.6882,,,,,,,,,,
,207.413,87.776,0.6876,,,,,,,,,,
,207.613,87.8606,0.6881,,,,,,,,,,
,207.813,87.9458,0.688,,,,,,,,,,
,208.013,88.0301,0.6881,,,,,,,,,,
,208.213,88.1153,0.688,,,,,,,,,,
,208.413,88.2002,0.6886,,,,,,,,,,
,208.613,88.2846,0.6884,,,,,,,,,,
,208.813,88.3688,0.6885,,,,,,,,,,
,209.013,88.4532,0.6881,,,,,,,,,,
,209.213,88.5382,0.6889,,,,,,,,,,
,209.413,88.6228,0.6882,,,,,,,,,,
,209.613,88.7078,0.6889,,,,,,,,,,
,209.813,88.7924,0.6884,,,,,,,,,,
,210.013,88.8774,0.689,,,,,,,,,,
,210.213,88.9619,0.6888,,,,,,,,,,
,210.413,89.0462,0.6893,,,,,,,,,,
,210.613,89.1307,0.6889,,,,,,,,,,
,210.813,89.2151,0.6891,,,,,,,,,,
,211.013,89.3005,0.6892,,,,,,,,,,
,211.213,89.385,0.6894,,,,,,,,,,
,211.413,89.4697,0.6892,,,,,,,,,,
,211.613,89.555,0.6897,,,,,,,,,,
,211.813,89.6396,0.6897,,,,,,,,,,
,212.013,89.7234,0.6896,,,,,,,,,,
,212.213,89.8078,0.6896,,,,,,,,,,
,212.413,89.8929,0.6896,,,,,,,,,,
,212.613,89.9776,0.6899,,,,,,,,,,
,212.813,90.0621,0.6895,,,,,,,,,,
,213.013,90.1471,0.6901,,,,,,,,,,
,213.213,90.2321,0.6896,,,,,,,,,,
,213.413,90.3166,0.6902,,,,,,,,,,
,213.613,90.4009,0.6896,,,,,,,,,,
,213.813,90.4853,0.6899,,,,,,,,,,
,214.013,90.57,0.6895,,,,,,,,,,
,214.213,90.655,0.6899,,,,,,,,,,
,214.413,90.7399,0.6898,,,,,,,,,,
,214.613,90.8247,0.6897,,,,,,,,,,
,214.813,90.9097,0.6898,,,,,,,,,,
,215.013,90.9942,0.6898,,,,,,,,,,
,215.213,91.0782,0.6893,,,,,,,,,,
,215.413,91.1625,0.6898,,,,,,,,,,
,215.613,91.2475,0.6894,,,,,,,,,,
,215.813,91.3325,0.6896,,,,,,,,,,
,216.013,91.417,0.6895,,,,,,,,,,
,216.213,91.5017,0.6895,,,,,,,,,,
,216.413,91.5869,0.6895,,,,,,,,,,
,216.613,91.6714,0.6893,,,,,,,,,,
,216.813,91.7553,0.6891,,,,,,,,,,
,217.013,91.8399,0.689,,,,,,,,,,
,217.213,91.9248,0.6893,,,,,,,,,,
,217.413,92.0097,0.6891,,,,,,,,,,
,217.613,92.0943,0.6891,,,,,,,,,,
,217.813,92.1795,0.6888,,,,,,,,,,
,218.013,92.2643,0.6892,,,,,,,,,,
,218.213,92.3485,0.6886,,,,,,,,,,
,218.413,92.4329,0.6889,,,,,,,,,,
,218.613,92.5173,0.6885,,,,,,,,,,
,218.813,92.6022,0.689,,,,,,,,,,
,219.013,92.6871,0.6885,,,,,,,,,,
,219.213,92.772,0.6891,,,,,,,,,,
,219.413,92.8566,0.6887,,,,,,,,,,
,219.613,92.9415,0.6892,,,,,,,,,,
,219.813,93.026,0.6886,,,,,,,,,,
,220.013,93.11,0.6891,,,,,,,,,,
,220.213,93.1946,0.6884,,,,,,,,,,
,220.413,93.2797,0.6892,,,,,,,,,,
,220.613,93.3647,0.6886,,,,,,,,,,
,220.813,93.4491,0.689,,,,,,,,,,
,221.013,93.5338,0.6889,,,,,,,,,,
,221.213,93.6189,0.6895,,,,,,,,,,
,221.413,93.7033,0.6888,,,,,,,,,,
,221.613,93.7873,0.6889,,,,,,,,,,
,221.813,93.8719,0.6885,,,,,,,,,,
,222.013,93.9571,0.6892,,,,,,,,,,
,222.213,94.0417,0.689,,,,,,,,,,
,222.413,94.1263,0.6893,,,,,,,,,,
,222.613,94.2113,0.6889,,,,,,,,,,
,222.813,94.2962,0.6894,,,,,,,,,,
,223.013,94.3806,0.689,,,,,,,,,,
,223.213,94.4647,0.6892,,,,,,,,,,
,223.413,94.5495,0.6892,,,,,,,,,,
,223.613,94.6343,0.6893,,,,,,,,,,
,223.813,94.719,0.689,,,,,,,,,,
,224.013,94.8038,0.6894,,,,,,,,,,
,224.213,94.8884,0.689,,,,,,,,,,
,224.413,94.9734,0.6897,,,,,,,,,,
,224.613,95.0579,0.6892,,,,,,,,,,
,224.813,95.1422,0.6896,,,,,,,,,,
,225.013,95.2266,0.6892,,,,,,,,,,
,225.213,95.3114,0.6896,,,,,,,,,,
,225.413,95.3964,0.6891,,,,,,,,,,
,225.613,95.481,0.6895,,,,,,,,,,
,225.813,95.5658,0.6891,,,,,,,,,,
,226.013,95.6508,0.6898,,,,,,,,,,
,226.213,95.7355,0.6894,,,,,,,,,,
,226.413,95.8192,0.6893,,,,,,,,,,
,226.613,95.9039,0.6889,,,,,,,,,,
,226.813,95.989,0.6892,,,,,,,,,,
,227.013,96.0736,0.689,,,,,,,,,,
,227.213,96.1583,0.6891,,,,,,,,,,
,227.413,96.2431,0.689,,,,,,,,,,
,227.613,96.3284,0.6893,,,,,,,,,,
,227.813,96.4124,0.6892,,,,,,,,,,
,228.013,96.4967,0.6893,,,,,,,,,,
,228.213,96.5814,0.689,,,,,,,,,,
,228.413,96.6661,0.6893,,,,,,,,,,
,228.613,96.7508,0.6893,,,,,,,,,,
,228.813,96.8357,0.6896,,,,,,,,,,
,229.013,96.9206,0.6893,,,,,,,,,,
,229.213,97.0054,0.6894,,,,,,,,,,
,229.413,97.0899,0.6895,,,,,,,,,,
,229.613,97.1741,0.6895,,,,,,,,,,
,229.813,97.2586,0.6895,,,,,,,,,,
,230.013,97.3437,0.6893,,,,,,,,,,
,230.213,97.4282,0.6896,,,,,,,,,,
,230.413,97.5131,0.6893,,,,,,,,,,
,230.613,97.5978,0.6896,,,,,,,,,,
,230.813,97.683,0.6896,,,,,,,,,,
,231.013,97.7673,0.6897,,,,,,,,,,
,231.213,97.8513,0.6892,,,,,,,,,,
,231.413,97.9359,0.69,,,,,,,,,,
,231.613,98.021,0.6896,,,,,,,,,,
,231.813,98.1057,0.69,,,,,,,,,,
,232.013,98.1901,0.6897,,,,,,,,,,
,232.213,98.2753,0.6903,,,,,,,,,,
,232.413,98.3601,0.6899,,,,,,,,,,
,232.613,98.4444,0.69,,,,,,,,,,
,232.813,98.5287,0.6898,,,,,,,,,,
,233.013,98.6133,0.6899,,,,,,,,,,
,233.213,98.6982,0.6903,,,,,,,,,,
,233.413,98.7828,0.6898,,,,,,,,,,
,233.613,98.8679,0.6904,,,,,,,,,,
,233.813,98.9524,0.69,,,,,,,,,,
,234.013,99.0375,0.6905,,,,,,,,,,
,234.213,99.1219,0.6902,,,,,,,,,,
,234.413,99.2061,0.6907,,,,,,,,,,
,234.613,99.2907,0.6902,,,,,,,,,,
,234.813,99.3756,0.6906,,,,,,,,,,
,235.013,99.4605,0.6904,,,,,,,,,,
,235.213,99.5449,0.6905,,,,,,,,,,
,235.413,99.6299,0.6905,,,,,,,,,,
,235.613,99.7148,0.6906,,,,,,,,,,
,235.813,99.7993,0.6908,,,,,,,,,,
,236.013,99.8832,0.6903,,,,,,,,,,
,236.213,99.9678,0.6908,,,,,,,,,,
,236.413,100.0531,0.6904,,,,,,,,,,
,236.613,100.1376,0.6909,,,,,,,,,,
,236.756,100.1987,0.6908,,,,,,,,,,