File: lab10/data/S1_LDPE_1.csv
Results Table 1,,,,,,,,,,,,,
,Specimen label,Thickness,Width,Length,Rate 1,,,,,,,,
,,(mm),(mm),(mm),(mm/min),,,,,,,,
1,LDPE-1,3.25,14.73,90.8,25.4,,,,,,,,
2,LDPE-5,3.25,14.73,87.88,127,,,,,,,,
3,LDPE-20,3.25,14.73,82.35,508,,,,,,,,
,,,,,,,,,,,,,
Results Table 2,,,,,,,,,,,,,
,,,,,,,,,,,,,
,,,,,,,,,,,,,
1,Time,Displacement,Force,,2,Time,Displacement,Force,,3,Time,Displacement,Force
,(s),(mm),(kN),,,(s),(mm),(kN),,,(s),(mm),(kN)
,0,0,-0.0088,,,0,0,-0.0072,,,0,0,-0.0055
,0.3,0.0996,0.0158,,,0.17,0.237,0.0535,,,0.078,0.2349,0.0593
,0.6,0.2268,0.0422,,,0.321,0.5659,0.1143,,,0.114,0.5328,0.1226
,0.9,0.3531,0.0636,,,0.513,0.9735,0.1744,,,0.159,0.8973,0.1845
,1.2,0.48,0.0835,,,0.746,1.4665,0.2346,,,0.208,1.3336,0.2461
,1.5,0.607,0.1017,,,1.028,2.0634,0.2939,,,0.271,1.8725,0.3067
,1.8,0.7344,0.1193,,,1.328,2.6985,0.3449,,,0.35,2.5394,0.3681
,2.1,0.8611,0.1356,,,1.628,3.3336,0.3858,,,0.455,3.4288,0.4291
,2.4,0.988,0.1503,,,1.928,3.9683,0.418,,,0.61,4.7413,0.4895
,2.7,1.1156,0.1648,,,2.228,4.6032,0.4439,,,0.886,7.0781,0.5424
,3,1.2417,0.1785,,,2.528,5.2382,0.4643,,,1.186,9.6182,0.5604
,3.3,1.3689,0.1916,,,2.828,5.8733,0.4802,,,1.486,12.1581,0.561
,3.6,1.4965,0.2042,,,3.128,6.5081,0.4924,,,1.786,14.698,0.5543
,3.9,1.6232,0.2158,,,3.428,7.1428,0.5019,,,2.086,17.2381,0.545
,4.2,1.7495,0.2272,,,3.728,7.7776,0.5088,,,2.386,19.778,0.5355
,4.5,1.8777,0.2386,,,4.028,8.4127,0.5142,,,2.686,22.3179,0.5271
,4.8,2.004,0.2489,,,4.328,9.0481,0.518,,,2.986,24.858,0.5203
,5.1,2.1308,0.2585,,,4.628,9.6831,0.52,,,3.286,27.3981,0.5155
,5.4,2.2586,0.2683,,,4.928,10.3181,0.5216,,,3.586,29.9381,0.5122
,5.7,2.385,0.2774,,,5.228,10.9527,0.522,,,3.886,32.4781,0.5088
,6,2.5121,0.2862,,,5.528,11.5881,0.5219,,,4.186,35.0181,0.5062
,6.3,2.6392,0.295,,,5.828,12.2234,0.5214,,,4.486,37.5579,0.5031
,6.6,2.7662,0.3028,,,6.128,12.8587,0.5207,,,4.786,40.0979,0.5001
,6.9,2.8931,0.3107,,,6.428,13.4935,0.5192,,,5.086,42.6381,0.4965
,7.2,3.0198,0.3184,,,6.728,14.1283,0.5175,,,5.386,45.1783,0.4921
,7.5,3.1476,0.3256,,,7.028,14.7631,0.5158,,,5.686,47.7181,0.4863
,7.8,3.2741,0.332,,,7.328,15.3982,0.5141,,,5.986,50.2582,0.4784
,8.1,3.4006,0.3389,,,7.628,16.0331,0.512,,,6.286,52.7982,0.4669
,8.4,3.5285,0.3454,,,7.928,16.668,0.51,,,6.586,55.3379,0.4482
,8.7,3.6553,0.3515,,,8.228,17.3028,0.5078,,,6.886,57.8778,0.4229
,9,3.7817,0.357,,,8.528,17.9376,0.5059,,,7.186,60.4181,0.411
,9.3,3.9097,0.3625,,,8.828,18.5727,0.5038,,,7.486,62.9581,0.4103
,9.6,4.0361,0.3679,,,9.128,19.2081,0.5019,,,7.786,65.498,0.4121
,9.9,4.1625,0.3731,,,9.428,19.843,0.5,,,8.086,68.038,0.4135
,10.2,4.2906,0.3783,,,9.728,20.4779,0.4979,,,8.386,70.5779,0.4147
,10.5,4.4172,0.3827,,,10.028,21.1131,0.4962,,,8.686,73.1179,0.4118
,10.8,4.5439,0.3872,,,10.328,21.7481,0.4945,,,8.813,74.1934,0.3525
,11.1,4.671,0.3918,,,10.628,22.3835,0.4928,,,8.826,74.3035,0.2818
,11.4,4.7982,0.3957,,,10.928,23.0185,0.4913,,,8.835,74.3797,0.1977
,11.7,4.9248,0.3996,,,11.228,23.6535,0.4898,,,8.844,74.4559,0.1173
,12,5.0521,0.4034,,,11.528,24.2882,0.4885,,,8.854,74.5406,0.0505
,12.3,5.1794,0.4071,,,11.828,24.923,0.4876,,,8.966,75.4886,-0.0004
,12.6,5.3061,0.4107,,,12.128,25.5582,0.4864,,,9.266,78.0288,-0.0008
,12.9,5.4327,0.414,,,12.428,26.193,0.4855,,,9.566,80.5688,-0.0009
,13.2,5.5606,0.4169,,,12.728,26.828,0.4846,,,9.866,83.1088,-0.0008
,13.5,5.6871,0.4201,,,13.028,27.4629,0.4838,,,10.166,85.6488,-0.0009
,13.8,5.8135,0.4229,,,13.328,28.0977,0.4832,,,10.466,88.1887,-0.0007
,14.1,5.9416,0.426,,,13.628,28.7327,0.4824,,,10.766,90.7286,-0.0007
,14.4,6.0679,0.4286,,,13.928,29.368,0.482,,,11.066,93.2687,-0.0007
,14.7,6.1949,0.4308,,,14.228,30.0031,0.4815,,,11.366,95.8088,-0.0008
,15,6.3225,0.4334,,,14.528,30.638,0.4811,,,,,
,15.3,6.4491,0.4356,,,14.828,31.2729,0.4807,,,,,
,15.6,6.5761,0.4381,,,15.128,31.9083,0.4803,,,,,
,15.9,6.7028,0.44,,,15.428,32.5432,0.4798,,,,,
,16.2,6.8306,0.4419,,,15.728,33.1786,0.4796,,,,,
,16.5,6.9569,0.4437,,,16.028,33.8134,0.4794,,,,,
,16.8,7.0838,0.4453,,,16.328,34.4481,0.4789,,,,,
,17.1,7.2115,0.4475,,,16.628,35.0831,0.4788,,,,,
,17.4,7.3381,0.449,,,16.928,35.7179,0.4784,,,,,
,17.7,7.4648,0.4505,,,17.228,36.3533,0.4781,,,,,
,18,7.5925,0.4522,,,17.528,36.9881,0.4779,,,,,
,18.3,7.7192,0.4533,,,17.828,37.6229,0.4775,,,,,
,18.6,7.8455,0.4547,,,18.128,38.2576,0.477,,,,,
,18.9,7.9738,0.4562,,,18.428,38.893,0.4766,,,,,
,19.2,8.1,0.4574,,,18.728,39.528,0.4765,,,,,
,19.5,8.2267,0.4581,,,19.028,40.1632,0.4761,,,,,
,19.8,8.3546,0.4592,,,19.328,40.798,0.4756,,,,,
,20.1,8.4811,0.4603,,,19.628,41.4328,0.4753,,,,,
,20.4,8.6083,0.4612,,,19.928,42.0678,0.475,,,,,
,20.7,8.735,0.4622,,,20.228,42.7035,0.4744,,,,,
,21,8.8622,0.4628,,,20.528,43.3384,0.4739,,,,,
,21.3,8.989,0.4637,,,20.828,43.9734,0.4734,,,,,
,21.6,9.1158,0.4645,,,21.128,44.6082,0.473,,,,,
,21.9,9.2436,0.4654,,,21.428,45.2431,0.4724,,,,,
,22.2,9.37,0.4658,,,21.728,45.8781,0.4718,,,,,
,22.5,9.4968,0.4663,,,22.028,46.5132,0.4713,,,,,
,22.8,9.6242,0.4671,,,22.328,47.1483,0.4705,,,,,
,23.1,9.7514,0.4675,,,22.628,47.7828,0.47,,,,,
,23.4,9.8776,0.4679,,,22.928,48.4178,0.4694,,,,,
,23.7,10.0055,0.4687,,,23.228,49.0528,0.4688,,,,,
,24,10.132,0.4686,,,23.528,49.6882,0.468,,,,,
,24.3,10.2587,0.4691,,,23.828,50.3231,0.4671,,,,,
,24.6,10.3864,0.4693,,,24.128,50.9579,0.4663,,,,,
,24.9,10.5132,0.4699,,,24.428,51.5927,0.4656,,,,,
,25.2,10.64,0.4701,,,24.728,52.2278,0.4647,,,,,
,25.5,10.767,0.4705,,,25.028,52.8631,0.4636,,,,,
,25.8,10.8945,0.4702,,,25.328,53.4985,0.4626,,,,,
,26.1,11.0212,0.4706,,,25.628,54.1334,0.4617,,,,,
,26.4,11.1477,0.4708,,,25.928,54.7684,0.4605,,,,,
,26.7,11.2756,0.4713,,,26.228,55.403,0.4594,,,,,
,27,11.402,0.4712,,,26.528,56.038,0.4582,,,,,
,27.3,11.5288,0.4711,,,26.828,56.6733,0.457,,,,,
,27.6,11.6567,0.4712,,,27.128,57.3082,0.4555,,,,,
,27.9,11.7833,0.4713,,,27.428,57.9431,0.4542,,,,,
,28.2,11.9095,0.4712,,,27.728,58.5777,0.4525,,,,,
,28.5,12.0377,0.4715,,,28.028,59.2128,0.4509,,,,,
,28.8,12.164,0.4713,,,28.328,59.8479,0.4493,,,,,
,29.1,12.2908,0.4712,,,28.628,60.4831,0.4476,,,,,
,29.4,12.4183,0.4712,,,28.928,61.1179,0.4453,,,,,
,29.7,12.5451,0.4712,,,29.228,61.7527,0.4431,,,,,
,30,12.6722,0.4711,,,29.528,62.3879,0.4411,,,,,
,30.3,12.799,0.4712,,,29.828,63.0231,0.4386,,,,,
,30.6,12.9264,0.4709,,,30.128,63.6585,0.4356,,,,,
,30.9,13.0531,0.4708,,,30.428,64.2935,0.4327,,,,,
,31.2,13.1797,0.4707,,,30.728,64.9283,0.4293,,,,,
,31.5,13.3074,0.4706,,,31.028,65.5631,0.4257,,,,,
,31.8,13.4342,0.4703,,,31.328,66.1982,0.4217,,,,,
,32.1,13.5605,0.4701,,,31.628,66.8332,0.4175,,,,,
,32.4,13.6885,0.4701,,,31.928,67.4683,0.4131,,,,,
,32.7,13.8151,0.4699,,,32.228,68.1029,0.4091,,,,,
,33,13.9417,0.4697,,,32.528,68.7378,0.4055,,,,,
,33.3,14.0697,0.4696,,,32.828,69.3726,0.4023,,,,,
,33.6,14.1961,0.4693,,,33.128,70.008,0.4003,,,,,
,33.9,14.3227,0.469,,,33.428,70.643,0.3989,,,,,
,34.2,14.4503,0.4689,,,33.728,71.2779,0.3979,,,,,
,34.5,14.5773,0.4685,,,34.028,71.9128,0.3972,,,,,
,34.8,14.7041,0.4683,,,34.328,72.5479,0.3973,,,,,
,35.1,14.8309,0.4682,,,34.628,73.1831,0.3975,,,,,
,35.4,14.9585,0.4678,,,34.928,73.8184,0.3978,,,,,
,35.7,15.0847,0.4674,,,35.228,74.4535,0.3982,,,,,
,36,15.2119,0.4673,,,35.528,75.0883,0.3985,,,,,
,36.3,15.3396,0.4672,,,35.828,75.7233,0.3992,,,,,
,36.6,15.466,0.467,,,36.128,76.3582,0.3993,,,,,
,36.9,15.5927,0.4663,,,36.428,76.9933,0.4,,,,,
,37.2,15.7204,0.4661,,,36.728,77.6281,0.4002,,,,,
,37.5,15.8472,0.4659,,,37.028,78.2629,0.4005,,,,,
,37.8,15.9737,0.4657,,,37.328,78.8976,0.4011,,,,,
,38.1,16.1015,0.4656,,,37.628,79.5327,0.4012,,,,,
,38.4,16.2282,0.4649,,,37.928,80.1679,0.4017,,,,,
,38.7,16.355,0.4644,,,38.228,80.8029,0.4018,,,,,
,39,16.4824,0.4645,,,38.528,81.4379,0.4023,,,,,
,39.3,16.6092,0.4643,,,38.828,82.073,0.4023,,,,,
,39.6,16.7362,0.4639,,,39.128,82.7079,0.4025,,,,,
,39.9,16.8628,0.4635,,,39.428,83.3429,0.4031,,,,,
,40.2,16.9907,0.4631,,,39.728,83.9786,0.4034,,,,,
,40.5,17.117,0.4628,,,40.028,84.6136,0.4035,,,,,
,40.8,17.2438,0.4627,,,40.328,85.2484,0.4039,,,,,
,41.1,17.3717,0.4624,,,40.628,85.883,0.4038,,,,,
,41.4,17.4982,0.462,,,40.928,86.5182,0.4043,,,,,
,41.7,17.6247,0.4616,,,41.228,87.1531,0.4046,,,,,
,42,17.7526,0.4616,,,41.528,87.7882,0.4048,,,,,
,42.3,17.8793,0.4611,,,41.828,88.4229,0.4053,,,,,
,42.6,18.0056,0.4604,,,42.128,89.0575,0.4057,,,,,
,42.9,18.1336,0.4603,,,42.428,89.6926,0.4059,,,,,
,43.2,18.2602,0.4599,,,42.728,90.328,0.4059,,,,,
,43.5,18.3868,0.4597,,,43.028,90.9631,0.4062,,,,,
,43.8,18.5142,0.4593,,,43.328,91.5979,0.4063,,,,,
,44.1,18.6412,0.4589,,,43.628,92.2329,0.4064,,,,,
,44.4,18.7681,0.4584,,,43.928,92.8679,0.4066,,,,,
,44.7,18.8949,0.4582,,,44.228,93.5032,0.4068,,,,,
,45,19.0222,0.4582,,,44.528,94.1385,0.4069,,,,,
,45.3,19.149,0.4577,,,44.828,94.7737,0.4071,,,,,
,45.6,19.2756,0.4571,,,45.128,95.4083,0.4071,,,,,
,45.9,19.4039,0.4568,,,45.428,96.0432,0.4073,,,,,
,46.2,19.53,0.4568,,,45.728,96.6779,0.4077,,,,,
,46.5,19.6568,0.4564,,,46.028,97.3132,0.4078,,,,,
,46.8,19.7842,0.4561,,,46.328,97.948,0.4078,,,,,
,47.1,19.9112,0.4558,,,46.628,98.5829,0.4081,,,,,
,47.4,20.0376,0.4553,,,46.928,99.2177,0.4081,,,,,
,47.7,20.1652,0.4552,,,47.228,99.8527,0.4084,,,,,
,48,20.2922,0.4548,,,47.528,100.4878,0.4084,,,,,
,48.3,20.4188,0.4545,,,47.828,101.1231,0.4087,,,,,
,48.6,20.546,0.4544,,,48.128,101.7581,0.4086,,,,,
,48.9,20.6734,0.4539,,,48.428,102.3928,0.4088,,,,,
,49.2,20.8001,0.4538,,,48.728,103.0279,0.4087,,,,,
,49.5,20.9268,0.4535,,,49.028,103.6633,0.4087,,,,,
,49.8,21.0545,0.4535,,,49.328,104.2984,0.409,,,,,
,50.1,21.1812,0.4529,,,49.628,104.9335,0.4092,,,,,
,50.4,21.3076,0.4524,,,49.928,105.5683,0.4094,,,,,
,50.7,21.4356,0.4522,,,50.228,106.203,0.4095,,,,,
,51,21.562,0.4521,,,50.528,106.8381,0.4095,,,,,
,51.3,21.6888,0.4518,,,50.828,107.4731,0.4093,,,,,
,51.6,21.8166,0.4516,,,51.128,108.1083,0.4095,,,,,
,51.9,21.9431,0.451,,,51.428,108.7428,0.4095,,,,,
,52.2,22.0698,0.4509,,,51.728,109.3778,0.4096,,,,,
,52.5,22.1975,0.4508,,,52.028,110.0127,0.4096,,,,,
,52.8,22.3241,0.4507,,,52.328,110.6478,0.4097,,,,,
,53.1,22.451,0.4504,,,52.628,111.2832,0.4097,,,,,
,53.4,22.578,0.4501,,,52.928,111.9181,0.4097,,,,,
,53.7,22.7053,0.4499,,,53.228,112.5529,0.4099,,,,,
,54,22.8321,0.4494,,,53.528,113.1877,0.41,,,,,
,54.3,22.9589,0.4493,,,53.828,113.823,0.4102,,,,,
,54.6,23.0867,0.4496,,,54.128,114.4584,0.4104,,,,,
,54.9,23.213,0.4491,,,54.428,115.0934,0.4107,,,,,
,55.2,23.3397,0.4487,,,54.728,115.7284,0.4106,,,,,
,55.5,23.4675,0.4485,,,55.028,116.3631,0.411,,,,,
,55.8,23.5942,0.4482,,,55.328,116.998,0.4113,,,,,
,56.1,23.7206,0.448,,,55.628,117.6332,0.4111,,,,,
,56.4,23.8484,0.4481,,,55.928,118.2681,0.4112,,,,,
,56.7,23.9752,0.4479,,,56.228,118.9031,0.4111,,,,,
,57,24.1018,0.4475,,,56.528,119.5377,0.4113,,,,,
,57.3,24.2294,0.4472,,,56.828,120.1729,0.4112,,,,,
,57.6,24.3562,0.4469,,,57.128,120.808,0.4111,,,,,
,57.9,24.4826,0.4467,,,57.428,121.443,0.4112,,,,,
,58.2,24.6101,0.4469,,,57.728,122.0782,0.4115,,,,,
,58.5,24.7373,0.4467,,,58.028,122.7128,0.4114,,,,,
,58.8,24.8643,0.4463,,,58.328,123.3478,0.4116,,,,,
,59.1,24.9906,0.4459,,,58.628,123.9828,0.4116,,,,,
,59.4,25.1186,0.446,,,58.928,124.6182,0.4118,,,,,
,59.7,25.2449,0.4459,,,59.228,125.2536,0.4119,,,,,
,60,25.3717,0.4457,,,59.528,125.8884,0.4119,,,,,
,60.3,25.4996,0.4453,,,59.828,126.5231,0.412,,,,,
,60.6,25.6257,0.445,,,60.128,127.1581,0.412,,,,,
,60.9,25.7529,0.445,,,60.428,127.7932,0.4123,,,,,
,61.2,25.8804,0.4454,,,60.728,128.4283,0.4123,,,,,
,61.5,26.0073,0.445,,,61.028,129.063,0.4124,,,,,
,61.8,26.1338,0.4443,,,61.328,129.698,0.4124,,,,,
,62.1,26.2612,0.4446,,,61.628,130.3328,0.4123,,,,,
,62.4,26.3883,0.4444,,,61.928,130.9678,0.4124,,,,,
,62.7,26.5149,0.4445,,,62.228,131.603,0.4123,,,,,
,63,26.642,0.4444,,,62.528,132.2381,0.4127,,,,,
,63.3,26.7691,0.4439,,,62.828,132.8729,0.4127,,,,,
,63.6,26.8963,0.4437,,,63.128,133.5077,0.4126,,,,,
,63.9,27.0228,0.4439,,,63.428,134.1428,0.4124,,,,,
,64.2,27.1509,0.4437,,,63.728,134.7783,0.4129,,,,,
,64.5,27.2772,0.4435,,,64.028,135.4135,0.413,,,,,
,64.8,27.4035,0.4436,,,64.328,136.0483,0.4129,,,,,
,65.1,27.5318,0.4434,,,64.628,136.6831,0.4129,,,,,
,65.4,27.658,0.4433,,,64.928,137.3182,0.4134,,,,,
,65.7,27.7847,0.4431,,,65.228,137.9532,0.4133,,,,,
,66,27.9125,0.4434,,,65.528,138.5883,0.4135,,,,,
,66.3,28.0391,0.443,,,65.828,139.2231,0.4137,,,,,
,66.6,28.1658,0.4429,,,66.128,139.8578,0.4137,,,,,
,66.9,28.2933,0.4426,,,66.428,140.4927,0.4138,,,,,
,67.2,28.4204,0.4428,,,66.728,141.128,0.414,,,,,
,67.5,28.547,0.4428,,,67.028,141.7629,0.414,,,,,
,67.8,28.674,0.4425,,,67.328,142.3979,0.4143,,,,,
,68.1,28.8014,0.4423,,,67.628,143.0331,0.4139,,,,,
,68.4,28.9282,0.4421,,,67.928,143.6678,0.4142,,,,,
,68.7,29.0548,0.4422,,,68.228,144.3028,0.4142,,,,,
,69,29.1825,0.4425,,,68.528,144.9383,0.4142,,,,,
,69.3,29.309,0.4424,,,68.828,145.5735,0.4141,,,,,
,69.6,29.4357,0.4419,,,69.128,146.2083,0.4142,,,,,
,69.9,29.5638,0.4419,,,69.428,146.8433,0.4142,,,,,
,70.2,29.6901,0.4419,,,69.728,147.4783,0.4144,,,,,
,70.5,29.8169,0.4419,,,70.028,148.1132,0.4145,,,,,
,70.8,29.944,0.4419,,,70.328,148.7482,0.4145,,,,,
,71.1,30.0713,0.4421,,,70.628,149.3832,0.4144,,,,,
,71.4,30.1978,0.4415,,,70.928,150.0177,0.4147,,,,,
,71.7,30.3252,0.4419,,,71.228,150.6526,0.4149,,,,,
,72,30.4523,0.4414,,,71.528,151.2878,0.4147,,,,,
,72.3,30.579,0.4414,,,71.828,151.9229,0.415,,,,,
,72.6,30.7059,0.4417,,,72.128,152.558,0.4147,,,,,
,72.9,30.8335,0.4416,,,72.428,153.193,0.4148,,,,,
,73.2,30.9603,0.4416,,,72.728,153.8279,0.4148,,,,,
,73.5,31.0865,0.4414,,,73.028,154.4629,0.4151,,,,,
,73.8,31.2147,0.4414,,,73.328,155.0983,0.4151,,,,,
,74.1,31.3411,0.4412,,,73.628,155.7336,0.4151,,,,,
,74.4,31.4677,0.4411,,,73.928,156.3685,0.4152,,,,,
,74.7,31.5957,0.4415,,,74.228,157.0033,0.4154,,,,,
,75,31.722,0.4415,,,74.528,157.6382,0.4153,,,,,
,75.3,31.8489,0.4413,,,74.828,158.2733,0.4155,,,,,
,75.6,31.9765,0.4413,,,75.128,158.9082,0.4155,,,,,
,75.9,32.1032,0.4411,,,75.428,159.5431,0.4155,,,,,
,76.2,32.2298,0.4409,,,75.728,160.1778,0.4156,,,,,
,76.5,32.3573,0.4411,,,76.028,160.8126,0.4156,,,,,
,76.8,32.4844,0.4412,,,76.328,161.4477,0.4155,,,,,
,77.1,32.6111,0.4412,,,76.628,162.0831,0.4155,,,,,
,77.4,32.738,0.4413,,,76.928,162.7182,0.4153,,,,,
,77.7,32.8651,0.4411,,,77.228,163.3529,0.4153,,,,,
,78,32.9923,0.441,,,77.528,163.9877,0.4154,,,,,
,78.3,33.1186,0.4409,,,77.828,164.6232,0.4157,,,,,
,78.6,33.2466,0.441,,,78.128,165.2583,0.416,,,,,
,78.9,33.373,0.441,,,78.428,165.8936,0.4159,,,,,
,79.2,33.4996,0.441,,,78.728,166.5284,0.416,,,,,
,79.5,33.6275,0.4411,,,79.028,167.1633,0.4164,,,,,
,79.8,33.7542,0.4411,,,79.328,167.7981,0.4164,,,,,
,80.1,33.8808,0.441,,,79.628,168.4332,0.4166,,,,,
,80.4,34.0083,0.441,,,79.928,169.0683,0.4163,,,,,
,80.7,34.1352,0.4412,,,80.228,169.7029,0.4164,,,,,
,81,34.2619,0.4408,,,80.528,170.3379,0.4162,,,,,
,81.3,34.389,0.4409,,,80.828,170.9728,0.4162,,,,,
,81.6,34.5163,0.4411,,,81.128,171.6077,0.4163,,,,,
,81.9,34.6428,0.4411,,,81.428,172.243,0.4161,,,,,
,82.2,34.7699,0.441,,,81.728,172.8782,0.4164,,,,,
,82.5,34.8974,0.4409,,,82.028,173.513,0.4161,,,,,
,82.8,35.0244,0.4411,,,82.328,174.1478,0.4161,,,,,
,83.1,35.1506,0.4409,,,82.628,174.7829,0.4161,,,,,
,83.4,35.2787,0.4411,,,82.928,175.4185,0.4163,,,,,
,83.7,35.4048,0.441,,,83.228,176.0534,0.4164,,,,,
,84,35.5317,0.4414,,,83.528,176.6886,0.4165,,,,,
,84.3,35.6596,0.4411,,,83.828,177.3232,0.4163,,,,,
,84.6,35.786,0.4413,,,84.128,177.958,0.4164,,,,,
,84.9,35.9129,0.4412,,,84.428,178.5931,0.4166,,,,,
,85.2,36.0404,0.4411,,,84.728,179.2281,0.4165,,,,,
,85.5,36.1673,0.4408,,,85.028,179.8632,0.4164,,,,,
,85.8,36.2939,0.4409,,,85.328,180.498,0.4166,,,,,
,86.1,36.4209,0.441,,,85.628,181.1327,0.4166,,,,,
,86.4,36.5483,0.4413,,,85.928,181.7677,0.4168,,,,,
,86.7,36.6751,0.4412,,,86.228,182.403,0.4169,,,,,
,87,36.8019,0.4415,,,86.528,183.0381,0.417,,,,,
,87.3,36.9294,0.4412,,,86.828,183.673,0.4172,,,,,
,87.6,37.0562,0.4411,,,87.128,184.3079,0.4167,,,,,
,87.9,37.1826,0.4411,,,87.428,184.9428,0.417,,,,,
,88.2,37.3109,0.4414,,,87.728,185.5781,0.4171,,,,,
,88.5,37.4371,0.4411,,,88.028,186.2136,0.4169,,,,,
,88.8,37.5635,0.4411,,,88.328,186.8484,0.417,,,,,
,89.1,37.6916,0.4415,,,88.628,187.4832,0.4168,,,,,
,89.4,37.818,0.4415,,,88.928,188.1181,0.417,,,,,
,89.7,37.9449,0.4418,,,89.228,188.7531,0.417,,,,,
,90,38.0722,0.4416,,,89.528,189.3883,0.4171,,,,,
,90.3,38.1992,0.4413,,,89.828,190.0232,0.4171,,,,,
,90.6,38.3256,0.441,,,90.128,190.658,0.4174,,,,,
,90.9,38.4532,0.4413,,,90.428,191.2927,0.4173,,,,,
,91.2,38.5804,0.4415,,,90.728,191.9279,0.4176,,,,,
,91.5,38.707,0.4414,,,91.028,192.563,0.4174,,,,,
,91.8,38.8338,0.4414,,,91.328,193.1982,0.4178,,,,,
,92.1,38.9614,0.4416,,,91.628,193.833,0.4177,,,,,
,92.4,39.0883,0.4416,,,91.928,194.4678,0.4178,,,,,
,92.7,39.2147,0.4412,,,92.228,195.1028,0.418,,,,,
,93,39.3425,0.4415,,,92.528,195.7381,0.418,,,,,
,93.3,39.4691,0.4415,,,92.828,196.3733,0.4181,,,,,
,93.6,39.5958,0.4417,,,93.128,197.0084,0.4182,,,,,
,93.9,39.7237,0.4418,,,93.428,197.6433,0.418,,,,,
,94.2,39.8501,0.4418,,,93.728,198.2783,0.4181,,,,,
,94.5,39.9769,0.4416,,,94.028,198.9131,0.418,,,,,
,94.8,40.1042,0.4416,,,94.328,199.5482,0.418,,,,,
,95.1,40.2313,0.4415,,,94.628,200.1833,0.418,,,,,
,95.4,40.358,0.4415,,,94.928,200.8179,0.418,,,,,
,95.7,40.4851,0.4421,,,95.228,201.4529,0.418,,,,,
,96,40.6123,0.4419,,,95.528,202.0878,0.4182,,,,,
,96.3,40.7391,0.442,,,95.828,202.7231,0.4182,,,,,
,96.6,40.8657,0.442,,,96.128,203.3581,0.4182,,,,,
,96.9,40.9935,0.4423,,,96.428,203.9931,0.4184,,,,,
,97.2,41.1202,0.4418,,,96.728,204.6277,0.4187,,,,,
,97.5,41.2465,0.4419,,,97.028,205.2626,0.4186,,,,,
,97.8,41.3749,0.4419,,,97.328,205.8981,0.4189,,,,,
,98.1,41.5012,0.4419,,,97.628,206.5334,0.4187,,,,,
,98.4,41.6278,0.4419,,,97.928,207.1684,0.419,,,,,
,98.7,41.7557,0.4419,,,98.228,207.8033,0.4187,,,,,
,99,41.882,0.4422,,,98.528,208.4381,0.4187,,,,,
,99.3,42.0088,0.4422,,,98.828,209.0732,0.4185,,,,,
,99.6,42.1362,0.4422,,,99.128,209.7083,0.4188,,,,,
,99.9,42.2632,0.4418,,,99.428,210.3434,0.4186,,,,,
,100.2,42.3898,0.4418,,,99.728,210.9781,0.4185,,,,,
,100.5,42.5169,0.4417,,,100.028,211.6127,0.4188,,,,,
,100.8,42.6445,0.442,,,100.328,212.2477,0.4187,,,,,
,101.1,42.7711,0.442,,,100.628,212.883,0.4186,,,,,
,101.4,42.8979,0.4421,,,100.928,213.5181,0.4186,,,,,
,101.7,43.0253,0.4424,,,101.228,214.1529,0.4187,,,,,
,102,43.1523,0.4422,,,101.528,214.7878,0.4183,,,,,
,102.3,43.2787,0.4421,,,101.828,215.4229,0.4186,,,,,
,102.6,43.4067,0.4421,,,102.128,216.058,0.4185,,,,,
,102.9,43.5331,0.4422,,,102.428,216.6935,0.4186,,,,,
,103.2,43.6597,0.4419,,,102.728,217.3285,0.4185,,,,,
,103.5,43.7874,0.4423,,,103.028,217.9634,0.4186,,,,,
,103.8,43.9142,0.442,,,103.328,218.5981,0.4187,,,,,
,104.1,44.041,0.4421,,,103.628,219.2334,0.4188,,,,,
,104.4,44.1681,0.4423,,,103.928,219.8683,0.4189,,,,,
,104.7,44.2952,0.4425,,,104.228,220.5033,0.4193,,,,,
,105,44.422,0.4422,,,104.528,221.138,0.4193,,,,,
,105.3,44.5488,0.4421,,,104.828,221.7728,0.4194,,,,,
,105.6,44.6765,0.4421,,,105.128,222.4076,0.4195,,,,,
,105.9,44.803,0.4422,,,105.428,223.0428,0.4192,,,,,
,106.2,44.9299,0.4422,,,105.728,223.6781,0.4195,,,,,
,106.5,45.0575,0.4421,,,106.028,224.3129,0.4192,,,,,
,106.8,45.1844,0.4421,,,106.328,224.9478,0.419,,,,,
,107.1,45.3107,0.4421,,,106.628,225.5831,0.4192,,,,,
,107.4,45.4387,0.4422,,,106.928,226.2182,0.4193,,,,,
,107.7,45.5652,0.4422,,,107.228,226.8533,0.4193,,,,,
,108,45.6918,0.4424,,,107.528,227.4886,0.4197,,,,,
,108.3,45.8196,0.4425,,,107.828,228.1235,0.4197,,,,,
,108.6,45.9461,0.4424,,,108.128,228.7583,0.42,,,,,
,108.9,46.073,0.4425,,,108.428,229.3931,0.4197,,,,,
,109.2,46.2003,0.4421,,,108.728,230.0285,0.4198,,,,,
,109.5,46.3273,0.4422,,,109.028,230.6632,0.4196,,,,,
,109.8,46.4541,0.4421,,,109.328,231.298,0.4196,,,,,
,110.1,46.581,0.4422,,,109.628,231.9328,0.4194,,,,,
,110.4,46.7084,0.4423,,,109.928,232.5676,0.4194,,,,,
,110.7,46.8352,0.4421,,,110.228,233.2028,0.4197,,,,,
,111,46.9617,0.4424,,,110.528,233.8381,0.4197,,,,,
,111.3,47.0896,0.4426,,,110.828,234.4731,0.42,,,,,
,111.6,47.2161,0.4423,,,111.128,235.1077,0.4198,,,,,
,111.9,47.3427,0.4424,,,111.428,235.7428,0.4199,,,,,
,112.2,47.4706,0.4423,,,111.728,236.3783,0.4199,,,,,
,112.5,47.5972,0.4422,,,112.028,237.0135,0.4202,,,,,
,112.8,47.7235,0.4421,,,112.328,237.6485,0.4202,,,,,
,113.1,47.8513,0.4419,,,112.628,238.2834,0.42,,,,,
,113.4,47.9781,0.442,,,112.928,238.9181,0.4201,,,,,
,113.7,48.1051,0.4422,,,113.228,239.5532,0.4205,,,,,
,114,48.232,0.4423,,,113.528,240.1882,0.4202,,,,,
,114.3,48.3594,0.4425,,,113.828,240.8233,0.4205,,,,,
,114.6,48.4857,0.4423,,,114.128,241.4579,0.4202,,,,,
,114.9,48.6129,0.4421,,,114.428,242.0927,0.4202,,,,,
,115.2,48.7403,0.4421,,,114.728,242.7278,0.4202,,,,,
,115.5,48.867,0.4417,,,115.028,243.3629,0.4201,,,,,
,115.8,48.9937,0.4419,,,115.328,243.9981,0.4201,,,,,
,116.1,49.1215,0.442,,,115.628,244.633,0.4206,,,,,
,116.4,49.2481,0.442,,,115.928,245.268,0.4206,,,,,
,116.7,49.3747,0.4417,,,116.228,245.9027,0.4206,,,,,
,117,49.5026,0.4422,,,116.528,246.5381,0.4207,,,,,
,117.3,49.629,0.442,,,116.828,247.1735,0.421,,,,,
,117.6,49.7557,0.442,,,117.128,247.8086,0.421,,,,,
,117.9,49.8835,0.4421,,,117.428,248.4434,0.4213,,,,,
,118.2,50.01,0.4415,,,117.728,249.0782,0.4213,,,,,
,118.5,50.1371,0.4417,,,118.028,249.713,0.4212,,,,,
,118.8,50.2639,0.4416,,,118.328,250.3481,0.4214,,,,,
,119.1,50.3917,0.4418,,,118.628,250.9832,0.4214,,,,,
,119.4,50.518,0.4415,,,118.928,251.6182,0.4217,,,,,
,119.7,50.6448,0.4417,,,119.228,252.2527,0.4216,,,,,
,120,50.7725,0.4416,,,119.528,252.8879,0.422,,,,,
,120.3,50.8991,0.4418,,,119.828,253.5228,0.422,,,,,
,120.6,51.0259,0.4417,,,120.128,254.158,0.4221,,,,,
,120.9,51.1537,0.4418,,,120.428,254.7931,0.4222,,,,,
,121.2,51.2802,0.4416,,,120.728,255.4279,0.4222,,,,,
,121.5,51.4067,0.4413,,,121.028,256.063,0.4223,,,,,
,121.8,51.5346,0.4415,,,121.328,256.6979,0.4223,,,,,
,122.1,51.6614,0.4414,,,121.628,257.3333,0.4225,,,,,
,122.4,51.7878,0.4413,,,121.928,257.9685,0.4228,,,,,
,122.7,51.9155,0.4413,,,122.228,258.6033,0.4231,,,,,
,123,52.042,0.4413,,,122.528,259.2382,0.423,,,,,
,123.3,52.169,0.4412,,,122.828,259.873,0.4232,,,,,
,123.6,52.2961,0.4413,,,123.128,260.5081,0.4231,,,,,
,123.9,52.4233,0.4412,,,123.428,261.1434,0.4231,,,,,
,124.2,52.55,0.4414,,,123.728,261.778,0.4232,,,,,
,124.5,52.6767,0.4413,,,124.028,262.4129,0.4232,,,,,
,124.8,52.8047,0.4414,,,124.328,263.0477,0.4234,,,,,
,125.1,52.931,0.4412,,,124.628,263.683,0.4232,,,,,
,125.4,53.0579,0.4411,,,124.928,264.3181,0.4236,,,,,
,125.7,53.1853,0.4411,,,125.228,264.9531,0.4234,,,,,
,126,53.3122,0.441,,,125.528,265.588,0.4236,,,,,
,126.3,53.4387,0.4408,,,125.828,266.2227,0.4234,,,,,
,126.6,53.5666,0.441,,,126.128,266.858,0.4236,,,,,
,126.9,53.6931,0.4405,,,126.428,267.4933,0.4236,,,,,
,127.2,53.8197,0.4405,,,126.728,268.1282,0.4232,,,,,
,127.5,53.9473,0.4404,,,127.028,268.7634,0.4234,,,,,
,127.8,54.0742,0.4405,,,127.328,269.3982,0.4235,,,,,
,128.1,54.201,0.4404,,,127.628,270.0332,0.4237,,,,,
,128.4,54.3278,0.4405,,,127.928,270.6684,0.424,,,,,
,128.7,54.4554,0.4404,,,128.228,271.3033,0.4239,,,,,
,129,54.5821,0.4405,,,128.528,271.9381,0.4238,,,,,
,129.3,54.7087,0.4407,,,128.828,272.5729,0.424,,,,,
,129.6,54.8367,0.4407,,,129.128,273.2079,0.4239,,,,,
,129.9,54.963,0.4404,,,129.428,273.843,0.4237,,,,,
,130.2,55.0897,0.4401,,,129.728,274.4781,0.424,,,,,
,130.5,55.2176,0.4402,,,130.028,275.1131,0.4241,,,,,
,130.8,55.344,0.4401,,,130.328,275.7479,0.4241,,,,,
,131.1,55.4706,0.44,,,130.628,276.3828,0.4242,,,,,
,131.4,55.5986,0.44,,,130.928,277.0178,0.4242,,,,,
,131.7,55.7252,0.4398,,,131.228,277.653,0.4242,,,,,
,132,55.8521,0.4399,,,131.528,278.2885,0.4242,,,,,
,132.3,55.9793,0.4399,,,131.828,278.9235,0.4241,,,,,
,132.6,56.1062,0.4397,,,132.128,279.5582,0.4242,,,,,
,132.9,56.2331,0.4399,,,132.428,280.1931,0.4241,,,,,
,133.2,56.3599,0.4397,,,132.728,280.8284,0.4244,,,,,
,133.5,56.4874,0.4396,,,133.028,281.4633,0.4246,,,,,
,133.8,56.614,0.4398,,,133.328,282.0982,0.4245,,,,,
,134.1,56.7407,0.4396,,,133.628,282.733,0.4243,,,,,
,134.4,56.8685,0.4395,,,133.928,283.3678,0.4245,,,,,
,134.7,56.9952,0.4393,,,134.228,284.0029,0.4242,,,,,
,135,57.1218,0.4391,,,134.528,284.6382,0.4245,,,,,
,135.3,57.2496,0.4391,,,134.828,285.273,0.4246,,,,,
,135.6,57.3763,0.439,,,135.128,285.9078,0.4246,,,,,
,135.9,57.5027,0.4388,,,135.428,286.5429,0.4246,,,,,
,136.2,57.6307,0.439,,,135.728,287.1778,0.4248,,,,,
,136.5,57.7571,0.4388,,,136.028,287.8132,0.4248,,,,,
,136.8,57.8839,0.4387,,,136.328,288.4485,0.4249,,,,,
,137.1,58.0112,0.4386,,,136.628,289.0835,0.4249,,,,,
,137.4,58.1382,0.4387,,,136.928,289.7181,0.4248,,,,,
,137.7,58.2653,0.4386,,,137.228,290.3532,0.425,,,,,
,138,58.3918,0.4387,,,137.528,290.9884,0.4249,,,,,
,138.3,58.5196,0.4387,,,137.828,291.6234,0.4253,,,,,
,138.6,58.6457,0.4386,,,138.128,292.2582,0.4254,,,,,
,138.9,58.7728,0.4384,,,138.428,292.8929,0.4252,,,,,
,139.2,58.9006,0.4383,,,138.728,293.5276,0.4253,,,,,
,139.5,59.027,0.4381,,,139.028,294.1628,0.4254,,,,,
,139.8,59.1538,0.438,,,139.328,294.798,0.4252,,,,,
,140.1,59.2816,0.438,,,139.628,295.4329,0.4254,,,,,
,140.4,59.4083,0.4379,,,139.928,296.068,0.4256,,,,,
,140.7,59.5348,0.4378,,,140.228,296.7028,0.4257,,,,,
,141,59.6626,0.4379,,,140.528,297.3381,0.4257,,,,,
,141.3,59.7891,0.4379,,,140.828,297.9731,0.4257,,,,,
,141.6,59.9159,0.4376,,,141.128,298.6086,0.4256,,,,,
,141.9,60.0435,0.4377,,,141.428,299.2433,0.4256,,,,,
,142.2,60.17,0.4376,,,141.728,299.8784,0.4256,,,,,
,142.5,60.2973,0.4377,,,142.028,300.5132,0.4258,,,,,
,142.8,60.4238,0.4376,,,142.328,301.1483,0.4256,,,,,
,143.1,60.5516,0.4375,,,142.628,301.7834,0.426,,,,,
,143.4,60.6781,0.437,,,142.928,302.4182,0.4261,,,,,
,143.7,60.8046,0.4372,,,143.228,303.0529,0.4261,,,,,
,144,60.9326,0.4371,,,143.528,303.6877,0.4257,,,,,
,144.3,61.0591,0.4368,,,143.828,304.3227,0.426,,,,,
,144.6,61.1859,0.4367,,,144.128,304.9579,0.4261,,,,,
,144.9,61.3137,0.4368,,,144.428,305.593,0.4265,,,,,
,145.2,61.4402,0.4366,,,144.728,306.2281,0.4267,,,,,
,145.5,61.5665,0.4366,,,145.028,306.8627,0.4267,,,,,
,145.8,61.6946,0.4368,,,145.328,307.4978,0.4264,,,,,
,146.1,61.8213,0.4363,,,145.628,308.1334,0.4266,,,,,
,146.4,61.9478,0.4366,,,145.928,308.7685,0.4268,,,,,
,146.7,62.0752,0.4366,,,146.228,309.4036,0.4272,,,,,
,147,62.2021,0.4363,,,146.528,310.0383,0.4272,,,,,
,147.3,62.3291,0.4358,,,146.828,310.6732,0.4273,,,,,
,147.6,62.456,0.4359,,,147.128,311.3082,0.4274,,,,,
,147.9,62.5834,0.436,,,147.428,311.9433,0.4276,,,,,
,148.2,62.7102,0.4357,,,147.728,312.5783,0.4277,,,,,
,148.5,62.8366,0.4355,,,148.028,313.2128,0.4276,,,,,
,148.8,62.9647,0.4353,,,148.328,313.8477,0.4282,,,,,
,149.1,63.091,0.435,,,148.628,314.4828,0.4281,,,,,
,149.4,63.2178,0.435,,,148.928,315.118,0.4282,,,,,
,149.7,63.3455,0.4347,,,149.228,315.7531,0.4284,,,,,
,150,63.4721,0.4351,,,149.528,316.388,0.4284,,,,,
,150.3,63.5989,0.4347,,,149.828,317.0228,0.4285,,,,,
,150.6,63.7265,0.435,,,150.128,317.6579,0.4287,,,,,
,150.9,63.8531,0.4344,,,150.428,318.2931,0.4292,,,,,
,151.2,63.98,0.4346,,,150.728,318.9288,0.4291,,,,,
,151.5,64.1068,0.4344,,,151.028,319.5634,0.4292,,,,,
,151.8,64.2344,0.4339,,,151.328,320.1984,0.4292,,,,,
,152.1,64.3611,0.4341,,,151.628,320.8332,0.4293,,,,,
,152.4,64.4877,0.4338,,,151.928,321.4682,0.4293,,,,,
,152.7,64.6155,0.4338,,,152.228,322.1033,0.4296,,,,,
,153,64.7421,0.4334,,,152.528,322.738,0.4295,,,,,
,153.3,64.8687,0.4331,,,152.828,323.3731,0.4298,,,,,
,153.6,64.9966,0.4331,,,153.128,324.0078,0.4297,,,,,
,153.9,65.1231,0.4331,,,153.428,324.6428,0.4296,,,,,
,154.2,65.2495,0.4332,,,153.728,325.278,0.4293,,,,,
,154.5,65.3776,0.4329,,,154.028,325.9131,0.4291,,,,,
,154.8,65.5043,0.4329,,,154.328,326.5479,0.4286,,,,,
,155.1,65.6306,0.4327,,,154.628,327.1829,0.4274,,,,,
,155.4,65.7585,0.4327,,,154.928,327.8179,0.4253,,,,,
,155.7,65.8851,0.4328,,,155.228,328.4532,0.4198,,,,,
,156,66.0122,0.4327,,,155.314,328.6352,0.3572,,,,,
,156.3,66.1392,0.4324,,,155.321,328.6499,0.2877,,,,,
,156.6,66.266,0.4324,,,155.327,328.6626,0.2204,,,,,
,156.9,66.3932,0.4323,,,155.333,328.6753,0.1569,,,,,
,157.2,66.5197,0.4322,,,155.342,328.6943,0.0795,,,,,
,157.5,66.6476,0.432,,,155.354,328.7197,0.0155,,,,,
,157.8,66.774,0.4318,,,155.562,329.1604,-0.0009,,,,,
,158.1,66.9007,0.4317,,,155.862,329.7952,-0.001,,,,,
,158.4,67.0283,0.4316,,,156.162,330.43,-0.0007,,,,,
,158.7,67.1552,0.4314,,,156.462,331.0652,-0.0007,,,,,
,159,67.2819,0.4312,,,156.762,331.7002,-0.0006,,,,,
,159.3,67.4094,0.4312,,,157.062,332.3351,-0.0007,,,,,
,159.6,67.5362,0.4313,,,157.362,332.9698,-0.0008,,,,,
,159.9,67.6627,0.4308,,,157.662,333.6047,-0.0006,,,,,
,160.2,67.7904,0.4309,,,157.962,334.2398,-0.0004,,,,,
,160.5,67.9173,0.4307,,,158.262,334.875,-0.0007,,,,,
,160.8,68.0439,0.4305,,,158.562,335.5101,-0.0006,,,,,
,161.1,68.1711,0.4306,,,158.862,336.1449,-0.0008,,,,,
,161.4,68.2982,0.4302,,,159.162,336.78,-0.0007,,,,,
,161.7,68.4253,0.4303,,,159.462,337.4149,-0.0009,,,,,
,162,68.5516,0.4301,,,159.76,338.046,-0.0008,,,,,
,162.3,68.6796,0.4303,,,,,,,,,,
,162.6,68.8061,0.43,,,,,,,,,,
,162.9,68.9327,0.4299,,,,,,,,,,
,163.2,69.0608,0.4301,,,,,,,,,,
,163.5,69.1871,0.4296,,,,,,,,,,
,163.8,69.3138,0.4295,,,,,,,,,,
,164.1,69.4416,0.4294,,,,,,,,,,
,164.4,69.5681,0.4293,,,,,,,,,,
,164.7,69.6948,0.4294,,,,,,,,,,
,165,69.8223,0.4292,,,,,,,,,,
,165.3,69.9491,0.4292,,,,,,,,,,
,165.6,70.076,0.4288,,,,,,,,,,
,165.9,70.2033,0.4289,,,,,,,,,,
,166.2,70.3303,0.4286,,,,,,,,,,
,166.5,70.4572,0.4286,,,,,,,,,,
,166.8,70.5836,0.4281,,,,,,,,,,
,167.1,70.7114,0.4281,,,,,,,,,,
,167.4,70.8381,0.4282,,,,,,,,,,
,167.7,70.9645,0.4282,,,,,,,,,,
,168,71.0926,0.4277,,,,,,,,,,
,168.3,71.219,0.4276,,,,,,,,,,
,168.6,71.3459,0.4276,,,,,,,,,,
,168.9,71.4735,0.4274,,,,,,,,,,
,169.2,71.6002,0.4272,,,,,,,,,,
,169.5,71.7267,0.4272,,,,,,,,,,
,169.8,71.8543,0.4269,,,,,,,,,,
,170.1,71.9813,0.427,,,,,,,,,,
,170.4,72.1079,0.4266,,,,,,,,,,
,170.7,72.235,0.4265,,,,,,,,,,
,171,72.3623,0.4267,,,,,,,,,,
,171.3,72.489,0.4263,,,,,,,,,,
,171.6,72.6159,0.4263,,,,,,,,,,
,171.9,72.7436,0.4262,,,,,,,,,,
,172.2,72.8701,0.4261,,,,,,,,,,
,172.5,72.9966,0.426,,,,,,,,,,
,172.8,73.1247,0.4257,,,,,,,,,,
,173.1,73.251,0.4256,,,,,,,,,,
,173.4,73.3779,0.4257,,,,,,,,,,
,173.7,73.5054,0.4254,,,,,,,,,,
,174,73.6324,0.4252,,,,,,,,,,
,174.3,73.7589,0.4249,,,,,,,,,,
,174.6,73.8864,0.4251,,,,,,,,,,
,174.9,74.0133,0.4246,,,,,,,,,,
,175.2,74.14,0.4247,,,,,,,,,,
,175.5,74.267,0.4243,,,,,,,,,,
,175.8,74.3946,0.4244,,,,,,,,,,
,176.1,74.5212,0.4242,,,,,,,,,,
,176.4,74.6477,0.4241,,,,,,,,,,
,176.7,74.7758,0.4241,,,,,,,,,,
,177,74.9022,0.4239,,,,,,,,,,
,177.3,75.0286,0.4238,,,,,,,,,,
,177.6,75.1567,0.4234,,,,,,,,,,
,177.9,75.2831,0.4232,,,,,,,,,,
,178.2,75.4099,0.423,,,,,,,,,,
,178.5,75.5375,0.4229,,,,,,,,,,
,178.8,75.6643,0.4229,,,,,,,,,,
,179.1,75.7907,0.4224,,,,,,,,,,
,179.4,75.9182,0.4225,,,,,,,,,,
,179.7,76.0452,0.4222,,,,,,,,,,
,180,76.172,0.422,,,,,,,,,,
,180.3,76.2991,0.4221,,,,,,,,,,
,180.6,76.4261,0.4219,,,,,,,,,,
,180.9,76.5532,0.4216,,,,,,,,,,
,181.2,76.6795,0.4214,,,,,,,,,,
,181.5,76.8078,0.4212,,,,,,,,,,
,181.8,76.9341,0.421,,,,,,,,,,
,182.1,77.0607,0.4211,,,,,,,,,,
,182.4,77.1885,0.4208,,,,,,,,,,
,182.7,77.315,0.4205,,,,,,,,,,
,183,77.4418,0.4205,,,,,,,,,,
,183.3,77.5692,0.4204,,,,,,,,,,
,183.6,77.6963,0.4201,,,,,,,,,,
,183.9,77.8228,0.42,,,,,,,,,,
,184.2,77.95,0.4197,,,,,,,,,,
,184.5,78.0775,0.4196,,,,,,,,,,
,184.8,78.204,0.4195,,,,,,,,,,
,185.1,78.3309,0.4196,,,,,,,,,,
,185.4,78.4583,0.4194,,,,,,,,,,
,185.7,78.5854,0.419,,,,,,,,,,
,186,78.7115,0.4189,,,,,,,,,,
,186.3,78.8396,0.4187,,,,,,,,,,
,186.6,78.9661,0.4184,,,,,,,,,,
,186.9,79.0928,0.4183,,,,,,,,,,
,187.2,79.2208,0.418,,,,,,,,,,
,187.5,79.3471,0.4179,,,,,,,,,,
,187.8,79.4739,0.4178,,,,,,,,,,
,188.1,79.6014,0.4173,,,,,,,,,,
,188.4,79.7282,0.4174,,,,,,,,,,
,188.7,79.855,0.417,,,,,,,,,,
,189,79.982,0.4169,,,,,,,,,,
,189.3,80.1094,0.4164,,,,,,,,,,
,189.6,80.236,0.4164,,,,,,,,,,
,189.9,80.3632,0.4163,,,,,,,,,,
,190.2,80.4904,0.4159,,,,,,,,,,
,190.5,80.6171,0.4155,,,,,,,,,,
,190.8,80.7436,0.4155,,,,,,,,,,
,191.1,80.8716,0.4152,,,,,,,,,,
,191.4,80.9982,0.415,,,,,,,,,,
,191.7,81.1245,0.4146,,,,,,,,,,
,192,81.2525,0.4144,,,,,,,,,,
,192.3,81.3789,0.4144,,,,,,,,,,
,192.6,81.506,0.4142,,,,,,,,,,
,192.9,81.6332,0.4139,,,,,,,,,,
,193.2,81.7603,0.4138,,,,,,,,,,
,193.5,81.8867,0.413,,,,,,,,,,
,193.8,82.0141,0.4131,,,,,,,,,,
,194.1,82.1413,0.4129,,,,,,,,,,
,194.4,82.2681,0.4125,,,,,,,,,,
,194.7,82.3948,0.4123,,,,,,,,,,
,195,82.5224,0.412,,,,,,,,,,
,195.3,82.6492,0.4119,,,,,,,,,,
,195.6,82.7756,0.4112,,,,,,,,,,
,195.9,82.9037,0.4112,,,,,,,,,,
,196.2,83.03,0.4107,,,,,,,,,,
,196.5,83.1567,0.4104,,,,,,,,,,
,196.8,83.2847,0.4104,,,,,,,,,,
,197.1,83.4109,0.4099,,,,,,,,,,
,197.4,83.5381,0.4096,,,,,,,,,,
,197.7,83.6651,0.4093,,,,,,,,,,
,198,83.7924,0.409,,,,,,,,,,
,198.3,83.919,0.4087,,,,,,,,,,
,198.6,84.0459,0.4086,,,,,,,,,,
,198.9,84.1733,0.4079,,,,,,,,,,
,199.2,84.3001,0.4078,,,,,,,,,,
,199.5,84.4269,0.4073,,,,,,,,,,
,199.8,84.5547,0.4072,,,,,,,,,,
,200.1,84.6813,0.4068,,,,,,,,,,
,200.4,84.8075,0.4065,,,,,,,,,,
,200.7,84.9358,0.4061,,,,,,,,,,
,201,85.0621,0.4057,,,,,,,,,,
,201.3,85.1886,0.4052,,,,,,,,,,
,201.6,85.3166,0.4049,,,,,,,,,,
,201.9,85.4428,0.4047,,,,,,,,,,
,202.2,85.57,0.4042,,,,,,,,,,
,202.5,85.6972,0.404,,,,,,,,,,
,202.8,85.8244,0.4037,,,,,,,,,,
,203.1,85.951,0.4034,,,,,,,,,,
,203.4,86.0779,0.4028,,,,,,,,,,
,203.7,86.2055,0.4027,,,,,,,,,,
,204,86.332,0.4018,,,,,,,,,,
,204.3,86.4588,0.402,,,,,,,,,,
,204.6,86.5863,0.4014,,,,,,,,,,
,204.9,86.7132,0.4009,,,,,,,,,,
,205.2,86.8397,0.4006,,,,,,,,,,
,205.5,86.9677,0.4002,,,,,,,,,,
,205.8,87.0941,0.4001,,,,,,,,,,
,206.1,87.2207,0.3995,,,,,,,,,,
,206.4,87.3482,0.3991,,,,,,,,,,
,206.7,87.4751,0.3987,,,,,,,,,,
,207,87.602,0.3983,,,,,,,,,,
,207.3,87.7291,0.3979,,,,,,,,,,
,207.6,87.8564,0.3973,,,,,,,,,,
,207.9,87.983,0.397,,,,,,,,,,
,208.2,88.1099,0.3965,,,,,,,,,,
,208.5,88.2375,0.3964,,,,,,,,,,
,208.8,88.3641,0.3957,,,,,,,,,,
,209.1,88.4906,0.3956,,,,,,,,,,
,209.4,88.6186,0.3953,,,,,,,,,,
,209.7,88.7454,0.3948,,,,,,,,,,
,210,88.8714,0.3945,,,,,,,,,,
,210.3,88.9997,0.3945,,,,,,,,,,
,210.6,89.1261,0.394,,,,,,,,,,
,210.9,89.2527,0.3936,,,,,,,,,,
,211.2,89.3806,0.3934,,,,,,,,,,
,211.5,89.507,0.393,,,,,,,,,,
,211.8,89.634,0.3925,,,,,,,,,,
,212.1,89.7611,0.3926,,,,,,,,,,
,212.4,89.8884,0.3921,,,,,,,,,,
,212.7,90.0151,0.3919,,,,,,,,,,
,213,90.1419,0.3916,,,,,,,,,,
,213.3,90.2692,0.3914,,,,,,,,,,
,213.6,90.3961,0.3912,,,,,,,,,,
,213.9,90.5229,0.3908,,,,,,,,,,
,214.2,90.6505,0.3907,,,,,,,,,,
,214.5,90.7772,0.3905,,,,,,,,,,
,214.8,90.9036,0.3904,,,,,,,,,,
,215.1,91.0316,0.3903,,,,,,,,,,
,215.4,91.1582,0.39,,,,,,,,,,
,215.7,91.2847,0.39,,,,,,,,,,
,216,91.4125,0.3901,,,,,,,,,,
,216.3,91.5391,0.39,,,,,,,,,,
,216.6,91.6661,0.3898,,,,,,,,,,
,216.9,91.7929,0.3898,,,,,,,,,,
,217.2,91.9204,0.3898,,,,,,,,,,
,217.5,92.0469,0.3897,,,,,,,,,,
,217.8,92.1738,0.3896,,,,,,,,,,
,218.1,92.3015,0.3895,,,,,,,,,,
,218.4,92.4282,0.3897,,,,,,,,,,
,218.7,92.5547,0.3898,,,,,,,,,,
,219,92.6825,0.3897,,,,,,,,,,
,219.3,92.8089,0.3894,,,,,,,,,,
,219.6,92.9357,0.39,,,,,,,,,,
,219.9,93.0637,0.3897,,,,,,,,,,
,220.2,93.1901,0.3899,,,,,,,,,,
,220.5,93.3167,0.3896,,,,,,,,,,
,220.8,93.4446,0.3897,,,,,,,,,,
,221.1,93.571,0.3899,,,,,,,,,,
,221.4,93.698,0.3898,,,,,,,,,,
,221.7,93.8249,0.3898,,,,,,,,,,
,222,93.9522,0.3899,,,,,,,,,,
,222.3,94.0791,0.3901,,,,,,,,,,
,222.6,94.2059,0.3898,,,,,,,,,,
,222.9,94.3334,0.3897,,,,,,,,,,
,223.2,94.4601,0.3899,,,,,,,,,,
,223.5,94.5868,0.3901,,,,,,,,,,
,223.8,94.7147,0.3902,,,,,,,,,,
,224.1,94.8413,0.3903,,,,,,,,,,
,224.4,94.9675,0.3902,,,,,,,,,,
,224.7,95.0955,0.3904,,,,,,,,,,
,225,95.2221,0.3904,,,,,,,,,,
,225.3,95.3487,0.3904,,,,,,,,,,
,225.6,95.4764,0.3906,,,,,,,,,,
,225.9,95.603,0.3907,,,,,,,,,,
,226.2,95.7298,0.3909,,,,,,,,,,
,226.5,95.8571,0.3907,,,,,,,,,,
,226.8,95.9845,0.391,,,,,,,,,,
,227.1,96.111,0.3908,,,,,,,,,,
,227.4,96.2377,0.3913,,,,,,,,,,
,227.7,96.3655,0.3913,,,,,,,,,,
,228,96.4921,0.3912,,,,,,,,,,
,228.3,96.6188,0.3917,,,,,,,,,,
,228.6,96.7464,0.3916,,,,,,,,,,
,228.9,96.8732,0.3917,,,,,,,,,,
,229.2,96.9997,0.3915,,,,,,,,,,
,229.5,97.1277,0.3917,,,,,,,,,,
,229.8,97.254,0.3918,,,,,,,,,,
,230.1,97.3807,0.3917,,,,,,,,,,
,230.4,97.5084,0.3919,,,,,,,,,,
,230.7,97.6351,0.3923,,,,,,,,,,
,231,97.7621,0.392,,,,,,,,,,
,231.3,97.889,0.3923,,,,,,,,,,
,231.6,98.0164,0.3923,,,,,,,,,,
,231.9,98.1432,0.3923,,,,,,,,,,
,232.2,98.2696,0.3924,,,,,,,,,,
,232.5,98.3976,0.3926,,,,,,,,,,
,232.8,98.5241,0.3923,,,,,,,,,,
,233.1,98.6506,0.3926,,,,,,,,,,
,233.4,98.7787,0.3927,,,,,,,,,,
,233.7,98.9055,0.3929,,,,,,,,,,
,234,99.0316,0.3927,,,,,,,,,,
,234.3,99.1595,0.393,,,,,,,,,,
,234.6,99.286,0.3929,,,,,,,,,,
,234.9,99.4127,0.3932,,,,,,,,,,
,235.2,99.5403,0.3931,,,,,,,,,,
,235.5,99.667,0.3934,,,,,,,,,,
,235.8,99.794,0.3934,,,,,,,,,,
,236.1,99.9209,0.3936,,,,,,,,,,
,236.4,100.0485,0.3935,,,,,,,,,,
,236.7,100.1751,0.3936,,,,,,,,,,
,237,100.3017,0.3937,,,,,,,,,,
,237.3,100.4294,0.3937,,,,,,,,,,
,237.6,100.5561,0.3939,,,,,,,,,,
,237.9,100.6829,0.3942,,,,,,,,,,
,238.2,100.8105,0.3942,,,,,,,,,,
,238.5,100.9372,0.3943,,,,,,,,,,
,238.8,101.0636,0.3944,,,,,,,,,,
,239.1,101.1913,0.3944,,,,,,,,,,
,239.4,101.3183,0.3945,,,,,,,,,,
,239.7,101.4449,0.3944,,,,,,,,,,
,240,101.5722,0.3945,,,,,,,,,,
,240.3,101.699,0.3948,,,,,,,,,,
,240.6,101.8262,0.3947,,,,,,,,,,
,240.9,101.9527,0.395,,,,,,,,,,
,241.2,102.0805,0.3951,,,,,,,,,,
,241.5,102.2071,0.3953,,,,,,,,,,
,241.8,102.3338,0.3953,,,,,,,,,,
,242.1,102.4617,0.3953,,,,,,,,,,
,242.4,102.5883,0.3955,,,,,,,,,,
,242.7,102.7149,0.3955,,,,,,,,,,
,243,102.8425,0.3956,,,,,,,,,,
,243.3,102.9693,0.3957,,,,,,,,,,
,243.6,103.0958,0.3959,,,,,,,,,,
,243.9,103.2236,0.396,,,,,,,,,,
,244.2,103.3502,0.3958,,,,,,,,,,
,244.5,103.4768,0.3959,,,,,,,,,,
,244.8,103.6045,0.396,,,,,,,,,,
,245.1,103.7311,0.3959,,,,,,,,,,
,245.4,103.8582,0.3962,,,,,,,,,,
,245.7,103.9848,0.3962,,,,,,,,,,
,246,104.1124,0.3963,,,,,,,,,,
,246.3,104.2392,0.3964,,,,,,,,,,
,246.6,104.3657,0.3962,,,,,,,,,,
,246.9,104.4936,0.3963,,,,,,,,,,
,247.2,104.6199,0.3964,,,,,,,,,,
,247.5,104.7468,0.3964,,,,,,,,,,
,247.8,104.8744,0.3965,,,,,,,,,,
,248.1,105.0012,0.3966,,,,,,,,,,
,248.4,105.1276,0.3966,,,,,,,,,,
,248.7,105.2553,0.3966,,,,,,,,,,
,249,105.3822,0.3962,,,,,,,,,,
,249.3,105.509,0.3967,,,,,,,,,,
,249.6,105.6362,0.3966,,,,,,,,,,
,249.9,105.7633,0.3967,,,,,,,,,,
,250.2,105.8899,0.3966,,,,,,,,,,
,250.5,106.0168,0.3965,,,,,,,,,,
,250.8,106.1444,0.3965,,,,,,,,,,
,251.1,106.2712,0.3965,,,,,,,,,,
,251.4,106.3978,0.3965,,,,,,,,,,
,251.7,106.5256,0.3965,,,,,,,,,,
,252,106.652,0.3963,,,,,,,,,,
,252.3,106.7788,0.3964,,,,,,,,,,
,252.6,106.9066,0.3966,,,,,,,,,,
,252.9,107.0331,0.3965,,,,,,,,,,
,253.2,107.1597,0.3968,,,,,,,,,,
,253.5,107.2876,0.3968,,,,,,,,,,
,253.8,107.414,0.3965,,,,,,,,,,
,254.1,107.541,0.3969,,,,,,,,,,
,254.4,107.6681,0.3967,,,,,,,,,,
,254.7,107.7954,0.3969,,,,,,,,,,
,255,107.9222,0.397,,,,,,,,,,
,255.3,108.0489,0.3973,,,,,,,,,,
,255.6,108.1766,0.3973,,,,,,,,,,
,255.9,108.303,0.3973,,,,,,,,,,
,256.2,108.4298,0.3975,,,,,,,,,,
,256.5,108.5577,0.3978,,,,,,,,,,
,256.8,108.684,0.398,,,,,,,,,,
,257.1,108.8108,0.3975,,,,,,,,,,
,257.4,108.9385,0.3979,,,,,,,,,,
,257.7,109.0655,0.3979,,,,,,,,,,
,258,109.1916,0.398,,,,,,,,,,
,258.3,109.3195,0.3983,,,,,,,,,,
,258.6,109.4461,0.3983,,,,,,,,,,
,258.9,109.573,0.3982,,,,,,,,,,
,259.2,109.7001,0.3984,,,,,,,,,,
,259.5,109.8271,0.3983,,,,,,,,,,
,259.8,109.9542,0.3985,,,,,,,,,,
,260.1,110.0806,0.3985,,,,,,,,,,
,260.4,110.2087,0.3986,,,,,,,,,,
,260.7,110.3351,0.3985,,,,,,,,,,
,261,110.4617,0.3983,,,,,,,,,,
,261.3,110.5894,0.3985,,,,,,,,,,
,261.6,110.716,0.3986,,,,,,,,,,
,261.9,110.8429,0.3985,,,,,,,,,,
,262.2,110.9705,0.3988,,,,,,,,,,
,262.5,111.0973,0.3987,,,,,,,,,,
,262.8,111.2238,0.3986,,,,,,,,,,
,263.1,111.3512,0.3988,,,,,,,,,,
,263.4,111.4783,0.3988,,,,,,,,,,
,263.7,111.6049,0.399,,,,,,,,,,
,264,111.732,0.3989,,,,,,,,,,
,264.3,111.8593,0.3992,,,,,,,,,,
,264.6,111.9863,0.3991,,,,,,,,,,
,264.9,112.1126,0.3993,,,,,,,,,,
,265.2,112.2407,0.3996,,,,,,,,,,
,265.5,112.3671,0.3995,,,,,,,,,,
,265.8,112.4936,0.3991,,,,,,,,,,
,266.1,112.6218,0.3996,,,,,,,,,,
,266.4,112.7479,0.3996,,,,,,,,,,
,266.7,112.8747,0.3994,,,,,,,,,,
,267,113.0025,0.3996,,,,,,,,,,
,267.3,113.1292,0.3995,,,,,,,,,,
,267.6,113.2561,0.3995,,,,,,,,,,
,267.9,113.3834,0.3998,,,,,,,,,,
,268.2,113.5102,0.3999,,,,,,,,,,
,268.5,113.637,0.3996,,,,,,,,,,
,268.8,113.7642,0.3998,,,,,,,,,,
,269.1,113.8912,0.4001,,,,,,,,,,
,269.4,114.0181,0.4003,,,,,,,,,,
,269.7,114.1446,0.4003,,,,,,,,,,
,270,114.2725,0.4004,,,,,,,,,,
,270.3,114.3992,0.4005,,,,,,,,,,
,270.6,114.5258,0.4007,,,,,,,,,,
,270.9,114.6536,0.4004,,,,,,,,,,
,271.2,114.7801,0.4003,,,,,,,,,,
,271.5,114.9069,0.4005,,,,,,,,,,
,271.8,115.0345,0.4005,,,,,,,,,,
,272.1,115.1613,0.4004,,,,,,,,,,
,272.4,115.2877,0.4004,,,,,,,,,,
,272.7,115.4152,0.4004,,,,,,,,,,
,273,115.5422,0.4003,,,,,,,,,,
,273.3,115.6691,0.4003,,,,,,,,,,
,273.6,115.7959,0.4005,,,,,,,,,,
,273.9,115.9234,0.4006,,,,,,,,,,
,274.2,116.0498,0.4006,,,,,,,,,,
,274.5,116.1767,0.4005,,,,,,,,,,
,274.8,116.3046,0.4008,,,,,,,,,,
,275.1,116.431,0.4006,,,,,,,,,,
,275.4,116.5578,0.4005,,,,,,,,,,
,275.7,116.6857,0.4008,,,,,,,,,,
,276,116.8121,0.4008,,,,,,,,,,
,276.3,116.9389,0.4007,,,,,,,,,,
,276.6,117.0665,0.4008,,,,,,,,,,
,276.9,117.1931,0.4008,,,,,,,,,,
,277.2,117.3198,0.4009,,,,,,,,,,
,277.5,117.4475,0.4008,,,,,,,,,,
,277.8,117.5741,0.4008,,,,,,,,,,
,278.1,117.7011,0.4008,,,,,,,,,,
,278.4,117.828,0.4007,,,,,,,,,,
,278.7,117.9554,0.4011,,,,,,,,,,
,279,118.0823,0.4009,,,,,,,,,,
,279.3,118.2087,0.4007,,,,,,,,,,
,279.6,118.3366,0.4008,,,,,,,,,,
,279.9,118.4632,0.4009,,,,,,,,,,
,280.2,118.5898,0.4008,,,,,,,,,,
,280.5,118.7178,0.4008,,,,,,,,,,
,280.8,118.8441,0.4006,,,,,,,,,,
,281.1,118.9707,0.4007,,,,,,,,,,
,281.4,119.0984,0.4008,,,,,,,,,,
,281.7,119.2253,0.401,,,,,,,,,,
,282,119.3517,0.4008,,,,,,,,,,
,282.3,119.4792,0.4007,,,,,,,,,,
,282.6,119.6062,0.4008,,,,,,,,,,
,282.9,119.733,0.4006,,,,,,,,,,
,283.2,119.8601,0.4008,,,,,,,,,,
,283.5,119.9873,0.4008,,,,,,,,,,
,283.8,120.1142,0.4009,,,,,,,,,,
,284.1,120.2406,0.4008,,,,,,,,,,
,284.4,120.3687,0.4005,,,,,,,,,,
,284.7,120.4949,0.4009,,,,,,,,,,
,285,120.6217,0.4011,,,,,,,,,,
,285.3,120.7497,0.4009,,,,,,,,,,
,285.6,120.8759,0.4011,,,,,,,,,,
,285.9,121.003,0.4011,,,,,,,,,,
,286.2,121.1304,0.401,,,,,,,,,,
,286.5,121.2572,0.4011,,,,,,,,,,
,286.8,121.384,0.4012,,,,,,,,,,
,287.1,121.5108,0.4012,,,,,,,,,,
,287.4,121.6385,0.4011,,,,,,,,,,
,287.7,121.7649,0.4012,,,,,,,,,,
,288,121.8919,0.4012,,,,,,,,,,
,288.3,122.0195,0.4012,,,,,,,,,,
,288.6,122.1463,0.4014,,,,,,,,,,
,288.9,122.2726,0.4012,,,,,,,,,,
,289.2,122.4006,0.4011,,,,,,,,,,
,289.5,122.5271,0.4014,,,,,,,,,,
,289.8,122.6535,0.4013,,,,,,,,,,
,290.1,122.7818,0.4015,,,,,,,,,,
,290.4,122.9082,0.4015,,,,,,,,,,
,290.7,123.0347,0.4011,,,,,,,,,,
,291,123.1624,0.4013,,,,,,,,,,
,291.3,123.2892,0.4014,,,,,,,,,,
,291.6,123.4161,0.4015,,,,,,,,,,
,291.9,123.5431,0.4013,,,,,,,,,,
,292.2,123.6702,0.4014,,,,,,,,,,
,292.5,123.797,0.4018,,,,,,,,,,
,292.8,123.9239,0.4015,,,,,,,,,,
,293.1,124.0514,0.4014,,,,,,,,,,
,293.4,124.1781,0.4013,,,,,,,,,,
,293.7,124.3046,0.4015,,,,,,,,,,
,294,124.4325,0.4015,,,,,,,,,,
,294.3,124.5592,0.4016,,,,,,,,,,
,294.6,124.6858,0.4016,,,,,,,,,,
,294.9,124.8135,0.4015,,,,,,,,,,
,295.2,124.9401,0.4017,,,,,,,,,,
,295.5,125.0669,0.4017,,,,,,,,,,
,295.8,125.1943,0.4018,,,,,,,,,,
,296.1,125.3214,0.4017,,,,,,,,,,
,296.4,125.4478,0.4018,,,,,,,,,,
,296.7,125.5751,0.4018,,,,,,,,,,
,297,125.7023,0.4019,,,,,,,,,,
,297.3,125.8293,0.402,,,,,,,,,,
,297.6,125.9558,0.4021,,,,,,,,,,
,297.9,126.0834,0.4023,,,,,,,,,,
,298.2,126.2102,0.4023,,,,,,,,,,
,298.5,126.3366,0.4021,,,,,,,,,,
,298.8,126.4648,0.4026,,,,,,,,,,
,299.1,126.5911,0.4026,,,,,,,,,,
,299.4,126.7177,0.4027,,,,,,,,,,
,299.7,126.8458,0.4026,,,,,,,,,,
,300,126.9718,0.4026,,,,,,,,,,
,300.3,127.099,0.4025,,,,,,,,,,
,300.6,127.2261,0.4024,,,,,,,,,,
,300.9,127.3533,0.4023,,,,,,,,,,
,301.2,127.4799,0.4026,,,,,,,,,,
,301.5,127.6073,0.4024,,,,,,,,,,
,301.8,127.7343,0.4024,,,,,,,,,,
,302.1,127.861,0.4026,,,,,,,,,,
,302.4,127.9878,0.4025,,,,,,,,,,
,302.7,128.1152,0.4025,,,,,,,,,,
,303,128.2422,0.4026,,,,,,,,,,
,303.3,128.3686,0.4028,,,,,,,,,,
,303.6,128.4965,0.4029,,,,,,,,,,
,303.9,128.6231,0.4031,,,,,,,,,,
,304.2,128.7497,0.4027,,,,,,,,,,
,304.5,128.8777,0.403,,,,,,,,,,
,304.8,129.0039,0.403,,,,,,,,,,
,305.1,129.1309,0.4025,,,,,,,,,,
,305.4,129.2581,0.4028,,,,,,,,,,
,305.7,129.3854,0.4026,,,,,,,,,,
,306,129.512,0.4027,,,,,,,,,,
,306.3,129.639,0.4028,,,,,,,,,,
,306.6,129.7664,0.403,,,,,,,,,,
,306.9,129.8929,0.4028,,,,,,,,,,
,307.2,130.02,0.4029,,,,,,,,,,
,307.5,130.1476,0.4028,,,,,,,,,,
,307.8,130.2742,0.403,,,,,,,,,,
,308.1,130.4005,0.4029,,,,,,,,,,
,308.4,130.5286,0.403,,,,,,,,,,
,308.7,130.655,0.4034,,,,,,,,,,
,309,130.7817,0.4033,,,,,,,,,,
,309.3,130.9096,0.4035,,,,,,,,,,
,309.6,131.0362,0.4037,,,,,,,,,,
,309.9,131.1631,0.4038,,,,,,,,,,
,310.2,131.2903,0.4037,,,,,,,,,,
,310.5,131.4174,0.4041,,,,,,,,,,
,310.8,131.544,0.4039,,,,,,,,,,
,311.1,131.671,0.4039,,,,,,,,,,
,311.4,131.7987,0.404,,,,,,,,,,
,311.7,131.925,0.4039,,,,,,,,,,
,312,132.0518,0.4039,,,,,,,,,,
,312.3,132.1796,0.4039,,,,,,,,,,
,312.6,132.3064,0.4039,,,,,,,,,,
,312.9,132.4325,0.4039,,,,,,,,,,
,313.2,132.5608,0.404,,,,,,,,,,
,313.5,132.687,0.4039,,,,,,,,,,
,313.8,132.8137,0.404,,,,,,,,,,
,314.1,132.9416,0.4042,,,,,,,,,,
,314.4,133.0681,0.404,,,,,,,,,,
,314.7,133.1949,0.4042,,,,,,,,,,
,315,133.3221,0.4043,,,,,,,,,,
,315.3,133.4494,0.4044,,,,,,,,,,
,315.6,133.5759,0.4045,,,,,,,,,,
,315.9,133.7031,0.4046,,,,,,,,,,
,316.2,133.8303,0.4045,,,,,,,,,,
,316.5,133.9571,0.4044,,,,,,,,,,
,316.8,134.0838,0.4044,,,,,,,,,,
,317.1,134.2116,0.4042,,,,,,,,,,
,317.4,134.3382,0.4041,,,,,,,,,,
,317.7,134.4646,0.4041,,,,,,,,,,
,318,134.5925,0.4042,,,,,,,,,,
,318.3,134.719,0.4041,,,,,,,,,,
,318.6,134.8458,0.4042,,,,,,,,,,
,318.9,134.9735,0.4043,,,,,,,,,,
,319.2,135.1002,0.4042,,,,,,,,,,
,319.5,135.2271,0.4042,,,,,,,,,,
,319.8,135.3539,0.4041,,,,,,,,,,
,320.1,135.4816,0.4044,,,,,,,,,,
,320.4,135.6079,0.4041,,,,,,,,,,
,320.7,135.7348,0.4044,,,,,,,,,,
,321,135.8625,0.4044,,,,,,,,,,
,321.3,135.9891,0.4042,,,,,,,,,,
,321.6,136.1158,0.4043,,,,,,,,,,
,321.9,136.2434,0.4044,,,,,,,,,,
,322.2,136.3702,0.4044,,,,,,,,,,
,322.5,136.4967,0.4043,,,,,,,,,,
,322.8,136.6247,0.4041,,,,,,,,,,
,323.1,136.7511,0.4044,,,,,,,,,,
,323.4,136.8777,0.4044,,,,,,,,,,
,323.7,137.0055,0.4043,,,,,,,,,,
,324,137.1321,0.4043,,,,,,,,,,
,324.3,137.2592,0.4045,,,,,,,,,,
,324.6,137.3859,0.4045,,,,,,,,,,
,324.9,137.5135,0.4045,,,,,,,,,,
,325.2,137.64,0.4046,,,,,,,,,,
,325.5,137.767,0.4044,,,,,,,,,,
,325.8,137.8944,0.4048,,,,,,,,,,
,326.1,138.0211,0.4045,,,,,,,,,,
,326.4,138.1478,0.4044,,,,,,,,,,
,326.7,138.2755,0.4044,,,,,,,,,,
,327,138.4022,0.4044,,,,,,,,,,
,327.3,138.5285,0.4046,,,,,,,,,,
,327.6,138.6564,0.4047,,,,,,,,,,
,327.9,138.7831,0.4046,,,,,,,,,,
,328.2,138.9098,0.4047,,,,,,,,,,
,328.5,139.0374,0.4048,,,,,,,,,,
,328.8,139.1642,0.4048,,,,,,,,,,
,329.1,139.2908,0.4051,,,,,,,,,,
,329.4,139.418,0.4051,,,,,,,,,,
,329.7,139.5455,0.4053,,,,,,,,,,
,330,139.6721,0.4051,,,,,,,,,,
,330.3,139.7988,0.405,,,,,,,,,,
,330.6,139.9266,0.405,,,,,,,,,,
,330.9,140.0529,0.405,,,,,,,,,,
,331.2,140.1798,0.4049,,,,,,,,,,
,331.5,140.3076,0.4049,,,,,,,,,,
,331.8,140.434,0.4049,,,,,,,,,,
,332.1,140.5607,0.405,,,,,,,,,,
,332.4,140.6887,0.4049,,,,,,,,,,
,332.7,140.8149,0.405,,,,,,,,,,
,333,140.942,0.405,,,,,,,,,,
,333.3,141.0694,0.405,,,,,,,,,,
,333.6,141.1961,0.4049,,,,,,,,,,
,333.9,141.3232,0.405,,,,,,,,,,
,334.2,141.45,0.4054,,,,,,,,,,
,334.5,141.5774,0.4052,,,,,,,,,,
,334.8,141.7039,0.4051,,,,,,,,,,
,335.1,141.8308,0.4052,,,,,,,,,,
,335.4,141.9588,0.4053,,,,,,,,,,
,335.7,142.0851,0.405,,,,,,,,,,
,336,142.2117,0.4052,,,,,,,,,,
,336.3,142.3396,0.4051,,,,,,,,,,
,336.6,142.4663,0.4049,,,,,,,,,,
,336.9,142.5925,0.4049,,,,,,,,,,
,337.2,142.7206,0.4051,,,,,,,,,,
,337.5,142.847,0.4051,,,,,,,,,,
,337.8,142.9738,0.4051,,,,,,,,,,
,338.1,143.1014,0.4053,,,,,,,,,,
,338.4,143.2283,0.4056,,,,,,,,,,
,338.7,143.355,0.4053,,,,,,,,,,
,339,143.4819,0.4055,,,,,,,,,,
,339.3,143.6095,0.4056,,,,,,,,,,
,339.6,143.736,0.4054,,,,,,,,,,
,339.9,143.8628,0.4055,,,,,,,,,,
,340.2,143.9905,0.4058,,,,,,,,,,
,340.5,144.117,0.4055,,,,,,,,,,
,340.8,144.2439,0.4053,,,,,,,,,,
,341.1,144.3715,0.4054,,,,,,,,,,
,341.4,144.4982,0.4054,,,,,,,,,,
,341.7,144.6247,0.4052,,,,,,,,,,
,342,144.7522,0.4055,,,,,,,,,,
,342.3,144.8792,0.4055,,,,,,,,,,
,342.6,145.0057,0.4057,,,,,,,,,,
,342.9,145.1333,0.4056,,,,,,,,,,
,343.2,145.2602,0.4057,,,,,,,,,,
,343.5,145.3872,0.4056,,,,,,,,,,
,343.8,145.5138,0.4057,,,,,,,,,,
,344.1,145.6415,0.4058,,,,,,,,,,
,344.4,145.7682,0.4058,,,,,,,,,,
,344.7,145.8945,0.4056,,,,,,,,,,
,345,146.0228,0.4058,,,,,,,,,,
,345.3,146.1492,0.4059,,,,,,,,,,
,345.6,146.2755,0.4056,,,,,,,,,,
,345.9,146.4036,0.4058,,,,,,,,,,
,346.2,146.5302,0.4055,,,,,,,,,,
,346.5,146.6567,0.4058,,,,,,,,,,
,346.8,146.7846,0.4058,,,,,,,,,,
,347.1,146.9111,0.4058,,,,,,,,,,
,347.4,147.0377,0.4058,,,,,,,,,,
,347.7,147.1654,0.406,,,,,,,,,,
,348,147.2922,0.4059,,,,,,,,,,
,348.3,147.4192,0.4062,,,,,,,,,,
,348.6,147.5458,0.4063,,,,,,,,,,
,348.9,147.6734,0.4064,,,,,,,,,,
,349.2,147.8002,0.4066,,,,,,,,,,
,349.5,147.9267,0.4063,,,,,,,,,,
,349.8,148.0545,0.4064,,,,,,,,,,
,350.1,148.181,0.4062,,,,,,,,,,
,350.4,148.3076,0.4061,,,,,,,,,,
,350.7,148.4355,0.4063,,,,,,,,,,
,351,148.5623,0.4061,,,,,,,,,,
,351.3,148.6888,0.4063,,,,,,,,,,
,351.6,148.8164,0.4063,,,,,,,,,,
,351.9,148.9432,0.4063,,,,,,,,,,
,352.2,149.07,0.4064,,,,,,,,,,
,352.5,149.1971,0.4065,,,,,,,,,,
,352.8,149.3244,0.4062,,,,,,,,,,
,353.1,149.451,0.4065,,,,,,,,,,
,353.4,149.5778,0.4063,,,,,,,,,,
,353.7,149.7057,0.4063,,,,,,,,,,
,354,149.8321,0.4062,,,,,,,,,,
,354.3,149.9587,0.4061,,,,,,,,,,
,354.6,150.0866,0.4061,,,,,,,,,,
,354.9,150.2127,0.4063,,,,,,,,,,
,355,150.2552,0.4064,,,,,,,,,,