File: lab10/data/S1_PC_1.csv
Results Table 1,,,,,,,,,,,,,
,Specimen label,Thickness,Width,Length,Rate 1,,,,,,,,
,,(mm),(mm),(mm),(mm/min),,,,,,,,
1,pc-1,3.1,12.75,93.95,25.4,,,,,,,,
2,pc-5,3.07,12.75,91.95,127,,,,,,,,
3,pc-20,3.07,12.7,89.1,508,,,,,,,,
,,,,,,,,,,,,,
Results Table 2,,,,,,,,,,,,,
,,,,,,,,,,,,,
,,,,,,,,,,,,,
1,Time,Displacement,Force,,2,Time,Displacement,Force,,3,Time,Displacement,Force
,(s),(mm),(kN),,,(s),(mm),(kN),,,(s),(mm),(kN)
,0,0,0.0189,,,0,0,0.0192,,,0,0,0.0409
,0.165,0.0343,0.0517,,,0.073,0.0445,0.0602,,,0.049,0.0432,0.0828
,0.24,0.0761,0.0925,,,0.095,0.0878,0.1012,,,0.058,0.086,0.1246
,0.342,0.1187,0.1329,,,0.119,0.1324,0.1425,,,0.066,0.1379,0.1745
,0.444,0.1616,0.1735,,,0.143,0.179,0.1848,,,0.072,0.1831,0.2177
,0.547,0.2056,0.214,,,0.165,0.2275,0.2279,,,0.078,0.2315,0.2638
,0.651,0.2491,0.2544,,,0.185,0.2748,0.2697,,,0.084,0.2816,0.3111
,0.755,0.2941,0.2951,,,0.205,0.322,0.3113,,,0.09,0.332,0.3584
,0.862,0.3387,0.3356,,,0.227,0.3718,0.3542,,,0.096,0.382,0.4048
,0.968,0.3843,0.3759,,,0.249,0.4191,0.3949,,,0.102,0.4311,0.45
,1.077,0.4297,0.4162,,,0.273,0.4692,0.4373,,,0.108,0.4794,0.4939
,1.184,0.4757,0.4563,,,0.297,0.519,0.4792,,,0.114,0.527,0.5365
,1.297,0.5228,0.4966,,,0.321,0.5693,0.5205,,,0.12,0.5743,0.5784
,1.41,0.5713,0.5369,,,0.345,0.6199,0.5619,,,0.126,0.6215,0.6198
,1.53,0.6213,0.5774,,,0.37,0.673,0.6024,,,0.132,0.6691,0.6611
,1.643,0.6701,0.6177,,,0.397,0.7302,0.6441,,,0.138,0.7173,0.7025
,1.76,0.7188,0.6578,,,0.423,0.7854,0.6866,,,0.144,0.7663,0.7441
,1.877,0.7689,0.6985,,,0.448,0.8383,0.7281,,,0.15,0.8163,0.7858
,1.997,0.8186,0.739,,,0.474,0.893,0.7706,,,0.156,0.8673,0.8272
,2.112,0.8685,0.7791,,,0.5,0.9477,0.8127,,,0.162,0.9192,0.8685
,2.234,0.9196,0.8193,,,0.526,1.003,0.8545,,,0.168,0.972,0.9097
,2.354,0.9708,0.8596,,,0.552,1.0585,0.896,,,0.174,1.0253,0.9511
,2.478,1.0227,0.8998,,,0.578,1.1137,0.9368,,,0.18,1.0792,0.9926
,2.602,1.0754,0.94,,,0.604,1.1687,0.977,,,0.186,1.1332,1.0338
,2.729,1.1289,0.9804,,,0.632,1.2277,1.0196,,,0.192,1.1873,1.0748
,2.856,1.183,1.0207,,,0.66,1.287,1.0622,,,0.198,1.2413,1.1155
,2.984,1.2371,1.061,,,0.688,1.3463,1.104,,,0.204,1.2951,1.1557
,3.115,1.2925,1.1013,,,0.716,1.4053,1.1452,,,0.212,1.3662,1.2084
,3.246,1.3484,1.1416,,,0.744,1.4642,1.1855,,,0.22,1.4366,1.2599
,3.384,1.4058,1.1821,,,0.772,1.5234,1.2261,,,0.228,1.5061,1.31
,3.518,1.4635,1.2226,,,0.802,1.5874,1.2686,,,0.236,1.5749,1.3586
,3.658,1.5223,1.2631,,,0.831,1.6493,1.3097,,,0.244,1.6429,1.4057
,3.799,1.582,1.3033,,,0.861,1.7128,1.3508,,,0.252,1.7105,1.4515
,3.94,1.6423,1.3436,,,0.892,1.7781,1.3925,,,0.26,1.7776,1.4962
,4.086,1.7032,1.3838,,,0.923,1.8435,1.4339,,,0.268,1.8445,1.5398
,4.233,1.7658,1.424,,,0.955,1.9114,1.4757,,,0.276,1.9114,1.5823
,4.382,1.8295,1.4644,,,0.987,1.9792,1.5168,,,0.284,1.9783,1.624
,4.538,1.8944,1.5045,,,1.02,2.0486,1.5581,,,0.292,2.0454,1.665
,4.695,1.9612,1.5447,,,1.054,2.1203,1.6001,,,0.3,2.1127,1.7053
,4.852,2.0284,1.5849,,,1.088,2.1927,1.6417,,,0.31,2.197,1.7546
,5.015,2.0966,1.625,,,1.122,2.265,1.682,,,0.32,2.2815,1.8024
,5.186,2.1688,1.6654,,,1.158,2.341,1.7236,,,0.33,2.3662,1.8489
,5.355,2.2408,1.7054,,,1.194,2.4173,1.7642,,,0.34,2.4511,1.8942
,5.529,2.3151,1.7457,,,1.232,2.4977,1.8059,,,0.35,2.536,1.938
,5.715,2.393,1.7861,,,1.271,2.5802,1.8472,,,0.36,2.6211,1.9802
,5.903,2.4724,1.8262,,,1.31,2.6625,1.8876,,,0.37,2.7061,2.0209
,6.096,2.5544,1.8666,,,1.35,2.7474,1.9279,,,0.382,2.8081,2.0681
,6.296,2.6393,1.9068,,,1.392,2.8364,1.9687,,,0.394,2.9099,2.1133
,6.496,2.7239,1.9451,,,1.436,2.9295,2.01,,,0.406,3.0116,2.1563
,6.696,2.809,1.9824,,,1.481,3.0249,2.0504,,,0.418,3.1131,2.1975
,6.896,2.8938,2.018,,,1.528,3.1242,2.0908,,,0.432,3.2316,2.2431
,7.096,2.9778,2.052,,,1.577,3.2275,2.1313,,,0.446,3.3502,2.286
,7.296,3.062,2.0845,,,1.628,3.336,2.1719,,,0.46,3.4687,2.3266
,7.496,3.1468,2.1166,,,1.682,3.4504,2.2125,,,0.476,3.604,2.3701
,7.696,3.232,2.1468,,,1.739,3.571,2.2529,,,0.493,3.7477,2.4129
,7.896,3.3164,2.1757,,,1.8,3.6997,2.2939,,,0.511,3.8999,2.4552
,8.096,3.4013,2.2036,,,1.864,3.8349,2.3347,,,0.531,4.0693,2.4982
,8.296,3.4864,2.2304,,,1.932,3.9797,2.3751,,,0.552,4.2474,2.5396
,8.496,3.5709,2.2561,,,2.007,4.1383,2.4156,,,0.576,4.4508,2.5817
,8.696,3.655,2.2801,,,2.088,4.3096,2.4561,,,0.603,4.6794,2.6227
,8.896,3.7392,2.3032,,,2.176,4.4954,2.4967,,,0.636,4.9585,2.6644
,9.096,3.8243,2.3254,,,2.275,4.7056,2.5368,,,0.678,5.3136,2.7053
,9.296,3.909,2.3467,,,2.392,4.9526,2.5773,,,0.756,5.9747,2.7456
,9.496,3.994,2.3677,,,2.531,5.2472,2.6176,,,0.899,7.1856,2.718
,9.696,4.0788,2.3869,,,2.718,5.6427,2.6562,,,0.953,7.6425,2.6779
,9.896,4.1636,2.4051,,,2.918,6.0666,2.6799,,,0.988,7.9386,2.6358
,10.096,4.2482,2.4225,,,3.118,6.4897,2.6862,,,1.006,8.0911,2.5935
,10.296,4.3324,2.4387,,,3.318,6.913,2.6766,,,1.017,8.1843,2.5474
,10.496,4.4168,2.4542,,,3.518,7.3359,2.6519,,,1.025,8.2521,2.5017
,10.696,4.5014,2.4692,,,3.716,7.756,2.6151,,,1.032,8.3115,2.4558
,10.896,4.5867,2.4834,,,3.867,8.0752,2.5748,,,1.038,8.3623,2.4148
,11.096,4.6712,2.4961,,,3.964,8.2806,2.5345,,,1.045,8.4215,2.3682
,11.296,4.7559,2.5081,,,4.017,8.3929,2.4939,,,1.053,8.4893,2.3198
,11.496,4.8408,2.5195,,,4.047,8.456,2.4521,,,1.062,8.5655,2.2746
,11.696,4.9253,2.5303,,,4.067,8.4982,2.4097,,,1.073,8.6586,2.2337
,11.896,5.0097,2.5397,,,4.083,8.532,2.3666,,,1.094,8.8364,2.1926
,12.096,5.0936,2.5483,,,4.097,8.5617,2.3249,,,1.241,10.0811,2.1644
,12.296,5.1789,2.5563,,,4.111,8.5915,2.2838,,,1.441,11.7744,2.1616
,12.496,5.2638,2.5632,,,4.128,8.6276,2.2403,,,1.641,13.4676,2.1679
,12.696,5.3484,2.5699,,,4.149,8.672,2.1987,,,1.841,15.161,2.1795
,12.896,5.4333,2.5756,,,4.182,8.7417,2.1571,,,2.041,16.8542,2.1891
,13.096,5.5183,2.5806,,,4.254,8.8947,2.1168,,,2.241,18.5476,2.1959
,13.296,5.6029,2.5848,,,4.454,9.3172,2.0922,,,2.441,20.2409,2.2017
,13.496,5.6869,2.5877,,,4.654,9.7407,2.0868,,,2.641,21.9344,2.2064
,13.696,5.7715,2.5899,,,4.854,10.1646,2.0831,,,2.841,23.6276,2.2095
,13.896,5.8563,2.5919,,,5.054,10.5876,2.0821,,,3.041,25.3212,2.2123
,14.096,5.9412,2.5932,,,5.254,11.0107,2.0837,,,3.241,27.014,2.2148
,14.296,6.0259,2.5937,,,5.454,11.4343,2.0865,,,3.441,28.7077,2.2162
,14.496,6.1106,2.5934,,,5.654,11.8578,2.0888,,,3.641,30.4011,2.2175
,14.696,6.1957,2.5928,,,5.854,12.2808,2.0904,,,3.841,32.0942,2.218
,14.896,6.2798,2.5903,,,6.054,12.7042,2.0922,,,4.041,33.7876,2.2179
,15.096,6.3645,2.5884,,,6.254,13.1276,2.0936,,,4.241,35.4809,2.2183
,15.296,6.4487,2.5852,,,6.454,13.5511,2.0948,,,4.441,37.1744,2.2183
,15.496,6.5335,2.5817,,,6.654,13.9738,2.0944,,,4.641,38.8679,2.219
,15.696,6.6183,2.5776,,,6.854,14.3977,2.0953,,,4.841,40.5608,2.2199
,15.896,6.7032,2.5732,,,7.054,14.821,2.0955,,,5.041,42.2545,2.2208
,16.096,6.7879,2.568,,,7.254,15.244,2.0955,,,5.241,43.9478,2.221
,16.296,6.8727,2.5626,,,7.454,15.6676,2.0956,,,5.441,45.6409,2.222
,16.496,6.9576,2.5568,,,7.654,16.0911,2.097,,,5.641,47.3342,2.2221
,16.696,7.0417,2.5497,,,7.854,16.514,2.0981,,,5.841,49.0275,2.2225
,16.896,7.126,2.5423,,,8.054,16.9373,2.0997,,,6.041,50.721,2.2228
,17.096,7.2108,2.5346,,,8.254,17.3612,2.1016,,,6.241,52.4144,2.2223
,17.296,7.2959,2.5272,,,8.454,17.7844,2.1034,,,6.441,54.1077,2.2226
,17.496,7.3806,2.5188,,,8.654,18.2075,2.1048,,,6.641,55.8007,2.2213
,17.696,7.4652,2.5098,,,8.854,18.631,2.1065,,,6.841,57.4945,2.22
,17.896,7.5506,2.5006,,,9.054,19.0548,2.1087,,,7.041,59.1876,2.2184
,18.096,7.6348,2.4901,,,9.254,19.4773,2.1097,,,7.241,60.8811,2.2148
,18.296,7.719,2.4791,,,9.454,19.9008,2.1109,,,7.441,62.5742,2.2097
,18.496,7.8033,2.4671,,,9.654,20.3246,2.1132,,,7.641,64.2676,2.198
,18.696,7.8884,2.4537,,,9.854,20.7475,2.1149,,,7.841,65.961,2.1791
,18.896,7.9731,2.4365,,,10.054,21.1708,2.1161,,,8.041,67.6544,2.1883
,19.096,8.0577,2.4124,,,10.254,21.5941,2.1174,,,8.241,69.3475,2.205
,19.28,8.1361,2.3749,,,10.454,22.0178,2.1193,,,8.441,71.0412,2.2245
,19.391,8.1828,2.3346,,,10.654,22.4407,2.1201,,,8.641,72.7344,2.2356
,19.469,8.2162,2.2938,,,10.854,22.8641,2.1213,,,8.841,74.4277,2.2413
,19.529,8.2411,2.2534,,,11.054,23.2877,2.1224,,,9.041,76.1209,2.2667
,19.585,8.2647,2.2126,,,11.254,23.7108,2.1236,,,9.241,77.8141,2.3063
,19.644,8.2894,2.1718,,,11.454,24.1339,2.1247,,,9.441,79.5077,2.3457
,19.715,8.3203,2.1312,,,11.654,24.5581,2.1262,,,9.641,81.2009,2.3813
,19.806,8.3584,2.0911,,,11.854,24.981,2.1271,,,9.841,82.8943,2.4122
,19.952,8.4206,2.0508,,,12.054,25.4041,2.128,,,10.041,84.5875,2.4378
,20.152,8.5054,2.0201,,,12.254,25.8278,2.129,,,10.241,86.2811,2.4617
,20.352,8.589,2.0027,,,12.454,26.2511,2.1299,,,10.441,87.9742,2.4841
,20.552,8.6737,1.9934,,,12.654,26.6741,2.1304,,,10.641,89.6678,2.5054
,20.752,8.7588,1.9877,,,12.854,27.0973,2.131,,,10.841,91.3607,2.5248
,20.952,8.8433,1.9837,,,13.054,27.5212,2.1322,,,11.041,93.0544,2.5435
,21.152,8.9281,1.9804,,,13.254,27.9441,2.133,,,11.241,94.7477,2.5601
,21.352,9.0129,1.9777,,,13.454,28.3675,2.1339,,,11.324,95.4502,2.4939
,21.552,9.098,1.9759,,,13.654,28.7906,2.1345,,,11.326,95.4672,2.4145
,21.752,9.1823,1.9736,,,13.854,29.2146,2.1362,,,11.328,95.4841,2.3125
,21.952,9.2668,1.9719,,,14.054,29.6371,2.1363,,,11.33,95.5011,2.1934
,22.152,9.3512,1.9694,,,14.254,30.0608,2.137,,,11.332,95.518,2.0621
,22.352,9.4359,1.9674,,,14.454,30.4844,2.1381,,,11.334,95.5349,1.9222
,22.552,9.5208,1.9659,,,14.654,30.9075,2.1386,,,11.336,95.5519,1.7773
,22.752,9.6055,1.9643,,,14.854,31.3309,2.1393,,,11.338,95.5688,1.6302
,22.952,9.6903,1.9631,,,15.054,31.7542,2.1401,,,11.34,95.5858,1.4835
,23.152,9.7752,1.9624,,,15.254,32.178,2.1411,,,,,
,23.352,9.86,1.9612,,,15.454,32.6006,2.1417,,,,,
,23.552,9.9441,1.9594,,,15.654,33.0244,2.1426,,,,,
,23.752,10.0285,1.9578,,,15.854,33.4478,2.1429,,,,,
,23.952,10.1133,1.957,,,16.054,33.8709,2.1433,,,,,
,24.152,10.1982,1.9564,,,16.254,34.294,2.1434,,,,,
,24.352,10.2828,1.956,,,16.454,34.7179,2.1443,,,,,
,24.552,10.3673,1.9554,,,16.654,35.1407,2.1445,,,,,
,24.752,10.4528,1.9558,,,16.854,35.5642,2.1451,,,,,
,24.952,10.5373,1.9554,,,17.054,35.9874,2.1453,,,,,
,25.152,10.6213,1.9552,,,17.254,36.4111,2.1464,,,,,
,25.352,10.7058,1.9556,,,17.454,36.8343,2.1467,,,,,
,25.552,10.7907,1.9565,,,17.654,37.2571,2.1465,,,,,
,25.752,10.8755,1.9568,,,17.854,37.6813,2.1474,,,,,
,25.952,10.96,1.9572,,,18.054,38.104,2.1476,,,,,
,26.152,11.0452,1.9579,,,18.254,38.5276,2.1478,,,,,
,26.352,11.1301,1.9586,,,18.454,38.9509,2.1476,,,,,
,26.552,11.2146,1.959,,,18.654,39.3748,2.1482,,,,,
,26.752,11.2987,1.9593,,,18.854,39.7972,2.1481,,,,,
,26.952,11.3831,1.9595,,,19.054,40.221,2.1486,,,,,
,27.152,11.4679,1.9595,,,19.254,40.6445,2.1494,,,,,
,27.352,11.5527,1.9597,,,19.454,41.0675,2.1492,,,,,
,27.552,11.6377,1.9602,,,19.654,41.4909,2.1494,,,,,
,27.752,11.7223,1.9604,,,19.854,41.9142,2.1495,,,,,
,27.952,11.8074,1.9614,,,20.054,42.338,2.1499,,,,,
,28.152,11.8919,1.9616,,,20.254,42.7604,2.1497,,,,,
,28.352,11.976,1.9611,,,20.454,43.1844,2.1497,,,,,
,28.552,12.0604,1.9612,,,20.654,43.6077,2.1503,,,,,
,28.752,12.1453,1.9616,,,20.854,44.0309,2.1501,,,,,
,28.952,12.2305,1.9623,,,21.054,44.4539,2.1497,,,,,
,29.152,12.3148,1.9619,,,21.254,44.8779,2.15,,,,,
,29.352,12.3998,1.9624,,,21.454,45.3008,2.1502,,,,,
,29.552,12.4848,1.9628,,,21.654,45.7241,2.1498,,,,,
,29.752,12.5693,1.9624,,,21.854,46.1477,2.1498,,,,,
,29.952,12.6532,1.9614,,,22.054,46.5711,2.1497,,,,,
,30.152,12.7377,1.9613,,,22.254,46.9943,2.1495,,,,,
,30.352,12.8229,1.9616,,,22.454,47.4172,2.1488,,,,,
,30.552,12.9076,1.9615,,,22.654,47.8416,2.1495,,,,,
,30.752,12.9924,1.962,,,22.854,48.2638,2.1487,,,,,
,30.952,13.0773,1.9622,,,23.054,48.6877,2.1485,,,,,
,31.152,13.1622,1.9622,,,23.254,49.1109,2.1482,,,,,
,31.352,13.2464,1.9618,,,23.454,49.5344,2.1478,,,,,
,31.552,13.3306,1.9614,,,23.654,49.9573,2.1472,,,,,
,31.752,13.4152,1.9616,,,23.854,50.3808,2.1468,,,,,
,31.952,13.5,1.9616,,,24.054,50.8046,2.1463,,,,,
,32.152,13.5849,1.9619,,,24.254,51.2274,2.1456,,,,,
,32.352,13.6696,1.9621,,,24.454,51.6509,2.1446,,,,,
,32.552,13.7545,1.9618,,,24.654,52.0741,2.1437,,,,,
,32.752,13.8393,1.962,,,24.854,52.4979,2.1429,,,,,
,32.952,13.9237,1.9618,,,25.054,52.9204,2.141,,,,,
,33.152,14.0081,1.9617,,,25.254,53.3444,2.1393,,,,,
,33.352,14.0925,1.9613,,,25.454,53.7676,2.1377,,,,,
,33.552,14.1775,1.9613,,,25.654,54.1911,2.1347,,,,,
,33.752,14.2623,1.9611,,,25.854,54.6141,2.1307,,,,,
,33.952,14.347,1.9612,,,26.054,55.0378,2.1256,,,,,
,34.152,14.4318,1.9613,,,26.254,55.4609,2.1189,,,,,
,34.352,14.5168,1.9617,,,26.454,55.8841,2.1107,,,,,
,34.552,14.6013,1.9617,,,26.654,56.3076,2.1018,,,,,
,34.752,14.6853,1.9617,,,26.854,56.731,2.094,,,,,
,34.952,14.7699,1.9618,,,27.054,57.1543,2.0874,,,,,
,35.152,14.8549,1.9621,,,27.254,57.5771,2.083,,,,,
,35.352,14.9396,1.962,,,27.454,58.0015,2.0802,,,,,
,35.552,15.0241,1.9622,,,27.654,58.4238,2.0781,,,,,
,35.752,15.1092,1.9628,,,27.854,58.8476,2.0767,,,,,
,35.952,15.1941,1.9635,,,28.054,59.2708,2.076,,,,,
,36.152,15.2782,1.9637,,,28.254,59.6944,2.0752,,,,,
,36.352,15.3627,1.9636,,,28.454,60.1175,2.0745,,,,,
,36.552,15.4471,1.9634,,,28.654,60.5408,2.0737,,,,,
,36.752,15.532,1.9638,,,28.854,60.9647,2.0729,,,,,
,36.952,15.6167,1.9642,,,29.054,61.3875,2.0719,,,,,
,37.152,15.7017,1.9647,,,29.254,61.8108,2.0698,,,,,
,37.352,15.7865,1.9653,,,29.454,62.2341,2.0657,,,,,
,37.552,15.8712,1.9653,,,29.654,62.6579,2.0561,,,,,
,37.752,15.9561,1.9655,,,29.854,63.0805,2.0316,,,,,
,37.952,16.0399,1.9647,,,30.054,63.5045,2.0045,,,,,
,38.152,16.1243,1.9649,,,30.254,63.9276,1.9885,,,,,
,38.352,16.2094,1.9653,,,30.454,64.3511,1.9798,,,,,
,38.552,16.2945,1.9661,,,30.654,64.7739,1.9813,,,,,
,38.752,16.3789,1.966,,,30.854,65.1977,1.9965,,,,,
,38.952,16.4637,1.9663,,,31.054,65.621,2.0248,,,,,
,39.152,16.5489,1.9667,,,31.254,66.0439,2.0606,,,,,
,39.352,16.6331,1.9665,,,31.454,66.4678,2.0938,,,,,
,39.552,16.7171,1.9666,,,31.654,66.8912,2.1187,,,,,
,39.752,16.8017,1.9673,,,31.854,67.3142,2.1325,,,,,
,39.952,16.8869,1.9681,,,32.054,67.7373,2.1376,,,,,
,40.152,16.9714,1.9686,,,32.254,68.1614,2.1403,,,,,
,40.352,17.0562,1.9687,,,32.454,68.584,2.1414,,,,,
,40.552,17.1413,1.9688,,,32.654,69.0075,2.1449,,,,,
,40.752,17.2259,1.9686,,,32.854,69.4309,2.1516,,,,,
,40.952,17.3104,1.9688,,,33.054,69.8545,2.1597,,,,,
,41.152,17.3942,1.9684,,,33.254,70.2775,2.1671,,,,,
,41.352,17.4791,1.9691,,,33.454,70.7008,2.1752,,,,,
,41.552,17.564,1.9693,,,33.654,71.1246,2.184,,,,,
,41.752,17.6489,1.9699,,,33.854,71.5475,2.1927,,,,,
,41.952,17.7338,1.9699,,,34.054,71.9708,2.2028,,,,,
,42.152,17.8185,1.9703,,,34.254,72.3944,2.2127,,,,,
,42.352,17.9033,1.9711,,,34.454,72.8178,2.2228,,,,,
,42.552,17.9876,1.9714,,,34.654,73.2407,2.2322,,,,,
,42.752,18.072,1.9715,,,34.854,73.6645,2.242,,,,,
,42.952,18.1564,1.9714,,,35.054,74.0877,2.2521,,,,,
,43.152,18.2415,1.9722,,,35.254,74.5109,2.2616,,,,,
,43.352,18.3264,1.9726,,,35.454,74.9338,2.2707,,,,,
,43.552,18.4109,1.9728,,,35.654,75.3577,2.2802,,,,,
,43.752,18.4957,1.9737,,,35.854,75.781,2.2907,,,,,
,43.952,18.5803,1.9739,,,36.054,76.2039,2.299,,,,,
,44.152,18.6651,1.9739,,,36.254,76.6277,2.3079,,,,,
,44.352,18.7488,1.9734,,,36.454,77.051,2.3165,,,,,
,44.552,18.8337,1.974,,,36.654,77.474,2.3249,,,,,
,44.752,18.919,1.9747,,,36.854,77.8973,2.3331,,,,,
,44.952,19.0035,1.9749,,,37.054,78.3214,2.3404,,,,,
,45.152,19.0882,1.9752,,,37.254,78.7442,2.3466,,,,,
,45.352,19.1731,1.9758,,,37.454,79.1677,2.3527,,,,,
,45.552,19.2581,1.976,,,37.654,79.5909,2.3587,,,,,
,45.752,19.3421,1.9759,,,37.854,80.0144,2.3646,,,,,
,45.952,19.4267,1.9759,,,38.054,80.4375,2.3709,,,,,
,46.152,19.5112,1.9766,,,38.254,80.8607,2.377,,,,,
,46.352,19.596,1.9766,,,38.454,81.2847,2.384,,,,,
,46.552,19.6809,1.9769,,,38.654,81.7073,2.3904,,,,,
,46.752,19.7657,1.9771,,,38.854,82.1308,2.3973,,,,,
,46.952,19.8505,1.9774,,,39.054,82.5542,2.4045,,,,,
,47.152,19.9351,1.9777,,,39.254,82.9778,2.4121,,,,,
,47.352,20.0198,1.9782,,,39.454,83.4006,2.4194,,,,,
,47.552,20.1039,1.9781,,,39.654,83.8242,2.4267,,,,,
,47.752,20.1884,1.9786,,,39.854,84.2477,2.4345,,,,,
,47.952,20.2734,1.979,,,40.054,84.6709,2.4418,,,,,
,48.152,20.3582,1.9794,,,40.254,85.0939,2.4488,,,,,
,48.352,20.4427,1.9794,,,40.454,85.5178,2.4553,,,,,
,48.552,20.5276,1.9802,,,40.654,85.9412,2.4618,,,,,
,48.752,20.6128,1.9812,,,40.854,86.3639,2.4686,,,,,
,48.952,20.6971,1.9815,,,41.054,86.788,2.4753,,,,,
,49.152,20.7812,1.9808,,,41.254,87.211,2.4817,,,,,
,49.352,20.8657,1.9807,,,41.454,87.6342,2.4873,,,,,
,49.552,20.9508,1.9809,,,41.654,88.0573,2.4931,,,,,
,49.752,21.0356,1.981,,,41.854,88.4812,2.4989,,,,,
,49.952,21.1201,1.9813,,,42.054,88.904,2.5045,,,,,
,50.152,21.2054,1.9823,,,42.254,89.3275,2.5099,,,,,
,50.352,21.2902,1.9823,,,42.454,89.7508,2.5151,,,,,
,50.552,21.3744,1.9821,,,42.654,90.1746,2.5207,,,,,
,50.752,21.4586,1.9819,,,42.854,90.5974,2.5253,,,,,
,50.952,21.5433,1.9821,,,43.054,91.0207,2.5306,,,,,
,51.152,21.6281,1.9827,,,43.254,91.4448,2.5361,,,,,
,51.352,21.7127,1.9834,,,43.454,91.8672,2.5404,,,,,
,51.552,21.7976,1.9836,,,43.654,92.2909,2.5451,,,,,
,51.752,21.8824,1.9839,,,43.854,92.7143,2.5494,,,,,
,51.952,21.9673,1.9841,,,44.054,93.138,2.5541,,,,,
,52.152,22.0517,1.984,,,44.254,93.5606,2.5584,,,,,
,52.352,22.1359,1.9841,,,44.454,93.9844,2.563,,,,,
,52.552,22.2203,1.9843,,,44.654,94.4078,2.5678,,,,,
,52.752,22.3054,1.9847,,,44.854,94.8308,2.5719,,,,,
,52.952,22.3903,1.985,,,45.054,95.254,2.5764,,,,,
,53.152,22.4749,1.9848,,,45.254,95.6779,2.5806,,,,,
,53.352,22.56,1.9853,,,45.454,96.1008,2.5846,,,,,
,53.552,22.6449,1.9856,,,45.654,96.524,2.5888,,,,,
,53.752,22.7291,1.9857,,,45.854,96.9479,2.5932,,,,,
,53.952,22.8132,1.9856,,,46.054,97.3708,2.5977,,,,,
,54.152,22.8979,1.9859,,,46.254,97.7942,2.6023,,,,,
,54.352,22.9831,1.9862,,,46.454,98.2172,2.6067,,,,,
,54.552,23.0676,1.9864,,,46.654,98.6414,2.6117,,,,,
,54.752,23.1523,1.9866,,,46.854,99.064,2.6162,,,,,
,54.952,23.2373,1.9871,,,47.054,99.4875,2.6212,,,,,
,55.152,23.322,1.9877,,,47.254,99.911,2.6259,,,,,
,55.352,23.4061,1.9877,,,47.454,100.3346,2.6305,,,,,
,55.552,23.4903,1.9875,,,47.507,100.4468,2.5715,,,,,
,55.752,23.5751,1.9877,,,47.509,100.451,2.496,,,,,
,55.952,23.6601,1.9881,,,47.511,100.4552,2.3958,,,,,
,56.152,23.745,1.9884,,,47.513,100.4594,2.277,,,,,
,56.352,23.8296,1.989,,,47.515,100.4636,2.1448,,,,,
,56.552,23.9147,1.9898,,,47.517,100.4678,2.0031,,,,,
,56.752,23.9994,1.9902,,,47.519,100.472,1.8555,,,,,
,56.952,24.0836,1.99,,,47.521,100.4762,1.705,,,,,
,57.152,24.1679,1.9901,,,47.523,100.4804,1.5544,,,,,
,57.352,24.2525,1.9901,,,,,,,,,,
,57.552,24.3376,1.9905,,,,,,,,,,
,57.752,24.4225,1.9908,,,,,,,,,,
,57.952,24.507,1.9908,,,,,,,,,,
,58.152,24.5918,1.9912,,,,,,,,,,
,58.352,24.6768,1.9914,,,,,,,,,,
,58.552,24.7611,1.9913,,,,,,,,,,
,58.752,24.845,1.9908,,,,,,,,,,
,58.952,24.9299,1.9911,,,,,,,,,,
,59.152,25.0149,1.9916,,,,,,,,,,
,59.352,25.0995,1.992,,,,,,,,,,
,59.552,25.184,1.9925,,,,,,,,,,
,59.752,25.2693,1.9931,,,,,,,,,,
,59.952,25.3542,1.9935,,,,,,,,,,
,60.152,25.4381,1.993,,,,,,,,,,
,60.352,25.5226,1.9932,,,,,,,,,,
,60.552,25.6072,1.9933,,,,,,,,,,
,60.752,25.6921,1.9937,,,,,,,,,,
,60.952,25.7768,1.9943,,,,,,,,,,
,61.152,25.8618,1.9946,,,,,,,,,,
,61.352,25.9466,1.9945,,,,,,,,,,
,61.552,26.0313,1.9948,,,,,,,,,,
,61.752,26.1159,1.9948,,,,,,,,,,
,61.952,26.1998,1.9945,,,,,,,,,,
,62.152,26.2845,1.9947,,,,,,,,,,
,62.352,26.3693,1.9952,,,,,,,,,,
,62.552,26.4544,1.9956,,,,,,,,,,
,62.752,26.5388,1.9953,,,,,,,,,,
,62.952,26.6238,1.9958,,,,,,,,,,
,63.152,26.7089,1.996,,,,,,,,,,
,63.352,26.7926,1.9955,,,,,,,,,,
,63.552,26.8769,1.9954,,,,,,,,,,
,63.752,26.9617,1.9959,,,,,,,,,,
,63.952,27.047,1.9967,,,,,,,,,,
,64.152,27.1314,1.9965,,,,,,,,,,
,64.352,27.2162,1.9967,,,,,,,,,,
,64.552,27.3015,1.9971,,,,,,,,,,
,64.752,27.386,1.997,,,,,,,,,,
,64.952,27.4701,1.9968,,,,,,,,,,
,65.152,27.5543,1.9968,,,,,,,,,,
,65.352,27.6394,1.9973,,,,,,,,,,
,65.552,27.7241,1.9975,,,,,,,,,,
,65.752,27.8089,1.9973,,,,,,,,,,
,65.952,27.8939,1.9976,,,,,,,,,,
,66.152,27.9787,1.9974,,,,,,,,,,
,66.352,28.0633,1.9975,,,,,,,,,,
,66.552,28.1472,1.9968,,,,,,,,,,
,66.752,28.2318,1.9969,,,,,,,,,,
,66.952,28.3162,1.9972,,,,,,,,,,
,67.152,28.4014,1.9978,,,,,,,,,,
,67.352,28.4864,1.9983,,,,,,,,,,
,67.552,28.5709,1.9982,,,,,,,,,,
,67.752,28.6557,1.9984,,,,,,,,,,
,67.952,28.7406,1.9987,,,,,,,,,,
,68.152,28.8249,1.9986,,,,,,,,,,
,68.352,28.909,1.9983,,,,,,,,,,
,68.552,28.9939,1.9989,,,,,,,,,,
,68.752,29.079,1.9993,,,,,,,,,,
,68.952,29.1636,1.9995,,,,,,,,,,
,69.152,29.2483,1.9994,,,,,,,,,,
,69.352,29.3332,1.9997,,,,,,,,,,
,69.552,29.4181,1.9997,,,,,,,,,,
,69.752,29.5018,1.9989,,,,,,,,,,
,69.952,29.5864,1.9991,,,,,,,,,,
,70.152,29.6714,1.9993,,,,,,,,,,
,70.352,29.7561,1.9997,,,,,,,,,,
,70.552,29.8409,1.9999,,,,,,,,,,
,70.752,29.9256,1.9999,,,,,,,,,,
,70.952,30.0106,2,,,,,,,,,,
,71.152,30.0951,1.9997,,,,,,,,,,
,71.352,30.1796,1.9997,,,,,,,,,,
,71.552,30.2639,1.9993,,,,,,,,,,
,71.752,30.3485,1.9995,,,,,,,,,,
,71.952,30.4334,1.9997,,,,,,,,,,
,72.152,30.5183,1.9998,,,,,,,,,,
,72.352,30.6029,2.0002,,,,,,,,,,
,72.552,30.6877,2.0004,,,,,,,,,,
,72.752,30.7728,2.0005,,,,,,,,,,
,72.952,30.8569,2.0003,,,,,,,,,,
,73.152,30.9411,2.0002,,,,,,,,,,
,73.352,31.026,2.0005,,,,,,,,,,
,73.552,31.111,2.0009,,,,,,,,,,
,73.752,31.1955,2.0008,,,,,,,,,,
,73.952,31.2801,2.001,,,,,,,,,,
,74.152,31.3654,2.0016,,,,,,,,,,
,74.352,31.45,2.0014,,,,,,,,,,
,74.552,31.5341,2.0011,,,,,,,,,,
,74.752,31.6185,2.0007,,,,,,,,,,
,74.952,31.7033,2.0011,,,,,,,,,,
,75.152,31.7881,2.0011,,,,,,,,,,
,75.352,31.8728,2.0015,,,,,,,,,,
,75.552,31.9578,2.002,,,,,,,,,,
,75.752,32.0427,2.002,,,,,,,,,,
,75.952,32.1274,2.0021,,,,,,,,,,
,76.152,32.2115,2.002,,,,,,,,,,
,76.352,32.2959,2.0019,,,,,,,,,,
,76.552,32.3806,2.0022,,,,,,,,,,
,76.752,32.4655,2.0026,,,,,,,,,,
,76.952,32.5505,2.0029,,,,,,,,,,
,77.152,32.6351,2.0027,,,,,,,,,,
,77.352,32.7201,2.003,,,,,,,,,,
,77.552,32.8047,2.003,,,,,,,,,,
,77.752,32.889,2.0027,,,,,,,,,,
,77.952,32.9731,2.0028,,,,,,,,,,
,78.152,33.0578,2.0031,,,,,,,,,,
,78.352,33.143,2.0034,,,,,,,,,,
,78.552,33.2275,2.0035,,,,,,,,,,
,78.752,33.3124,2.0034,,,,,,,,,,
,78.952,33.3972,2.0033,,,,,,,,,,
,79.152,33.4821,2.0035,,,,,,,,,,
,79.352,33.5661,2.0034,,,,,,,,,,
,79.552,33.6503,2.0032,,,,,,,,,,
,79.752,33.7354,2.0038,,,,,,,,,,
,79.952,33.8202,2.004,,,,,,,,,,
,80.152,33.9051,2.0044,,,,,,,,,,
,80.352,33.9899,2.0045,,,,,,,,,,
,80.552,34.0747,2.0043,,,,,,,,,,
,80.752,34.1593,2.0043,,,,,,,,,,
,80.952,34.2435,2.0041,,,,,,,,,,
,81.152,34.3279,2.004,,,,,,,,,,
,81.352,34.4126,2.004,,,,,,,,,,
,81.552,34.4977,2.0044,,,,,,,,,,
,81.752,34.5824,2.0044,,,,,,,,,,
,81.952,34.667,2.0043,,,,,,,,,,
,82.152,34.7518,2.0044,,,,,,,,,,
,82.352,34.8367,2.0048,,,,,,,,,,
,82.552,34.9208,2.0046,,,,,,,,,,
,82.752,35.0048,2.0043,,,,,,,,,,
,82.952,35.09,2.0048,,,,,,,,,,
,83.152,35.1749,2.0051,,,,,,,,,,
,83.352,35.2595,2.0051,,,,,,,,,,
,83.552,35.3442,2.0051,,,,,,,,,,
,83.752,35.4294,2.0052,,,,,,,,,,
,83.952,35.5141,2.0054,,,,,,,,,,
,84.152,35.598,2.005,,,,,,,,,,
,84.352,35.6826,2.0051,,,,,,,,,,
,84.552,35.7674,2.0053,,,,,,,,,,
,84.752,35.8522,2.0055,,,,,,,,,,
,84.952,35.9368,2.0057,,,,,,,,,,
,85.152,36.0218,2.0059,,,,,,,,,,
,85.352,36.1066,2.0061,,,,,,,,,,
,85.552,36.1912,2.0059,,,,,,,,,,
,85.752,36.2755,2.0054,,,,,,,,,,
,85.952,36.3597,2.0053,,,,,,,,,,
,86.152,36.4446,2.0056,,,,,,,,,,
,86.352,36.5292,2.0055,,,,,,,,,,
,86.552,36.6142,2.0061,,,,,,,,,,
,86.752,36.6988,2.0062,,,,,,,,,,
,86.952,36.7838,2.0065,,,,,,,,,,
,87.152,36.8689,2.0066,,,,,,,,,,
,87.352,36.9527,2.0058,,,,,,,,,,
,87.552,37.037,2.0054,,,,,,,,,,
,87.752,37.1217,2.0057,,,,,,,,,,
,87.952,37.2071,2.006,,,,,,,,,,
,88.152,37.2914,2.0058,,,,,,,,,,
,88.352,37.3763,2.0062,,,,,,,,,,
,88.552,37.4615,2.0063,,,,,,,,,,
,88.752,37.5458,2.0059,,,,,,,,,,
,88.952,37.63,2.0055,,,,,,,,,,
,89.152,37.7143,2.0056,,,,,,,,,,
,89.352,37.7994,2.0062,,,,,,,,,,
,89.552,37.8839,2.0057,,,,,,,,,,
,89.752,37.9689,2.0059,,,,,,,,,,
,89.952,38.0538,2.0061,,,,,,,,,,
,90.152,38.1386,2.0061,,,,,,,,,,
,90.352,38.2231,2.0059,,,,,,,,,,
,90.552,38.3072,2.0056,,,,,,,,,,
,90.752,38.3917,2.0056,,,,,,,,,,
,90.952,38.4765,2.0057,,,,,,,,,,
,91.152,38.5615,2.0061,,,,,,,,,,
,91.352,38.6464,2.0062,,,,,,,,,,
,91.552,38.7312,2.006,,,,,,,,,,
,91.752,38.8159,2.0058,,,,,,,,,,
,91.952,38.9004,2.0056,,,,,,,,,,
,92.152,38.9848,2.0053,,,,,,,,,,
,92.352,39.0688,2.005,,,,,,,,,,
,92.552,39.154,2.0057,,,,,,,,,,
,92.752,39.2391,2.0059,,,,,,,,,,
,92.952,39.3237,2.0061,,,,,,,,,,
,93.152,39.4084,2.0059,,,,,,,,,,
,93.352,39.4934,2.0062,,,,,,,,,,
,93.552,39.5778,2.0063,,,,,,,,,,
,93.752,39.6618,2.0057,,,,,,,,,,
,93.952,39.7465,2.0058,,,,,,,,,,
,94.152,39.8315,2.006,,,,,,,,,,
,94.352,39.9162,2.0062,,,,,,,,,,
,94.552,40.0007,2.006,,,,,,,,,,
,94.752,40.0857,2.0063,,,,,,,,,,
,94.952,40.1706,2.0063,,,,,,,,,,
,95.152,40.2549,2.0062,,,,,,,,,,
,95.352,40.3394,2.0058,,,,,,,,,,
,95.552,40.4238,2.0055,,,,,,,,,,
,95.752,40.5088,2.0057,,,,,,,,,,
,95.952,40.5936,2.006,,,,,,,,,,
,96.152,40.6783,2.0057,,,,,,,,,,
,96.352,40.7632,2.006,,,,,,,,,,
,96.552,40.8479,2.0058,,,,,,,,,,
,96.752,40.9327,2.006,,,,,,,,,,
,96.952,41.0167,2.0055,,,,,,,,,,
,97.152,41.1011,2.0055,,,,,,,,,,
,97.352,41.1861,2.0057,,,,,,,,,,
,97.552,41.271,2.0057,,,,,,,,,,
,97.752,41.3554,2.0059,,,,,,,,,,
,97.952,41.4402,2.0063,,,,,,,,,,
,98.152,41.5254,2.0063,,,,,,,,,,
,98.352,41.6098,2.006,,,,,,,,,,
,98.552,41.694,2.0054,,,,,,,,,,
,98.752,41.7785,2.0054,,,,,,,,,,
,98.952,41.8635,2.0057,,,,,,,,,,
,99.152,41.9482,2.0059,,,,,,,,,,
,99.352,42.0329,2.0063,,,,,,,,,,
,99.552,42.1179,2.0064,,,,,,,,,,
,99.752,42.2028,2.0063,,,,,,,,,,
,99.952,42.2872,2.006,,,,,,,,,,
,100.152,42.3714,2.0056,,,,,,,,,,
,100.352,42.456,2.005,,,,,,,,,,
,100.552,42.5407,2.005,,,,,,,,,,
,100.752,42.6254,2.0056,,,,,,,,,,
,100.952,42.7104,2.0054,,,,,,,,,,
,101.152,42.7952,2.0055,,,,,,,,,,
,101.352,42.88,2.0053,,,,,,,,,,
,101.552,42.9644,2.0051,,,,,,,,,,
,101.752,43.0488,2.0047,,,,,,,,,,
,101.952,43.133,2.0043,,,,,,,,,,
,102.152,43.218,2.0045,,,,,,,,,,
,102.352,43.303,2.0049,,,,,,,,,,
,102.552,43.3876,2.005,,,,,,,,,,
,102.752,43.4724,2.0054,,,,,,,,,,
,102.952,43.5576,2.0054,,,,,,,,,,
,103.152,43.642,2.0052,,,,,,,,,,
,103.352,43.7258,2.0045,,,,,,,,,,
,103.552,43.8104,2.0045,,,,,,,,,,
,103.752,43.8955,2.0044,,,,,,,,,,
,103.952,43.9802,2.0044,,,,,,,,,,
,104.152,44.065,2.0047,,,,,,,,,,
,104.352,44.1499,2.0051,,,,,,,,,,
,104.552,44.2348,2.0054,,,,,,,,,,
,104.752,44.319,2.005,,,,,,,,,,
,104.952,44.4033,2.0046,,,,,,,,,,
,105.152,44.488,2.0046,,,,,,,,,,
,105.352,44.5727,2.0046,,,,,,,,,,
,105.552,44.6577,2.0046,,,,,,,,,,
,105.752,44.7422,2.0048,,,,,,,,,,
,105.952,44.8269,2.0047,,,,,,,,,,
,106.152,44.9119,2.0051,,,,,,,,,,
,106.352,44.9965,2.0052,,,,,,,,,,
,106.552,45.0806,2.0049,,,,,,,,,,
,106.752,45.165,2.0048,,,,,,,,,,
,106.952,45.2502,2.005,,,,,,,,,,
,107.152,45.335,2.0048,,,,,,,,,,
,107.352,45.4195,2.0047,,,,,,,,,,
,107.552,45.5043,2.0049,,,,,,,,,,
,107.752,45.5895,2.0052,,,,,,,,,,
,107.952,45.6738,2.0051,,,,,,,,,,
,108.152,45.7579,2.0047,,,,,,,,,,
,108.352,45.8426,2.0051,,,,,,,,,,
,108.552,45.9274,2.005,,,,,,,,,,
,108.752,46.0123,2.0049,,,,,,,,,,
,108.952,46.0965,2.0048,,,,,,,,,,
,109.152,46.1818,2.005,,,,,,,,,,
,109.352,46.2667,2.0049,,,,,,,,,,
,109.552,46.3511,2.0048,,,,,,,,,,
,109.752,46.4353,2.0048,,,,,,,,,,
,109.952,46.5198,2.0047,,,,,,,,,,
,110.152,46.6046,2.0047,,,,,,,,,,
,110.352,46.6893,2.0052,,,,,,,,,,
,110.552,46.7743,2.0054,,,,,,,,,,
,110.752,46.8591,2.0056,,,,,,,,,,
,110.952,46.944,2.0056,,,,,,,,,,
,111.152,47.0285,2.0054,,,,,,,,,,
,111.352,47.1127,2.0048,,,,,,,,,,
,111.552,47.1972,2.0046,,,,,,,,,,
,111.752,47.2817,2.0043,,,,,,,,,,
,111.952,47.3671,2.0046,,,,,,,,,,
,112.152,47.4513,2.0044,,,,,,,,,,
,112.352,47.5364,2.0048,,,,,,,,,,
,112.552,47.6216,2.0051,,,,,,,,,,
,112.752,47.7058,2.005,,,,,,,,,,
,112.952,47.7898,2.0044,,,,,,,,,,
,113.152,47.8744,2.0041,,,,,,,,,,
,113.352,47.9596,2.0043,,,,,,,,,,
,113.552,48.0439,2.004,,,,,,,,,,
,113.752,48.1288,2.0038,,,,,,,,,,
,113.952,48.2138,2.0038,,,,,,,,,,
,114.152,48.2986,2.0039,,,,,,,,,,
,114.352,48.383,2.0039,,,,,,,,,,
,114.552,48.4673,2.0036,,,,,,,,,,
,114.752,48.5518,2.0034,,,,,,,,,,
,114.952,48.6365,2.0034,,,,,,,,,,
,115.152,48.7216,2.0038,,,,,,,,,,
,115.352,48.8063,2.0036,,,,,,,,,,
,115.552,48.8911,2.0033,,,,,,,,,,
,115.752,48.976,2.0036,,,,,,,,,,
,115.952,49.0604,2.0034,,,,,,,,,,
,116.152,49.1445,2.0031,,,,,,,,,,
,116.352,49.2291,2.0031,,,,,,,,,,
,116.552,49.314,2.0035,,,,,,,,,,
,116.752,49.399,2.0036,,,,,,,,,,
,116.952,49.4837,2.0034,,,,,,,,,,
,117.152,49.5683,2.0031,,,,,,,,,,
,117.352,49.6534,2.0032,,,,,,,,,,
,117.552,49.7377,2.0028,,,,,,,,,,
,117.752,49.8217,2.0028,,,,,,,,,,
,117.952,49.9065,2.0028,,,,,,,,,,
,118.152,49.9915,2.0032,,,,,,,,,,
,118.352,50.0763,2.0031,,,,,,,,,,
,118.552,50.161,2.0034,,,,,,,,,,
,118.752,50.2459,2.0035,,,,,,,,,,
,118.952,50.3308,2.0037,,,,,,,,,,
,119.152,50.4149,2.0033,,,,,,,,,,
,119.352,50.4992,2.0026,,,,,,,,,,
,119.552,50.584,2.0027,,,,,,,,,,
,119.752,50.6688,2.0023,,,,,,,,,,
,119.952,50.7535,2.0023,,,,,,,,,,
,120.152,50.8384,2.0023,,,,,,,,,,
,120.352,50.9231,2.0022,,,,,,,,,,
,120.552,51.0079,2.0024,,,,,,,,,,
,120.752,51.0923,2.0025,,,,,,,,,,
,120.952,51.1765,2.0021,,,,,,,,,,
,121.152,51.2613,2.0021,,,,,,,,,,
,121.352,51.3462,2.002,,,,,,,,,,
,121.552,51.4309,2.0022,,,,,,,,,,
,121.752,51.5156,2.0021,,,,,,,,,,
,121.952,51.6004,2.0019,,,,,,,,,,
,122.152,51.6856,2.002,,,,,,,,,,
,122.352,51.7698,2.0016,,,,,,,,,,
,122.552,51.854,2.0012,,,,,,,,,,
,122.752,51.9385,2.0008,,,,,,,,,,
,122.952,52.0236,2.0013,,,,,,,,,,
,123.152,52.1081,2.0008,,,,,,,,,,
,123.352,52.1928,2.001,,,,,,,,,,
,123.552,52.2779,2.0013,,,,,,,,,,
,123.752,52.3629,2.0014,,,,,,,,,,
,123.952,52.4471,2.0012,,,,,,,,,,
,124.152,52.5311,2.0008,,,,,,,,,,
,124.352,52.6161,2.0009,,,,,,,,,,
,124.552,52.7009,2.0006,,,,,,,,,,
,124.752,52.7854,2.0007,,,,,,,,,,
,124.952,52.8703,2.0008,,,,,,,,,,
,125.152,52.9552,2.0008,,,,,,,,,,
,125.352,53.0401,2.0006,,,,,,,,,,
,125.552,53.1243,2.0004,,,,,,,,,,
,125.752,53.2085,1.9999,,,,,,,,,,
,125.952,53.293,1.9998,,,,,,,,,,
,126.152,53.3781,2.0002,,,,,,,,,,
,126.352,53.4631,2.0001,,,,,,,,,,
,126.552,53.5476,2.0001,,,,,,,,,,
,126.752,53.6325,2.0003,,,,,,,,,,
,126.952,53.7174,2.0007,,,,,,,,,,
,127.152,53.8017,2.0002,,,,,,,,,,
,127.352,53.8856,1.9998,,,,,,,,,,
,127.552,53.9706,2,,,,,,,,,,
,127.752,54.0557,2.0003,,,,,,,,,,
,127.952,54.1402,1.9999,,,,,,,,,,
,128.152,54.225,1.9998,,,,,,,,,,
,128.352,54.31,1.9997,,,,,,,,,,
,128.552,54.3948,1.9995,,,,,,,,,,
,128.752,54.4788,1.999,,,,,,,,,,
,128.952,54.5631,1.9986,,,,,,,,,,
,129.152,54.6479,1.9983,,,,,,,,,,
,129.352,54.7327,1.9982,,,,,,,,,,
,129.552,54.8177,1.9981,,,,,,,,,,
,129.752,54.9021,1.9977,,,,,,,,,,
,129.952,54.9872,1.9977,,,,,,,,,,
,130.152,55.0719,1.9978,,,,,,,,,,
,130.352,55.1563,1.9974,,,,,,,,,,
,130.552,55.2404,1.997,,,,,,,,,,
,130.752,55.3253,1.997,,,,,,,,,,
,130.952,55.4104,1.9967,,,,,,,,,,
,131.152,55.4948,1.9966,,,,,,,,,,
,131.352,55.5796,1.9966,,,,,,,,,,
,131.552,55.6644,1.9962,,,,,,,,,,
,131.752,55.7494,1.996,,,,,,,,,,
,131.952,55.8336,1.9956,,,,,,,,,,
,132.152,55.9178,1.9952,,,,,,,,,,
,132.352,56.0027,1.9952,,,,,,,,,,
,132.552,56.0875,1.9949,,,,,,,,,,
,132.752,56.1721,1.9946,,,,,,,,,,
,132.952,56.2566,1.9941,,,,,,,,,,
,133.152,56.3419,1.9945,,,,,,,,,,
,133.352,56.4267,1.9942,,,,,,,,,,
,133.552,56.5108,1.9941,,,,,,,,,,
,133.752,56.5951,1.9933,,,,,,,,,,
,133.952,56.68,1.9932,,,,,,,,,,
,134.152,56.7647,1.993,,,,,,,,,,
,134.352,56.8492,1.9925,,,,,,,,,,
,134.552,56.9344,1.9924,,,,,,,,,,
,134.752,57.019,1.9919,,,,,,,,,,
,134.952,57.1039,1.9916,,,,,,,,,,
,135.152,57.1884,1.9911,,,,,,,,,,
,135.352,57.2727,1.9904,,,,,,,,,,
,135.552,57.3572,1.9897,,,,,,,,,,
,135.752,57.4421,1.9894,,,,,,,,,,
,135.952,57.5269,1.9892,,,,,,,,,,
,136.152,57.6115,1.9886,,,,,,,,,,
,136.352,57.6965,1.9882,,,,,,,,,,
,136.552,57.7813,1.9877,,,,,,,,,,
,136.752,57.8656,1.9867,,,,,,,,,,
,136.952,57.9497,1.9854,,,,,,,,,,
,137.152,58.0343,1.9848,,,,,,,,,,
,137.352,58.1195,1.9842,,,,,,,,,,
,137.552,58.2039,1.9835,,,,,,,,,,
,137.752,58.2888,1.9827,,,,,,,,,,
,137.952,58.374,1.982,,,,,,,,,,
,138.152,58.4588,1.9809,,,,,,,,,,
,138.352,58.5429,1.9799,,,,,,,,,,
,138.552,58.6271,1.9787,,,,,,,,,,
,138.752,58.712,1.9779,,,,,,,,,,
,138.952,58.7967,1.9771,,,,,,,,,,
,139.152,58.8816,1.9766,,,,,,,,,,
,139.352,58.9665,1.9756,,,,,,,,,,
,139.552,59.0513,1.975,,,,,,,,,,
,139.752,59.1359,1.9745,,,,,,,,,,
,139.952,59.2202,1.9738,,,,,,,,,,
,140.152,59.3044,1.9732,,,,,,,,,,
,140.352,59.3892,1.9733,,,,,,,,,,
,140.552,59.4742,1.9733,,,,,,,,,,
,140.752,59.5589,1.9736,,,,,,,,,,
,140.952,59.6436,1.9737,,,,,,,,,,
,141.152,59.7285,1.9742,,,,,,,,,,
,141.352,59.8134,1.9746,,,,,,,,,,
,141.552,59.8975,1.9746,,,,,,,,,,
,141.752,59.9817,1.9749,,,,,,,,,,
,141.952,60.0666,1.9755,,,,,,,,,,
,142.152,60.1516,1.9763,,,,,,,,,,
,142.352,60.2363,1.9767,,,,,,,,,,
,142.552,60.3209,1.9772,,,,,,,,,,
,142.752,60.406,1.9782,,,,,,,,,,
,142.952,60.4906,1.9789,,,,,,,,,,
,143.152,60.5747,1.9794,,,,,,,,,,
,143.352,60.6593,1.9801,,,,,,,,,,
,143.552,60.7441,1.9812,,,,,,,,,,
,143.752,60.829,1.9822,,,,,,,,,,
,143.952,60.9135,1.9832,,,,,,,,,,
,144.152,60.9984,1.9842,,,,,,,,,,
,144.352,61.0832,1.9852,,,,,,,,,,
,144.552,61.1678,1.9861,,,,,,,,,,
,144.752,61.2522,1.9872,,,,,,,,,,
,144.952,61.3365,1.9879,,,,,,,,,,
,145.152,61.4213,1.9889,,,,,,,,,,
,145.352,61.5061,1.99,,,,,,,,,,
,145.552,61.591,1.9913,,,,,,,,,,
,145.752,61.6757,1.9921,,,,,,,,,,
,145.952,61.7605,1.9934,,,,,,,,,,
,146.152,61.8453,1.9945,,,,,,,,,,
,146.352,61.9296,1.9954,,,,,,,,,,
,146.552,62.0139,1.9964,,,,,,,,,,
,146.752,62.0986,1.9977,,,,,,,,,,
,146.952,62.1837,1.9989,,,,,,,,,,
,147.152,62.2683,2.0001,,,,,,,,,,
,147.352,62.3529,2.0017,,,,,,,,,,
,147.552,62.4381,2.003,,,,,,,,,,
,147.752,62.5228,2.0042,,,,,,,,,,
,147.952,62.6069,2.005,,,,,,,,,,
,148.152,62.6912,2.0059,,,,,,,,,,
,148.352,62.776,2.0068,,,,,,,,,,
,148.552,62.8607,2.0081,,,,,,,,,,
,148.752,62.9455,2.0092,,,,,,,,,,
,148.952,63.0303,2.0103,,,,,,,,,,
,149.152,63.1153,2.0113,,,,,,,,,,
,149.352,63.2,2.0124,,,,,,,,,,
,149.552,63.2842,2.0132,,,,,,,,,,
,149.752,63.3686,2.0136,,,,,,,,,,
,149.952,63.4533,2.0148,,,,,,,,,,
,150.152,63.5383,2.0157,,,,,,,,,,
,150.352,63.6231,2.0166,,,,,,,,,,
,150.552,63.7078,2.0175,,,,,,,,,,
,150.752,63.7928,2.0181,,,,,,,,,,
,150.952,63.8773,2.019,,,,,,,,,,
,151.152,63.9615,2.0196,,,,,,,,,,
,151.352,64.0457,2.02,,,,,,,,,,
,151.552,64.1306,2.021,,,,,,,,,,
,151.752,64.2156,2.0219,,,,,,,,,,
,151.952,64.3001,2.0224,,,,,,,,,,
,152.152,64.3849,2.0231,,,,,,,,,,
,152.352,64.47,2.0239,,,,,,,,,,
,152.552,64.5546,2.0245,,,,,,,,,,
,152.752,64.6385,2.0245,,,,,,,,,,
,152.952,64.7231,2.0252,,,,,,,,,,
,153.152,64.808,2.0258,,,,,,,,,,
,153.352,64.893,2.0266,,,,,,,,,,
,153.552,64.9776,2.027,,,,,,,,,,
,153.752,65.0624,2.0276,,,,,,,,,,
,153.952,65.1475,2.0283,,,,,,,,,,
,154.152,65.2317,2.0285,,,,,,,,,,
,154.352,65.3162,2.029,,,,,,,,,,
,154.552,65.4005,2.0291,,,,,,,,,,
,154.752,65.4854,2.0299,,,,,,,,,,
,154.952,65.5704,2.0306,,,,,,,,,,
,155.152,65.6549,2.031,,,,,,,,,,
,155.352,65.7395,2.0316,,,,,,,,,,
,155.552,65.8243,2.0323,,,,,,,,,,
,155.752,65.9093,2.0329,,,,,,,,,,
,155.952,65.9931,2.0327,,,,,,,,,,
,156.152,66.0775,2.033,,,,,,,,,,
,156.352,66.1626,2.0338,,,,,,,,,,
,156.552,66.2475,2.0339,,,,,,,,,,
,156.752,66.3321,2.0345,,,,,,,,,,
,156.952,66.4167,2.035,,,,,,,,,,
,157.152,66.5021,2.0359,,,,,,,,,,
,157.352,66.5863,2.0361,,,,,,,,,,
,157.552,66.6707,2.0364,,,,,,,,,,
,157.752,66.7552,2.0365,,,,,,,,,,
,157.952,66.8401,2.0371,,,,,,,,,,
,158.152,66.9248,2.0375,,,,,,,,,,
,158.352,67.0094,2.0379,,,,,,,,,,
,158.552,67.0944,2.0381,,,,,,,,,,
,158.752,67.1794,2.0386,,,,,,,,,,
,158.952,67.2638,2.0389,,,,,,,,,,
,159.152,67.348,2.0387,,,,,,,,,,
,159.352,67.4326,2.0388,,,,,,,,,,
,159.552,67.5172,2.0386,,,,,,,,,,
,159.752,67.602,2.0391,,,,,,,,,,
,159.952,67.687,2.0394,,,,,,,,,,
,160.152,67.7714,2.0396,,,,,,,,,,
,160.352,67.8566,2.0406,,,,,,,,,,
,160.552,67.9412,2.0416,,,,,,,,,,
,160.752,68.0254,2.0423,,,,,,,,,,
,160.952,68.1097,2.0434,,,,,,,,,,
,161.152,68.1946,2.0451,,,,,,,,,,
,161.352,68.2797,2.0468,,,,,,,,,,
,161.552,68.3642,2.0484,,,,,,,,,,
,161.752,68.4489,2.0502,,,,,,,,,,
,161.952,68.5341,2.0522,,,,,,,,,,
,162.152,68.6187,2.0534,,,,,,,,,,
,162.352,68.7025,2.0551,,,,,,,,,,
,162.552,68.7869,2.0566,,,,,,,,,,
,162.752,68.8721,2.0588,,,,,,,,,,
,162.952,68.9568,2.0609,,,,,,,,,,
,163.152,69.0415,2.063,,,,,,,,,,
,163.352,69.1264,2.0652,,,,,,,,,,
,163.552,69.2115,2.0676,,,,,,,,,,
,163.752,69.2959,2.0697,,,,,,,,,,
,163.952,69.38,2.0719,,,,,,,,,,
,164.152,69.4646,2.0742,,,,,,,,,,
,164.352,69.5493,2.0767,,,,,,,,,,
,164.552,69.6343,2.0795,,,,,,,,,,
,164.752,69.719,2.0818,,,,,,,,,,
,164.952,69.8037,2.0844,,,,,,,,,,
,165.152,69.8886,2.087,,,,,,,,,,
,165.352,69.9732,2.0895,,,,,,,,,,
,165.552,70.0573,2.0922,,,,,,,,,,
,165.752,70.1417,2.0949,,,,,,,,,,
,165.952,70.2266,2.0977,,,,,,,,,,
,166.152,70.3117,2.1005,,,,,,,,,,
,166.352,70.3964,2.1031,,,,,,,,,,
,166.552,70.4811,2.1059,,,,,,,,,,
,166.752,70.5661,2.109,,,,,,,,,,
,166.952,70.6506,2.1117,,,,,,,,,,
,167.152,70.7345,2.1144,,,,,,,,,,
,167.352,70.8191,2.1174,,,,,,,,,,
,167.552,70.9042,2.1208,,,,,,,,,,
,167.752,70.9889,2.1235,,,,,,,,,,
,167.952,71.0735,2.1264,,,,,,,,,,
,168.152,71.1585,2.1291,,,,,,,,,,
,168.352,71.2433,2.1321,,,,,,,,,,
,168.552,71.3277,2.1349,,,,,,,,,,
,168.752,71.412,2.1377,,,,,,,,,,
,168.952,71.4967,2.1409,,,,,,,,,,
,169.152,71.5814,2.1437,,,,,,,,,,
,169.352,71.6661,2.1462,,,,,,,,,,
,169.552,71.7511,2.149,,,,,,,,,,
,169.752,71.8358,2.1519,,,,,,,,,,
,169.952,71.9206,2.1549,,,,,,,,,,
,170.152,72.0052,2.1581,,,,,,,,,,
,170.352,72.0894,2.1606,,,,,,,,,,
,170.552,72.1739,2.1634,,,,,,,,,,
,170.752,72.2588,2.1659,,,,,,,,,,
,170.952,72.3437,2.1691,,,,,,,,,,
,171.152,72.4282,2.1722,,,,,,,,,,
,171.352,72.5129,2.1753,,,,,,,,,,
,171.552,72.598,2.1792,,,,,,,,,,
,171.752,72.6825,2.1822,,,,,,,,,,
,171.952,72.7667,2.1851,,,,,,,,,,
,172.152,72.851,2.1883,,,,,,,,,,
,172.352,72.9362,2.192,,,,,,,,,,
,172.552,73.0208,2.1951,,,,,,,,,,
,172.752,73.1056,2.1984,,,,,,,,,,
,172.952,73.1906,2.2015,,,,,,,,,,
,173.152,73.2755,2.2048,,,,,,,,,,
,173.352,73.36,2.2077,,,,,,,,,,
,173.552,73.444,2.2106,,,,,,,,,,
,173.752,73.5285,2.2133,,,,,,,,,,
,173.952,73.6133,2.2163,,,,,,,,,,
,174.152,73.6983,2.2194,,,,,,,,,,
,174.352,73.783,2.2223,,,,,,,,,,
,174.552,73.8678,2.2253,,,,,,,,,,
,174.752,73.9528,2.2284,,,,,,,,,,
,174.952,74.0371,2.231,,,,,,,,,,
,175.152,74.1212,2.2333,,,,,,,,,,
,175.352,74.2057,2.2361,,,,,,,,,,
,175.552,74.2907,2.2389,,,,,,,,,,
,175.752,74.3755,2.2417,,,,,,,,,,
,175.952,74.4603,2.2439,,,,,,,,,,
,176.152,74.5452,2.2468,,,,,,,,,,
,176.352,74.6299,2.2494,,,,,,,,,,
,176.552,74.7145,2.2515,,,,,,,,,,
,176.752,74.7983,2.253,,,,,,,,,,
,176.952,74.8831,2.2551,,,,,,,,,,
,177.152,74.9682,2.2574,,,,,,,,,,
,177.352,75.0529,2.2593,,,,,,,,,,
,177.552,75.1376,2.2614,,,,,,,,,,
,177.752,75.2225,2.2627,,,,,,,,,,
,177.952,75.3075,2.264,,,,,,,,,,
,178.152,75.3916,2.2648,,,,,,,,,,
,178.352,75.4759,2.2657,,,,,,,,,,
,178.552,75.5606,2.2661,,,,,,,,,,
,178.752,75.6454,2.267,,,,,,,,,,
,178.952,75.7302,2.2675,,,,,,,,,,
,179.152,75.815,2.2677,,,,,,,,,,
,179.352,75.8998,2.2677,,,,,,,,,,
,179.552,75.9843,2.2676,,,,,,,,,,
,179.752,76.0691,2.2675,,,,,,,,,,
,179.952,76.153,2.2669,,,,,,,,,,
,180.152,76.2376,2.2668,,,,,,,,,,
,180.352,76.3228,2.2671,,,,,,,,,,
,180.552,76.4077,2.2672,,,,,,,,,,
,180.752,76.4923,2.2673,,,,,,,,,,
,180.952,76.577,2.2673,,,,,,,,,,
,181.152,76.6621,2.2678,,,,,,,,,,
,181.352,76.7463,2.2679,,,,,,,,,,
,181.552,76.8305,2.268,,,,,,,,,,
,181.752,76.9153,2.2684,,,,,,,,,,
,181.952,77.0002,2.269,,,,,,,,,,
,182.152,77.0849,2.2696,,,,,,,,,,
,182.352,77.1695,2.2704,,,,,,,,,,
,182.552,77.2544,2.2709,,,,,,,,,,
,182.752,77.3391,2.2717,,,,,,,,,,
,182.952,77.4237,2.2719,,,,,,,,,,
,183.152,77.5077,2.2721,,,,,,,,,,
,183.352,77.5924,2.2728,,,,,,,,,,
,183.552,77.6773,2.2741,,,,,,,,,,
,183.752,77.7621,2.2753,,,,,,,,,,
,183.952,77.8469,2.2772,,,,,,,,,,
,184.152,77.9318,2.2793,,,,,,,,,,
,184.352,78.0166,2.2815,,,,,,,,,,
,184.552,78.101,2.2836,,,,,,,,,,
,184.752,78.1855,2.2859,,,,,,,,,,
,184.952,78.2697,2.2878,,,,,,,,,,
,185.152,78.3547,2.2903,,,,,,,,,,
,185.352,78.4397,2.2928,,,,,,,,,,
,185.552,78.5243,2.2952,,,,,,,,,,
,185.752,78.6091,2.2974,,,,,,,,,,
,185.952,78.694,2.2998,,,,,,,,,,
,186.152,78.7785,2.302,,,,,,,,,,
,186.352,78.8624,2.3035,,,,,,,,,,
,186.552,78.9471,2.3059,,,,,,,,,,
,186.752,79.0323,2.3083,,,,,,,,,,
,186.952,79.1168,2.3102,,,,,,,,,,
,187.152,79.2015,2.3125,,,,,,,,,,
,187.352,79.2864,2.3148,,,,,,,,,,
,187.552,79.3714,2.3169,,,,,,,,,,
,187.752,79.4556,2.3188,,,,,,,,,,
,187.952,79.5398,2.3209,,,,,,,,,,
,188.152,79.6245,2.3231,,,,,,,,,,
,188.352,79.7093,2.3256,,,,,,,,,,
,188.552,79.7942,2.3278,,,,,,,,,,
,188.752,79.879,2.33,,,,,,,,,,
,188.952,79.9641,2.3323,,,,,,,,,,
,189.152,80.0487,2.3345,,,,,,,,,,
,189.352,80.133,2.3366,,,,,,,,,,
,189.552,80.2173,2.3386,,,,,,,,,,
,189.752,80.3019,2.3404,,,,,,,,,,
,189.952,80.387,2.3429,,,,,,,,,,
,190.152,80.4717,2.3447,,,,,,,,,,
,190.352,80.5564,2.3467,,,,,,,,,,
,190.552,80.6411,2.3484,,,,,,,,,,
,190.752,80.7261,2.3499,,,,,,,,,,
,190.952,80.8104,2.3506,,,,,,,,,,
,191.152,80.8943,2.3502,,,,,,,,,,
,191.343,80.9753,2.3265,,,,,,,,,,
,191.346,80.9766,2.2508,,,,,,,,,,
,191.348,80.9774,2.169,,,,,,,,,,
,191.35,80.9782,2.0687,,,,,,,,,,
,191.352,80.979,1.9549,,,,,,,,,,
,191.354,80.9799,1.8313,,,,,,,,,,
,191.356,80.9807,1.7014,,,,,,,,,,
,191.358,80.9816,1.568,,,,,,,,,,
,191.36,80.9824,1.4336,,,,,,,,,,
,191.361,80.9828,1.3667,,,,,,,,,,