File: lab10/data/S1_PMMA_1.csv
Results Table 1,,,,,,,,,,,,,,,,,,
,Specimen label,Thickness,Width,Length,Rate 1,,,,,,,,,,,,,
,,(mm),(mm),(mm),(mm/min),,,,,,,,,,,,,
1,PMMA-RT-.1,3.43,12.57,91.44,2.54,,,,,,,,,,,,,
2,PMMA-RT-1.0,3.28,12.45,91.01,25.4,,,,,,,,,,,,,
3,PMMA-50-.1,3.28,12.6,92.71,2.54,,,,,,,,,,,,,
4,PMMA-50-1.0,3.2,12.62,87.86,25.4,,,,,,,,,,,,,
,,,,,,,,,,,,,,,,,,
Results Table 2,,,,,,,,,,,,,,,,,,
,,,,,,,,,,,,,,,,,,
,,,,,,,,,,,,,,,,,,
1,Time,Displacement,Force,,2,Time,Displacement,Force,,3,Time,Displacement,Force,,4,Time,Displacement,Force
,(s),(mm),(kN),,,(s),(mm),(kN),,,(s),(mm),(kN),,,(s),(mm),(kN)
,0,0,0.032,,,0,0,0.035,,,0,0,-0.2804,,,0,0,-0.2585
,0.4,0.0105,0.0479,,,0.193,0.0514,0.1166,,,0.4,0.0124,-0.2684,,,0.242,0.0782,-0.1841
,0.8,0.0282,0.0722,,,0.315,0.1081,0.1979,,,0.8,0.0289,-0.2535,,,0.454,0.1672,-0.1035
,1.2,0.0451,0.0954,,,0.454,0.1674,0.2786,,,1.2,0.0459,-0.2384,,,0.666,0.2569,-0.0223
,1.6,0.0618,0.1174,,,0.597,0.2281,0.3593,,,1.6,0.0628,-0.223,,,0.884,0.3493,0.0587
,2,0.079,0.1392,,,0.751,0.2923,0.4408,,,2,0.0794,-0.2085,,,1.107,0.4435,0.1395
,2.4,0.0957,0.1604,,,0.909,0.3595,0.5221,,,2.4,0.0964,-0.1937,,,1.336,0.5402,0.2202
,2.8,0.1127,0.1815,,,1.067,0.4269,0.6033,,,2.8,0.1132,-0.1783,,,1.574,0.6411,0.3011
,3.2,0.1299,0.2034,,,1.231,0.4953,0.6845,,,3.2,0.1304,-0.1634,,,1.824,0.7465,0.3818
,3.6,0.1469,0.2248,,,1.392,0.5639,0.7653,,,3.6,0.1474,-0.1486,,,2.076,0.8531,0.4624
,4,0.1636,0.2447,,,1.557,0.6338,0.8461,,,4,0.1642,-0.1338,,,2.331,0.9613,0.5429
,4.4,0.1806,0.2645,,,1.724,0.7047,0.9269,,,4.4,0.1815,-0.1183,,,2.605,1.0766,0.6238
,4.8,0.1974,0.2847,,,1.896,0.777,1.0076,,,4.8,0.1983,-0.1038,,,2.88,1.1934,0.7046
,5.2,0.2143,0.3042,,,2.068,0.8503,1.0886,,,5.2,0.215,-0.0899,,,3.167,1.3154,0.7849
,5.6,0.2315,0.3243,,,2.243,0.9244,1.1691,,,5.6,0.2321,-0.0754,,,3.468,1.4423,0.8656
,6,0.2483,0.3429,,,2.421,1,1.2502,,,6,0.2492,-0.0608,,,3.784,1.5758,0.946
,6.4,0.2655,0.3623,,,2.607,1.0779,1.3312,,,6.4,0.2656,-0.0468,,,4.115,1.7162,1.0264
,6.8,0.2825,0.3812,,,2.79,1.1556,1.4117,,,6.8,0.2828,-0.0316,,,4.472,1.8674,1.1069
,7.2,0.2994,0.4004,,,2.979,1.2354,1.4926,,,7.2,0.2997,-0.0172,,,4.857,2.0303,1.1874
,7.6,0.3166,0.4201,,,3.169,1.3164,1.5735,,,7.6,0.3167,-0.0034,,,5.257,2.1999,1.2638
,8,0.3336,0.4392,,,3.363,1.3987,1.6542,,,8,0.3338,0.0107,,,5.657,2.3695,1.3332
,8.4,0.3502,0.4573,,,3.563,1.4833,1.7351,,,8.4,0.3509,0.0249,,,6.057,2.5379,1.3931
,8.8,0.3673,0.4761,,,3.766,1.5689,1.8156,,,8.8,0.3676,0.0393,,,6.457,2.7074,1.4485
,9.2,0.3839,0.4944,,,3.975,1.657,1.8964,,,9.2,0.3846,0.0536,,,6.857,2.877,1.4962
,9.6,0.4008,0.5135,,,4.186,1.7462,1.9768,,,9.6,0.4013,0.0666,,,7.257,3.0469,1.5385
,10,0.418,0.5325,,,4.401,1.8374,2.0575,,,10,0.4183,0.0806,,,7.657,3.2153,1.5733
,10.4,0.435,0.5514,,,4.623,1.9316,2.1381,,,10.4,0.4354,0.0946,,,8.057,3.3851,1.6038
,10.8,0.4517,0.5698,,,4.852,2.0283,2.2188,,,10.8,0.4522,0.1081,,,8.457,3.5547,1.6295
,11.2,0.4689,0.5883,,,5.088,2.1283,2.2997,,,11.2,0.4693,0.1212,,,8.857,3.7241,1.6506
,11.6,0.4858,0.6066,,,5.33,2.2306,2.3801,,,11.6,0.4863,0.1346,,,9.257,3.8926,1.6655
,12,0.5027,0.6247,,,5.581,2.3368,2.4607,,,12,0.5033,0.1486,,,9.657,4.0619,1.6799
,12.4,0.5198,0.6435,,,5.838,2.4461,2.5412,,,12.4,0.5204,0.1615,,,10.057,4.2319,1.6888
,12.8,0.5364,0.6615,,,6.106,2.5602,2.6217,,,12.8,0.5376,0.1751,,,10.457,4.4015,1.6989
,13.2,0.5533,0.6793,,,6.392,2.6806,2.7023,,,13.2,0.5542,0.1879,,,10.857,4.5699,1.7024
,13.6,0.5703,0.6971,,,6.691,2.8068,2.7831,,,13.6,0.5712,0.2006,,,11.257,4.7399,1.7031
,14,0.5872,0.715,,,7,2.9383,2.8636,,,14,0.5881,0.2138,,,11.657,4.9092,1.6983
,14.4,0.6044,0.7333,,,7.332,3.0786,2.944,,,14.4,0.6047,0.2252,,,12.057,5.0789,1.6956
,14.8,0.6215,0.7516,,,7.685,3.2284,3.0244,,,14.8,0.6218,0.2391,,,12.457,5.2472,1.6888
,15.2,0.6383,0.7697,,,8.073,3.3918,3.1043,,,15.2,0.6389,0.2507,,,12.857,5.4169,1.6811
,15.6,0.6555,0.7874,,,8.469,3.5597,3.1802,,,15.6,0.6556,0.2646,,,13.257,5.5867,1.6735
,16,0.6723,0.8046,,,8.869,3.7295,3.2503,,,16,0.6728,0.2759,,,13.657,5.7559,1.6635
,16.4,0.689,0.8217,,,9.269,3.8988,3.3133,,,16.4,0.6897,0.29,,,14.057,5.9248,1.6561
,16.8,0.7059,0.8389,,,9.669,4.0674,3.3681,,,16.8,0.7067,0.3015,,,14.457,6.0944,1.6469
,17.2,0.7226,0.8562,,,10.069,4.2373,3.4186,,,17.2,0.7238,0.3153,,,14.857,6.264,1.6408
,17.6,0.7393,0.8733,,,10.469,4.4069,3.4623,,,17.6,0.7405,0.3272,,,15.257,6.4335,1.6344
,18,0.7564,0.891,,,10.869,4.5761,3.4998,,,18,0.7573,0.3387,,,15.657,6.602,1.6282
,18.4,0.7733,0.9084,,,11.269,4.7447,3.5314,,,18.4,0.7742,0.3517,,,16.057,6.7719,1.6211
,18.8,0.7902,0.9256,,,11.669,4.9143,3.5585,,,18.8,0.791,0.3635,,,16.457,6.9412,1.6166
,19.2,0.8075,0.9429,,,12.069,5.0842,3.5811,,,19.2,0.808,0.3756,,,16.857,7.1108,1.6107
,19.6,0.8243,0.96,,,12.469,5.2532,3.5995,,,19.6,0.8252,0.3886,,,17.257,7.2794,1.6057
,20,0.841,0.9761,,,12.869,5.4222,3.6132,,,20,0.8419,0.4006,,,17.657,7.449,1.5996
,20.4,0.8581,0.9933,,,13.269,5.5918,3.6244,,,20.4,0.859,0.4123,,,18.057,7.6186,1.5951
,20.8,0.8747,1.0095,,,13.669,5.7615,3.6317,,,20.8,0.876,0.4234,,,18.457,7.7881,1.5897
,21.2,0.8915,1.0263,,,14.069,5.9305,3.6358,,,21.2,0.8926,0.436,,,18.857,7.9568,1.584
,21.6,0.9085,1.0427,,,14.469,6.0995,3.6368,,,21.6,0.9098,0.4489,,,19.257,8.1265,1.5783
,22,0.9255,1.0595,,,14.641,6.1727,3.5342,,,22,0.9265,0.4589,,,19.657,8.2961,1.5724
,22.4,0.9423,1.0763,,,14.645,6.1744,3.2766,,,22.4,0.9432,0.4706,,,20.057,8.4658,1.5665
,22.8,0.9595,1.0934,,,14.649,6.1761,2.9216,,,22.8,0.9602,0.4828,,,20.457,8.6338,1.5588
,23.2,0.9764,1.11,,,14.653,6.1778,2.5181,,,23.2,0.9771,0.4941,,,20.857,8.8037,1.5545
,23.6,0.9936,1.1268,,,14.657,6.1795,2.1018,,,23.6,0.9938,0.5051,,,21.257,8.9732,1.5473
,24,1.0106,1.1429,,,,,,,,24,1.0111,0.5167,,,21.657,9.1428,1.5424
,24.4,1.0272,1.1585,,,,,,,,24.4,1.0281,0.5283,,,22.057,9.3112,1.5349
,24.8,1.0444,1.1748,,,,,,,,24.8,1.0447,0.5399,,,22.457,9.4811,1.5285
,25.2,1.061,1.1903,,,,,,,,25.2,1.0619,0.5513,,,22.857,9.651,1.5225
,25.6,1.0778,1.2062,,,,,,,,25.6,1.0786,0.5617,,,23.257,9.8201,1.5134
,26,1.095,1.2231,,,,,,,,26,1.0955,0.5726,,,23.657,9.9888,1.5059
,26.4,1.1119,1.239,,,,,,,,26.4,1.1124,0.5842,,,24.057,10.1584,1.4961
,26.8,1.1287,1.2546,,,,,,,,26.8,1.1293,0.5955,,,24.457,10.3279,1.487
,27.2,1.146,1.271,,,,,,,,27.2,1.1462,0.605,,,24.857,10.4972,1.4765
,27.6,1.1628,1.2862,,,,,,,,27.6,1.1631,0.6164,,,25.257,10.6658,1.4653
,28,1.1796,1.3018,,,,,,,,28,1.1802,0.626,,,25.657,10.836,1.454
,28.4,1.1967,1.3173,,,,,,,,28.4,1.1974,0.637,,,26.057,11.0054,1.4431
,28.8,1.2135,1.3326,,,,,,,,28.8,1.2145,0.6478,,,26.457,11.1749,1.4314
,29.2,1.2304,1.348,,,,,,,,29.2,1.2311,0.6579,,,26.857,11.3433,1.4191
,29.6,1.2473,1.3632,,,,,,,,29.6,1.2483,0.6687,,,27.257,11.513,1.4081
,30,1.2643,1.379,,,,,,,,30,1.265,0.678,,,27.657,11.6826,1.3972
,30.4,1.2814,1.3945,,,,,,,,30.4,1.2817,0.6885,,,28.057,11.8518,1.3872
,30.8,1.2986,1.4102,,,,,,,,30.8,1.2987,0.6995,,,28.457,12.0207,1.3769
,31.2,1.3154,1.4253,,,,,,,,31.2,1.3159,0.7092,,,28.857,12.1903,1.3682
,31.6,1.3327,1.4407,,,,,,,,31.6,1.3326,0.7188,,,29.257,12.3601,1.3606
,32,1.3494,1.455,,,,,,,,32,1.3498,0.7293,,,29.657,12.5294,1.3538
,32.4,1.3663,1.4697,,,,,,,,32.4,1.3667,0.739,,,30.057,12.698,1.347
,32.8,1.3834,1.4847,,,,,,,,32.8,1.3837,0.7496,,,30.457,12.8678,1.341
,33.2,1.4003,1.4993,,,,,,,,33.2,1.4008,0.7587,,,30.857,13.0373,1.3363
,33.6,1.4169,1.5134,,,,,,,,33.6,1.4175,0.7692,,,31.257,13.2067,1.3263
,34,1.434,1.5279,,,,,,,,34,1.4345,0.7785,,,31.657,13.3753,1.3053
,34.4,1.4509,1.5427,,,,,,,,34.4,1.4514,0.7877,,,31.881,13.4703,1.2243
,34.8,1.4678,1.5574,,,,,,,,34.8,1.4682,0.7981,,,31.886,13.4723,1.1084
,35.2,1.485,1.5724,,,,,,,,35.2,1.4853,0.8076,,,31.89,13.474,0.9805
,35.6,1.502,1.5868,,,,,,,,35.6,1.5026,0.817,,,31.894,13.4757,0.839
,36,1.5187,1.6011,,,,,,,,36,1.5193,0.8262,,,,,
,36.4,1.5356,1.6151,,,,,,,,36.4,1.5365,0.836,,,,,
,36.8,1.5525,1.6288,,,,,,,,36.8,1.5535,0.8446,,,,,
,37.2,1.5693,1.6427,,,,,,,,37.2,1.5702,0.8545,,,,,
,37.6,1.5862,1.6563,,,,,,,,37.6,1.5872,0.8632,,,,,
,38,1.603,1.6699,,,,,,,,38,1.6042,0.8717,,,,,
,38.4,1.62,1.6838,,,,,,,,38.4,1.6208,0.8803,,,,,
,38.8,1.6371,1.6978,,,,,,,,38.8,1.6378,0.89,,,,,
,39.2,1.6539,1.7111,,,,,,,,39.2,1.6547,0.8989,,,,,
,39.6,1.6712,1.7252,,,,,,,,39.6,1.6716,0.9056,,,,,
,40,1.6881,1.7386,,,,,,,,40,1.6888,0.9156,,,,,
,40.4,1.7048,1.7519,,,,,,,,40.4,1.7058,0.9236,,,,,
,40.8,1.7217,1.7652,,,,,,,,40.8,1.7227,0.9336,,,,,
,41.2,1.7385,1.7782,,,,,,,,41.2,1.7396,0.9409,,,,,
,41.6,1.7552,1.7914,,,,,,,,41.6,1.7563,0.9478,,,,,
,42,1.7723,1.8042,,,,,,,,42,1.7731,0.9551,,,,,
,42.4,1.7894,1.8176,,,,,,,,42.4,1.7902,0.9634,,,,,
,42.8,1.8061,1.8304,,,,,,,,42.8,1.8068,0.9715,,,,,
,43.2,1.8233,1.8438,,,,,,,,43.2,1.8237,0.9793,,,,,
,43.6,1.8402,1.8564,,,,,,,,43.6,1.8409,0.9871,,,,,
,44,1.8571,1.8694,,,,,,,,44,1.8576,0.9945,,,,,
,44.4,1.8741,1.8821,,,,,,,,44.4,1.8748,1.002,,,,,
,44.8,1.8908,1.8944,,,,,,,,44.8,1.8919,1.01,,,,,
,45.2,1.9076,1.907,,,,,,,,45.2,1.9086,1.0173,,,,,
,45.6,1.9245,1.9192,,,,,,,,45.6,1.9256,1.0252,,,,,
,46,1.9412,1.9312,,,,,,,,46,1.9424,1.0319,,,,,
,46.4,1.9584,1.9439,,,,,,,,46.4,1.9591,1.0388,,,,,
,46.8,1.9756,1.9562,,,,,,,,46.8,1.9763,1.0459,,,,,
,47.2,1.9923,1.9684,,,,,,,,47.2,1.9931,1.0525,,,,,
,47.6,2.0094,1.9806,,,,,,,,47.6,2.01,1.0594,,,,,
,48,2.0265,1.9926,,,,,,,,48,2.0271,1.0665,,,,,
,48.4,2.0433,2.0043,,,,,,,,48.4,2.0439,1.0729,,,,,
,48.8,2.0602,2.0162,,,,,,,,48.8,2.0608,1.0799,,,,,
,49.2,2.0773,2.028,,,,,,,,49.2,2.0779,1.0865,,,,,
,49.6,2.094,2.039,,,,,,,,49.6,2.0948,1.0929,,,,,
,50,2.1108,2.0509,,,,,,,,50,2.1114,1.0989,,,,,
,50.4,2.1277,2.0623,,,,,,,,50.4,2.1284,1.1048,,,,,
,50.8,2.1448,2.0738,,,,,,,,50.8,2.1452,1.1107,,,,,
,51.2,2.1619,2.0854,,,,,,,,51.2,2.1622,1.1173,,,,,
,51.6,2.179,2.0968,,,,,,,,51.6,2.1793,1.1229,,,,,
,52,2.1958,2.1077,,,,,,,,52,2.1962,1.1289,,,,,
,52.4,2.2128,2.1187,,,,,,,,52.4,2.2135,1.1349,,,,,
,52.8,2.2297,2.1298,,,,,,,,52.8,2.2303,1.1407,,,,,
,53.2,2.2465,2.1406,,,,,,,,53.2,2.2473,1.1465,,,,,
,53.6,2.2636,2.1518,,,,,,,,53.6,2.2642,1.1519,,,,,
,54,2.2804,2.1626,,,,,,,,54,2.2812,1.1575,,,,,
,54.4,2.2976,2.1734,,,,,,,,54.4,2.2978,1.1625,,,,,
,54.8,2.3145,2.1842,,,,,,,,54.8,2.3149,1.168,,,,,
,55.2,2.3315,2.1951,,,,,,,,55.2,2.3317,1.1725,,,,,
,55.6,2.3486,2.206,,,,,,,,55.6,2.3486,1.1777,,,,,
,56,2.3658,2.2165,,,,,,,,56,2.366,1.1828,,,,,
,56.4,2.3823,2.2265,,,,,,,,56.4,2.383,1.1879,,,,,
,56.8,2.3995,2.2371,,,,,,,,56.8,2.3997,1.1921,,,,,
,57.2,2.4162,2.2473,,,,,,,,57.2,2.4168,1.1967,,,,,
,57.6,2.433,2.2572,,,,,,,,57.6,2.4337,1.2009,,,,,
,58,2.45,2.2674,,,,,,,,58,2.4505,1.2058,,,,,
,58.4,2.4671,2.2774,,,,,,,,58.4,2.4676,1.2098,,,,,
,58.8,2.4838,2.2869,,,,,,,,58.8,2.4843,1.2136,,,,,
,59.2,2.5009,2.2971,,,,,,,,59.2,2.5014,1.2176,,,,,
,59.6,2.5178,2.3069,,,,,,,,59.6,2.5183,1.2215,,,,,
,60,2.5347,2.3166,,,,,,,,60,2.5353,1.2254,,,,,
,60.4,2.5519,2.3261,,,,,,,,60.4,2.5525,1.229,,,,,
,60.8,2.5685,2.3356,,,,,,,,60.8,2.5698,1.2322,,,,,
,61.2,2.5853,2.3446,,,,,,,,61.2,2.5863,1.2362,,,,,
,61.6,2.6023,2.354,,,,,,,,61.6,2.6033,1.2399,,,,,
,62,2.6189,2.363,,,,,,,,62,2.6202,1.2435,,,,,
,62.4,2.636,2.3721,,,,,,,,62.4,2.6368,1.2467,,,,,
,62.8,2.6531,2.3812,,,,,,,,62.8,2.6538,1.25,,,,,
,63.2,2.6699,2.3899,,,,,,,,63.2,2.6707,1.253,,,,,
,63.6,2.687,2.3992,,,,,,,,63.6,2.6875,1.2562,,,,,
,64,2.704,2.4082,,,,,,,,64,2.7046,1.2593,,,,,
,64.4,2.7207,2.4166,,,,,,,,64.4,2.7214,1.2625,,,,,
,64.8,2.7377,2.4256,,,,,,,,64.8,2.7384,1.2654,,,,,
,65.2,2.7547,2.4341,,,,,,,,65.2,2.7556,1.2682,,,,,
,65.6,2.7712,2.4424,,,,,,,,65.6,2.7723,1.2702,,,,,
,66,2.7883,2.4509,,,,,,,,66,2.7891,1.2734,,,,,
,66.4,2.8051,2.4594,,,,,,,,66.4,2.806,1.2762,,,,,
,66.8,2.8221,2.4678,,,,,,,,66.8,2.8227,1.2788,,,,,
,67.2,2.8391,2.4766,,,,,,,,67.2,2.8397,1.2809,,,,,
,67.6,2.8561,2.4849,,,,,,,,67.6,2.8569,1.2832,,,,,
,68,2.873,2.4932,,,,,,,,68,2.8736,1.2855,,,,,
,68.4,2.89,2.5014,,,,,,,,68.4,2.8906,1.288,,,,,
,68.8,2.9067,2.5092,,,,,,,,68.8,2.9079,1.29,,,,,
,69.2,2.9236,2.5172,,,,,,,,69.2,2.9245,1.2919,,,,,
,69.6,2.9406,2.5251,,,,,,,,69.6,2.9416,1.294,,,,,
,70,2.9573,2.5327,,,,,,,,70,2.9585,1.2952,,,,,
,70.4,2.9743,2.5402,,,,,,,,70.4,2.9751,1.2966,,,,,
,70.8,2.9915,2.5484,,,,,,,,70.8,2.9921,1.2987,,,,,
,71.2,3.0084,2.5555,,,,,,,,71.2,3.0089,1.3,,,,,
,71.6,3.0255,2.5631,,,,,,,,71.6,3.0259,1.3016,,,,,
,72,3.0427,2.5708,,,,,,,,72,3.0429,1.3035,,,,,
,72.4,3.0594,2.5779,,,,,,,,72.4,3.0599,1.305,,,,,
,72.8,3.0766,2.5855,,,,,,,,72.8,3.0768,1.3061,,,,,
,73.2,3.0932,2.5925,,,,,,,,73.2,3.0939,1.3075,,,,,
,73.6,3.1101,2.5995,,,,,,,,73.6,3.1106,1.3088,,,,,
,74,3.1271,2.6067,,,,,,,,74,3.1275,1.3103,,,,,
,74.4,3.1441,2.6139,,,,,,,,74.4,3.1445,1.3117,,,,,
,74.8,3.1609,2.6207,,,,,,,,74.8,3.1613,1.3129,,,,,
,75.2,3.1782,2.6282,,,,,,,,75.2,3.1782,1.3142,,,,,
,75.6,3.195,2.6348,,,,,,,,75.6,3.1953,1.3156,,,,,
,76,3.2119,2.6417,,,,,,,,76,3.2122,1.3172,,,,,
,76.4,3.2291,2.6486,,,,,,,,76.4,3.2295,1.3188,,,,,
,76.8,3.2459,2.6553,,,,,,,,76.8,3.2466,1.32,,,,,
,77.2,3.2627,2.6613,,,,,,,,77.2,3.2634,1.3213,,,,,
,77.6,3.2797,2.6676,,,,,,,,77.6,3.2806,1.3232,,,,,
,78,3.2965,2.6741,,,,,,,,78,3.2972,1.3245,,,,,
,78.4,3.3135,2.6806,,,,,,,,78.4,3.3141,1.3258,,,,,
,78.8,3.3307,2.687,,,,,,,,78.8,3.331,1.3276,,,,,
,79.2,3.3475,2.6927,,,,,,,,79.2,3.348,1.3291,,,,,
,79.6,3.3647,2.6993,,,,,,,,79.6,3.3648,1.3297,,,,,
,80,3.3816,2.7054,,,,,,,,80,3.3818,1.3293,,,,,
,80.4,3.3984,2.711,,,,,,,,80.4,3.3988,1.3308,,,,,
,80.8,3.4155,2.7174,,,,,,,,80.8,3.4156,1.3319,,,,,
,81.2,3.4324,2.723,,,,,,,,81.2,3.433,1.3321,,,,,
,81.6,3.449,2.7284,,,,,,,,81.6,3.4497,1.3324,,,,,
,82,3.466,2.7338,,,,,,,,82,3.4667,1.334,,,,,
,82.4,3.4828,2.7397,,,,,,,,82.4,3.4837,1.3349,,,,,
,82.8,3.4997,2.7452,,,,,,,,82.8,3.5003,1.336,,,,,
,83.2,3.517,2.7513,,,,,,,,83.2,3.5174,1.3367,,,,,
,83.6,3.534,2.7569,,,,,,,,83.6,3.5345,1.3373,,,,,
,84,3.5507,2.7617,,,,,,,,84,3.5514,1.3381,,,,,
,84.4,3.5678,2.7674,,,,,,,,84.4,3.5684,1.3388,,,,,
,84.8,3.5845,2.7723,,,,,,,,84.8,3.5854,1.339,,,,,
,85.2,3.6013,2.7776,,,,,,,,85.2,3.6023,1.3398,,,,,
,85.6,3.6183,2.7827,,,,,,,,85.6,3.6193,1.341,,,,,
,86,3.635,2.7875,,,,,,,,86,3.6364,1.3437,,,,,
,86.4,3.6519,2.7924,,,,,,,,86.4,3.6529,1.3453,,,,,
,86.8,3.6689,2.7977,,,,,,,,86.8,3.6698,1.3474,,,,,
,87.2,3.6857,2.8023,,,,,,,,87.2,3.6867,1.3493,,,,,
,87.6,3.7029,2.8076,,,,,,,,87.6,3.7035,1.3506,,,,,
,88,3.72,2.8126,,,,,,,,88,3.7209,1.3517,,,,,
,88.4,3.7367,2.817,,,,,,,,88.4,3.7376,1.3518,,,,,
,88.8,3.7537,2.8218,,,,,,,,88.8,3.7546,1.353,,,,,
,89.2,3.7706,2.8263,,,,,,,,89.2,3.7715,1.3526,,,,,
,89.6,3.7872,2.8303,,,,,,,,89.6,3.7883,1.3541,,,,,
,90,3.8042,2.8348,,,,,,,,90,3.8052,1.3546,,,,,
,90.4,3.8213,2.8389,,,,,,,,90.4,3.8221,1.3553,,,,,
,90.8,3.838,2.8434,,,,,,,,90.8,3.8388,1.3551,,,,,
,91.2,3.8551,2.8477,,,,,,,,91.2,3.8556,1.3558,,,,,
,91.6,3.872,2.8522,,,,,,,,91.6,3.8726,1.3562,,,,,
,92,3.889,2.8559,,,,,,,,92,3.8895,1.3559,,,,,
,92.4,3.9061,2.8603,,,,,,,,92.4,3.9066,1.3565,,,,,
,92.8,3.9228,2.8644,,,,,,,,92.8,3.9238,1.3567,,,,,
,93.2,3.9397,2.8686,,,,,,,,93.2,3.9405,1.3567,,,,,
,93.6,3.9566,2.8726,,,,,,,,93.6,3.9576,1.357,,,,,
,94,3.9733,2.8766,,,,,,,,94,3.9744,1.3565,,,,,
,94.4,3.9904,2.8806,,,,,,,,94.4,3.9913,1.3561,,,,,
,94.8,4.0076,2.8847,,,,,,,,94.8,4.008,1.356,,,,,
,95.2,4.0244,2.8888,,,,,,,,95.2,4.0252,1.3555,,,,,
,95.6,4.0416,2.8929,,,,,,,,95.6,4.0419,1.3556,,,,,
,96,4.0586,2.8964,,,,,,,,96,4.0588,1.3544,,,,,
,96.4,4.0755,2.9001,,,,,,,,96.4,4.0758,1.3543,,,,,
,96.8,4.0925,2.904,,,,,,,,96.8,4.0928,1.3536,,,,,
,97.2,4.1095,2.9075,,,,,,,,97.2,4.11,1.3528,,,,,
,97.6,4.126,2.9103,,,,,,,,97.6,4.1268,1.3533,,,,,
,98,4.1432,2.914,,,,,,,,98,4.1436,1.3518,,,,,
,98.4,4.1599,2.9171,,,,,,,,98.4,4.1607,1.3514,,,,,
,98.8,4.1769,2.9208,,,,,,,,98.8,4.1773,1.3499,,,,,
,99.2,4.1941,2.9246,,,,,,,,99.2,4.1943,1.3502,,,,,
,99.6,4.2111,2.928,,,,,,,,99.6,4.2114,1.3489,,,,,
,100,4.228,2.931,,,,,,,,100,4.2282,1.3478,,,,,
,100.4,4.2451,2.9344,,,,,,,,100.4,4.2454,1.3471,,,,,
,100.8,4.2619,2.9376,,,,,,,,100.8,4.2625,1.3457,,,,,
,101.2,4.2788,2.9407,,,,,,,,101.2,4.2795,1.3451,,,,,
,101.6,4.2959,2.9438,,,,,,,,101.6,4.2964,1.3435,,,,,
,102,4.3126,2.9465,,,,,,,,102,4.3134,1.342,,,,,
,102.4,4.3296,2.9494,,,,,,,,102.4,4.3301,1.3412,,,,,
,102.8,4.3466,2.9524,,,,,,,,102.8,4.3472,1.3397,,,,,
,103.2,4.3635,2.9554,,,,,,,,103.2,4.3639,1.3374,,,,,
,103.6,4.3806,2.9586,,,,,,,,103.6,4.3808,1.3356,,,,,
,104,4.3979,2.9617,,,,,,,,104,4.3981,1.3353,,,,,
,104.4,4.4145,2.9641,,,,,,,,104.4,4.415,1.3334,,,,,
,104.8,4.4315,2.9673,,,,,,,,104.8,4.4318,1.3306,,,,,
,105.2,4.4483,2.9701,,,,,,,,105.2,4.4491,1.3288,,,,,
,105.6,4.4649,2.9724,,,,,,,,105.6,4.4658,1.3271,,,,,
,106,4.4819,2.9749,,,,,,,,106,4.4826,1.3259,,,,,
,106.4,4.4987,2.9771,,,,,,,,106.4,4.4997,1.324,,,,,
,106.8,4.5156,2.9797,,,,,,,,106.8,4.5165,1.3209,,,,,
,107.2,4.5326,2.9822,,,,,,,,107.2,4.5332,1.3178,,,,,
,107.6,4.5495,2.9846,,,,,,,,107.6,4.5503,1.3153,,,,,
,108,4.5664,2.9869,,,,,,,,108,4.5672,1.3124,,,,,
,108.4,4.5837,2.9896,,,,,,,,108.4,4.584,1.3095,,,,,
,108.8,4.6004,2.992,,,,,,,,108.8,4.6013,1.3074,,,,,
,109.2,4.6171,2.994,,,,,,,,109.2,4.6182,1.3053,,,,,
,109.6,4.6342,2.9965,,,,,,,,109.6,4.6353,1.3028,,,,,
,110,4.6508,2.9986,,,,,,,,110,4.6521,1.2998,,,,,
,110.4,4.6678,3.0011,,,,,,,,110.4,4.6687,1.2977,,,,,
,110.8,4.6848,3.0032,,,,,,,,110.8,4.6859,1.2951,,,,,
,111.2,4.7017,3.0054,,,,,,,,111.2,4.7026,1.2931,,,,,
,111.6,4.7188,3.0079,,,,,,,,111.6,4.7193,1.289,,,,,
,112,4.7357,3.01,,,,,,,,112,4.7365,1.2875,,,,,
,112.4,4.7526,3.0117,,,,,,,,112.4,4.7533,1.2851,,,,,
,112.8,4.7696,3.014,,,,,,,,112.8,4.7702,1.2828,,,,,
,113.2,4.7865,3.0155,,,,,,,,113.2,4.7875,1.2806,,,,,
,113.6,4.8032,3.0175,,,,,,,,113.6,4.8044,1.2775,,,,,
,114,4.8202,3.0195,,,,,,,,114,4.8211,1.275,,,,,
,114.4,4.8369,3.0208,,,,,,,,114.4,4.8379,1.2724,,,,,
,114.8,4.8538,3.0228,,,,,,,,114.8,4.8547,1.2708,,,,,
,115.2,4.871,3.0247,,,,,,,,115.2,4.8717,1.2696,,,,,
,115.6,4.888,3.0265,,,,,,,,115.6,4.8885,1.2683,,,,,
,116,4.9048,3.0282,,,,,,,,116,4.9054,1.2664,,,,,
,116.4,4.9221,3.0302,,,,,,,,116.4,4.9224,1.264,,,,,
,116.8,4.9387,3.0317,,,,,,,,116.8,4.9395,1.2638,,,,,
,117.2,4.9557,3.0334,,,,,,,,117.2,4.9563,1.2611,,,,,
,117.6,4.9726,3.0349,,,,,,,,117.6,4.9735,1.2601,,,,,
,118,4.9894,3.0364,,,,,,,,118,4.9907,1.259,,,,,
,118.4,5.0063,3.0382,,,,,,,,118.4,5.0072,1.2564,,,,,
,118.8,5.0233,3.04,,,,,,,,118.8,5.0242,1.2556,,,,,
,119.2,5.0404,3.0416,,,,,,,,119.2,5.0409,1.2544,,,,,
,119.6,5.0574,3.0433,,,,,,,,119.6,5.0579,1.2529,,,,,
,120,5.0748,3.0456,,,,,,,,120,5.0749,1.2512,,,,,
,120.4,5.0915,3.0462,,,,,,,,120.4,5.0919,1.2489,,,,,
,120.8,5.1087,3.0478,,,,,,,,120.8,5.1088,1.2463,,,,,
,121.2,5.1254,3.0488,,,,,,,,121.2,5.1259,1.2442,,,,,
,121.6,5.1422,3.05,,,,,,,,121.6,5.1427,1.2423,,,,,
,122,5.1592,3.0511,,,,,,,,122,5.1596,1.2395,,,,,
,122.4,5.1762,3.0526,,,,,,,,122.4,5.1766,1.2379,,,,,
,122.8,5.193,3.0536,,,,,,,,122.8,5.1935,1.2361,,,,,
,123.2,5.21,3.0549,,,,,,,,123.2,5.2103,1.2343,,,,,
,123.6,5.227,3.0562,,,,,,,,123.6,5.2274,1.2335,,,,,
,124,5.244,3.0575,,,,,,,,124,5.2442,1.2318,,,,,
,124.4,5.2612,3.0591,,,,,,,,124.4,5.2614,1.229,,,,,
,124.8,5.278,3.0597,,,,,,,,124.8,5.2787,1.2269,,,,,
,125.2,5.2949,3.061,,,,,,,,125.2,5.2954,1.2243,,,,,
,125.6,5.3119,3.0622,,,,,,,,125.6,5.3127,1.2218,,,,,
,126,5.3286,3.063,,,,,,,,126,5.3294,1.2195,,,,,
,126.4,5.3455,3.0639,,,,,,,,126.4,5.3463,1.2174,,,,,
,126.8,5.3627,3.0652,,,,,,,,126.8,5.3632,1.216,,,,,
,127.2,5.3794,3.0662,,,,,,,,127.2,5.3801,1.214,,,,,
,127.6,5.3964,3.0672,,,,,,,,127.6,5.3968,1.2109,,,,,
,128,5.4136,3.0682,,,,,,,,128,5.414,1.2085,,,,,
,128.4,5.4304,3.0689,,,,,,,,128.4,5.4309,1.2064,,,,,
,128.8,5.4474,3.0701,,,,,,,,128.8,5.4479,1.2041,,,,,
,129.2,5.4644,3.0712,,,,,,,,129.2,5.4651,1.2017,,,,,
,129.6,5.4811,3.0717,,,,,,,,129.6,5.482,1.1995,,,,,
,130,5.4979,3.0727,,,,,,,,130,5.4989,1.1963,,,,,
,130.4,5.5148,3.0732,,,,,,,,130.4,5.5159,1.1939,,,,,
,130.8,5.5316,3.0737,,,,,,,,130.8,5.5325,1.1906,,,,,
,131.2,5.5487,3.0746,,,,,,,,131.2,5.5493,1.1887,,,,,
,131.6,5.5657,3.0753,,,,,,,,131.6,5.5664,1.1874,,,,,
,132,5.5826,3.0759,,,,,,,,132,5.5831,1.1854,,,,,
,132.4,5.5997,3.0766,,,,,,,,132.4,5.6001,1.1848,,,,,
,132.8,5.6163,3.0766,,,,,,,,132.8,5.6172,1.1828,,,,,
,133.2,5.6331,3.0771,,,,,,,,133.2,5.6341,1.1811,,,,,
,133.6,5.6502,3.0779,,,,,,,,133.6,5.6512,1.1806,,,,,
,134,5.6669,3.0783,,,,,,,,134,5.6681,1.1781,,,,,
,134.4,5.6836,3.0784,,,,,,,,134.4,5.6848,1.1771,,,,,
,134.8,5.7007,3.0792,,,,,,,,134.8,5.7017,1.1754,,,,,
,135.2,5.7175,3.0795,,,,,,,,135.2,5.7186,1.174,,,,,
,135.6,5.7346,3.0806,,,,,,,,135.6,5.7352,1.1736,,,,,
,136,5.7517,3.0812,,,,,,,,136,5.7524,1.1721,,,,,
,136.4,5.7687,3.0816,,,,,,,,136.4,5.7694,1.1709,,,,,
,136.8,5.7856,3.0822,,,,,,,,136.8,5.7862,1.1704,,,,,
,137.2,5.8025,3.0824,,,,,,,,137.2,5.8033,1.1692,,,,,
,137.6,5.8193,3.0829,,,,,,,,137.6,5.8201,1.1694,,,,,
,138,5.8363,3.083,,,,,,,,138,5.837,1.1673,,,,,
,138.4,5.8532,3.0831,,,,,,,,138.4,5.854,1.1669,,,,,
,138.8,5.8699,3.0832,,,,,,,,138.8,5.8707,1.1655,,,,,
,139.2,5.8873,3.0838,,,,,,,,139.2,5.8876,1.1646,,,,,
,139.6,5.9039,3.0837,,,,,,,,139.6,5.9045,1.164,,,,,
,140,5.921,3.0844,,,,,,,,140,5.9214,1.163,,,,,
,140.4,5.9382,3.0847,,,,,,,,140.4,5.9383,1.1636,,,,,
,140.8,5.9551,3.0852,,,,,,,,140.8,5.9556,1.1623,,,,,
,141.2,5.9717,3.0849,,,,,,,,141.2,5.9724,1.1619,,,,,
,141.6,5.9887,3.0855,,,,,,,,141.6,5.9895,1.1628,,,,,
,142,6.0056,3.0857,,,,,,,,142,6.0065,1.162,,,,,
,142.4,6.0225,3.0858,,,,,,,,142.4,6.0232,1.1622,,,,,
,142.8,6.0394,3.0857,,,,,,,,142.8,6.0403,1.1611,,,,,
,143.2,6.0564,3.0858,,,,,,,,143.2,6.0572,1.1606,,,,,
,143.6,6.0737,3.086,,,,,,,,143.6,6.0738,1.1621,,,,,
,144,6.0905,3.0862,,,,,,,,144,6.091,1.1639,,,,,
,144.4,6.1075,3.0862,,,,,,,,144.4,6.1077,1.1653,,,,,
,144.8,6.1246,3.0864,,,,,,,,144.8,6.1248,1.166,,,,,
,145.2,6.142,3.087,,,,,,,,145.2,6.1419,1.1674,,,,,
,145.6,6.1583,3.0864,,,,,,,,145.6,6.1588,1.1679,,,,,
,146,6.1755,3.0866,,,,,,,,146,6.1757,1.1673,,,,,
,146.4,6.1923,3.0861,,,,,,,,146.4,6.1927,1.1684,,,,,
,146.8,6.2089,3.086,,,,,,,,146.8,6.2096,1.1683,,,,,
,147.2,6.2262,3.0868,,,,,,,,147.2,6.2264,1.1695,,,,,
,147.6,6.2431,3.0864,,,,,,,,147.6,6.2436,1.1689,,,,,
,148,6.2601,3.0867,,,,,,,,148,6.2604,1.169,,,,,
,148.4,6.2772,3.0863,,,,,,,,148.4,6.2775,1.1678,,,,,
,148.8,6.294,3.0861,,,,,,,,148.8,6.2945,1.1679,,,,,
,149.2,6.3109,3.0857,,,,,,,,149.2,6.3115,1.1675,,,,,
,149.6,6.328,3.0858,,,,,,,,149.6,6.3285,1.1655,,,,,
,150,6.3447,3.0853,,,,,,,,150,6.3457,1.1653,,,,,
,150.4,6.3614,3.0851,,,,,,,,150.4,6.3623,1.1625,,,,,
,150.8,6.3785,3.0854,,,,,,,,150.8,6.3793,1.162,,,,,
,151.2,6.3953,3.0854,,,,,,,,151.2,6.3961,1.1596,,,,,
,151.6,6.4123,3.0852,,,,,,,,151.6,6.4129,1.1578,,,,,
,152,6.4296,3.0848,,,,,,,,152,6.4301,1.1573,,,,,
,152.4,6.4462,3.0842,,,,,,,,152.4,6.4469,1.1566,,,,,
,152.8,6.4634,3.0841,,,,,,,,152.8,6.4638,1.1553,,,,,
,153.2,6.4802,3.0838,,,,,,,,153.2,6.481,1.1553,,,,,
,153.6,6.4969,3.0834,,,,,,,,153.6,6.4978,1.1544,,,,,
,154,6.514,3.0833,,,,,,,,154,6.5147,1.153,,,,,
,154.4,6.5307,3.0829,,,,,,,,154.4,6.532,1.1528,,,,,
,154.8,6.5475,3.0825,,,,,,,,154.8,6.5486,1.1519,,,,,
,155.2,6.5645,3.0824,,,,,,,,155.2,6.5653,1.1505,,,,,
,155.6,6.5814,3.0821,,,,,,,,155.6,6.5823,1.1501,,,,,
,156,6.5984,3.0814,,,,,,,,156,6.599,1.1501,,,,,
,156.4,6.6155,3.0813,,,,,,,,156.4,6.616,1.1497,,,,,
,156.8,6.6324,3.0807,,,,,,,,156.8,6.6332,1.149,,,,,
,157.2,6.6491,3.08,,,,,,,,157.2,6.6501,1.1478,,,,,
,157.6,6.6662,3.0798,,,,,,,,157.6,6.6672,1.1472,,,,,
,158,6.6828,3.0793,,,,,,,,158,6.6841,1.1466,,,,,
,158.4,6.6996,3.079,,,,,,,,158.4,6.7007,1.1457,,,,,
,158.8,6.7167,3.0787,,,,,,,,158.8,6.7178,1.1454,,,,,
,159.2,6.7335,3.0781,,,,,,,,159.2,6.7346,1.144,,,,,
,159.6,6.7505,3.0779,,,,,,,,159.6,6.7513,1.1432,,,,,
,160,6.7675,3.077,,,,,,,,160,6.7684,1.1422,,,,,
,160.4,6.7846,3.0765,,,,,,,,160.4,6.7851,1.1428,,,,,
,160.8,6.8015,3.0761,,,,,,,,160.8,6.802,1.1422,,,,,
,161.2,6.8186,3.0757,,,,,,,,161.2,6.8192,1.1426,,,,,
,161.6,6.8354,3.0752,,,,,,,,161.6,6.8362,1.1426,,,,,
,162,6.8525,3.0748,,,,,,,,162,6.853,1.1412,,,,,
,162.4,6.8691,3.0741,,,,,,,,162.4,6.87,1.1396,,,,,
,162.8,6.886,3.0734,,,,,,,,162.8,6.8868,1.1369,,,,,
,163.2,6.903,3.0731,,,,,,,,163.2,6.9035,1.1356,,,,,
,163.6,6.9202,3.0725,,,,,,,,163.6,6.9205,1.1348,,,,,
,164,6.9369,3.0715,,,,,,,,164,6.9374,1.1338,,,,,
,164.4,6.9542,3.0712,,,,,,,,164.4,6.9543,1.1325,,,,,
,164.8,6.9709,3.0705,,,,,,,,164.8,6.9714,1.1319,,,,,
,165.2,6.9879,3.0702,,,,,,,,165.2,6.9884,1.1313,,,,,
,165.6,7.0049,3.0695,,,,,,,,165.6,7.0057,1.1306,,,,,
,166,7.0217,3.069,,,,,,,,166,7.0226,1.1294,,,,,
,166.4,7.0386,3.0685,,,,,,,,166.4,7.0394,1.1284,,,,,
,166.42,7.0393,2.9217,,,,,,,,166.8,7.0566,1.128,,,,,
,166.424,7.0394,2.671,,,,,,,,167.2,7.0731,1.1265,,,,,
,166.428,7.0396,2.3534,,,,,,,,167.6,7.0899,1.1255,,,,,
,166.432,7.0398,2.0058,,,,,,,,168,7.107,1.1246,,,,,
,,,,,,,,,,,168.4,7.1241,1.1237,,,,,
,,,,,,,,,,,168.8,7.1407,1.1227,,,,,
,,,,,,,,,,,169.2,7.158,1.1218,,,,,
,,,,,,,,,,,169.6,7.1749,1.1212,,,,,
,,,,,,,,,,,170,7.1918,1.1192,,,,,
,,,,,,,,,,,170.4,7.2088,1.1172,,,,,
,,,,,,,,,,,170.8,7.2258,1.1165,,,,,
,,,,,,,,,,,171.2,7.2426,1.115,,,,,
,,,,,,,,,,,171.6,7.2596,1.1134,,,,,
,,,,,,,,,,,172,7.2765,1.1117,,,,,
,,,,,,,,,,,172.4,7.2935,1.1096,,,,,
,,,,,,,,,,,172.8,7.3108,1.1089,,,,,
,,,,,,,,,,,173.2,7.3275,1.1066,,,,,
,,,,,,,,,,,173.6,7.3447,1.1052,,,,,
,,,,,,,,,,,174,7.3616,1.1031,,,,,
,,,,,,,,,,,174.4,7.3784,1.1018,,,,,
,,,,,,,,,,,174.8,7.3954,1.1007,,,,,
,,,,,,,,,,,175.2,7.4123,1.0989,,,,,
,,,,,,,,,,,175.6,7.429,1.0971,,,,,
,,,,,,,,,,,176,7.4459,1.0953,,,,,
,,,,,,,,,,,176.4,7.4628,1.0938,,,,,
,,,,,,,,,,,176.8,7.4797,1.0923,,,,,
,,,,,,,,,,,177.2,7.4969,1.0918,,,,,
,,,,,,,,,,,177.6,7.5139,1.0905,,,,,
,,,,,,,,,,,178,7.5308,1.0895,,,,,
,,,,,,,,,,,178.4,7.5479,1.0884,,,,,
,,,,,,,,,,,178.8,7.5645,1.0873,,,,,
,,,,,,,,,,,179.2,7.5814,1.0861,,,,,
,,,,,,,,,,,179.6,7.5983,1.0852,,,,,
,,,,,,,,,,,180,7.615,1.0838,,,,,
,,,,,,,,,,,180.4,7.632,1.0848,,,,,
,,,,,,,,,,,180.8,7.6489,1.0852,,,,,
,,,,,,,,,,,181.2,7.6658,1.0857,,,,,
,,,,,,,,,,,181.6,7.6832,1.0859,,,,,
,,,,,,,,,,,182,7.7001,1.087,,,,,
,,,,,,,,,,,182.4,7.7168,1.0882,,,,,
,,,,,,,,,,,182.8,7.7338,1.0882,,,,,
,,,,,,,,,,,183.2,7.7506,1.0882,,,,,
,,,,,,,,,,,183.6,7.7672,1.0873,,,,,
,,,,,,,,,,,184,7.7843,1.0866,,,,,
,,,,,,,,,,,184.4,7.8012,1.0847,,,,,
,,,,,,,,,,,184.8,7.818,1.0842,,,,,
,,,,,,,,,,,185.2,7.8353,1.0835,,,,,
,,,,,,,,,,,185.6,7.852,1.0826,,,,,
,,,,,,,,,,,186,7.8689,1.0821,,,,,
,,,,,,,,,,,186.4,7.8861,1.082,,,,,
,,,,,,,,,,,186.8,7.9029,1.0817,,,,,
,,,,,,,,,,,187.2,7.9196,1.0804,,,,,
,,,,,,,,,,,187.6,7.9365,1.0791,,,,,
,,,,,,,,,,,188,7.9534,1.0773,,,,,
,,,,,,,,,,,188.4,7.9704,1.0765,,,,,
,,,,,,,,,,,188.8,7.9875,1.0755,,,,,
,,,,,,,,,,,189.2,8.0044,1.0746,,,,,
,,,,,,,,,,,189.6,8.0216,1.0741,,,,,
,,,,,,,,,,,190,8.0385,1.0744,,,,,
,,,,,,,,,,,190.4,8.0553,1.0737,,,,,
,,,,,,,,,,,190.8,8.0724,1.0735,,,,,
,,,,,,,,,,,191.2,8.0894,1.0729,,,,,
,,,,,,,,,,,191.6,8.1059,1.0722,,,,,
,,,,,,,,,,,192,8.1232,1.0723,,,,,
,,,,,,,,,,,192.4,8.1398,1.0722,,,,,
,,,,,,,,,,,192.8,8.1569,1.0723,,,,,
,,,,,,,,,,,193.2,8.174,1.0726,,,,,
,,,,,,,,,,,193.6,8.1911,1.0719,,,,,
,,,,,,,,,,,194,8.2079,1.0719,,,,,
,,,,,,,,,,,194.4,8.225,1.0713,,,,,
,,,,,,,,,,,194.8,8.2419,1.0708,,,,,
,,,,,,,,,,,195.2,8.2586,1.0702,,,,,
,,,,,,,,,,,195.6,8.2758,1.0704,,,,,
,,,,,,,,,,,196,8.2925,1.0697,,,,,
,,,,,,,,,,,196.4,8.3095,1.0709,,,,,
,,,,,,,,,,,196.8,8.3265,1.072,,,,,
,,,,,,,,,,,197.2,8.3434,1.0729,,,,,
,,,,,,,,,,,197.6,8.3607,1.0732,,,,,
,,,,,,,,,,,198,8.3778,1.0734,,,,,
,,,,,,,,,,,198.4,8.3944,1.0721,,,,,
,,,,,,,,,,,198.8,8.4117,1.073,,,,,
,,,,,,,,,,,199.2,8.4282,1.073,,,,,
,,,,,,,,,,,199.6,8.445,1.0743,,,,,
,,,,,,,,,,,200,8.4621,1.0753,,,,,
,,,,,,,,,,,200.4,8.479,1.0761,,,,,
,,,,,,,,,,,200.8,8.4956,1.0778,,,,,
,,,,,,,,,,,201.2,8.5128,1.0801,,,,,
,,,,,,,,,,,201.6,8.5298,1.0816,,,,,
,,,,,,,,,,,202,8.5466,1.0831,,,,,
,,,,,,,,,,,202.4,8.5638,1.084,,,,,
,,,,,,,,,,,202.8,8.5805,1.0842,,,,,
,,,,,,,,,,,203.2,8.5973,1.084,,,,,
,,,,,,,,,,,203.6,8.6141,1.0845,,,,,
,,,,,,,,,,,204,8.6308,1.0823,,,,,
,,,,,,,,,,,204.4,8.6478,1.0812,,,,,
,,,,,,,,,,,204.8,8.6648,1.079,,,,,
,,,,,,,,,,,205.2,8.6817,1.0766,,,,,
,,,,,,,,,,,205.6,8.6988,1.0742,,,,,
,,,,,,,,,,,206,8.7158,1.0716,,,,,
,,,,,,,,,,,206.4,8.7326,1.0714,,,,,
,,,,,,,,,,,206.8,8.7497,1.0713,,,,,
,,,,,,,,,,,207.2,8.7667,1.0712,,,,,
,,,,,,,,,,,207.6,8.7832,1.0715,,,,,
,,,,,,,,,,,208,8.8004,1.0708,,,,,
,,,,,,,,,,,208.4,8.8171,1.07,,,,,
,,,,,,,,,,,208.8,8.8339,1.0688,,,,,
,,,,,,,,,,,209.2,8.8511,1.0684,,,,,
,,,,,,,,,,,209.6,8.8681,1.0682,,,,,
,,,,,,,,,,,210,8.8848,1.0678,,,,,
,,,,,,,,,,,210.4,8.9019,1.0674,,,,,
,,,,,,,,,,,210.8,8.9186,1.0671,,,,,
,,,,,,,,,,,211.2,8.9356,1.0666,,,,,
,,,,,,,,,,,211.6,8.9526,1.0662,,,,,
,,,,,,,,,,,212,8.9694,1.0657,,,,,
,,,,,,,,,,,212.4,8.9862,1.0654,,,,,
,,,,,,,,,,,212.8,9.0033,1.0653,,,,,
,,,,,,,,,,,213.2,9.0203,1.0652,,,,,
,,,,,,,,,,,213.6,9.0375,1.0647,,,,,
,,,,,,,,,,,214,9.0545,1.0656,,,,,
,,,,,,,,,,,214.4,9.0714,1.0648,,,,,
,,,,,,,,,,,214.8,9.0887,1.0658,,,,,
,,,,,,,,,,,215.2,9.1052,1.0663,,,,,
,,,,,,,,,,,215.6,9.1221,1.0679,,,,,
,,,,,,,,,,,216,9.1392,1.0692,,,,,
,,,,,,,,,,,216.4,9.1561,1.0717,,,,,
,,,,,,,,,,,216.8,9.1729,1.0739,,,,,
,,,,,,,,,,,217.2,9.19,1.076,,,,,
,,,,,,,,,,,217.6,9.207,1.0791,,,,,
,,,,,,,,,,,218,9.2239,1.0819,,,,,
,,,,,,,,,,,218.4,9.2411,1.0856,,,,,
,,,,,,,,,,,218.8,9.258,1.0886,,,,,
,,,,,,,,,,,219.2,9.2748,1.0926,,,,,
,,,,,,,,,,,219.6,9.2917,1.0961,,,,,
,,,,,,,,,,,220,9.3085,1.099,,,,,
,,,,,,,,,,,220.4,9.3256,1.104,,,,,
,,,,,,,,,,,220.8,9.3424,1.1065,,,,,
,,,,,,,,,,,221.2,9.3594,1.1103,,,,,
,,,,,,,,,,,221.6,9.3766,1.1127,,,,,
,,,,,,,,,,,222,9.3934,1.1143,,,,,
,,,,,,,,,,,222.4,9.4103,1.1151,,,,,
,,,,,,,,,,,222.8,9.4275,1.1179,,,,,
,,,,,,,,,,,223.2,9.4445,1.1201,,,,,
,,,,,,,,,,,223.6,9.4608,1.1213,,,,,
,,,,,,,,,,,224,9.478,1.1239,,,,,
,,,,,,,,,,,224.4,9.4948,1.1251,,,,,
,,,,,,,,,,,224.8,9.5114,1.1263,,,,,
,,,,,,,,,,,225.2,9.5288,1.1274,,,,,
,,,,,,,,,,,225.6,9.5459,1.1289,,,,,
,,,,,,,,,,,226,9.5627,1.1307,,,,,
,,,,,,,,,,,226.4,9.5796,1.1322,,,,,
,,,,,,,,,,,226.8,9.5965,1.1327,,,,,
,,,,,,,,,,,227.2,9.6134,1.1335,,,,,
,,,,,,,,,,,227.6,9.63,1.1343,,,,,
,,,,,,,,,,,228,9.6469,1.1352,,,,,
,,,,,,,,,,,228.4,9.6638,1.1358,,,,,
,,,,,,,,,,,228.8,9.6807,1.1361,,,,,
,,,,,,,,,,,229.2,9.6975,1.1364,,,,,
,,,,,,,,,,,229.6,9.7147,1.1374,,,,,
,,,,,,,,,,,230,9.7319,1.1384,,,,,
,,,,,,,,,,,230.4,9.7486,1.1381,,,,,
,,,,,,,,,,,230.8,9.7657,1.1376,,,,,
,,,,,,,,,,,231.2,9.7826,1.1375,,,,,
,,,,,,,,,,,231.6,9.7993,1.1374,,,,,
,,,,,,,,,,,232,9.8162,1.1375,,,,,
,,,,,,,,,,,232.4,9.8332,1.1364,,,,,
,,,,,,,,,,,232.8,9.8499,1.1376,,,,,
,,,,,,,,,,,233.2,9.8671,1.1371,,,,,
,,,,,,,,,,,233.6,9.8839,1.1372,,,,,
,,,,,,,,,,,234,9.901,1.1373,,,,,
,,,,,,,,,,,234.4,9.9181,1.1375,,,,,
,,,,,,,,,,,234.8,9.935,1.1376,,,,,
,,,,,,,,,,,235.2,9.9518,1.1373,,,,,
,,,,,,,,,,,235.6,9.9687,1.1372,,,,,
,,,,,,,,,,,236,9.9855,1.1373,,,,,
,,,,,,,,,,,236.4,10.0024,1.1371,,,,,
,,,,,,,,,,,236.8,10.0197,1.1364,,,,,
,,,,,,,,,,,237.2,10.0363,1.1359,,,,,
,,,,,,,,,,,237.6,10.0536,1.1358,,,,,
,,,,,,,,,,,238,10.0706,1.135,,,,,
,,,,,,,,,,,238.4,10.0875,1.134,,,,,
,,,,,,,,,,,238.8,10.1046,1.1324,,,,,
,,,,,,,,,,,239.2,10.1217,1.1309,,,,,
,,,,,,,,,,,239.6,10.1383,1.1295,,,,,
,,,,,,,,,,,240,10.1555,1.1278,,,,,
,,,,,,,,,,,240.4,10.1721,1.1252,,,,,
,,,,,,,,,,,240.8,10.189,1.1233,,,,,
,,,,,,,,,,,241.2,10.2062,1.1218,,,,,
,,,,,,,,,,,241.6,10.2231,1.1196,,,,,
,,,,,,,,,,,242,10.24,1.117,,,,,
,,,,,,,,,,,242.4,10.257,1.113,,,,,
,,,,,,,,,,,242.8,10.2741,1.11,,,,,
,,,,,,,,,,,243.2,10.2909,1.107,,,,,
,,,,,,,,,,,243.6,10.3079,1.1039,,,,,
,,,,,,,,,,,244,10.3248,1.0994,,,,,
,,,,,,,,,,,244.4,10.3416,1.0948,,,,,
,,,,,,,,,,,244.8,10.3586,1.0917,,,,,
,,,,,,,,,,,245.2,10.3754,1.0873,,,,,
,,,,,,,,,,,245.6,10.3925,1.0834,,,,,
,,,,,,,,,,,246,10.4097,1.0793,,,,,
,,,,,,,,,,,246.4,10.4263,1.0754,,,,,
,,,,,,,,,,,246.8,10.4436,1.0717,,,,,
,,,,,,,,,,,247.2,10.4603,1.0677,,,,,
,,,,,,,,,,,247.6,10.477,1.0633,,,,,
,,,,,,,,,,,248,10.494,1.0609,,,,,
,,,,,,,,,,,248.4,10.5108,1.0582,,,,,
,,,,,,,,,,,248.8,10.5275,1.0575,,,,,
,,,,,,,,,,,249.2,10.5446,1.0573,,,,,
,,,,,,,,,,,249.6,10.5616,1.0567,,,,,
,,,,,,,,,,,250,10.5783,1.0555,,,,,
,,,,,,,,,,,250.4,10.5956,1.0546,,,,,
,,,,,,,,,,,250.8,10.6125,1.0533,,,,,
,,,,,,,,,,,251.2,10.6291,1.0522,,,,,
,,,,,,,,,,,251.6,10.6462,1.0517,,,,,
,,,,,,,,,,,252,10.6627,1.0508,,,,,
,,,,,,,,,,,252.4,10.6798,1.0501,,,,,
,,,,,,,,,,,252.8,10.6967,1.0497,,,,,
,,,,,,,,,,,253.2,10.7135,1.0495,,,,,
,,,,,,,,,,,253.6,10.7307,1.0498,,,,,
,,,,,,,,,,,254,10.7477,1.0496,,,,,
,,,,,,,,,,,254.4,10.7645,1.0494,,,,,
,,,,,,,,,,,254.8,10.7816,1.0492,,,,,
,,,,,,,,,,,255.2,10.7988,1.049,,,,,
,,,,,,,,,,,255.6,10.8153,1.049,,,,,
,,,,,,,,,,,256,10.8323,1.0499,,,,,
,,,,,,,,,,,256.4,10.8491,1.0505,,,,,
,,,,,,,,,,,256.8,10.8659,1.0515,,,,,
,,,,,,,,,,,257.2,10.883,1.0532,,,,,
,,,,,,,,,,,257.6,10.9001,1.0544,,,,,
,,,,,,,,,,,258,10.9168,1.054,,,,,
,,,,,,,,,,,258.4,10.934,1.0539,,,,,
,,,,,,,,,,,258.8,10.9508,1.0536,,,,,
,,,,,,,,,,,259.2,10.9679,1.0522,,,,,
,,,,,,,,,,,259.6,10.9848,1.052,,,,,
,,,,,,,,,,,260,11.0016,1.0501,,,,,
,,,,,,,,,,,260.4,11.0185,1.0496,,,,,
,,,,,,,,,,,260.8,11.0355,1.0494,,,,,
,,,,,,,,,,,261.2,11.0524,1.0493,,,,,
,,,,,,,,,,,261.6,11.0696,1.0492,,,,,
,,,,,,,,,,,262,11.0869,1.0499,,,,,
,,,,,,,,,,,262.4,11.1035,1.0492,,,,,
,,,,,,,,,,,262.8,11.1208,1.0493,,,,,
,,,,,,,,,,,263.2,11.1376,1.0487,,,,,
,,,,,,,,,,,263.6,11.1544,1.0486,,,,,
,,,,,,,,,,,264,11.1714,1.0492,,,,,
,,,,,,,,,,,264.4,11.1882,1.0491,,,,,
,,,,,,,,,,,264.8,11.205,1.0492,,,,,
,,,,,,,,,,,265.2,11.2222,1.0497,,,,,
,,,,,,,,,,,265.6,11.239,1.0496,,,,,
,,,,,,,,,,,266,11.256,1.0488,,,,,
,,,,,,,,,,,266.4,11.2732,1.0481,,,,,
,,,,,,,,,,,266.8,11.2902,1.047,,,,,
,,,,,,,,,,,267.2,11.307,1.0467,,,,,
,,,,,,,,,,,267.6,11.3239,1.0463,,,,,
,,,,,,,,,,,268,11.3406,1.0456,,,,,
,,,,,,,,,,,268.4,11.3575,1.046,,,,,
,,,,,,,,,,,268.8,11.3746,1.0457,,,,,
,,,,,,,,,,,269.2,11.3912,1.046,,,,,
,,,,,,,,,,,269.6,11.4083,1.0464,,,,,
,,,,,,,,,,,270,11.4255,1.0469,,,,,
,,,,,,,,,,,270.4,11.4421,1.0483,,,,,
,,,,,,,,,,,270.8,11.4594,1.0488,,,,,
,,,,,,,,,,,271.2,11.4762,1.0492,,,,,
,,,,,,,,,,,271.6,11.493,1.0502,,,,,
,,,,,,,,,,,272,11.5098,1.0501,,,,,
,,,,,,,,,,,272.4,11.5266,1.0513,,,,,
,,,,,,,,,,,272.8,11.5435,1.0521,,,,,
,,,,,,,,,,,273.2,11.5605,1.0514,,,,,
,,,,,,,,,,,273.6,11.5776,1.052,,,,,
,,,,,,,,,,,274,11.5943,1.0503,,,,,
,,,,,,,,,,,274.4,11.6115,1.0499,,,,,
,,,,,,,,,,,274.8,11.6282,1.0482,,,,,
,,,,,,,,,,,275.2,11.6452,1.0483,,,,,
,,,,,,,,,,,275.6,11.6622,1.0482,,,,,
,,,,,,,,,,,276,11.6789,1.048,,,,,
,,,,,,,,,,,276.4,11.6957,1.048,,,,,
,,,,,,,,,,,276.8,11.7126,1.0476,,,,,
,,,,,,,,,,,277.2,11.7294,1.0482,,,,,
,,,,,,,,,,,277.6,11.7465,1.049,,,,,
,,,,,,,,,,,278,11.7638,1.0497,,,,,
,,,,,,,,,,,278.4,11.7806,1.0495,,,,,
,,,,,,,,,,,278.8,11.7976,1.0505,,,,,
,,,,,,,,,,,279.2,11.8146,1.0505,,,,,
,,,,,,,,,,,279.6,11.8313,1.0509,,,,,
,,,,,,,,,,,280,11.8483,1.0513,,,,,
,,,,,,,,,,,280.4,11.8653,1.0511,,,,,
,,,,,,,,,,,280.8,11.882,1.0523,,,,,
,,,,,,,,,,,281.2,11.8989,1.0521,,,,,
,,,,,,,,,,,281.6,11.9159,1.0515,,,,,
,,,,,,,,,,,282,11.933,1.051,,,,,
,,,,,,,,,,,282.4,11.95,1.0518,,,,,
,,,,,,,,,,,282.8,11.967,1.0519,,,,,
,,,,,,,,,,,283.2,11.9839,1.052,,,,,
,,,,,,,,,,,283.6,12.0009,1.0523,,,,,
,,,,,,,,,,,284,12.0176,1.0523,,,,,
,,,,,,,,,,,284.4,12.0345,1.0523,,,,,
,,,,,,,,,,,284.8,12.0518,1.0527,,,,,
,,,,,,,,,,,285.2,12.0684,1.0508,,,,,
,,,,,,,,,,,285.6,12.0856,1.051,,,,,
,,,,,,,,,,,286,12.1026,1.0506,,,,,
,,,,,,,,,,,286.4,12.1196,1.0504,,,,,
,,,,,,,,,,,286.8,12.1367,1.0504,,,,,
,,,,,,,,,,,287.2,12.1538,1.0509,,,,,
,,,,,,,,,,,287.6,12.1704,1.0509,,,,,
,,,,,,,,,,,288,12.1876,1.0511,,,,,
,,,,,,,,,,,288.4,12.2042,1.0515,,,,,
,,,,,,,,,,,288.8,12.2211,1.052,,,,,
,,,,,,,,,,,289.2,12.2381,1.0528,,,,,
,,,,,,,,,,,289.6,12.255,1.053,,,,,
,,,,,,,,,,,290,12.2719,1.0534,,,,,
,,,,,,,,,,,290.4,12.2891,1.0542,,,,,
,,,,,,,,,,,290.8,12.3059,1.0546,,,,,
,,,,,,,,,,,291.2,12.3228,1.0545,,,,,
,,,,,,,,,,,291.6,12.34,1.0553,,,,,
,,,,,,,,,,,292,12.3565,1.0543,,,,,
,,,,,,,,,,,292.4,12.3734,1.0537,,,,,
,,,,,,,,,,,292.8,12.3904,1.0526,,,,,
,,,,,,,,,,,293.2,12.4071,1.0512,,,,,
,,,,,,,,,,,293.6,12.4241,1.0496,,,,,
,,,,,,,,,,,294,12.4413,1.0487,,,,,
,,,,,,,,,,,294.4,12.4582,1.0481,,,,,
,,,,,,,,,,,294.8,12.4752,1.0478,,,,,
,,,,,,,,,,,295.2,12.4922,1.0478,,,,,
,,,,,,,,,,,295.6,12.509,1.0479,,,,,
,,,,,,,,,,,296,12.5259,1.0475,,,,,
,,,,,,,,,,,296.4,12.5427,1.0481,,,,,
,,,,,,,,,,,296.8,12.5594,1.048,,,,,
,,,,,,,,,,,297.2,12.5765,1.049,,,,,
,,,,,,,,,,,297.6,12.5932,1.0487,,,,,
,,,,,,,,,,,298,12.6102,1.0493,,,,,
,,,,,,,,,,,298.4,12.6274,1.0505,,,,,
,,,,,,,,,,,298.8,12.6443,1.0509,,,,,
,,,,,,,,,,,299.2,12.661,1.0519,,,,,
,,,,,,,,,,,299.6,12.6781,1.0534,,,,,
,,,,,,,,,,,300,12.6948,1.0542,,,,,
,,,,,,,,,,,300.4,12.7117,1.0551,,,,,
,,,,,,,,,,,300.8,12.7286,1.0568,,,,,
,,,,,,,,,,,301.2,12.7455,1.0569,,,,,
,,,,,,,,,,,301.6,12.7625,1.0584,,,,,
,,,,,,,,,,,302,12.7795,1.0592,,,,,
,,,,,,,,,,,302.4,12.7966,1.0607,,,,,
,,,,,,,,,,,302.8,12.8136,1.0611,,,,,
,,,,,,,,,,,303.2,12.8309,1.0627,,,,,
,,,,,,,,,,,303.6,12.8476,1.0643,,,,,
,,,,,,,,,,,304,12.8648,1.0653,,,,,
,,,,,,,,,,,304.4,12.8813,1.0657,,,,,
,,,,,,,,,,,304.8,12.8981,1.0655,,,,,
,,,,,,,,,,,305.2,12.9152,1.0661,,,,,
,,,,,,,,,,,305.6,12.9322,1.0659,,,,,
,,,,,,,,,,,306,12.9489,1.0664,,,,,
,,,,,,,,,,,306.4,12.9662,1.0669,,,,,
,,,,,,,,,,,306.8,12.983,1.0678,,,,,
,,,,,,,,,,,307.2,12.9999,1.0689,,,,,
,,,,,,,,,,,307.6,13.0169,1.0691,,,,,
,,,,,,,,,,,308,13.0339,1.0705,,,,,
,,,,,,,,,,,308.4,13.0507,1.072,,,,,
,,,,,,,,,,,308.8,13.0675,1.0723,,,,,
,,,,,,,,,,,309.2,13.0846,1.0728,,,,,
,,,,,,,,,,,309.6,13.1015,1.0743,,,,,
,,,,,,,,,,,310,13.1189,1.0751,,,,,
,,,,,,,,,,,310.4,13.1356,1.0761,,,,,
,,,,,,,,,,,310.8,13.1528,1.0766,,,,,
,,,,,,,,,,,311.2,13.1698,1.0766,,,,,
,,,,,,,,,,,311.6,13.1865,1.0767,,,,,
,,,,,,,,,,,312,13.2036,1.0774,,,,,
,,,,,,,,,,,312.4,13.2205,1.0782,,,,,
,,,,,,,,,,,312.8,13.2372,1.0792,,,,,
,,,,,,,,,,,313.2,13.2541,1.0793,,,,,
,,,,,,,,,,,313.6,13.271,1.0784,,,,,
,,,,,,,,,,,314,13.288,1.0776,,,,,
,,,,,,,,,,,314.4,13.3052,1.0767,,,,,
,,,,,,,,,,,314.8,13.3221,1.0756,,,,,
,,,,,,,,,,,315.2,13.3389,1.0743,,,,,
,,,,,,,,,,,315.6,13.3559,1.0723,,,,,
,,,,,,,,,,,316,13.3726,1.0712,,,,,
,,,,,,,,,,,316.4,13.3894,1.0701,,,,,
,,,,,,,,,,,316.8,13.4064,1.0703,,,,,
,,,,,,,,,,,317.2,13.4231,1.0695,,,,,
,,,,,,,,,,,317.6,13.44,1.0687,,,,,
,,,,,,,,,,,318,13.4572,1.0684,,,,,
,,,,,,,,,,,318.4,13.4739,1.0673,,,,,
,,,,,,,,,,,318.8,13.4911,1.0666,,,,,
,,,,,,,,,,,319.2,13.5081,1.0658,,,,,
,,,,,,,,,,,319.6,13.5249,1.0647,,,,,
,,,,,,,,,,,320,13.5419,1.064,,,,,
,,,,,,,,,,,320.4,13.5586,1.0622,,,,,
,,,,,,,,,,,320.8,13.5754,1.061,,,,,
,,,,,,,,,,,321.2,13.5925,1.0602,,,,,
,,,,,,,,,,,321.6,13.6093,1.059,,,,,
,,,,,,,,,,,322,13.6261,1.0586,,,,,
,,,,,,,,,,,322.4,13.6433,1.0585,,,,,
,,,,,,,,,,,322.8,13.6602,1.0572,,,,,
,,,,,,,,,,,323.2,13.677,1.0561,,,,,
,,,,,,,,,,,323.6,13.6942,1.0559,,,,,
,,,,,,,,,,,324,13.711,1.0543,,,,,
,,,,,,,,,,,324.4,13.7277,1.0542,,,,,
,,,,,,,,,,,324.8,13.7447,1.0543,,,,,
,,,,,,,,,,,325.2,13.7614,1.0534,,,,,
,,,,,,,,,,,325.6,13.7784,1.053,,,,,
,,,,,,,,,,,326,13.7956,1.0524,,,,,
,,,,,,,,,,,326.4,13.8125,1.0527,,,,,
,,,,,,,,,,,326.8,13.8297,1.0519,,,,,
,,,,,,,,,,,327.2,13.8465,1.0515,,,,,
,,,,,,,,,,,327.6,13.8635,1.0518,,,,,
,,,,,,,,,,,328,13.8805,1.0524,,,,,
,,,,,,,,,,,328.4,13.8975,1.0527,,,,,
,,,,,,,,,,,328.8,13.9141,1.0529,,,,,
,,,,,,,,,,,329.2,13.9313,1.0535,,,,,
,,,,,,,,,,,329.6,13.948,1.0535,,,,,
,,,,,,,,,,,330,13.9649,1.0544,,,,,
,,,,,,,,,,,330.4,13.9823,1.0547,,,,,
,,,,,,,,,,,330.8,13.9992,1.0547,,,,,
,,,,,,,,,,,331.2,14.016,1.0531,,,,,
,,,,,,,,,,,331.6,14.0332,1.0525,,,,,
,,,,,,,,,,,332,14.05,1.0519,,,,,
,,,,,,,,,,,332.4,14.0667,1.0508,,,,,
,,,,,,,,,,,332.8,14.0839,1.0496,,,,,
,,,,,,,,,,,333.2,14.1007,1.0498,,,,,
,,,,,,,,,,,333.6,14.1176,1.0504,,,,,
,,,,,,,,,,,334,14.1346,1.0507,,,,,
,,,,,,,,,,,334.4,14.1516,1.0518,,,,,
,,,,,,,,,,,334.8,14.1686,1.0512,,,,,
,,,,,,,,,,,335.2,14.1859,1.0514,,,,,
,,,,,,,,,,,335.6,14.2025,1.0509,,,,,
,,,,,,,,,,,336,14.2196,1.0509,,,,,
,,,,,,,,,,,336.4,14.2363,1.0508,,,,,
,,,,,,,,,,,336.8,14.253,1.0497,,,,,
,,,,,,,,,,,337.2,14.2701,1.0486,,,,,
,,,,,,,,,,,337.6,14.2869,1.0482,,,,,
,,,,,,,,,,,338,14.3038,1.0469,,,,,
,,,,,,,,,,,338.4,14.3208,1.0455,,,,,
,,,,,,,,,,,338.8,14.3379,1.0455,,,,,
,,,,,,,,,,,339.2,14.3548,1.0443,,,,,
,,,,,,,,,,,339.6,14.372,1.0443,,,,,
,,,,,,,,,,,340,14.3889,1.0448,,,,,
,,,,,,,,,,,340.4,14.4053,1.0442,,,,,
,,,,,,,,,,,340.8,14.4225,1.0443,,,,,
,,,,,,,,,,,341.2,14.4391,1.0445,,,,,
,,,,,,,,,,,341.6,14.4559,1.0442,,,,,
,,,,,,,,,,,342,14.4731,1.0446,,,,,
,,,,,,,,,,,342.4,14.4899,1.0462,,,,,
,,,,,,,,,,,342.8,14.507,1.0462,,,,,
,,,,,,,,,,,343.2,14.524,1.0465,,,,,
,,,,,,,,,,,343.6,14.5408,1.0477,,,,,
,,,,,,,,,,,344,14.558,1.0494,,,,,
,,,,,,,,,,,344.4,14.5747,1.0499,,,,,
,,,,,,,,,,,344.8,14.5914,1.0503,,,,,
,,,,,,,,,,,345.2,14.6085,1.0511,,,,,
,,,,,,,,,,,345.6,14.6251,1.0514,,,,,
,,,,,,,,,,,346,14.6421,1.0519,,,,,
,,,,,,,,,,,346.4,14.6593,1.0533,,,,,
,,,,,,,,,,,346.8,14.6762,1.0535,,,,,
,,,,,,,,,,,347.2,14.6929,1.0546,,,,,
,,,,,,,,,,,347.6,14.7102,1.0564,,,,,
,,,,,,,,,,,348,14.7269,1.0574,,,,,
,,,,,,,,,,,348.4,14.7438,1.0589,,,,,
,,,,,,,,,,,348.8,14.7608,1.0595,,,,,
,,,,,,,,,,,349.2,14.7777,1.0609,,,,,
,,,,,,,,,,,349.6,14.7944,1.0609,,,,,
,,,,,,,,,,,350,14.8115,1.0622,,,,,
,,,,,,,,,,,350.4,14.8285,1.0635,,,,,
,,,,,,,,,,,350.8,14.8455,1.0637,,,,,
,,,,,,,,,,,351.2,14.8628,1.0643,,,,,
,,,,,,,,,,,351.6,14.8796,1.0645,,,,,
,,,,,,,,,,,352,14.8968,1.0647,,,,,
,,,,,,,,,,,352.4,14.9133,1.0651,,,,,
,,,,,,,,,,,352.8,14.9303,1.0655,,,,,
,,,,,,,,,,,353.2,14.9473,1.066,,,,,
,,,,,,,,,,,353.6,14.9641,1.0671,,,,,
,,,,,,,,,,,354,14.981,1.0692,,,,,
,,,,,,,,,,,354.4,14.9983,1.0707,,,,,
,,,,,,,,,,,354.745,15.0128,1.071,,,,,