File: lab01/data/S1_Al6061_11.csv
Results Table 1
,Specimen label,Width,Thickness,Length,Tensile strain (Displacement) at Break (Standard),Maximum Tensile stress
,,(mm),(mm),(mm),(%),(MPa)
"1","Aa6061-1","12.90","1.57","63.37","19.95","324.43"
"2","Aa6061-2_1","12.75","1.57","64.01","7.85","308.10"
"3","Aa6061-2_2","12.57","1.55","67.23","5.98","329.27"
"4","Aa6061-2_3","12.40","1.50","70.08","9.22","351.97"

1,Time,Displacement,Force
,(s),(mm),(N)
"","0.0000","0.0000","45.1803"
"","0.1000","0.0044","53.9835"
"","0.2000","0.0182","83.6953"
"","0.3000","0.0479","284.7020"
"","0.4000","0.0683","429.4221"
"","0.5000","0.0888","576.7107"
"","0.6000","0.1111","738.6375"
"","0.7000","0.1314","900.3177"
"","0.8000","0.1528","1090.7120"
"","0.9000","0.1738","1280.9901"
"","1.0000","0.1948","1474.0070"
"","1.1000","0.2166","1671.5790"
"","1.2000","0.2371","1846.1594"
"","1.3000","0.2587","2015.6860"
"","1.4000","0.2792","2172.6213"
"","1.5000","0.3012","2347.9038"
"","1.6000","0.3222","2511.7642"
"","1.7000","0.3433","2679.3193"
"","1.8000","0.3642","2841.8967"
"","1.9000","0.3852","3006.1782"
"","2.0000","0.4073","3178.4431"
"","2.1000","0.4273","3329.5129"
"","2.2000","0.4492","3497.7651"
"","2.3000","0.4697","3650.2573"
"","2.4000","0.4913","3813.2451"
"","2.5000","0.5127","3969.7952"
"","2.6000","0.5336","4120.0361"
"","2.7000","0.5546","4268.2153"
"","2.8000","0.5757","4411.3906"
"","2.9000","0.5977","4554.2466"
"","3.0000","0.6181","4673.5552"
"","3.1000","0.6398","4793.5635"
"","3.2000","0.6605","4893.8101"
"","3.3000","0.6820","4989.8994"
"","3.4000","0.7034","5069.5327"
"","3.5000","0.7238","5139.1592"
"","3.6000","0.7454","5199.6455"
"","3.7000","0.7660","5250.8408"
"","3.8000","0.7880","5298.6304"
"","3.9000","0.8085","5333.3198"
"","4.0000","0.8301","5371.4678"
"","4.1000","0.8509","5397.7671"
"","4.2000","0.8724","5427.2842"
"","4.3000","0.8942","5447.9243"
"","4.4000","0.9144","5466.8022"
"","4.5000","0.9362","5485.2192"
"","4.6000","0.9564","5498.4292"
"","4.7000","0.9786","5516.6982"
"","4.8000","0.9996","5523.7749"
"","4.9000","1.0204","5539.5762"
"","5.0000","1.0415","5546.9160"
"","5.1000","1.0625","5559.6274"
"","5.2000","1.0846","5568.5854"
"","5.3000","1.1048","5573.6089"
"","5.4000","1.1266","5584.3276"
"","5.5000","1.1471","5589.1411"
"","5.6000","1.1689","5599.2622"
"","5.7000","1.1902","5601.1689"
"","5.8000","1.2110","5610.9248"
"","5.9000","1.2323","5615.4224"
"","6.0000","1.2533","5622.1509"
"","6.1000","1.2751","5629.3018"
"","6.2000","1.2955","5630.0400"
"","6.3000","1.3170","5640.6284"
"","6.4000","1.3376","5641.2080"
"","6.5000","1.3592","5650.5410"
"","6.6000","1.3805","5651.2856"
"","6.7000","1.4011","5658.3462"
"","6.8000","1.4229","5663.3364"
"","6.9000","1.4434","5667.0923"
"","7.0000","1.4656","5675.6006"
"","7.1000","1.4862","5674.4331"
"","7.2000","1.5075","5684.8638"
"","7.3000","1.5285","5684.2393"
"","7.4000","1.5494","5692.4951"
"","7.5000","1.5713","5695.7251"
"","7.6000","1.5916","5698.9590"
"","7.7000","1.6134","5705.8428"
"","7.8000","1.6338","5708.4531"
"","7.9000","1.6558","5717.9214"
"","8.0000","1.6768","5715.3765"
"","8.1000","1.6978","5725.2476"
"","8.2000","1.7189","5725.3364"
"","8.3000","1.7398","5732.3130"
"","8.4000","1.7621","5738.4019"
"","8.5000","1.7823","5737.3081"
"","8.6000","1.8039","5746.7661"
"","8.7000","1.8245","5748.2632"
"","8.8000","1.8464","5757.2612"
"","8.9000","1.8675","5756.4800"
"","9.0000","1.8882","5764.3110"
"","9.1000","1.9094","5765.7461"
"","9.2000","1.9302","5771.4136"
"","9.3000","1.9525","5778.6167"
"","9.4000","1.9727","5775.6733"
"","9.5000","1.9944","5787.3428"
"","9.6000","2.0151","5787.1685"
"","9.7000","2.0367","5796.4917"
"","9.8000","2.0583","5797.1802"
"","9.9000","2.0784","5800.6743"
"","10.0000","2.1001","5807.0840"
"","10.1000","2.1206","5809.2446"
"","10.2000","2.1428","5818.4131"
"","10.3000","2.1629","5814.6318"
"","10.4000","2.1847","5827.8379"
"","10.5000","2.2056","5826.0957"
"","10.6000","2.2268","5834.2783"
"","10.7000","2.2488","5837.2393"
"","10.8000","2.2689","5838.9712"
"","10.9000","2.2908","5847.0835"
"","11.0000","2.3113","5847.6226"
"","11.1000","2.3333","5857.6392"
"","11.2000","2.3542","5855.6567"
"","11.3000","2.3754","5865.1182"
"","11.4000","2.3964","5865.5933"
"","11.5000","2.4172","5871.7119"
"","11.6000","2.4394","5877.3804"
"","11.7000","2.4594","5876.2783"
"","11.8000","2.4813","5885.3960"
"","11.9000","2.5017","5885.9556"
"","12.0000","2.5235","5895.8564"
"","12.1000","2.5449","5895.5581"
"","12.2000","2.5656","5901.9526"
"","12.3000","2.5869","5903.7520"
"","12.4000","2.6077","5909.4487"
"","12.5000","2.6298","5915.3574"
"","12.6000","2.6502","5914.8354"
"","12.7000","2.6718","5923.8804"
"","12.8000","2.6923","5923.4419"
"","12.9000","2.7138","5934.0972"
"","13.0000","2.7354","5932.9497"
"","13.1000","2.7556","5937.0552"
"","13.2000","2.7774","5942.5059"
"","13.3000","2.7979","5945.7358"
"","13.4000","2.8202","5954.7168"
"","13.5000","2.8408","5951.2437"
"","13.6000","2.8622","5961.5391"
"","13.7000","2.8829","5961.1465"
"","13.8000","2.9042","5968.9614"
"","13.9000","2.9262","5971.5776"
"","14.0000","2.9464","5972.6021"
"","14.1000","2.9681","5979.6138"
"","14.2000","2.9886","5980.9141"
"","14.3000","3.0106","5990.5327"
"","14.4000","3.0316","5988.0303"
"","14.5000","3.0525","5996.8403"
"","14.6000","3.0736","5997.3989"
"","14.7000","3.0944","6003.3999"
"","14.8000","3.1167","6009.2759"
"","14.9000","3.1368","6007.1528"
"","15.0000","3.1585","6015.8296"
"","15.1000","3.1791","6016.6733"
"","15.2000","3.2010","6025.4131"
"","15.3000","3.2222","6024.2432"
"","15.4000","3.2428","6030.7178"
"","15.5000","3.2642","6032.2534"
"","15.6000","3.2849","6038.2212"
"","15.7000","3.3072","6044.4077"
"","15.8000","3.3274","6041.0854"
"","15.9000","3.3490","6051.3145"
"","16.0000","3.3696","6050.1216"
"","16.1000","3.3913","6059.4150"
"","16.2000","3.4128","6059.1514"
"","16.3000","3.4332","6063.0093"
"","16.4000","3.4547","6067.8071"
"","16.5000","3.4753","6070.4233"
"","16.6000","3.4975","6078.3813"
"","16.7000","3.5182","6074.8687"
"","16.8000","3.5393","6084.4751"
"","16.9000","3.5605","6084.1704"
"","17.0000","3.5815","6090.0332"
"","17.1000","3.6035","6094.4966"
"","17.2000","3.6236","6093.7358"
"","17.3000","3.6455","6101.3262"
"","17.4000","3.6661","6102.1499"
"","17.5000","3.6878","6110.1670"
"","17.6000","3.7088","6108.1318"
"","17.7000","3.7298","6115.6182"
"","17.8000","3.7510","6115.5640"
"","17.9000","3.7719","6120.9341"
"","18.0000","3.7940","6126.1689"
"","18.1000","3.8142","6124.4946"
"","18.2000","3.8361","6133.8901"
"","18.3000","3.8564","6132.0684"
"","18.4000","3.8782","6142.0293"
"","18.5000","3.8994","6139.8091"
"","18.6000","3.9202","6145.5259"
"","18.7000","3.9415","6146.6055"
"","18.8000","3.9621","6150.9907"
"","18.9000","3.9846","6158.5039"
"","19.0000","4.0046","6153.6997"
"","19.1000","4.0265","6164.2749"
"","19.2000","4.0469","6162.4302"
"","19.3000","4.0684","6170.9009"
"","19.4000","4.0903","6171.7856"
"","19.5000","4.1106","6172.3657"
"","19.6000","4.1321","6176.8442"
"","19.7000","4.1527","6179.7827"
"","19.8000","4.1749","6187.3232"
"","19.9000","4.1955","6183.4561"
"","20.0000","4.2169","6192.4351"
"","20.1000","4.2376","6191.5947"
"","20.2000","4.2589","6198.8579"
"","20.3000","4.2808","6200.6968"
"","20.4000","4.3010","6199.9194"
"","20.5000","4.3227","6206.7632"
"","20.6000","4.3433","6206.5674"
"","20.7000","4.3651","6214.8325"
"","20.8000","4.3863","6212.3726"
"","20.9000","4.4072","6219.2275"
"","21.0000","4.4284","6220.1904"
"","21.1000","4.4493","6224.1118"
"","21.2000","4.4713","6228.4326"
"","21.3000","4.4916","6226.2100"
"","21.4000","4.5132","6233.7783"
"","21.5000","4.5336","6232.4385"
"","21.6000","4.5554","6241.6641"
"","21.7000","4.5770","6241.0645"
"","21.8000","4.5973","6243.3374"
"","21.9000","4.6189","6247.5781"
"","22.0000","4.6394","6248.3047"
"","22.1000","4.6617","6256.0981"
"","22.2000","4.6822","6251.4199"
"","22.3000","4.7037","6260.1270"
"","22.4000","4.7245","6259.1196"
"","22.5000","4.7459","6266.2183"
"","22.6000","4.7678","6267.2520"
"","22.7000","4.7880","6267.8916"
"","22.8000","4.8094","6271.1953"
"","22.9000","4.8300","6273.5454"
"","23.0000","4.8521","6280.6157"
"","23.1000","4.8728","6276.5347"
"","23.2000","4.8938","6282.6001"
"","23.3000","4.9151","6285.4214"
"","23.4000","4.9361","6288.9019"
"","23.5000","4.9582","6292.3389"
"","23.6000","4.9784","6290.1309"
"","23.7000","5.0002","6297.0234"
"","23.8000","5.0207","6296.5146"
"","23.9000","5.0426","6303.7979"
"","24.0000","5.0636","6300.9717"
"","24.1000","5.0845","6306.9658"
"","24.2000","5.1057","6307.6479"
"","24.3000","5.1264","6310.7051"
"","24.4000","5.1485","6315.9292"
"","24.5000","5.1688","6311.9834"
"","24.6000","5.1905","6319.5513"
"","24.7000","5.2111","6318.7549"
"","24.8000","5.2327","6326.3057"
"","24.9000","5.2545","6325.7046"
"","25.0000","5.2747","6327.4204"
"","25.1000","5.2963","6330.3105"
"","25.2000","5.3168","6331.1616"
"","25.3000","5.3393","6339.3726"
"","25.4000","5.3596","6331.9185"
"","25.5000","5.3809","6341.4497"
"","25.6000","5.4017","6339.4370"
"","25.7000","5.4231","6346.6885"
"","25.8000","5.4450","6348.0845"
"","25.9000","5.4652","6347.0425"
"","26.0000","5.4867","6351.5684"
"","26.1000","5.5074","6352.2422"
"","26.2000","5.5295","6359.2871"
"","26.3000","5.5502","6353.9214"
"","26.4000","5.5714","6361.1113"
"","26.5000","5.5924","6360.1025"
"","26.6000","5.6135","6366.3101"
"","26.7000","5.6357","6368.6274"
"","26.8000","5.6556","6365.7700"
"","26.9000","5.6772","6371.6934"
"","27.0000","5.6979","6371.0732"
"","27.1000","5.7196","6377.1675"
"","27.2000","5.7407","6373.9883"
"","27.3000","5.7617","6380.6636"
"","27.4000","5.7830","6380.5894"
"","27.5000","5.8039","6384.0693"
"","27.6000","5.8261","6388.8296"
"","27.7000","5.8463","6384.4136"
"","27.8000","5.8680","6391.2319"
"","27.9000","5.8885","6388.5898"
"","28.0000","5.9100","6396.3584"
"","28.1000","5.9317","6395.0645"
"","28.2000","5.9521","6396.5000"
"","28.3000","5.9736","6399.0688"
"","28.4000","5.9943","6400.3833"
"","28.5000","6.0163","6407.0942"
"","28.6000","6.0369","6401.4346"
"","28.7000","6.0585","6409.5815"
"","28.8000","6.0791","6406.1963"
"","28.9000","6.1004","6412.9458"
"","29.0000","6.1225","6413.6572"
"","29.1000","6.1426","6411.6655"
"","29.2000","6.1644","6416.8701"
"","29.3000","6.1845","6415.3726"
"","29.4000","6.2068","6424.4678"
"","29.5000","6.2274","6418.4526"
"","29.6000","6.2487","6425.2036"
"","29.7000","6.2694","6423.4136"
"","29.8000","6.2908","6428.8237"
"","29.9000","6.3128","6430.5454"
"","30.0000","6.3329","6427.6016"
"","30.1000","6.3547","6433.6436"
"","30.2000","6.3752","6432.3486"
"","30.3000","6.3972","6439.6836"
"","30.4000","6.4183","6435.0894"
"","30.5000","6.4392","6439.8521"
"","30.6000","6.4604","6439.8564"
"","30.7000","6.4811","6441.4556"
"","30.8000","6.5033","6447.2988"
"","30.9000","6.5235","6441.0635"
"","31.0000","6.5453","6449.6265"
"","31.1000","6.5658","6446.9448"
"","31.2000","6.5873","6453.1743"
"","31.3000","6.6090","6452.6030"
"","31.4000","6.6295","6453.6050"
"","31.5000","6.6510","6455.3521"
"","31.6000","6.6716","6455.4336"
"","31.7000","6.6938","6462.0176"
"","31.8000","6.7145","6456.6401"
"","31.9000","6.7357","6462.1865"
"","32.0000","6.7564","6460.2314"
"","32.1000","6.7777","6466.7754"
"","32.2000","6.7995","6466.4463"
"","32.3000","6.8199","6466.6519"
"","32.4000","6.8415","6469.3516"
"","32.5000","6.8618","6469.1035"
"","32.6000","6.8841","6476.2466"
"","32.7000","6.9048","6469.9219"
"","32.8000","6.9260","6476.5215"
"","32.9000","6.9470","6474.2280"
"","33.0000","6.9681","6478.9087"
"","33.1000","6.9902","6481.8179"
"","33.2000","7.0103","6477.0439"
"","33.3000","7.0321","6483.5229"
"","33.4000","7.0526","6480.6431"
"","33.5000","7.0745","6488.0161"
"","33.6000","7.0955","6482.9282"
"","33.7000","7.1163","6487.2935"
"","33.8000","7.1377","6487.8174"
"","33.9000","7.1585","6490.1738"
"","34.0000","7.1807","6494.4526"
"","34.1000","7.2008","6488.4385"
"","34.2000","7.2227","6496.4688"
"","34.3000","7.2432","6492.0024"
"","34.4000","7.2647","6498.0117"
"","34.5000","7.2863","6496.7588"
"","34.6000","7.3069","6498.4707"
"","34.7000","7.3283","6499.4453"
"","34.8000","7.3490","6500.9429"
"","34.9000","7.3710","6505.1289"
"","35.0000","7.3916","6500.7129"
"","35.1000","7.4131","6506.9268"
"","35.2000","7.4337","6502.9448"
"","35.3000","7.4550","6509.4731"
"","35.4000","7.4769","6509.1299"
"","35.5000","7.4973","6507.9346"
"","35.6000","7.5189","6511.4126"
"","35.7000","7.5392","6509.2363"
"","35.8000","7.5613","6517.2134"
"","35.9000","7.5822","6510.7832"
"","36.0000","7.6035","6516.9258"
"","36.1000","7.6242","6511.9243"
"","36.2000","7.6453","6519.5522"
"","36.3000","7.6676","6520.9502"
"","36.4000","7.6876","6515.9038"
"","36.5000","7.7097","6522.7358"
"","36.6000","7.7297","6518.6084"
"","36.7000","7.7519","6527.1465"
"","36.8000","7.7730","6520.8071"
"","36.9000","7.7937","6525.3315"
"","37.0000","7.8150","6524.1016"
"","37.1000","7.8359","6526.4688"
"","37.2000","7.8582","6530.7759"
"","37.3000","7.8783","6525.0137"
"","37.4000","7.9000","6531.4331"
"","37.5000","7.9206","6528.0581"
"","37.6000","7.9421","6533.9907"
"","37.7000","7.9636","6531.3643"
"","37.8000","7.9840","6532.0923"
"","37.9000","8.0055","6534.2017"
"","38.0000","8.0263","6534.9302"
"","38.1000","8.0483","6539.2671"
"","38.2000","8.0690","6534.7075"
"","38.3000","8.0904","6539.0142"
"","38.4000","8.1110","6536.2900"
"","38.5000","8.1323","6540.3530"
"","38.6000","8.1543","6542.7549"
"","38.7000","8.1746","6539.3457"
"","38.8000","8.1963","6543.7129"
"","38.9000","8.2167","6541.0337"
"","39.0000","8.2387","6547.7393"
"","39.1000","8.2595","6542.0771"
"","39.2000","8.2805","6545.7021"
"","39.3000","8.3018","6544.8740"
"","39.4000","8.3227","6547.1553"
"","39.5000","8.3448","6550.6621"
"","39.6000","8.3651","6545.9429"
"","39.7000","8.3868","6551.1880"
"","39.8000","8.4073","6548.5137"
"","39.9000","8.4291","6554.6846"
"","40.0000","8.4504","6549.6558"
"","40.1000","8.4710","6551.9824"
"","40.2000","8.4924","6552.4570"
"","40.3000","8.5131","6553.1060"
"","40.4000","8.5354","6558.2832"
"","40.5000","8.5556","6550.7979"
"","40.6000","8.5773","6558.8154"
"","40.7000","8.5979","6555.2227"
"","40.8000","8.6193","6560.1157"
"","40.9000","8.6409","6558.1665"
"","41.0000","8.6614","6557.2568"
"","41.1000","8.6830","6559.6172"
"","41.2000","8.7035","6558.7690"
"","41.3000","8.7256","6564.6978"
"","41.4000","8.7462","6558.9199"
"","41.5000","8.7678","6564.9321"
"","41.6000","8.7885","6560.6372"
"","41.7000","8.8096","6564.7021"
"","41.8000","8.8318","6565.7080"
"","41.9000","8.8518","6560.9507"
"","42.0000","8.8735","6565.7495"
"","42.1000","8.8940","6563.8369"
"","42.2000","8.9158","6569.4824"
"","42.3000","8.9370","6564.8838"
"","42.4000","8.9581","6569.2104"
"","42.5000","8.9792","6567.1392"
"","42.6000","8.9997","6568.3945"
"","42.7000","9.0224","6573.8066"
"","42.8000","9.0424","6565.9629"
"","42.9000","9.0641","6571.3579"
"","43.0000","9.0846","6566.9639"
"","43.1000","9.1065","6574.3291"
"","43.2000","9.1279","6570.8286"
"","43.3000","9.1484","6571.2886"
"","43.4000","9.1696","6572.0947"
"","43.5000","9.1905","6573.5869"
"","43.6000","9.2127","6577.2676"
"","43.7000","9.2329","6570.5625"
"","43.8000","9.2545","6576.6514"
"","43.9000","9.2751","6572.9009"
"","44.0000","9.2967","6577.9971"
"","44.1000","9.3183","6575.8257"
"","44.2000","9.3385","6574.5811"
"","44.3000","9.3604","6577.9878"
"","44.4000","9.3809","6575.9131"
"","44.5000","9.4031","6581.9087"
"","44.6000","9.4235","6574.2412"
"","44.7000","9.4451","6581.2363"
"","44.8000","9.4657","6575.6006"
"","44.9000","9.4870","6580.7515"
"","45.0000","9.5089","6580.4907"
"","45.1000","9.5290","6576.8296"
"","45.2000","9.5510","6582.6943"
"","45.3000","9.5715","6578.8945"
"","45.4000","9.5933","6584.7012"
"","45.5000","9.6143","6579.2104"
"","45.6000","9.6355","6583.1631"
"","45.7000","9.6565","6579.9058"
"","45.8000","9.6773","6581.7461"
"","45.9000","9.6995","6585.1182"
"","46.0000","9.7198","6579.5576"
"","46.1000","9.7415","6584.6147"
"","46.2000","9.7620","6581.4004"
"","46.3000","9.7835","6587.0151"
"","46.4000","9.8050","6583.5156"
"","46.5000","9.8256","6583.8174"
"","46.6000","9.8470","6583.8105"
"","46.7000","9.8677","6584.0146"
"","46.8000","9.8899","6589.0791"
"","46.9000","9.9104","6581.6494"
"","47.0000","9.9318","6586.4512"
"","47.1000","9.9526","6583.7212"
"","47.2000","9.9740","6588.3232"
"","47.3000","9.9957","6586.2036"
"","47.4000","10.0160","6584.4565"
"","47.5000","10.0378","6587.4951"
"","47.6000","10.0580","6584.4385"
"","47.7000","10.0803","6591.3042"
"","47.8000","10.1009","6583.1528"
"","47.9000","10.1223","6589.8208"
"","48.0000","10.1432","6585.7051"
"","48.1000","10.1644","6588.6973"
"","48.2000","10.1864","6589.5430"
"","48.3000","10.2066","6584.5527"
"","48.4000","10.2285","6589.3052"
"","48.5000","10.2488","6585.0576"
"","48.6000","10.2707","6591.2358"
"","48.7000","10.2916","6586.0645"
"","48.8000","10.3126","6589.7578"
"","48.9000","10.3337","6586.9883"
"","49.0000","10.3546","6588.1221"
"","49.1000","10.3767","6592.4399"
"","49.2000","10.3970","6585.1851"
"","49.3000","10.4188","6590.8862"
"","49.4000","10.4393","6586.8242"
"","49.5000","10.4610","6592.3438"
"","49.6000","10.4825","6588.0015"
"","49.7000","10.5031","6587.2915"
"","49.8000","10.5245","6588.0068"
"","49.9000","10.5451","6587.4512"
"","50.0000","10.5674","6592.2017"
"","50.1000","10.5875","6584.4565"
"","50.2000","10.6093","6591.3169"
"","50.3000","10.6298","6586.2788"
"","50.4000","10.6512","6590.6182"
"","50.5000","10.6730","6588.6514"
"","50.6000","10.6933","6585.8652"
"","50.7000","10.7150","6589.1182"
"","50.8000","10.7356","6587.0581"
"","50.9000","10.7578","6591.9531"
"","51.0000","10.7783","6584.1436"
"","51.1000","10.7998","6590.5952"
"","51.2000","10.8208","6585.7007"
"","51.3000","10.8417","6588.3516"
"","51.4000","10.8637","6588.5874"
"","51.5000","10.8838","6583.8101"
"","51.6000","10.9054","6587.9019"
"","51.7000","10.9260","6585.1211"
"","51.8000","10.9478","6589.2173"
"","51.9000","10.9690","6584.2734"
"","52.0000","10.9900","6587.0928"
"","52.1000","11.0112","6584.1636"
"","52.2000","11.0319","6584.4619"
"","52.3000","11.0542","6587.9546"
"","52.4000","11.0743","6579.9141"
"","52.5000","11.0962","6586.2842"
"","52.6000","11.1167","6580.8931"
"","52.7000","11.1384","6586.3745"
"","52.8000","11.1598","6581.3086"
"","52.9000","11.1802","6581.7715"
"","53.0000","11.2018","6581.4517"
"","53.1000","11.2221","6579.0610"
"","53.2000","11.2447","6584.2285"
"","53.3000","11.2649","6575.0957"
"","53.4000","11.2867","6581.3193"
"","53.5000","11.3070","6574.1919"
"","53.6000","11.3287","6581.2437"
"","53.7000","11.3506","6576.6133"
"","53.8000","11.3706","6573.2720"
"","53.9000","11.3925","6575.5078"
"","54.0000","11.4130","6572.1108"
"","54.1000","11.4351","6576.4517"
"","54.2000","11.4557","6567.3999"
"","54.3000","11.4769","6571.8906"
"","54.4000","11.4978","6567.2627"
"","54.5000","11.5191","6568.8208"
"","54.6000","11.5409","6567.0049"
"","54.7000","11.5612","6561.6807"
"","54.8000","11.5828","6564.2280"
"","54.9000","11.6034","6559.7183"
"","55.0000","11.6254","6563.0449"
"","55.1000","11.6462","6553.2319"
"","55.2000","11.6673","6556.8843"
"","55.3000","11.6885","6552.1909"
"","55.4000","11.7094","6551.2285"
"","55.5000","11.7311","6549.1572"
"","55.6000","11.7518","6543.4277"
"","55.7000","11.7734","6544.2002"
"","55.8000","11.7939","6537.7271"
"","55.9000","11.8156","6539.6602"
"","56.0000","11.8369","6529.9438"
"","56.1000","11.8578","6531.6206"
"","56.2000","11.8791","6524.5601"
"","56.3000","11.8998","6522.4619"
"","56.4000","11.9220","6521.1279"
"","56.5000","11.9425","6509.7837"
"","56.6000","11.9641","6512.3066"
"","56.7000","11.9846","6501.5337"
"","56.8000","12.0061","6502.7788"
"","56.9000","12.0277","6490.8960"
"","57.0000","12.0481","6487.0664"
"","57.1000","12.0695","6480.5688"
"","57.2000","12.0902","6474.2715"
"","57.3000","12.1122","6469.5986"
"","57.4000","12.1331","6455.4946"
"","57.5000","12.1542","6455.2710"
"","57.6000","12.1753","6441.3315"
"","57.7000","12.1963","6435.1626"
"","57.8000","12.2184","6423.1089"
"","57.9000","12.2385","6410.4556"
"","58.0000","12.2602","6399.8833"
"","58.1000","12.2808","6386.5288"
"","58.2000","12.3026","6374.5557"
"","58.3000","12.3235","6354.0391"
"","58.4000","12.3446","6342.9678"
"","58.5000","12.3657","6316.9404"
"","58.6000","12.3865","6300.2349"
"","58.7000","12.4088","6271.6460"
"","58.8000","12.4290","6245.6841"
"","58.9000","12.4507","6215.7212"
"","59.0000","12.4712","6184.1401"
"","59.1000","12.4930","6148.3477"
"","59.2000","12.5145","6103.8184"
"","59.3000","12.5351","6064.2222"
"","59.4000","12.5564","6010.7725"
"","59.5000","12.5771","5958.5278"
"","59.6000","12.5994","5893.9849"
"","59.7000","12.6197","5826.7305"
"","59.8000","12.6413","5744.0410"
"","59.8510","12.6520","5487.5151"
"","59.8540","12.6526","5179.7871"
"","59.8560","12.6530","4922.2256"
"","59.8580","12.6535","4635.4482"
"","59.8600","12.6539","4328.2954"
"","59.8620","12.6543","4008.5659"
"","59.8640","12.6547","3682.9084"
"","59.8660","12.6551","3356.9727"
2,Time,Displacement,Force
,(s),(mm),(N)
"","0.0000","0.0000","42.9112"
"","0.1000","0.0054","43.2120"
"","0.2000","0.0219","44.4002"
"","0.3000","0.0490","48.1063"
"","0.4000","0.0697","100.9262"
"","0.5000","0.0903","253.5507"
"","0.6000","0.1123","431.9255"
"","0.7000","0.1333","622.4483"
"","0.8000","0.1544","817.8358"
"","0.9000","0.1753","1010.9627"
"","1.0000","0.1965","1202.2736"
"","1.1000","0.2185","1386.4570"
"","1.2000","0.2388","1548.1625"
"","1.3000","0.2605","1720.6360"
"","1.4000","0.2811","1877.5048"
"","1.5000","0.3028","2045.5084"
"","1.6000","0.3239","2205.6985"
"","1.7000","0.3447","2364.9739"
"","1.8000","0.3661","2527.4778"
"","1.9000","0.3867","2683.0532"
"","2.0000","0.4088","2848.8552"
"","2.1000","0.4291","2997.4695"
"","2.2000","0.4508","3158.6804"
"","2.3000","0.4715","3309.3364"
"","2.4000","0.4931","3466.4392"
"","2.5000","0.5148","3621.8933"
"","2.6000","0.5351","3765.1860"
"","2.7000","0.5568","3918.7285"
"","2.8000","0.5770","4058.0583"
"","2.9000","0.5994","4213.0996"
"","3.0000","0.6199","4347.0947"
"","3.1000","0.6411","4482.9556"
"","3.2000","0.6621","4605.7441"
"","3.3000","0.6832","4722.1299"
"","3.4000","0.7052","4830.2354"
"","3.5000","0.7255","4917.8433"
"","3.6000","0.7472","5000.6255"
"","3.7000","0.7678","5066.7627"
"","3.8000","0.7896","5128.4497"
"","3.9000","0.8107","5174.4580"
"","4.0000","0.8317","5219.8926"
"","4.1000","0.8529","5255.0054"
"","4.2000","0.8739","5288.1450"
"","4.3000","0.8958","5316.9995"
"","4.4000","0.9160","5337.7935"
"","4.5000","0.9378","5363.0630"
"","4.6000","0.9583","5378.9077"
"","4.7000","0.9800","5399.1309"
"","4.8000","1.0012","5408.8198"
"","4.9000","1.0219","5426.1973"
"","5.0000","1.0434","5435.9409"
"","5.1000","1.0641","5448.0029"
"","5.2000","1.0864","5459.8516"
"","5.3000","1.1066","5464.4185"
"","5.4000","1.1284","5478.2642"
"","5.5000","1.1490","5481.6167"
"","5.6000","1.1703","5493.6523"
"","5.7000","1.1919","5496.4819"
"","5.8000","1.2124","5504.8110"
"","5.9000","1.2340","5510.7417"
"","6.0000","1.2545","5516.8369"
"","6.1000","1.2767","5525.9937"
"","6.2000","1.2972","5525.0015"
"","6.3000","1.3187","5536.7803"
"","6.4000","1.3394","5537.1499"
"","6.5000","1.3606","5546.6274"
"","6.6000","1.3827","5549.3662"
"","6.7000","1.4030","5552.7051"
"","6.8000","1.4245","5559.6245"
"","6.9000","1.4451","5563.3491"
"","7.0000","1.4672","5572.0176"
"","7.1000","1.4880","5571.2612"
"","7.2000","1.5092","5580.6133"
"","7.3000","1.5300","5581.1582"
"","7.4000","1.5510","5588.1484"
"","7.5000","1.5733","5593.1382"
"","7.6000","1.5933","5592.6372"
"","7.7000","1.6151","5601.9248"
"","7.8000","1.6357","5603.4556"
"","7.9000","1.6575","5612.2583"
"","8.0000","1.6788","5611.5532"
"","8.1000","1.6992","5619.1392"
"","8.2000","1.7207","5622.0537"
"","8.3000","1.7414","5626.1924"
"","8.4000","1.7637","5633.7358"
"","8.5000","1.7835","5631.4941"
"","8.6000","1.8055","5643.0981"
"","8.7000","1.8261","5641.6240"
"","8.8000","1.8476","5651.0234"
"","8.9000","1.8693","5651.6514"
"","9.0000","1.8897","5656.5845"
"","9.1000","1.9114","5661.6284"
"","9.2000","1.9319","5664.1885"
"","9.3000","1.9541","5673.0049"
"","9.4000","1.9747","5671.2319"
"","9.5000","1.9961","5680.9014"
"","9.6000","2.0169","5681.1655"
"","9.7000","2.0381","5688.9268"
"","9.8000","2.0599","5691.9873"
"","9.9000","2.0802","5693.9263"
"","10.0000","2.1020","5700.4814"
"","10.1000","2.1223","5702.1978"
"","10.2000","2.1444","5711.9385"
"","10.3000","2.1654","5710.1816"
"","10.4000","2.1864","5719.0518"
"","10.5000","2.2074","5719.0000"
"","10.6000","2.2284","5726.6445"
"","10.7000","2.2504","5730.4814"
"","10.8000","2.2708","5731.2266"
"","10.9000","2.2925","5739.7749"
"","11.0000","2.3129","5740.1421"
"","11.1000","2.3347","5751.0542"
"","11.2000","2.3560","5748.9883"
"","11.3000","2.3765","5755.5317"
"","11.4000","2.3979","5757.7368"
"","11.5000","2.4186","5763.3262"
"","11.6000","2.4409","5770.0356"
"","11.7000","2.4613","5767.4385"
"","11.8000","2.4831","5778.8906"
"","11.9000","2.5036","5778.6992"
"","12.0000","2.5251","5787.3594"
"","12.1000","2.5468","5788.0156"
"","12.2000","2.5670","5791.2539"
"","12.3000","2.5887","5796.5562"
"","12.4000","2.6091","5798.7432"
"","12.5000","2.6314","5807.7861"
"","12.6000","2.6520","5805.9526"
"","12.7000","2.6734","5815.5952"
"","12.8000","2.6942","5815.6797"
"","12.9000","2.7153","5822.6650"
"","13.0000","2.7374","5826.9189"
"","13.1000","2.7575","5827.4619"
"","13.2000","2.7792","5833.7935"
"","13.3000","2.7997","5836.0381"
"","13.4000","2.8217","5844.7432"
"","13.5000","2.8427","5842.3330"
"","13.6000","2.8638","5851.8037"
"","13.7000","2.8847","5851.2544"
"","13.8000","2.9057","5859.2866"
"","13.9000","2.9279","5863.6177"
"","14.0000","2.9479","5861.9849"
"","14.1000","2.9697","5870.6631"
"","14.2000","2.9903","5871.4570"
"","14.3000","3.0122","5880.5181"
"","14.4000","3.0334","5879.3135"
"","14.5000","3.0540","5885.6152"
"","14.6000","3.0752","5888.4976"
"","14.7000","3.0961","5892.9023"
"","14.8000","3.1183","5900.1333"
"","14.9000","3.1386","5896.7310"
"","15.0000","3.1601","5907.1465"
"","15.1000","3.1811","5906.5469"
"","15.2000","3.2024","5913.9126"
"","15.3000","3.2241","5916.1382"
"","15.4000","3.2444","5918.4917"
"","15.5000","3.2661","5923.4976"
"","15.6000","3.2867","5925.9785"
"","15.7000","3.3087","5934.7632"
"","15.8000","3.3293","5931.0991"
"","15.9000","3.3507","5941.3291"
"","16.0000","3.3715","5940.0400"
"","16.1000","3.3927","5947.2822"
"","16.2000","3.4146","5949.9937"
"","16.3000","3.4348","5950.4736"
"","16.4000","3.4567","5958.3535"
"","16.5000","3.4770","5958.2769"
"","16.6000","3.4991","5968.6074"
"","16.7000","3.5199","5964.5308"
"","16.8000","3.5411","5973.4102"
"","16.9000","3.5620","5972.9839"
"","17.0000","3.5829","5979.7603"
"","17.1000","3.6052","5983.9873"
"","17.2000","3.6252","5982.2563"
"","17.3000","3.6472","5991.2251"
"","17.4000","3.6675","5990.8516"
"","17.5000","3.6893","5999.5742"
"","17.6000","3.7109","5998.7114"
"","17.7000","3.7315","6003.2412"
"","17.8000","3.7526","6005.3271"
"","17.9000","3.7734","6009.8003"
"","18.0000","3.7957","6016.5034"
"","18.1000","3.8160","6013.1533"
"","18.2000","3.8376","6022.3560"
"","18.3000","3.8582","6021.4692"
"","18.4000","3.8798","6030.1172"
"","18.5000","3.9014","6030.4531"
"","18.6000","3.9216","6032.3862"
"","18.7000","3.9434","6037.8447"
"","18.8000","3.9639","6038.4648"
"","18.9000","3.9860","6046.6753"
"","19.0000","4.0067","6043.5376"
"","19.1000","4.0280","6052.1328"
"","19.2000","4.0489","6052.1289"
"","19.3000","4.0702","6058.8237"
"","19.4000","4.0920","6061.2153"
"","19.5000","4.1121","6060.4980"
"","19.6000","4.1339","6067.2979"
"","19.7000","4.1542","6067.4253"
"","19.8000","4.1762","6076.2393"
"","19.9000","4.1974","6073.9165"
"","20.0000","4.2181","6079.7178"
"","20.1000","4.2395","6082.1255"
"","20.2000","4.2602","6085.5352"
"","20.3000","4.2825","6091.4238"
"","20.4000","4.3027","6087.8555"
"","20.5000","4.3245","6096.3823"
"","20.6000","4.3451","6094.8350"
"","20.7000","4.3667","6103.7178"
"","20.8000","4.3883","6102.3745"
"","20.9000","4.4088","6106.2622"
"","21.0000","4.4299","6108.1797"
"","21.1000","4.4507","6112.6445"
"","21.2000","4.4729","6119.2461"
"","21.3000","4.4933","6114.4111"
"","21.4000","4.5145","6122.1113"
"","21.5000","4.5357","6123.3027"
"","21.6000","4.5570","6129.7129"
"","21.7000","4.5788","6130.2563"
"","21.8000","4.5991","6131.1621"
"","21.9000","4.6208","6136.0947"
"","22.0000","4.6413","6137.2109"
"","22.1000","4.6634","6144.5894"
"","22.2000","4.6841","6141.2378"
"","22.3000","4.7053","6148.9248"
"","22.4000","4.7263","6148.4595"
"","22.5000","4.7472","6153.9932"
"","22.6000","4.7692","6157.0332"
"","22.7000","4.7895","6155.8442"
"","22.8000","4.8111","6161.5103"
"","22.9000","4.8317","6161.6172"
"","23.0000","4.8536","6169.8403"
"","23.1000","4.8749","6166.6699"
"","23.2000","4.8956","6172.8096"
"","23.3000","4.9169","6173.5708"
"","23.4000","4.9376","6176.7993"
"","23.5000","4.9600","6183.2236"
"","23.6000","4.9800","6176.7212"
"","23.7000","5.0017","6186.6963"
"","23.8000","5.0222","6184.5591"
3,Time,Displacement,Force
,(s),(mm),(N)
"","0.0000","0.0000","43.0887"
"","0.1000","0.0032","44.2471"
"","0.2000","0.0154","44.2460"
"","0.3000","0.0458","44.8865"
"","0.4000","0.0661","49.9945"
"","0.5000","0.0877","103.5471"
"","0.6000","0.1083","265.5775"
"","0.7000","0.1296","448.3242"
"","0.8000","0.1502","629.9376"
"","0.9000","0.1725","827.3776"
"","1.0000","0.1929","1007.4890"
"","1.1000","0.2142","1193.7312"
"","1.2000","0.2352","1364.8438"
"","1.3000","0.2564","1527.2188"
"","1.4000","0.2782","1698.2559"
"","1.5000","0.2985","1857.0662"
"","1.6000","0.3202","2027.2174"
"","1.7000","0.3407","2183.5754"
"","1.8000","0.3628","2352.6179"
"","1.9000","0.3834","2507.2090"
"","2.0000","0.4045","2668.1648"
"","2.1000","0.4258","2828.8730"
"","2.2000","0.4468","2987.6965"
"","2.3000","0.4689","3155.0557"
"","2.4000","0.4889","3303.5667"
"","2.5000","0.5108","3468.7046"
"","2.6000","0.5313","3619.1396"
"","2.7000","0.5529","3779.9429"
"","2.8000","0.5743","3936.4539"
"","2.9000","0.5950","4087.5334"
"","3.0000","0.6163","4241.8735"
"","3.1000","0.6372","4392.5610"
"","3.2000","0.6592","4550.2485"
"","3.3000","0.6796","4692.7661"
"","3.4000","0.7013","4846.0015"
"","3.5000","0.7217","4985.9507"
"","3.6000","0.7433","5136.7163"
"","3.7000","0.7649","5281.9272"
"","3.8000","0.7855","5418.8979"
"","3.9000","0.8070","5560.1997"
"","4.0000","0.8273","5689.1357"
"","4.1000","0.8496","5828.5034"
"","4.2000","0.8702","5945.6860"
"","4.3000","0.8917","6062.0439"
"","4.4000","0.9121","6153.2021"
"","4.5000","0.9336","6235.4214"
"","4.6000","0.9557","6286.5654"
"","4.7000","0.9759","6309.0459"
"","4.8000","0.9977","6318.8345"
"","4.9000","1.0179","6316.1641"
"","5.0000","1.0402","6317.0137"
"","5.1000","1.0610","6302.7466"
"","5.2000","1.0820","6303.4766"
"","5.3000","1.1030","6293.3237"
"","5.4000","1.1242","6291.6050"
"","5.5000","1.1464","6286.3589"
"","5.6000","1.1664","6277.2251"
"","5.7000","1.1882","6276.9038"
"","5.8000","1.2087","6269.0913"
"","5.9000","1.2305","6270.0688"
"","6.0000","1.2517","6261.2803"
"","6.1000","1.2723","6260.9150"
"","6.2000","1.2935","6256.8525"
"","6.3000","1.3145","6256.9531"
"","6.4000","1.3365","6257.3599"
"","6.5000","1.3571","6251.6460"
"","6.6000","1.3784","6254.3018"
"","6.7000","1.3992","6251.7983"
"","6.8000","1.4206","6255.0625"
"","6.9000","1.4424","6253.6104"
"","7.0000","1.4628","6252.6313"
"","7.1000","1.4844","6254.2026"
"","7.2000","1.5050","6253.1279"
"","7.3000","1.5270","6257.6040"
"","7.4000","1.5476","6251.7402"
"","7.5000","1.5688","6256.6206"
"","7.6000","1.5899","6254.0049"
"","7.7000","1.6109","6257.0630"
"","7.8000","1.6329","6258.0483"
"","7.9000","1.6532","6254.5225"
"","8.0000","1.6750","6258.5054"
"","8.1000","1.6954","6257.0103"
"","8.2000","1.7175","6262.4336"
"","8.3000","1.7384","6256.1089"
"","8.4000","1.7594","6261.3857"
"","8.5000","1.7805","6259.9771"
"","8.6000","1.8014","6262.2539"
"","8.7000","1.8236","6264.7842"
"","8.8000","1.8436","6259.4985"
"","8.9000","1.8655","6266.7607"
"","9.0000","1.8860","6264.0938"
"","9.1000","1.9076","6270.0698"
"","9.2000","1.9290","6267.5713"
"","9.3000","1.9497","6269.8638"
"","9.4000","1.9710","6270.5122"
"","9.5000","1.9917","6272.1836"
"","9.6000","2.0139","6277.2422"
"","9.7000","2.0343","6273.5005"
"","9.8000","2.0560","6280.8618"
"","9.9000","2.0766","6277.6958"
"","10.0000","2.0980","6284.5781"
"","10.1000","2.1198","6284.4067"
"","10.2000","2.1400","6284.0210"
"","10.3000","2.1616","6287.8892"
"","10.4000","2.1822","6288.8408"
"","10.5000","2.2042","6295.8218"
"","10.6000","2.2249","6290.9580"
"","10.7000","2.2463","6298.9146"
"","10.8000","2.2672","6297.0713"
"","10.9000","2.2882","6302.6899"
"","11.0000","2.3105","6305.3071"
"","11.1000","2.3306","6302.4780"
"","11.2000","2.3524","6308.2529"
"","11.3000","2.3727","6306.2690"
"","11.4000","2.3948","6314.1270"
"","11.5000","2.4159","6310.4419"
"","11.6000","2.4366","6314.6240"
"","11.7000","2.4576","6314.4443"
"","11.8000","2.4787","6319.1714"
"","11.9000","2.5009","6322.5356"
"","12.0000","2.5210","6318.4082"
"","12.1000","2.5427","6324.8940"
"","12.2000","2.5633","6323.2466"
"","12.3000","2.5850","6329.5215"
"","12.4000","2.6063","6326.3052"
"","12.5000","2.6269","6328.8843"
"","12.6000","2.6484","6330.8628"
"","12.7000","2.6692","6332.1060"
"","12.8000","2.6913","6337.4995"
"","12.9000","2.7116","6331.8633"
"","13.0000","2.7334","6339.6714"
"","13.1000","2.7537","6334.9902"
"","13.2000","2.7754","6342.1602"
"","13.3000","2.7970","6340.8853"
"","13.4000","2.8173","6340.3418"
"","13.5000","2.8392","6344.9771"
"","13.6000","2.8597","6343.4155"
"","13.7000","2.8818","6350.9302"
"","13.8000","2.9024","6344.5889"
"","13.9000","2.9238","6351.7368"
"","14.0000","2.9446","6348.7798"
"","14.1000","2.9656","6353.2202"
"","14.2000","2.9875","6354.5332"
"","14.3000","3.0079","6353.0645"
"","14.4000","3.0296","6357.5693"
"","14.5000","3.0500","6356.4004"
"","14.6000","3.0720","6363.7124"
"","14.7000","3.0930","6358.9937"
"","14.8000","3.1139","6363.8853"
"","14.9000","3.1350","6362.7720"
"","15.0000","3.1560","6366.1538"
"","15.1000","3.1782","6370.3955"
"","15.2000","3.1985","6365.0044"
"","15.3000","3.2200","6371.5762"
"","15.4000","3.2406","6369.5171"
"","15.5000","3.2623","6375.9780"
"","15.6000","3.2837","6373.3174"
"","15.7000","3.3044","6375.7954"
"","15.8000","3.3258","6376.5308"
"","15.9000","3.3462","6377.0391"
"","16.0000","3.3687","6384.3750"
"","16.1000","3.3888","6376.3364"
"","16.2000","3.4106","6386.0127"
"","16.3000","3.4313","6381.7471"
"","16.4000","3.4527","6387.6309"
"","16.5000","3.4746","6386.8174"
"","16.6000","3.4948","6385.8638"
"","16.7000","3.5166","6389.4360"
"","16.8000","3.5369","6387.7866"
"","16.9000","3.5590","6394.2969"
"","17.0000","3.5796","6389.6328"
"","17.1000","3.6009","6396.0903"
"","17.2000","3.6218","6393.0610"
"","17.3000","3.6428","6396.4077"
"","17.4000","3.6650","6399.9897"
"","17.5000","3.6851","6395.3950"
"","17.6000","3.7069","6400.0913"
"","17.7000","3.7275","6398.7524"
"","17.8000","3.7493","6405.4653"
"","17.9000","3.7705","6400.6665"
"","18.0000","3.7913","6403.9424"
"","18.1000","3.8125","6402.8857"
"","18.2000","3.8333","6405.8325"
"","18.3000","3.8555","6409.4282"
"","18.4000","3.8757","6404.1772"
"","18.5000","3.8975","6411.0576"
"","18.6000","3.9179","6407.9033"
"","18.7000","3.9396","6414.2861"
"","18.8000","3.9610","6411.1392"
"","18.9000","3.9816","6412.5767"
"","19.0000","4.0031","6413.1558"
"","19.0900","4.0216","6413.8486"
4,Time,Displacement,Force
,(s),(mm),(N)
"","0.0000","0.0000","42.5625"
"","0.1000","0.0033","43.7274"
"","0.2000","0.0156","44.0655"
"","0.3000","0.0461","48.2017"
"","0.4000","0.0662","67.7533"
"","0.5000","0.0880","217.7080"
"","0.6000","0.1083","386.5715"
"","0.7000","0.1301","570.7018"
"","0.8000","0.1505","745.5123"
"","0.9000","0.1728","933.8248"
"","1.0000","0.1933","1100.3121"
"","1.1000","0.2147","1267.3116"
"","1.2000","0.2356","1427.2659"
"","1.3000","0.2565","1588.6818"
"","1.4000","0.2785","1756.8129"
"","1.5000","0.2987","1907.3044"
"","1.6000","0.3204","2070.1018"
"","1.7000","0.3409","2221.2368"
"","1.8000","0.3628","2383.1396"
"","1.9000","0.3839","2535.7966"
"","2.0000","0.4049","2688.6958"
"","2.1000","0.4261","2840.8125"
"","2.2000","0.4468","2989.9844"
"","2.3000","0.4691","3149.7791"
"","2.4000","0.4892","3290.2927"
"","2.5000","0.5111","3447.1304"
"","2.6000","0.5315","3589.5728"
"","2.7000","0.5532","3742.3618"
"","2.8000","0.5747","3890.5632"
"","2.9000","0.5951","4030.9370"
"","3.0000","0.6166","4178.6201"
"","3.1000","0.6370","4316.5581"
"","3.2000","0.6595","4471.7358"
"","3.3000","0.6799","4606.3760"
"","3.4000","0.7016","4753.1997"
"","3.5000","0.7220","4886.9302"
"","3.6000","0.7436","5029.9702"
"","3.7000","0.7654","5172.4712"
"","3.8000","0.7855","5299.9092"
"","3.9000","0.8074","5441.1948"
"","4.0000","0.8278","5567.6792"
"","4.1000","0.8500","5706.1060"
"","4.2000","0.8705","5828.3135"
"","4.3000","0.8917","5953.4414"
"","4.4000","0.9128","6072.2515"
"","4.5000","0.9340","6186.7637"
"","4.6000","0.9558","6294.4023"
"","4.7000","0.9761","6379.1992"
"","4.8000","0.9978","6455.6064"
"","4.9000","1.0184","6501.9458"
"","5.0000","1.0403","6533.2002"
"","5.1000","1.0611","6534.7144"
"","5.2000","1.0823","6537.9561"
"","5.3000","1.1034","6529.7192"
"","5.4000","1.1243","6523.7910"
"","5.5000","1.1461","6516.7280"
"","5.6000","1.1667","6505.7734"
"","5.7000","1.1883","6500.4268"
"","5.8000","1.2088","6490.1182"
"","5.9000","1.2305","6487.3447"
"","6.0000","1.2519","6476.0708"
"","6.1000","1.2726","6472.4316"
"","6.2000","1.2941","6464.5454"
"","6.3000","1.3147","6459.7607"
"","6.4000","1.3369","6458.8086"
"","6.5000","1.3574","6447.1260"
"","6.6000","1.3790","6448.4277"
"","6.7000","1.3995","6439.8960"
"","6.8000","1.4210","6442.0493"
"","6.9000","1.4426","6435.1084"
"","7.0000","1.4630","6431.6831"
"","7.1000","1.4845","6431.3511"
"","7.2000","1.5051","6428.8042"
"","7.3000","1.5272","6432.0815"
"","7.4000","1.5480","6424.7354"
"","7.5000","1.5692","6428.6240"
"","7.6000","1.5902","6425.0850"
"","7.7000","1.6112","6426.3569"
"","7.8000","1.6333","6427.4370"
"","7.9000","1.6535","6421.2949"
"","8.0000","1.6752","6425.1860"
"","8.1000","1.6957","6422.8491"
"","8.2000","1.7175","6427.2896"
"","8.3000","1.7386","6422.1079"
"","8.4000","1.7595","6425.2852"
"","8.5000","1.7807","6422.8057"
"","8.6000","1.8015","6423.9727"
"","8.7000","1.8237","6426.3804"
"","8.8000","1.8439","6419.6064"
"","8.9000","1.8656","6425.7480"
"","9.0000","1.8862","6421.9951"
"","9.1000","1.9080","6427.4482"
"","9.2000","1.9295","6423.9478"
"","9.3000","1.9500","6424.2393"
"","9.4000","1.9714","6423.1865"
"","9.5000","1.9919","6422.9360"
"","9.6000","2.0143","6428.1016"
"","9.7000","2.0346","6420.3823"
"","9.8000","2.0562","6426.8960"
"","9.9000","2.0768","6422.0503"
"","10.0000","2.0983","6427.4521"
"","10.1000","2.1200","6426.4790"
"","10.2000","2.1404","6424.0312"
"","10.3000","2.1619","6426.4922"
"","10.4000","2.1825","6425.4609"
"","10.5000","2.2045","6429.2603"
"","10.6000","2.2253","6424.4351"
"","10.7000","2.2465","6428.5410"
"","10.8000","2.2675","6426.7134"
"","10.9000","2.2887","6430.4604"
"","11.0000","2.3106","6430.8628"
"","11.1000","2.3307","6426.0786"
"","11.2000","2.3524","6431.6489"
"","11.3000","2.3730","6428.7739"
"","11.4000","2.3948","6434.1948"
"","11.5000","2.4159","6429.2676"
"","11.6000","2.4368","6433.5347"
"","11.7000","2.4580","6431.8364"
"","11.8000","2.4789","6433.5181"
"","11.9000","2.5012","6436.7441"
"","12.0000","2.5213","6430.5596"
"","12.1000","2.5432","6436.4194"
"","12.2000","2.5637","6432.0415"
"","12.3000","2.5854","6438.3335"
"","12.4000","2.6067","6434.0132"
"","12.5000","2.6273","6435.6616"
"","12.6000","2.6488","6436.0479"
"","12.7000","2.6692","6435.7222"
"","12.8000","2.6915","6440.9243"
"","12.9000","2.7120","6434.1904"
"","13.0000","2.7335","6440.3794"
"","13.1000","2.7541","6437.0239"
"","13.2000","2.7755","6441.9492"
"","13.3000","2.7974","6441.7822"
"","13.4000","2.8176","6439.1123"
"","13.5000","2.8393","6442.3657"
"","13.6000","2.8598","6440.0815"
"","13.7000","2.8819","6446.3101"
"","13.8000","2.9027","6440.5547"
"","13.9000","2.9238","6446.6758"
"","14.0000","2.9447","6444.2495"
"","14.1000","2.9659","6447.8501"
"","14.2000","2.9878","6448.1616"
"","14.3000","3.0080","6443.6675"
"","14.4000","3.0298","6448.7769"
"","14.5000","3.0502","6444.7544"
"","14.6000","3.0723","6452.2163"
"","14.7000","3.0934","6446.6836"
"","14.8000","3.1143","6451.1172"
"","14.9000","3.1356","6449.5356"
"","15.0000","3.1563","6450.2866"
"","15.1000","3.1785","6454.2046"
"","15.2000","3.1986","6446.9531"
"","15.3000","3.2202","6453.0244"
"","15.4000","3.2409","6450.2285"
"","15.5000","3.2625","6454.8711"
"","15.6000","3.2840","6452.6914"
"","15.7000","3.3045","6452.4204"
"","15.8000","3.3261","6454.2026"
"","15.9000","3.3466","6453.0439"
"","16.0000","3.3688","6458.4717"
"","16.1000","3.3894","6451.1606"
"","16.2000","3.4109","6457.1323"
"","16.3000","3.4316","6452.4897"
"","16.4000","3.4528","6457.4458"
"","16.5000","3.4748","6457.5181"
"","16.6000","3.4949","6453.4590"
"","16.7000","3.5166","6457.4995"
"","16.8000","3.5371","6455.8013"
"","16.9000","3.5592","6461.4639"
"","17.0000","3.5798","6453.8496"
"","17.1000","3.6011","6459.6006"
"","17.2000","3.6219","6455.4336"
"","17.3000","3.6432","6459.7441"
"","17.4000","3.6654","6461.0654"
"","17.5000","3.6855","6455.0488"
"","17.6000","3.7073","6460.5723"
"","17.7000","3.7277","6456.6470"
"","17.8000","3.7498","6463.3228"
"","17.9000","3.7707","6456.7036"
"","18.0000","3.7914","6459.5933"
"","18.1000","3.8128","6459.2754"
"","18.2000","3.8335","6459.3003"
"","18.3000","3.8557","6462.6665"
"","18.4000","3.8757","6454.4546"
"","18.5000","3.8977","6463.2515"
"","18.6000","3.9183","6457.9243"
"","18.7000","3.9399","6463.8130"
"","18.8000","3.9616","6460.4917"
"","18.9000","3.9819","6459.4766"
"","19.0000","4.0035","6461.7632"
"","19.1000","4.0239","6458.5669"
"","19.2000","4.0462","6465.0186"
"","19.3000","4.0666","6456.7432"
"","19.4000","4.0881","6463.7871"
"","19.5000","4.1088","6459.1147"
"","19.6000","4.1301","6463.7178"
"","19.7000","4.1521","6463.6387"
"","19.8000","4.1721","6458.5396"
"","19.9000","4.1940","6463.1821"
"","20.0000","4.2143","6458.5781"
"","20.1000","4.2365","6465.9902"
"","20.2000","4.2574","6458.5664"
"","20.3000","4.2786","6463.7109"
"","20.4000","4.2996","6459.5879"
"","20.5000","4.3205","6463.0562"
"","20.6000","4.3428","6464.6924"
"","20.7000","4.3627","6458.8403"
"","20.8000","4.3845","6463.3057"
"","20.9000","4.4050","6459.5630"
"","21.0000","4.4268","6465.5200"
"","21.1000","4.4481","6459.8540"
"","21.2000","4.4687","6462.2031"
"","21.3000","4.4902","6461.6992"
"","21.4000","4.5110","6462.4922"
"","21.5000","4.5332","6465.2407"
"","21.6000","4.5534","6458.3525"
"","21.7000","4.5750","6463.3101"
"","21.8000","4.5955","6459.0825"
"","21.9000","4.6172","6465.3477"
"","22.0000","4.6387","6460.7949"
"","22.1000","4.6591","6460.5928"
"","22.2000","4.6808","6462.1694"
"","22.3000","4.7012","6459.9580"
"","22.4000","4.7234","6464.9658"
"","22.5000","4.7439","6457.9541"
"","22.6000","4.7655","6463.0630"
"","22.7000","4.7862","6458.3623"
"","22.8000","4.8075","6462.2598"
"","22.9000","4.8293","6461.7241"
"","23.0000","4.8497","6458.4712"
"","23.1000","4.8714","6460.4722"
"","23.2000","4.8918","6457.7715"
"","23.3000","4.9139","6463.0845"
"","23.4000","4.9346","6455.1548"
"","23.5000","4.9558","6460.4243"
"","23.6000","4.9768","6455.6294"
"","23.7000","4.9977","6459.0225"
"","23.8000","5.0201","6460.3945"
"","23.9000","5.0402","6453.0151"
"","24.0000","5.0618","6457.8696"
"","24.1000","5.0824","6454.1558"
"","24.2000","5.1042","6458.6304"
"","24.3000","5.1256","6452.6089"
"","24.4000","5.1462","6453.7114"
"","24.5000","5.1674","6453.0312"
"","24.6000","5.1881","6452.9702"
"","24.7000","5.2105","6455.7554"
"","24.8000","5.2307","6446.6968"
"","24.9000","5.2520","6451.2700"
"","25.0000","5.2730","6447.7158"
"","25.1000","5.2945","6450.7017"
"","25.2000","5.3161","6446.9927"
"","25.3000","5.3365","6445.6621"
"","25.4000","5.3582","6445.6851"
"","25.5000","5.3787","6442.3638"
"","25.6000","5.4007","6444.9893"
"","25.7000","5.4214","6436.6602"
"","25.8000","5.4427","6440.2827"
"","25.9000","5.4635","6435.1401"
"","26.0000","5.4848","6438.4810"
"","26.1000","5.5068","6434.6055"
"","26.2000","5.5270","6430.3213"
"","26.3000","5.5487","6431.3726"
"","26.4000","5.5692","6426.7231"
"","26.5000","5.5910","6429.3169"
"","26.6000","5.6121","6419.5698"
"","26.7000","5.6331","6422.0146"
"","26.8000","5.6542","6415.6191"
"","26.9000","5.6751","6415.1392"
"","27.0000","5.6975","6413.9023"
"","27.1000","5.7175","6403.8501"
"","27.2000","5.7394","6407.8369"
"","27.3000","5.7597","6398.8877"
"","27.4000","5.7814","6400.3115"
"","27.5000","5.8028","6389.5078"
"","27.6000","5.8233","6388.3340"
"","27.7000","5.8447","6382.7290"
"","27.8000","5.8655","6379.3794"
"","27.9000","5.8878","6374.9985"
"","28.0000","5.9080","6363.4438"
"","28.1000","5.9296","6364.4551"
"","28.2000","5.9502","6351.9731"
"","28.3000","5.9717","6350.6367"
"","28.4000","5.9934","6335.7974"
"","28.5000","6.0138","6331.9712"
"","28.6000","6.0355","6321.6025"
"","28.7000","6.0560","6314.3916"
"","28.8000","6.0782","6305.1797"
"","28.9000","6.0987","6289.3569"
"","29.0000","6.1202","6284.4180"
"","29.1000","6.1409","6265.7974"
"","29.2000","6.1622","6257.0347"
"","29.3000","6.1840","6237.4731"
"","29.4000","6.2043","6223.5840"
"","29.5000","6.2261","6203.8779"
"","29.6000","6.2465","6185.5649"
"","29.7000","6.2684","6164.9634"
"","29.8000","6.2896","6137.0527"
"","29.9000","6.3104","6117.4805"
"","30.0000","6.3316","6084.3682"
"","30.1000","6.3523","6056.2769"
"","30.2000","6.3747","6017.0190"
"","30.3000","6.3948","5979.0098"
"","30.4000","6.4166","5934.8281"
"","30.5000","6.4370","5887.4912"
"","30.6000","6.4588","5827.3770"
"","30.6790","6.4761","5550.0327"
"","30.6820","6.4767","5242.9111"
"","30.6840","6.4771","4984.4404"
"","30.6860","6.4775","4695.9961"
"","30.6880","6.4779","4386.5879"
"","30.6900","6.4784","4064.1367"
"","30.6920","6.4788","3735.4006"
"","30.6940","6.4792","3406.1301"