File: lab02/data/S1_Al2024_11.csv
Results Table 1
,Specimen label,Width,Thickness,Length,Tensile strain (Displacement) at Break (Standard),Maximum Tensile stress
,,(mm),(mm),(mm),(%),(MPa)
"1","Aluminum 2024-1","10.46","1.63","75.67","19.55","469.89"
"2","Aluminum 2024-2_1","10.29","1.55","61.52","9.92","466.68"
"3","Aluminum 2024-2_2","10.01","1.52","65.33","7.14","511.47"
"4","Aluminum 2024-2_3","9.70","1.30","67.84","10.98","633.19"

1,Time,Displacement,Force
,(s),(mm),(N)
"","0.0000","0.0000","41.8449"
"","0.1000","0.0035","44.1320"
"","0.2000","0.0167","44.3655"
"","0.3000","0.0465","44.3756"
"","0.4000","0.0665","44.7819"
"","0.5000","0.0880","44.8912"
"","0.6000","0.1096","44.7739"
"","0.7000","0.1300","45.2586"
"","0.8000","0.1517","57.6345"
"","0.9000","0.1719","138.5266"
"","1.0000","0.1940","293.6732"
"","1.1000","0.2150","463.7945"
"","1.2000","0.2358","632.8143"
"","1.3000","0.2572","779.5758"
"","1.4000","0.2778","908.6455"
"","1.5000","0.3001","1061.8811"
"","1.6000","0.3203","1194.6865"
"","1.7000","0.3420","1333.1198"
"","1.8000","0.3626","1459.8704"
"","1.9000","0.3843","1598.1938"
"","2.0000","0.4057","1731.3463"
"","2.1000","0.4264","1860.0909"
"","2.2000","0.4475","1989.2317"
"","2.3000","0.4683","2116.3296"
"","2.4000","0.4904","2251.0569"
"","2.5000","0.5108","2370.8169"
"","2.6000","0.5321","2499.3389"
"","2.7000","0.5532","2624.2666"
"","2.8000","0.5746","2752.0271"
"","2.9000","0.5963","2878.5139"
"","3.0000","0.6166","2996.2795"
"","3.1000","0.6383","3122.7571"
"","3.2000","0.6589","3241.2239"
"","3.3000","0.6810","3369.6548"
"","3.4000","0.7016","3484.3025"
"","3.5000","0.7229","3607.4031"
"","3.6000","0.7438","3724.2249"
"","3.7000","0.7648","3842.5945"
"","3.8000","0.7867","3964.1633"
"","3.9000","0.8070","4074.2148"
"","4.0000","0.8287","4193.5259"
"","4.1000","0.8492","4302.7158"
"","4.2000","0.8712","4421.8564"
"","4.3000","0.8924","4530.4707"
"","4.4000","0.9133","4640.3325"
"","4.5000","0.9345","4746.8511"
"","4.6000","0.9552","4850.6948"
"","4.7000","0.9777","4960.2593"
"","4.8000","0.9975","5050.0576"
"","4.9000","1.0193","5151.4966"
"","5.0000","1.0398","5237.8936"
"","5.1000","1.0615","5328.6841"
"","5.2000","1.0830","5405.5952"
"","5.3000","1.1036","5476.7847"
"","5.4000","1.1250","5536.3940"
"","5.5000","1.1457","5587.6450"
"","5.6000","1.1680","5630.7178"
"","5.7000","1.1883","5659.4795"
"","5.8000","1.2098","5690.6533"
"","5.9000","1.2305","5710.7783"
"","6.0000","1.2520","5736.6230"
"","6.1000","1.2737","5752.0503"
"","6.2000","1.2940","5774.8657"
"","6.3000","1.3155","5790.3818"
"","6.4000","1.3362","5807.6846"
"","6.5000","1.3581","5824.8066"
"","6.6000","1.3785","5833.9136"
"","6.7000","1.4001","5856.2896"
"","6.8000","1.4211","5864.2866"
"","6.9000","1.4424","5883.0508"
"","7.0000","1.4643","5893.7363"
"","7.1000","1.4846","5905.8921"
"","7.2000","1.5063","5919.9629"
"","7.3000","1.5267","5928.6929"
"","7.4000","1.5486","5945.9390"
"","7.5000","1.5697","5950.3682"
"","7.6000","1.5905","5966.9736"
"","7.7000","1.6118","5975.1187"
"","7.8000","1.6326","5987.1460"
"","7.9000","1.6547","6000.2798"
"","8.0000","1.6750","6004.5557"
"","8.1000","1.6968","6021.0952"
"","8.2000","1.7173","6027.1455"
"","8.3000","1.7389","6042.7129"
"","8.4000","1.7606","6047.0107"
"","8.5000","1.7810","6059.2280"
"","8.6000","1.8025","6067.7202"
"","8.7000","1.8228","6078.2207"
"","8.8000","1.8453","6091.7305"
"","8.9000","1.8656","6093.9668"
"","9.0000","1.8871","6110.0000"
"","9.1000","1.9076","6115.0791"
"","9.2000","1.9293","6129.1367"
"","9.3000","1.9509","6133.7920"
"","9.4000","1.9712","6142.9883"
"","9.5000","1.9929","6154.4985"
"","9.6000","2.0135","6161.6885"
"","9.7000","2.0358","6175.1851"
"","9.8000","2.0564","6176.3184"
"","9.9000","2.0777","6192.2104"
"","10.0000","2.0985","6196.4707"
"","10.1000","2.1195","6208.5615"
"","10.2000","2.1417","6217.8506"
"","10.3000","2.1616","6220.8330"
"","10.4000","2.1835","6234.9175"
"","10.5000","2.2040","6239.8726"
"","10.6000","2.2258","6254.0898"
"","10.7000","2.2471","6256.5977"
"","10.8000","2.2680","6269.3691"
"","10.9000","2.2892","6275.1680"
"","11.0000","2.3100","6285.1177"
"","11.1000","2.3323","6296.3628"
"","11.2000","2.3526","6297.2412"
"","11.3000","2.3740","6311.0039"
"","11.4000","2.3945","6314.7583"
"","11.5000","2.4163","6329.7837"
"","11.6000","2.4376","6331.6865"
"","11.7000","2.4583","6342.8789"
"","11.8000","2.4795","6349.5352"
"","11.9000","2.5003","6359.0659"
"","12.0000","2.5225","6370.3032"
"","12.1000","2.5429","6369.8062"
"","12.2000","2.5644","6384.6484"
"","12.3000","2.5851","6387.7949"
"","12.4000","2.6066","6400.7700"
"","12.5000","2.6284","6406.2158"
"","12.6000","2.6487","6412.0708"
"","12.7000","2.6704","6422.5815"
"","12.8000","2.6909","6427.9644"
"","12.9000","2.7130","6441.3735"
"","13.0000","2.7335","6440.9292"
"","13.1000","2.7547","6454.0386"
"","13.2000","2.7758","6458.4570"
"","13.3000","2.7969","6469.3906"
"","13.4000","2.8189","6477.2300"
"","13.5000","2.8391","6479.7334"
"","13.6000","2.8611","6492.9033"
"","13.7000","2.8815","6495.5244"
"","13.8000","2.9032","6508.2534"
"","13.9000","2.9243","6509.7476"
"","14.0000","2.9453","6520.9424"
"","14.1000","2.9664","6525.8213"
"","14.2000","2.9874","6536.0107"
"","14.3000","3.0094","6544.3979"
"","14.4000","3.0297","6546.1597"
"","14.5000","3.0515","6559.0894"
"","14.6000","3.0718","6560.7793"
"","14.7000","3.0936","6574.6650"
"","14.8000","3.1150","6576.6641"
"","14.9000","3.1357","6585.2725"
"","15.0000","3.1571","6591.9424"
"","15.1000","3.1775","6598.0601"
"","15.2000","3.1999","6611.6519"
"","15.3000","3.2203","6609.2720"
"","15.4000","3.2419","6622.6729"
"","15.5000","3.2621","6622.0181"
"","15.6000","3.2839","6638.4473"
"","15.7000","3.3058","6641.8364"
"","15.8000","3.3260","6645.6812"
"","15.9000","3.3478","6655.8828"
"","16.0000","3.3680","6659.7095"
"","16.1000","3.3905","6674.5234"
"","16.2000","3.4109","6670.7148"
"","16.3000","3.4322","6684.3203"
"","16.4000","3.4531","6686.7573"
"","16.5000","3.4744","6697.1294"
"","16.6000","3.4964","6703.9805"
"","16.7000","3.5165","6705.4854"
"","16.8000","3.5383","6717.2705"
"","16.9000","3.5588","6719.6587"
"","17.0000","3.5806","6732.2837"
"","17.1000","3.6016","6732.7979"
"","17.2000","3.6225","6741.9053"
"","17.3000","3.6436","6746.9946"
"","17.4000","3.6647","6755.3354"
"","17.5000","3.6867","6764.0132"
"","17.6000","3.7072","6764.7031"
"","17.7000","3.7287","6774.6699"
"","17.8000","3.7492","6777.8481"
"","17.9000","3.7707","6788.5122"
"","18.0000","3.7925","6793.3052"
"","18.1000","3.8129","6797.3286"
"","18.2000","3.8345","6805.6650"
"","18.3000","3.8550","6810.2046"
"","18.4000","3.8772","6822.5400"
"","18.5000","3.8976","6820.2080"
"","18.6000","3.9190","6831.6543"
"","18.7000","3.9399","6834.0635"
"","18.8000","3.9611","6843.2510"
"","18.9000","3.9830","6850.1128"
"","19.0000","4.0034","6851.2983"
"","19.1000","4.0250","6861.2041"
"","19.2000","4.0455","6865.0156"
"","19.3000","4.0677","6877.2456"
"","19.4000","4.0884","6874.7876"
"","19.5000","4.1095","6884.9941"
"","19.6000","4.1305","6889.1255"
"","19.7000","4.1515","6896.5225"
"","19.8000","4.1737","6904.5483"
"","19.9000","4.1937","6903.0264"
"","20.0000","4.2155","6915.6997"
"","20.1000","4.2361","6917.7808"
"","20.2000","4.2579","6928.8599"
"","20.3000","4.2790","6929.8574"
"","20.4000","4.2998","6936.2871"
"","20.5000","4.3211","6941.2129"
"","20.6000","4.3418","6947.0605"
"","20.7000","4.3640","6956.6631"
"","20.8000","4.3844","6955.9404"
"","20.9000","4.4062","6967.5737"
"","21.0000","4.4267","6967.9326"
"","21.1000","4.4482","6978.9922"
"","21.2000","4.4699","6981.7974"
"","21.3000","4.4902","6984.6846"
"","21.4000","4.5117","6992.0615"
"","21.5000","4.5322","6995.9263"
"","21.6000","4.5543","7007.0825"
"","21.7000","4.5750","7005.4839"
"","21.8000","4.5965","7016.2231"
"","21.9000","4.6173","7017.5835"
"","22.0000","4.6383","7026.3037"
"","22.1000","4.6606","7033.5918"
"","22.2000","4.6807","7032.7192"
"","22.3000","4.7025","7041.8774"
"","22.4000","4.7228","7042.9883"
"","22.5000","4.7450","7055.6714"
"","22.6000","4.7659","7053.9912"
"","22.7000","4.7868","7061.5181"
"","22.8000","4.8077","7064.8887"
"","22.9000","4.8289","7073.3467"
"","23.0000","4.8509","7080.3335"
"","23.1000","4.8711","7078.6343"
"","23.2000","4.8928","7089.3804"
"","23.3000","4.9134","7090.9204"
"","23.4000","4.9352","7101.2490"
"","23.5000","4.9564","7101.0239"
"","23.6000","4.9770","7106.9956"
"","23.7000","4.9986","7113.0864"
"","23.8000","5.0193","7117.1240"
"","23.9000","5.0415","7126.8081"
"","24.0000","5.0616","7123.3081"
"","24.1000","5.0835","7135.4546"
"","24.2000","5.1039","7134.0078"
"","24.3000","5.1256","7144.9985"
"","24.4000","5.1470","7147.0005"
"","24.5000","5.1674","7149.6250"
"","24.6000","5.1892","7157.7944"
"","24.7000","5.2097","7159.7397"
"","24.8000","5.2318","7170.5767"
"","24.9000","5.2524","7167.8760"
"","25.0000","5.2740","7177.8530"
"","25.1000","5.2947","7178.3042"
"","25.2000","5.3158","7185.9717"
"","25.3000","5.3377","7191.5068"
"","25.4000","5.3580","7191.6021"
"","25.5000","5.3797","7199.6265"
"","25.6000","5.4001","7201.3638"
"","25.7000","5.4221","7212.4160"
"","25.8000","5.4430","7210.6265"
"","25.9000","5.4641","7218.3721"
"","26.0000","5.4851","7220.4390"
"","26.1000","5.5061","7226.3105"
"","26.2000","5.5284","7235.1226"
"","26.3000","5.5486","7231.4844"
"","26.4000","5.5701","7240.5601"
"","26.5000","5.5907","7242.0703"
"","26.6000","5.6125","7252.2158"
"","26.7000","5.6337","7251.3843"
"","26.8000","5.6545","7257.5190"
"","26.9000","5.6758","7261.2764"
"","27.0000","5.6964","7264.4673"
"","27.1000","5.7188","7275.4614"
"","27.2000","5.7389","7269.7661"
"","27.3000","5.7607","7282.2505"
"","27.4000","5.7813","7281.0986"
"","27.5000","5.8029","7290.2515"
"","27.6000","5.8246","7292.8013"
"","27.7000","5.8450","7293.5840"
"","27.8000","5.8666","7300.5625"
"","27.9000","5.8871","7301.7397"
"","28.0000","5.9091","7311.7393"
"","28.1000","5.9296","7309.9541"
"","28.2000","5.9511","7319.0586"
"","28.3000","5.9719","7319.0854"
"","28.4000","5.9929","7325.3794"
"","28.5000","6.0150","7332.6533"
"","28.6000","6.0352","7330.0332"
"","28.7000","6.0570","7338.3496"
"","28.8000","6.0775","7338.8911"
"","28.9000","6.0996","7350.0342"
"","29.0000","6.1206","7347.2822"
"","29.1000","6.1415","7353.0869"
"","29.2000","6.1626","7355.1514"
"","29.3000","6.1835","7361.0781"
"","29.4000","6.2056","7367.4707"
"","29.5000","6.2257","7364.4468"
"","29.6000","6.2476","7374.9976"
"","29.7000","6.2680","7374.3091"
"","29.8000","6.2898","7384.2100"
"","29.9000","6.3110","7383.5664"
"","30.0000","6.3317","7387.4683"
"","30.1000","6.3531","7390.8379"
"","30.2000","6.3739","7394.8442"
"","30.3000","6.3962","7403.2656"
"","30.4000","6.4164","7399.0068"
"","30.5000","6.4383","7409.8291"
"","30.6000","6.4588","7407.6445"
"","30.7000","6.4802","7416.5127"
"","30.8000","6.5018","7418.3276"
"","30.9000","6.5222","7419.4478"
"","31.0000","6.5437","7425.4780"
"","31.1000","6.5643","7427.5112"
"","31.2000","6.5863","7436.0073"
"","31.3000","6.6070","7433.0425"
"","31.4000","6.6285","7441.9253"
"","31.5000","6.6493","7441.2944"
"","31.6000","6.6704","7447.6885"
"","31.7000","6.6924","7453.0786"
"","31.8000","6.7125","7449.8257"
"","31.9000","6.7344","7458.7705"
"","32.0000","6.7548","7457.5483"
"","32.1000","6.7769","7468.4844"
"","32.2000","6.7978","7465.4355"
"","32.3000","6.8188","7472.5845"
"","32.4000","6.8399","7473.3184"
"","32.5000","6.8606","7477.5933"
"","32.6000","6.8830","7485.5610"
"","32.7000","6.9031","7480.6392"
"","32.8000","6.9251","7490.2451"
"","32.9000","6.9452","7487.0884"
"","33.0000","6.9673","7499.1650"
"","33.1000","6.9886","7497.4575"
"","33.2000","7.0092","7501.0610"
"","33.3000","7.0306","7504.4111"
"","33.4000","7.0513","7506.8003"
"","33.5000","7.0735","7515.7739"
"","33.6000","7.0937","7509.9453"
"","33.7000","7.1153","7519.2139"
"","33.8000","7.1361","7519.1089"
"","33.9000","7.1576","7526.1816"
"","34.0000","7.1790","7527.7388"
"","34.1000","7.1995","7528.5112"
"","34.2000","7.2211","7534.2812"
"","34.3000","7.2417","7535.2422"
"","34.4000","7.2639","7544.2568"
"","34.5000","7.2843","7539.5488"
"","34.6000","7.3058","7547.7393"
"","34.7000","7.3267","7547.2524"
"","34.8000","7.3478","7553.1826"
"","34.9000","7.3693","7556.3154"
"","35.0000","7.3901","7556.9487"
"","35.1000","7.4116","7561.7856"
"","35.2000","7.4321","7561.7930"
"","35.3000","7.4541","7570.8389"
"","35.4000","7.4749","7567.3594"
"","35.5000","7.4963","7575.0068"
"","35.6000","7.5172","7573.9272"
"","35.7000","7.5382","7578.6484"
"","35.8000","7.5603","7585.5693"
"","35.9000","7.5806","7581.8271"
"","36.0000","7.6024","7589.8340"
"","36.1000","7.6228","7587.5176"
"","36.2000","7.6446","7596.9321"
"","36.3000","7.6658","7595.4600"
"","36.4000","7.6866","7598.4673"
"","36.5000","7.7077","7600.7925"
"","36.6000","7.7285","7603.9629"
"","36.7000","7.7507","7611.8408"
"","36.8000","7.7711","7606.7983"
"","36.9000","7.7926","7614.8555"
"","37.0000","7.8134","7614.5762"
"","37.1000","7.8347","7620.0762"
"","37.2000","7.8566","7623.7314"
"","37.3000","7.8769","7621.5000"
"","37.4000","7.8984","7626.6050"
"","37.5000","7.9190","7626.8291"
"","37.6000","7.9410","7635.9072"
"","37.7000","7.9616","7632.1265"
"","37.8000","7.9831","7639.6206"
"","37.9000","8.0039","7638.4844"
"","38.0000","8.0250","7643.7393"
"","38.1000","8.0471","7648.0293"
"","38.2000","8.0672","7643.9453"
"","38.3000","8.0889","7651.7085"
"","38.4000","8.1094","7650.7783"
"","38.5000","8.1315","7659.9287"
"","38.6000","8.1525","7656.8311"
"","38.7000","8.1736","7661.8008"
"","38.8000","8.1946","7661.7891"
"","38.9000","8.2155","7665.1274"
"","39.0000","8.2377","7672.4746"
"","39.1000","8.2578","7666.2168"
"","39.2000","8.2796","7674.5020"
"","39.3000","8.3000","7672.4292"
"","39.4000","8.3218","7681.1440"
"","39.5000","8.3432","7681.4062"
"","39.6000","8.3638","7682.2222"
"","39.7000","8.3852","7685.4116"
"","39.8000","8.4059","7686.8506"
"","39.9000","8.4280","7693.8564"
"","40.0000","8.4484","7689.7002"
"","40.1000","8.4699","7695.7031"
"","40.2000","8.4907","7695.2974"
"","40.3000","8.5122","7702.1577"
"","40.4000","8.5338","7703.2104"
"","40.5000","8.5540","7701.0796"
"","40.6000","8.5758","7707.5586"
"","40.7000","8.5964","7707.5161"
"","40.8000","8.6184","7715.5830"
"","40.9000","8.6389","7709.8960"
"","41.0000","8.6604","7717.7578"
"","41.1000","8.6812","7716.4604"
"","41.2000","8.7025","7722.0620"
"","41.3000","8.7243","7724.4624"
"","41.4000","8.7447","7722.3770"
"","41.5000","8.7665","7728.5117"
"","41.6000","8.7869","7726.2163"
"","41.7000","8.8090","7735.7598"
"","41.8000","8.8298","7731.5020"
"","41.9000","8.8509","7736.0830"
"","42.0000","8.8720","7736.5176"
"","42.1000","8.8927","7739.2993"
"","42.2000","8.9149","7746.1968"
"","42.3000","8.9352","7740.6392"
"","42.4000","8.9569","7747.7886"
"","42.5000","8.9774","7745.8516"
"","42.6000","8.9991","7753.2500"
"","42.7000","9.0206","7753.3672"
"","42.8000","9.0412","7754.0786"
"","42.9000","9.0625","7756.5796"
"","43.0000","9.0831","7756.6089"
"","43.1000","9.1054","7764.7632"
"","43.2000","9.1257","7757.6875"
"","43.3000","9.1472","7765.7163"
"","43.4000","9.1680","7765.4844"
"","43.5000","9.1896","7771.9497"
"","43.6000","9.2112","7772.8530"
"","43.7000","9.2316","7770.8384"
"","43.8000","9.2531","7775.4810"
"","43.9000","9.2735","7773.0166"
"","44.0000","9.2957","7782.4893"
"","44.1000","9.3163","7776.7490"
"","44.2000","9.3378","7783.9961"
"","44.3000","9.3588","7782.5039"
"","44.4000","9.3798","7786.7021"
"","44.5000","9.4019","7791.6548"
"","44.6000","9.4220","7786.3833"
"","44.7000","9.4436","7792.7402"
"","44.8000","9.4642","7790.9253"
"","44.9000","9.4861","7798.5234"
"","45.0000","9.5071","7795.6357"
"","45.1000","9.5280","7798.9883"
"","45.2000","9.5493","7800.1582"
"","45.3000","9.5701","7801.7520"
"","45.4000","9.5923","7809.2568"
"","45.5000","9.6125","7802.1987"
"","45.6000","9.6344","7810.5645"
"","45.7000","9.6547","7805.5410"
"","45.8000","9.6763","7813.6758"
"","45.9000","9.6979","7813.7524"
"","46.0000","9.7184","7812.9678"
"","46.1000","9.7398","7816.6006"
"","46.2000","9.7605","7817.1177"
"","46.3000","9.7827","7824.8931"
"","46.4000","9.8029","7818.0454"
"","46.5000","9.8247","7825.7754"
"","46.6000","9.8451","7822.2378"
"","46.7000","9.8668","7829.4106"
"","46.8000","9.8885","7830.3911"
"","46.9000","9.9089","7827.2925"
"","47.0000","9.9306","7832.0576"
"","47.1000","9.9510","7831.0107"
"","47.2000","9.9733","7839.0732"
"","47.3000","9.9938","7833.4160"
"","47.4000","10.0149","7838.5615"
"","47.5000","10.0360","7839.0898"
"","47.6000","10.0570","7841.8618"
"","47.7000","10.0791","7846.0308"
"","47.8000","10.0989","7838.4062"
"","47.9000","10.1211","7848.9521"
"","48.0000","10.1415","7844.5459"
"","48.1000","10.1634","7852.4380"
"","48.2000","10.1846","7848.8770"
"","48.3000","10.2055","7852.0874"
"","48.4000","10.2269","7853.7524"
"","48.5000","10.2474","7853.0103"
"","48.6000","10.2697","7860.9863"
"","48.7000","10.2897","7852.7109"
"","48.8000","10.3115","7861.4810"
"","48.9000","10.3319","7857.8330"
"","49.0000","10.3537","7865.4551"
"","49.1000","10.3753","7864.9751"
"","49.2000","10.3957","7863.5068"
"","49.3000","10.4173","7867.0420"
"","49.4000","10.4377","7865.2671"
"","49.5000","10.4601","7874.1895"
"","49.6000","10.4805","7867.1665"
"","49.7000","10.5021","7873.4873"
"","49.8000","10.5227","7869.7568"
"","49.9000","10.5442","7876.9131"
"","50.0000","10.5659","7877.4980"
"","50.1000","10.5862","7874.7676"
"","50.2000","10.6078","7879.7998"
"","50.3000","10.6283","7877.4624"
"","50.4000","10.6505","7886.2554"
"","50.5000","10.6711","7879.9517"
"","50.6000","10.6922","7884.0249"
"","50.7000","10.7134","7884.1274"
"","50.8000","10.7345","7887.4307"
"","50.9000","10.7565","7891.3203"
"","51.0000","10.7766","7885.7339"
"","51.1000","10.7984","7891.8970"
"","51.2000","10.8187","7888.3799"
"","51.3000","10.8408","7897.3652"
"","51.4000","10.8617","7892.1924"
"","51.5000","10.8827","7895.8765"
"","51.6000","10.9039","7895.6016"
"","51.7000","10.9247","7897.1982"
"","51.8000","10.9468","7903.2622"
"","51.9000","10.9672","7897.7085"
"","52.0000","10.9889","7903.6206"
"","52.1000","11.0094","7900.2358"
"","52.2000","11.0310","7905.9517"
"","52.3000","11.0525","7905.7603"
"","52.4000","11.0732","7905.6455"
"","52.5000","11.0946","7907.4087"
"","52.6000","11.1152","7907.1992"
"","52.7000","11.1374","7914.0181"
"","52.8000","11.1578","7907.1128"
"","52.9000","11.1794","7913.8105"
"","53.0000","11.1999","7909.1685"
"","53.1000","11.2213","7915.8999"
"","53.2000","11.2433","7918.1855"
"","53.3000","11.2636","7913.8828"
"","53.4000","11.2851","7917.6812"
"","53.5000","11.3057","7916.9556"
"","53.6000","11.3279","7923.9956"
"","53.7000","11.3486","7917.8491"
"","53.8000","11.3697","7921.6304"
"","53.9000","11.3905","7921.0259"
"","54.0000","11.4117","7924.3882"
"","54.1000","11.4339","7928.8037"
"","54.2000","11.4540","7922.3789"
"","54.3000","11.4755","7928.3149"
"","54.4000","11.4962","7925.9595"
"","54.5000","11.5180","7931.3120"
"","54.6000","11.5391","7929.3525"
"","54.7000","11.5600","7931.0322"
"","54.8000","11.5814","7931.6377"
"","54.9000","11.6023","7932.6465"
"","55.0000","11.6243","7937.7627"
"","55.1000","11.6446","7931.6743"
"","55.2000","11.6661","7936.0693"
"","55.3000","11.6867","7933.2666"
"","55.4000","11.7084","7939.7803"
"","55.5000","11.7299","7938.9937"
"","55.6000","11.7504","7937.7412"
"","55.7000","11.7719","7940.2178"
"","55.8000","11.7925","7939.2935"
"","55.9000","11.8146","7946.6938"
"","56.0000","11.8352","7940.3525"
"","56.1000","11.8567","7945.2842"
"","56.2000","11.8774","7942.2837"
"","56.3000","11.8987","7946.2930"
"","56.4000","11.9207","7949.1748"
"","56.5000","11.9408","7943.3604"
"","56.6000","11.9627","7949.1592"
"","56.7000","11.9831","7947.0239"
"","56.8000","12.0050","7953.5947"
"","56.9000","12.0259","7948.6860"
"","57.0000","12.0468","7950.7700"
"","57.1000","12.0678","7949.6719"
"","57.2000","12.0890","7953.7725"
"","57.3000","12.1110","7957.2661"
"","57.4000","12.1313","7951.3052"
"","57.5000","12.1530","7957.4512"
"","57.6000","12.1735","7954.2778"
"","57.7000","12.1954","7960.6006"
"","57.8000","12.2165","7957.2061"
"","57.9000","12.2374","7957.5439"
"","58.0000","12.2586","7957.8726"
"","58.1000","12.2795","7958.7949"
"","58.2000","12.3016","7964.0815"
"","58.3000","12.3219","7957.6089"
"","58.4000","12.3436","7963.5845"
"","58.5000","12.3642","7960.4907"
"","58.6000","12.3857","7965.5444"
"","58.7000","12.4072","7964.6831"
"","58.8000","12.4278","7962.8237"
"","58.9000","12.4493","7965.7310"
"","59.0000","12.4698","7963.7720"
"","59.1000","12.4920","7971.1206"
"","59.2000","12.5126","7964.5850"
"","59.3000","12.5340","7968.9609"
"","59.4000","12.5549","7967.4082"
"","59.5000","12.5758","7969.3511"
"","59.6000","12.5979","7973.2158"
"","59.7000","12.6181","7967.2173"
"","59.8000","12.6398","7972.2568"
"","59.9000","12.6603","7969.2485"
"","60.0000","12.6824","7976.2993"
"","60.1000","12.7034","7972.0171"
"","60.2000","12.7244","7974.0947"
"","60.3000","12.7450","7971.4565"
"","60.4000","12.7662","7975.3594"
"","60.5000","12.7885","7980.0957"
"","60.6000","12.8087","7972.6494"
"","60.7000","12.8300","7975.6626"
"","60.8000","12.8510","7975.8042"
"","60.9000","12.8728","7980.4653"
"","61.0000","12.8939","7977.2651"
"","61.1000","12.9148","7978.3262"
"","61.2000","12.9360","7978.6455"
"","61.3000","12.9569","7979.3647"
"","61.4000","12.9789","7984.2134"
"","61.5000","12.9993","7977.6548"
"","61.6000","13.0208","7982.0195"
"","61.7000","13.0416","7979.5977"
"","61.8000","13.0630","7983.8105"
"","61.9000","13.0846","7984.0913"
"","62.0000","13.1051","7981.0278"
"","62.1000","13.1268","7984.1895"
"","62.2000","13.1473","7981.4375"
"","62.3000","13.1693","7988.4121"
"","62.4000","13.1899","7982.0044"
"","62.5000","13.2113","7985.9731"
"","62.6000","13.2320","7982.6260"
"","62.7000","13.2532","7985.5552"
"","62.8000","13.2752","7989.7163"
"","62.9000","13.2954","7982.9155"
"","63.0000","13.3172","7988.0439"
"","63.1000","13.3376","7984.2793"
"","63.2000","13.3597","7991.8252"
"","63.3000","13.3806","7986.1226"
"","63.4000","13.4017","7988.3730"
"","63.5000","13.4226","7985.9414"
"","63.6000","13.4436","7988.1763"
"","63.7000","13.4658","7992.6411"
"","63.8000","13.4860","7984.5684"
"","63.9000","13.5077","7990.0513"
"","64.0000","13.5281","7986.1714"
"","64.1000","13.5499","7992.6641"
"","64.2000","13.5713","7989.2256"
"","64.3000","13.5920","7988.2271"
"","64.4000","13.6133","7988.2734"
"","64.5000","13.6340","7986.8608"
"","64.6000","13.6564","7993.6475"
"","64.7000","13.6766","7984.7476"
"","64.8000","13.6983","7990.1763"
"","64.9000","13.7188","7985.1138"
"","65.0000","13.7405","7989.8374"
"","65.1000","13.7620","7987.5596"
"","65.2000","13.7823","7983.4575"
"","65.3000","13.8039","7985.9888"
"","65.4000","13.8244","7982.3076"
"","65.5000","13.8465","7988.4766"
"","65.6000","13.8672","7980.4717"
"","65.7000","13.8885","7982.4648"
"","65.8000","13.9093","7978.5562"
"","65.9000","13.9306","7979.9004"
"","66.0000","13.9526","7981.1221"
"","66.1000","13.9729","7972.1494"
"","66.2000","13.9946","7974.9956"
"","66.3000","14.0151","7969.8125"
"","66.4000","14.0369","7975.3154"
"","66.5000","14.0580","7968.9248"
"","66.6000","14.0790","7968.2773"
"","66.7000","14.1001","7965.7852"
"","66.8000","14.1206","7963.9033"
"","66.9000","14.1431","7970.9492"
"","67.0000","14.1632","7960.0483"
"","67.1000","14.1851","7964.5889"
"","67.2000","14.2054","7959.1982"
"","67.3000","14.2276","7965.6714"
"","67.4000","14.2488","7957.4570"
"","67.5000","14.2694","7954.7798"
"","67.6000","14.2908","7955.0244"
"","67.7000","14.3114","7953.2305"
"","67.8000","14.3338","7956.5825"
"","67.9000","14.3538","7943.6445"
"","68.0000","14.3756","7949.3203"
"","68.1000","14.3960","7942.4756"
"","68.2000","14.4176","7945.3706"
"","68.3000","14.4392","7937.9717"
"","68.4000","14.4597","7929.9985"
"","68.5000","14.4813","7927.9043"
"","68.6000","14.5018","7920.8506"
"","68.7000","14.5240","7918.4697"
"","68.8000","14.5446","7899.5571"
"","68.9000","14.5662","7899.4849"
"","69.0000","14.5867","7887.4028"
"","69.1000","14.6079","7884.8330"
"","69.2000","14.6298","7865.6807"
"","69.3000","14.6502","7851.0435"
"","69.4000","14.6717","7850.1157"
"","69.5000","14.6924","7822.9062"
"","69.6000","14.7144","7803.9287"
"","69.7000","14.7352","7768.5820"
"","69.8000","14.7564","7762.4165"
"","69.9000","14.7774","7665.7886"
"","69.9900","14.7959","7362.8647"
"","69.9920","14.7964","7083.3184"
"","69.9940","14.7968","6745.9839"
"","69.9960","14.7972","6366.0093"
"","69.9980","14.7977","5955.9746"
"","70.0000","14.7982","5526.6240"
"","70.0020","14.7987","5087.1279"
"","70.0040","14.7992","4645.4961"
"","70.0050","14.7994","4426.0908"
2,Time,Displacement,Force
,(s),(mm),(N)
"","0.0000","0.0000","45.0410"
"","0.1000","0.0054","46.5274"
"","0.2000","0.0214","49.3232"
"","0.3000","0.0494","163.5525"
"","0.4000","0.0700","331.4466"
"","0.5000","0.0905","507.3879"
"","0.6000","0.1127","704.0001"
"","0.7000","0.1336","889.9436"
"","0.8000","0.1546","1076.0309"
"","0.9000","0.1756","1261.2334"
"","1.0000","0.1967","1446.1937"
"","1.1000","0.2187","1637.7695"
"","1.2000","0.2390","1813.1002"
"","1.3000","0.2606","1997.1130"
"","1.4000","0.2812","2165.8826"
"","1.5000","0.3029","2334.6555"
"","1.6000","0.3240","2484.9622"
"","1.7000","0.3448","2635.9241"
"","1.8000","0.3661","2793.8691"
"","1.9000","0.3868","2948.0322"
"","2.0000","0.4088","3113.1951"
"","2.1000","0.4291","3263.9082"
"","2.2000","0.4509","3427.7361"
"","2.3000","0.4716","3580.6199"
"","2.4000","0.4932","3739.0408"
"","2.5000","0.5148","3895.6980"
"","2.6000","0.5353","4040.7029"
"","2.7000","0.5569","4192.7261"
"","2.8000","0.5771","4331.3467"
"","2.9000","0.5995","4483.1704"
"","3.0000","0.6200","4616.5498"
"","3.1000","0.6413","4753.8555"
"","3.2000","0.6622","4882.3765"
"","3.3000","0.6834","5008.6587"
"","3.4000","0.7053","5131.1938"
"","3.5000","0.7256","5236.5186"
"","3.6000","0.7473","5339.6860"
"","3.7000","0.7679","5425.6460"
"","3.8000","0.7898","5504.8984"
"","3.9000","0.8108","5562.7065"
"","4.0000","0.8319","5613.5474"
"","4.1000","0.8530","5648.6226"
"","4.2000","0.8741","5680.6919"
"","4.3000","0.8959","5706.4956"
"","4.4000","0.9161","5727.9302"
"","4.5000","0.9379","5751.9507"
"","4.6000","0.9584","5769.7104"
"","4.7000","0.9802","5791.3101"
"","4.8000","1.0013","5803.6934"
"","4.9000","1.0220","5825.3730"
"","5.0000","1.0435","5837.5073"
"","5.1000","1.0643","5854.8770"
"","5.2000","1.0865","5870.9360"
"","5.3000","1.1068","5880.4116"
"","5.4000","1.1285","5900.2695"
"","5.5000","1.1491","5907.6304"
"","5.6000","1.1704","5925.5181"
"","5.7000","1.1920","5932.6519"
"","5.8000","1.2125","5947.5840"
"","5.9000","1.2342","5958.6797"
"","6.0000","1.2546","5970.0327"
"","6.1000","1.2768","5985.6357"
"","6.2000","1.2973","5988.5229"
"","6.3000","1.3188","6007.6357"
"","6.4000","1.3396","6012.6128"
"","6.5000","1.3608","6027.9785"
"","6.6000","1.3827","6035.5903"
"","6.7000","1.4031","6044.3511"
"","6.8000","1.4247","6057.8267"
"","6.9000","1.4452","6065.6836"
"","7.0000","1.4673","6080.5430"
"","7.1000","1.4881","6083.6572"
"","7.2000","1.5093","6099.9863"
"","7.3000","1.5301","6104.9141"
"","7.4000","1.5512","6117.5034"
"","7.5000","1.5734","6127.4561"
"","7.6000","1.5934","6130.7939"
"","7.7000","1.6152","6147.3301"
"","7.8000","1.6358","6152.0742"
"","7.9000","1.6576","6167.1279"
"","8.0000","1.6789","6170.4634"
"","8.1000","1.6994","6182.9531"
"","8.2000","1.7209","6191.4937"
"","8.3000","1.7415","6199.7300"
"","8.4000","1.7638","6212.4907"
"","8.5000","1.7836","6213.1509"
"","8.6000","1.8057","6231.4668"
"","8.7000","1.8262","6233.6294"
"","8.8000","1.8478","6248.2065"
"","8.9000","1.8694","6252.8110"
"","9.0000","1.8898","6261.7251"
"","9.1000","1.9115","6271.8467"
"","9.2000","1.9320","6278.4092"
"","9.3000","1.9542","6292.4521"
"","9.4000","1.9748","6293.3975"
"","9.5000","1.9963","6308.7529"
"","9.6000","2.0171","6312.3315"
"","9.7000","2.0382","6325.0303"
"","9.8000","2.0601","6332.4155"
"","9.9000","2.0803","6337.1113"
"","10.0000","2.1021","6349.2017"
"","10.1000","2.1225","6354.2808"
"","10.2000","2.1445","6368.8291"
"","10.3000","2.1654","6370.5376"
"","10.4000","2.1865","6383.1138"
"","10.5000","2.2075","6386.9512"
"","10.6000","2.2286","6398.6963"
"","10.7000","2.2506","6406.6826"
"","10.8000","2.2709","6410.2427"
"","10.9000","2.2927","6424.0073"
"","11.0000","2.3130","6427.1138"
"","11.1000","2.3349","6443.0059"
"","11.2000","2.3561","6443.3774"
"","11.3000","2.3766","6453.1362"
"","11.4000","2.3980","6459.9185"
"","11.5000","2.4187","6468.6304"
"","11.6000","2.4411","6480.6206"
"","11.7000","2.4614","6479.8525"
"","11.8000","2.4831","6495.7881"
"","11.9000","2.5037","6498.4829"
"","12.0000","2.5252","6511.0391"
"","12.1000","2.5469","6515.0186"
"","12.2000","2.5672","6521.0254"
"","12.3000","2.5888","6530.5605"
"","12.4000","2.6093","6535.8604"
"","12.5000","2.6316","6549.5044"
"","12.6000","2.6522","6548.9053"
"","12.7000","2.6735","6562.8179"
"","12.8000","2.6943","6566.3472"
"","12.9000","2.7154","6576.7012"
"","13.0000","2.7375","6585.0103"
"","13.1000","2.7576","6587.1240"
"","13.2000","2.7793","6597.6016"
"","13.3000","2.7997","6602.5117"
"","13.4000","2.8219","6616.1909"
"","13.5000","2.8428","6615.4004"
"","13.6000","2.8639","6627.6587"
"","13.7000","2.8848","6630.6030"
"","13.8000","2.9058","6642.2173"
"","13.9000","2.9281","6650.1938"
"","14.0000","2.9480","6649.2588"
"","14.1000","2.9699","6663.3696"
"","14.2000","2.9904","6665.9429"
"","14.3000","3.0123","6679.3086"
"","14.4000","3.0335","6680.7202"
"","14.5000","3.0541","6689.3755"
"","14.6000","3.0754","6696.5664"
"","14.7000","3.0962","6702.6265"
"","14.8000","3.1185","6713.9849"
"","14.9000","3.1387","6711.7529"
"","15.0000","3.1603","6726.0073"
"","15.1000","3.1812","6728.1045"
"","15.2000","3.2025","6739.0166"
"","15.3000","3.2243","6744.2349"
"","15.4000","3.2445","6747.7310"
"","15.5000","3.2662","6757.4775"
"","15.6000","3.2868","6761.8989"
"","15.7000","3.3088","6774.3555"
"","15.8000","3.3294","6772.6069"
"","15.9000","3.3508","6785.8262"
"","16.0000","3.3716","6787.3130"
"","16.1000","3.3928","6797.4062"
"","16.2000","3.4147","6804.0483"
"","16.3000","3.4349","6805.1279"
"","16.4000","3.4569","6817.3081"
"","16.5000","3.4771","6818.7886"
"","16.6000","3.4993","6833.1494"
"","16.7000","3.5200","6831.0840"
"","16.8000","3.5412","6842.4165"
"","16.9000","3.5622","6844.8359"
"","17.0000","3.5830","6853.4390"
"","17.1000","3.6053","6862.4570"
"","17.2000","3.6253","6861.0186"
"","17.3000","3.6474","6874.2954"
"","17.4000","3.6677","6875.1240"
"","17.5000","3.6894","6887.8716"
"","17.6000","3.7110","6889.7500"
"","17.7000","3.7316","6895.3389"
"","17.8000","3.7528","6900.8008"
"","17.9000","3.7735","6907.3730"
"","18.0000","3.7958","6917.7383"
"","18.1000","3.8161","6915.4585"
"","18.2000","3.8377","6928.2690"
"","18.3000","3.8583","6929.4385"
"","18.4000","3.8799","6941.4443"
"","18.5000","3.9015","6944.2026"
"","18.6000","3.9218","6947.7544"
"","18.7000","3.9435","6956.3433"
"","18.8000","3.9640","6958.9087"
"","18.9000","3.9861","6970.8013"
"","19.0000","4.0068","6968.7998"
"","19.1000","4.0282","6980.1650"
"","19.2000","4.0490","6982.5410"
"","19.3000","4.0703","6991.9272"
"","19.4000","4.0921","6997.6108"
"","19.5000","4.1122","6997.2388"
"","19.6000","4.1340","7008.0205"
"","19.7000","4.1544","7009.7095"
"","19.8000","4.1763","7021.8130"
"","19.9000","4.1975","7022.1768"
"","20.0000","4.2183","7029.3716"
"","20.1000","4.2396","7034.1206"
"","20.2000","4.2603","7039.1938"
"","20.3000","4.2827","7049.3169"
"","20.4000","4.3028","7046.4707"
"","20.5000","4.3246","7058.3491"
"","20.6000","4.3452","7058.6851"
"","20.7000","4.3669","7070.0474"
"","20.8000","4.3884","7071.9697"
"","20.9000","4.4089","7076.4502"
"","21.0000","4.4300","7081.5967"
"","21.1000","4.4508","7087.4082"
"","21.2000","4.4730","7097.8989"
"","21.3000","4.4934","7094.2529"
"","21.4000","4.5147","7104.1455"
"","21.5000","4.5358","7107.8599"
"","21.6000","4.5571","7116.9404"
"","21.7000","4.5789","7120.4609"
"","21.8000","4.5992","7121.7432"
"","21.9000","4.6209","7129.7280"
"","22.0000","4.6414","7132.4648"
"","22.1000","4.6635","7143.4907"
"","22.2000","4.6842","7141.2305"
"","22.3000","4.7054","7150.9951"
"","22.4000","4.7264","7153.7012"
"","22.5000","4.7473","7160.3691"
"","22.6000","4.7693","7167.2188"
"","22.7000","4.7896","7165.9990"
"","22.8000","4.8113","7175.4380"
"","22.9000","4.8318","7176.9761"
"","23.0000","4.8537","7188.2681"
"","23.1000","4.8750","7187.2817"
"","23.2000","4.8958","7194.0107"
"","23.3000","4.9170","7198.2236"
"","23.4000","4.9377","7202.9106"
"","23.5000","4.9601","7212.9883"
"","23.6000","4.9801","7206.9756"
"","23.7000","5.0019","7219.0298"
"","23.8000","5.0224","7219.1509"
"","23.9000","5.0441","7229.6904"
"","24.0000","5.0656","7231.8872"
"","24.1000","5.0861","7235.6655"
"","24.2000","5.1075","7240.8281"
"","24.3000","5.1282","7244.4102"
"","24.4000","5.1505","7255.2622"
"","24.5000","5.1709","7250.0830"
"","24.6000","5.1923","7260.3149"
"","24.7000","5.2130","7260.7734"
"","24.8000","5.2345","7270.5747"
"","24.9000","5.2563","7274.1948"
"","25.0000","5.2765","7274.9697"
"","25.1000","5.2981","7282.4707"
"","25.2000","5.3187","7284.5732"
"","25.3000","5.3406","7293.7622"
"","25.4000","5.3612","7290.6768"
"","25.5000","5.3826","7300.8066"
"","25.6000","5.4036","7301.8164"
"","25.7000","5.4249","7309.2280"
"","25.8000","5.4469","7314.9370"
"","25.9000","5.4671","7313.2969"
"","26.0000","5.4887","7321.9976"
"","26.1000","5.5092","7321.7651"
"","26.2000","5.5310","7332.6440"
"","26.3000","5.5522","7331.6538"
"","26.4000","5.5731","7336.9922"
"","26.5000","5.5943","7340.7881"
"","26.6000","5.6151","7344.8604"
"","26.7000","5.6372","7354.5239"
"","26.8000","5.6575","7350.1626"
"","26.9000","5.6793","7360.8667"
"","27.0000","5.6998","7359.4443"
"","27.1000","5.7214","7369.4380"
"","27.2000","5.7431","7370.9399"
"","27.3000","5.7635","7372.6846"
"","27.4000","5.7850","7377.8564"
"","27.5000","5.8054","7380.2134"
"","27.6000","5.8277","7391.5059"
"","27.7000","5.8481","7387.2358"
"","27.8000","5.8697","7396.5625"
"","27.9000","5.8901","7395.8257"
"","28.0000","5.9117","7404.4302"
"","28.1000","5.9335","7407.6714"
"","28.2000","5.9538","7407.0146"
"","28.3000","5.9755","7415.2930"
"","28.4000","5.9960","7415.2715"
"","28.5000","6.0182","7426.2461"
"","28.6000","6.0389","7422.2876"
"","28.7000","6.0602","7430.1475"
"","28.8000","6.0811","7430.9429"
"","28.9000","6.1019","7436.2314"
"","28.9160","6.1055","7438.2285"
3,Time,Displacement,Force
,(s),(mm),(N)
"","0.0000","0.0000","43.1483"
"","0.1000","0.0032","44.2530"
"","0.2000","0.0157","44.6764"
"","0.3000","0.0460","45.5461"
"","0.4000","0.0663","56.5414"
"","0.5000","0.0878","156.2140"
"","0.6000","0.1084","304.1210"
"","0.7000","0.1298","468.6927"
"","0.8000","0.1504","629.9926"
"","0.9000","0.1726","807.2222"
"","1.0000","0.1931","969.5015"
"","1.1000","0.2144","1139.2538"
"","1.2000","0.2353","1303.1858"
"","1.3000","0.2566","1464.5667"
"","1.4000","0.2784","1607.8110"
"","1.5000","0.2987","1743.4504"
"","1.6000","0.3204","1891.7227"
"","1.7000","0.3409","2028.3138"
"","1.8000","0.3629","2178.4312"
"","1.9000","0.3835","2316.3801"
"","2.0000","0.4047","2459.1804"
"","2.1000","0.4259","2601.1323"
"","2.2000","0.4469","2741.3748"
"","2.3000","0.4690","2888.8459"
"","2.4000","0.4891","3018.7786"
"","2.5000","0.5110","3162.7622"
"","2.6000","0.5315","3294.0120"
"","2.7000","0.5531","3434.3823"
"","2.8000","0.5744","3570.4263"
"","2.9000","0.5952","3702.6785"
"","3.0000","0.6164","3836.8818"
"","3.1000","0.6374","3968.4958"
"","3.2000","0.6593","4106.6367"
"","3.3000","0.6798","4231.2646"
"","3.4000","0.7015","4366.5728"
"","3.5000","0.7218","4490.1328"
"","3.6000","0.7435","4624.2080"
"","3.7000","0.7650","4754.2026"
"","3.8000","0.7856","4877.9932"
"","3.9000","0.8071","5007.1538"
"","4.0000","0.8275","5127.9590"
"","4.1000","0.8498","5262.4819"
"","4.2000","0.8704","5381.6343"
"","4.3000","0.8919","5509.4546"
"","4.4000","0.9123","5626.6162"
"","4.5000","0.9338","5753.8535"
"","4.6000","0.9558","5880.8877"
"","4.7000","0.9760","5995.5479"
"","4.8000","0.9978","6121.6572"
"","4.9000","1.0180","6235.8213"
"","5.0000","1.0404","6364.7119"
"","5.1000","1.0611","6478.6938"
"","5.2000","1.0822","6598.1636"
"","5.3000","1.1032","6714.1914"
"","5.4000","1.1243","6831.6685"
"","5.5000","1.1465","6954.0786"
"","5.6000","1.1665","7060.5425"
"","5.7000","1.1883","7178.6636"
"","5.8000","1.2088","7283.3052"
"","5.9000","1.2306","7393.9771"
"","6.0000","1.2518","7485.9805"
"","6.1000","1.2724","7553.6812"
"","6.2000","1.2937","7589.6875"
"","6.3000","1.3146","7620.7505"
"","6.4000","1.3367","7627.8345"
"","6.5000","1.3572","7629.8408"
"","6.6000","1.3786","7615.7280"
"","6.7000","1.3993","7607.7520"
"","6.8000","1.4208","7592.7310"
"","6.9000","1.4426","7578.9189"
"","7.0000","1.4630","7582.9580"
"","7.1000","1.4846","7573.1606"
"","7.2000","1.5052","7580.0083"
"","7.3000","1.5272","7574.1523"
"","7.4000","1.5477","7575.5337"
"","7.5000","1.5690","7572.0386"
"","7.6000","1.5900","7573.4868"
"","7.7000","1.6111","7571.9146"
"","7.8000","1.6331","7570.6040"
"","7.9000","1.6534","7576.9097"
"","8.0000","1.6751","7566.5444"
"","8.1000","1.6956","7579.7202"
"","8.2000","1.7177","7569.1826"
"","8.3000","1.7385","7571.9351"
"","8.4000","1.7595","7575.5449"
"","8.5000","1.7806","7570.8086"
"","8.6000","1.8015","7574.8408"
"","8.7000","1.8238","7569.0449"
"","8.8000","1.8438","7576.7510"
"","8.9000","1.8657","7566.2656"
"","9.0000","1.8861","7578.9497"
"","9.1000","1.9078","7568.8198"
"","9.2000","1.9291","7573.2427"
"","9.3000","1.9498","7576.1689"
"","9.4000","1.9711","7568.2954"
"","9.5000","1.9919","7577.7134"
"","9.6000","2.0141","7569.5732"
"","9.7000","2.0345","7578.7388"
"","9.8000","2.0562","7570.0762"
"","9.9000","2.0768","7578.1978"
"","10.0000","2.0982","7573.3765"
"","10.1000","2.1200","7572.7583"
"","10.2000","2.1402","7580.2290"
"","10.3000","2.1618","7567.2119"
"","10.4000","2.1823","7581.8926"
"","10.5000","2.2043","7571.7480"
"","10.6000","2.2250","7574.4165"
"","10.7000","2.2465","7575.4033"
"","10.8000","2.2674","7576.8003"
"","10.9000","2.2884","7579.1182"
"","11.0000","2.3107","7572.6562"
"","11.1000","2.3308","7583.3770"
"","11.2000","2.3525","7569.2451"
"","11.3000","2.3729","7582.3569"
"","11.4000","2.3949","7571.4053"
"","11.5000","2.4160","7576.3008"
"","11.6000","2.4368","7579.6016"
"","11.7000","2.4578","7574.5366"
"","11.8000","2.4789","7579.6880"
"","11.9000","2.5010","7575.0122"
"","12.0000","2.5212","7581.5322"
"","12.1000","2.5429","7572.9399"
"","12.2000","2.5635","7583.1406"
"","12.3000","2.5852","7574.1777"
"","12.4000","2.6065","7577.0132"
"","12.5000","2.6270","7583.0601"
"","12.6000","2.6486","7572.9258"
"","12.7000","2.6693","7583.0601"
"","12.8000","2.6915","7574.1885"
"","12.9000","2.7117","7581.0698"
"","13.0000","2.7335","7573.6680"
"","13.1000","2.7539","7581.0366"
"","13.2000","2.7756","7573.1499"
"","13.3000","2.7971","7577.8120"
"","13.4000","2.8174","7581.4346"
"","13.5000","2.8393","7570.2993"
"","13.6000","2.8598","7584.6230"
"","13.7000","2.8819","7572.5747"
"","13.8000","2.9025","7578.5615"
"","13.9000","2.9240","7576.8857"
"","14.0000","2.9448","7577.9902"
"","14.1000","2.9658","7577.6367"
"","14.2000","2.9877","7574.1709"
"","14.3000","3.0080","7582.8428"
"","14.4000","3.0298","7570.8618"
"","14.5000","3.0502","7584.7031"
"","14.6000","3.0721","7574.1387"
"","14.7000","3.0932","7577.6235"
"","14.8000","3.1141","7581.5181"
"","14.9000","3.1352","7573.8745"
"","15.0000","3.1562","7580.5093"
"","15.1000","3.1784","7576.0127"
"","15.2000","3.1987","7580.3228"
"","15.3000","3.2202","7573.7544"
"","15.4000","3.2408","7580.6030"
"","15.5000","3.2624","7576.1304"
"","15.6000","3.2838","7575.7178"
"","15.7000","3.3045","7583.0981"
"","15.8000","3.3259","7571.8442"
"","15.9000","3.3464","7583.8320"
"","16.0000","3.3688","7572.2886"
"","16.1000","3.3890","7578.5190"
"","16.2000","3.4108","7573.4897"
"","16.3000","3.4314","7578.9268"
"","16.4000","3.4529","7574.9463"
"","16.5000","3.4747","7575.5947"
"","16.6000","3.4950","7581.7124"
"","16.7000","3.5167","7568.8066"
"","16.8000","3.5371","7582.6250"
"","16.9000","3.5591","7568.5410"
"","17.0000","3.5797","7578.8535"
"","17.1000","3.6010","7578.6650"
"","17.2000","3.6219","7580.3667"
"","17.3000","3.6430","7590.4170"
"","17.4000","3.6651","7590.4199"
"","17.5000","3.6853","7606.2925"
"","17.6000","3.7071","7627.5386"
"","17.7000","3.7276","7652.6738"
"","17.8000","3.7495","7682.7192"
"","17.9000","3.7706","7686.3540"
"","18.0000","3.7915","7708.4570"
"","18.1000","3.8126","7726.3647"
"","18.2000","3.8335","7738.4634"
"","18.3000","3.8557","7740.6079"
"","18.4000","3.8758","7731.2456"
"","18.5000","3.8977","7747.9614"
"","18.6000","3.9181","7748.3589"
"","18.7000","3.9397","7758.4946"
"","18.8000","3.9612","7752.1748"
"","18.9000","3.9817","7760.7437"
"","19.0000","4.0032","7764.0024"
"","19.1000","4.0239","7763.3618"
"","19.2000","4.0462","7767.5918"
"","19.3000","4.0665","7759.8833"
"","19.4000","4.0883","7776.6084"
"","19.5000","4.1088","7761.9434"
"","19.6000","4.1302","7776.8765"
"","19.7000","4.1519","7766.1211"
"","19.8000","4.1722","7772.9180"
"","19.9000","4.1937","7777.4756"
"","20.0000","4.2143","7771.8579"
"","20.1000","4.2364","7780.1006"
"","20.2000","4.2572","7769.1465"
"","20.3000","4.2785","7785.4404"
"","20.4000","4.2994","7771.9302"
"","20.5000","4.3204","7783.1938"
"","20.6000","4.3425","7775.8813"
"","20.7000","4.3625","7776.7036"
"","20.8000","4.3845","7784.5215"
"","20.9000","4.4049","7774.6235"
"","21.0000","4.4269","7790.6182"
"","21.1000","4.4480","7770.3989"
"","21.2000","4.4688","7793.3311"
"","21.3000","4.4900","7773.8950"
"","21.4000","4.5105","7786.0811"
"","21.5000","4.5331","7779.9971"
"","21.6000","4.5531","7778.2275"
"","21.7000","4.5751","7792.1436"
"","21.8000","4.5953","7776.3179"
"","21.9000","4.6173","7797.1094"
"","22.0000","4.6387","7772.3882"
"","22.1000","4.6591","7796.5840"
"","22.1350","4.6669","7800.7393"
4,Time,Displacement,Force
,(s),(mm),(N)
"","0.0000","0.0000","41.5319"
"","0.1000","0.0029","41.9368"
"","0.2000","0.0143","42.5165"
"","0.3000","0.0455","48.6522"
"","0.4000","0.0657","120.4075"
"","0.5000","0.0873","251.6586"
"","0.6000","0.1078","399.5920"
"","0.7000","0.1294","559.4001"
"","0.8000","0.1499","712.1636"
"","0.9000","0.1722","877.6572"
"","1.0000","0.1925","1025.3601"
"","1.1000","0.2142","1175.5237"
"","1.2000","0.2349","1310.7323"
"","1.3000","0.2561","1449.7954"
"","1.4000","0.2778","1591.5396"
"","1.5000","0.2981","1723.2263"
"","1.6000","0.3197","1865.5121"
"","1.7000","0.3402","1999.0250"
"","1.8000","0.3622","2142.4421"
"","1.9000","0.3830","2274.7668"
"","2.0000","0.4044","2411.2866"
"","2.1000","0.4253","2542.6199"
"","2.2000","0.4463","2674.6699"
"","2.3000","0.4684","2812.6204"
"","2.4000","0.4884","2934.5425"
"","2.5000","0.5104","3070.5103"
"","2.6000","0.5308","3192.7932"
"","2.7000","0.5527","3326.5513"
"","2.8000","0.5739","3451.6353"
"","2.9000","0.5946","3575.1973"
"","3.0000","0.6158","3699.5803"
"","3.1000","0.6364","3820.9219"
"","3.2000","0.6590","3954.4922"
"","3.3000","0.6791","4070.2258"
"","3.4000","0.7010","4198.7026"
"","3.5000","0.7212","4314.1963"
"","3.6000","0.7431","4441.7529"
"","3.7000","0.7647","4564.7505"
"","3.8000","0.7849","4679.6167"
"","3.9000","0.8067","4803.8853"
"","4.0000","0.8272","4918.9736"
"","4.1000","0.8495","5045.6187"
"","4.2000","0.8698","5157.1362"
"","4.3000","0.8912","5277.8740"
"","4.4000","0.9120","5392.7847"
"","4.5000","0.9335","5512.6006"
"","4.6000","0.9551","5632.1772"
"","4.7000","0.9755","5744.1631"
"","4.8000","0.9971","5864.0195"
"","4.9000","1.0177","5976.5107"
"","5.0000","1.0397","6099.0171"
"","5.1000","1.0603","6209.4292"
"","5.2000","1.0817","6326.7271"
"","5.3000","1.1027","6439.4556"
"","5.4000","1.1237","6553.0762"
"","5.5000","1.1454","6669.4180"
"","5.6000","1.1660","6777.9878"
"","5.7000","1.1876","6892.3979"
"","5.8000","1.2081","6998.5972"
"","5.9000","1.2299","7114.1401"
"","6.0000","1.2511","7221.3374"
"","6.1000","1.2720","7328.4751"
"","6.2000","1.2933","7433.9966"
"","6.3000","1.3141","7535.9092"
"","6.4000","1.3363","7643.0796"
"","6.5000","1.3566","7733.2573"
"","6.6000","1.3783","7828.0894"
"","6.7000","1.3988","7901.9331"
"","6.8000","1.4205","7938.2056"
"","6.9000","1.4419","7943.8110"
"","7.0000","1.4624","7958.5811"
"","7.0690","1.4774","7706.9902"
"","7.1690","1.4980","7785.7515"
"","7.2690","1.5197","7810.4355"
"","7.3690","1.5411","7791.9482"
"","7.4690","1.5618","7797.2153"
"","7.5690","1.5831","7794.9971"
"","7.6690","1.6038","7787.2158"
"","7.7690","1.6260","7797.6582"
"","7.8690","1.6464","7783.7070"
"","7.9690","1.6680","7787.7393"
"","8.0690","1.6886","7781.9390"
"","8.1690","1.7101","7785.3970"
"","8.2690","1.7316","7775.4976"
"","8.3690","1.7520","7786.7544"
"","8.4690","1.7736","7775.3955"
"","8.5690","1.7941","7784.1660"
"","8.6690","1.8164","7782.1338"
"","8.7690","1.8370","7779.0215"
"","8.8690","1.8583","7793.9058"
"","8.9690","1.8792","7777.4307"
"","9.0690","1.9005","7796.7227"
"","9.1690","1.9224","7776.7642"
"","9.2690","1.9426","7795.1484"
"","9.3690","1.9643","7777.3223"
"","9.4690","1.9847","7793.4639"
"","9.5690","2.0068","7784.6533"
"","9.6690","2.0277","7784.4546"
"","9.7690","2.0489","7797.5845"
"","9.8690","2.0698","7779.3198"
"","9.9690","2.0908","7799.4644"
"","10.0690","2.1129","7779.0894"
"","10.1690","2.1331","7793.5176"
"","10.2690","2.1546","7786.7188"
"","10.3690","2.1753","7788.9248"
"","10.4690","2.1971","7792.3784"
"","10.5690","2.2183","7784.7065"
"","10.6690","2.2391","7800.8301"
"","10.7690","2.2604","7784.6704"
"","10.8690","2.2812","7799.4893"
"","10.9690","2.3034","7784.8853"
"","11.0690","2.3236","7793.3013"
"","11.1690","2.3452","7794.9019"
"","11.2690","2.3659","7787.4751"
"","11.3690","2.3874","7799.2388"
"","11.4690","2.4090","7784.1147"
"","11.5690","2.4293","7803.1162"
"","11.6690","2.4510","7783.1274"
"","11.7690","2.4716","7798.9468"
"","11.8690","2.4938","7790.8345"
"","11.9690","2.5142","7791.4575"
"","12.0690","2.5359","7802.2593"
"","12.1690","2.5566","7787.7285"
"","12.2690","2.5779","7806.5737"
"","12.3690","2.5997","7784.7915"
"","12.4690","2.6199","7804.0361"
"","12.5690","2.6417","7791.8281"
"","12.6690","2.6620","7798.5332"
"","12.7690","2.6841","7800.6616"
"","12.8690","2.7051","7790.5713"
"","12.9690","2.7261","7809.8335"
"","13.0690","2.7471","7790.7896"
"","13.1690","2.7680","7805.7573"
"","13.2690","2.7903","7793.2432"
"","13.3690","2.8103","7798.8452"
"","13.4690","2.8321","7804.9219"
"","13.5690","2.8527","7798.4678"
"","13.6690","2.8745","7810.0649"
"","13.7690","2.8959","7794.0747"
"","13.8690","2.9164","7808.3853"
"","13.9690","2.9376","7797.6567"
"","14.0690","2.9584","7802.9819"
"","14.1690","2.9805","7793.5889"
"","14.2690","3.0009","7797.8154"
"","14.3690","3.0226","7804.7866"
"","14.4690","3.0432","7809.3857"
"","14.5690","3.0649","7844.9346"
"","14.6690","3.0865","7843.4438"
"","14.7690","3.1068","7855.7754"
"","14.8690","3.1285","7822.3037"
"","14.9690","3.1489","7848.6738"
"","15.0690","3.1711","7864.8770"
"","15.1690","3.1917","7843.1211"
"","15.2690","3.2129","7876.0474"
"","15.3690","3.2339","7855.9854"
"","15.4690","3.2551","7877.1470"
"","15.5690","3.2770","7865.4238"
"","15.6690","3.2972","7878.2207"
"","15.7690","3.3190","7879.1582"
"","15.8690","3.3394","7877.7588"
"","15.9690","3.3613","7890.2026"
"","16.0690","3.3824","7871.3037"
"","16.1690","3.4035","7902.5225"
"","16.2690","3.4247","7870.3828"
"","16.3690","3.4453","7900.8340"
"","16.4690","3.4677","7879.3521"
"","16.5690","3.4877","7887.5132"
"","16.6690","3.5093","7904.3984"
"","16.7690","3.5299","7881.0425"
"","16.8690","3.5517","7904.0156"
"","16.9690","3.5729","7881.3574"
"","17.0690","3.5937","7901.5322"
"","17.1690","3.6149","7892.8276"
"","17.2690","3.6359","7896.5889"
"","17.3690","3.6581","7898.6465"
"","17.4690","3.6784","7889.4316"
"","17.5690","3.7001","7905.7231"
"","17.6690","3.7206","7891.6870"
"","17.7690","3.7423","7900.0449"
"","17.8690","3.7637","7887.8862"
"","17.9690","3.7840","7893.2012"
"","18.0690","3.8057","7898.2817"
"","18.1690","3.8262","7889.8691"
"","18.2690","3.8484","7856.3975"
"","18.3690","3.8689","7803.0029"
"","18.4690","3.8903","7873.2549"
"","18.5690","3.9112","7809.1636"
"","18.6690","3.9324","7862.8457"
"","18.7690","3.9546","7819.1230"
"","18.8690","3.9746","7802.7456"
"","18.9690","3.9963","7833.5098"
"","19.0690","4.0168","7847.0933"
"","19.1690","4.0387","7868.1582"
"","19.2690","4.0597","7867.4780"
"","19.3690","4.0806","7888.2314"
"","19.4690","4.1018","7889.5532"
"","19.5690","4.1226","7897.9253"
"","19.6690","4.1449","7905.8921"
"","19.7690","4.1649","7902.8735"
"","19.8690","4.1868","7917.8833"
"","19.9690","4.2073","7904.8940"
"","20.0690","4.2290","7912.8101"
"","20.1690","4.2505","7900.4580"
"","20.2690","4.2712","7910.0996"
"","20.3690","4.2926","7912.9746"
"","20.4690","4.3130","7911.0796"
"","20.5690","4.3356","7919.8560"
"","20.6690","4.3556","7909.5737"
"","20.7690","4.3772","7932.2139"
"","20.8690","4.3979","7919.6753"
"","20.9690","4.4193","7929.5562"
"","21.0690","4.4412","7922.8906"
"","21.1690","4.4613","7923.8101"
"","21.2690","4.4831","7929.2222"
"","21.3690","4.5037","7916.8140"
"","21.4690","4.5258","7919.9604"
"","21.5690","4.5463","7904.1948"
"","21.6690","4.5677","7916.7368"
"","21.7690","4.5885","7905.9033"
"","21.8690","4.6098","7910.8911"
"","21.9690","4.6317","7900.5718"
"","22.0690","4.6518","7902.2490"
"","22.1690","4.6737","7911.2759"
"","22.2690","4.6941","7897.1304"
"","22.3690","4.7159","7916.2148"
"","22.4690","4.7369","7896.8267"
"","22.5690","4.7582","7914.9395"
"","22.6690","4.7791","7907.7490"
"","22.7690","4.8001","7906.3467"
"","22.8690","4.8222","7898.1338"
"","22.9690","4.8424","7889.2686"
"","23.0690","4.8642","7909.4619"
"","23.1690","4.8846","7898.1235"
"","23.2690","4.9065","7907.7930"
"","23.3690","4.9277","7897.4790"
"","23.4690","4.9484","7910.5640"
"","23.5690","4.9699","7903.6519"
"","23.6690","4.9903","7905.2397"
"","23.7690","5.0128","7912.9800"
"","23.8690","5.0331","7894.3252"
"","23.9690","5.0546","7910.1763"
"","24.0690","5.0752","7897.0269"
"","24.1690","5.0968","7904.3301"
"","24.2690","5.1186","7903.4634"
"","24.3690","5.1389","7906.2202"
"","24.4690","5.1603","7912.4473"
"","24.5690","5.1809","7904.2642"
"","24.6690","5.2031","7911.5742"
"","24.7690","5.2237","7895.7007"
"","24.8690","5.2447","7904.8687"
"","24.9690","5.2659","7897.3569"
"","25.0690","5.2871","7903.3003"
"","25.1690","5.3090","7906.9556"
"","25.2690","5.3291","7901.3364"
"","25.3690","5.3510","7913.1206"
"","25.4690","5.3715","7901.9106"
"","25.5690","5.3933","7912.4341"
"","25.6690","5.4144","7898.5415"
"","25.7690","5.4354","7901.8896"
"","25.8690","5.4566","7896.3218"
"","25.9690","5.4774","7902.9160"
"","26.0690","5.4996","7908.3032"
"","26.1690","5.5198","7899.7070"
"","26.2690","5.5414","7916.4824"
"","26.3690","5.5620","7903.6260"
"","26.4690","5.5835","7912.6226"
"","26.5690","5.6051","7903.1387"
"","26.6690","5.6257","7904.1509"
"","26.7690","5.6472","7900.5996"
"","26.8690","5.6678","7898.5020"
"","26.9690","5.6902","7910.6367"
"","27.0690","5.7104","7896.9146"
"","27.1690","5.7321","7916.8389"
"","27.2690","5.7526","7903.6206"
"","27.3690","5.7739","7911.9595"
"","27.4690","5.7958","7906.8916"
"","27.5690","5.8161","7903.8506"
"","27.6690","5.8377","7906.3394"
"","27.7690","5.8582","7896.8579"
"","27.8690","5.8804","7910.8984"
"","27.9690","5.9009","7901.3618"
"","28.0690","5.9221","7915.8232"
"","28.1690","5.9431","7907.2998"
"","28.2690","5.9642","7911.2725"
"","28.3690","5.9864","7908.5791"
"","28.4690","6.0066","7902.8457"
"","28.5690","6.0285","7909.7891"
"","28.6690","6.0489","7896.7295"
"","28.7690","6.0707","7910.0220"
"","28.8690","6.0917","7902.8950"
"","28.9690","6.1128","7913.1826"
"","29.0690","6.1338","7908.7368"
"","29.1690","6.1548","7910.5122"
"","29.2690","6.1768","7911.8916"
"","29.3690","6.1972","7902.7637"
"","29.4690","6.2189","7911.0527"
"","29.5690","6.2394","7895.3271"
"","29.6690","6.2609","7908.5215"
"","29.7690","6.2826","7906.1509"
"","29.8690","6.3030","7909.2393"
"","29.9690","6.3246","7917.1479"
"","30.0690","6.3450","7910.1978"
"","30.1690","6.3673","7917.8638"
"","30.2690","6.3878","7900.9727"
"","30.3690","6.4093","7908.7324"
"","30.4690","6.4299","7895.7544"
"","30.5690","6.4513","7907.8115"
"","30.6690","6.4733","7906.8267"
"","30.7690","6.4933","7905.0703"
"","30.8690","6.5149","7918.4995"
"","30.9690","6.5354","7912.3369"
"","31.0690","6.5576","7918.5718"
"","31.1690","6.5785","7906.2739"
"","31.2690","6.5997","7913.0708"
"","31.3690","6.6206","7893.6353"
"","31.4690","6.6418","7899.8843"
"","31.5690","6.6637","7910.3267"
"","31.6690","6.6840","7906.6299"
"","31.7690","6.7055","7915.1460"
"","31.8690","6.7262","7911.4258"
"","31.9690","6.7480","7918.7275"
"","32.0690","6.7691","7908.3530"
"","32.1690","6.7899","7918.1440"
"","32.2690","6.8113","7914.6782"
"","32.3690","6.8321","7901.7476"
"","32.4690","6.8543","7899.3877"
"","32.5690","6.8745","7895.3818"
"","32.6690","6.8962","7916.3970"
"","32.7690","6.9169","7910.3687"
"","32.8690","6.9382","7914.2695"
"","32.9690","6.9598","7911.2627"
"","33.0690","6.9803","7913.6045"
"","33.1690","7.0020","7915.4243"
"","33.2690","7.0224","7902.3911"
"","33.3690","7.0445","7896.1631"
"","33.4690","7.0652","7886.8462"
"","33.5690","7.0865","7908.6797"
"","33.6690","7.1073","7908.4121"
"","33.7690","7.1286","7909.7710"
"","33.8690","7.1504","7905.0986"
"","33.9690","7.1708","7906.1084"
"","34.0690","7.1924","7912.1260"
"","34.1690","7.2129","7900.5034"
"","34.2690","7.2350","7844.7134"
"","34.3690","7.2559","7811.2686"
"","34.4690","7.2770","7855.4243"
"","34.5690","7.2978","7817.9702"
"","34.6690","7.3188","7799.0352"
"","34.7690","7.3411","7810.8169"
"","34.8690","7.3612","7764.1992"
"","34.9690","7.3830","7772.9902"
"","35.0690","7.4035","7715.7148"
"","35.1690","7.4254","7707.9355"
"","35.2690","7.4467","7599.9253"
"","35.3500","7.4630","7327.5889"
"","35.3520","7.4635","7053.4058"
"","35.3540","7.4639","6720.9199"
"","35.3560","7.4644","6345.3823"
"","35.3580","7.4648","5939.2383"
"","35.3600","7.4653","5513.3950"
"","35.3620","7.4657","5077.0850"
"","35.3640","7.4662","4638.3159"
"","35.3650","7.4665","4420.1699"