File: lab02/data/S1_Brass_11.csv
Results Table 1
,Specimen label,Width,Thickness,Length,Tensile strain (Displacement) at Break (Standard),Maximum Tensile stress
,,(mm),(mm),(mm),(%),(MPa)
"1","Brass 1","12.80","3.20","69.34","40.87","383.43"
"2","Brass 2_1","12.70","3.12","69.34","12.33","370.70"
"3","Brass 2_2","12.27","3.05","77.88","13.02","410.88"
"4","Brass 2_3","11.68","3.05","84.58","17.72","438.80"

1,Time,Displacement,Force
,(s),(mm),(N)
"","0.0000","0.0000","97.7163"
"","0.1000","0.0035","111.5954"
"","0.2000","0.0159","133.3081"
"","0.3000","0.0465","185.2380"
"","0.4000","0.0668","399.7439"
"","0.4640","0.0800","653.5379"
"","0.5230","0.0922","906.4387"
"","0.5760","0.1041","1157.8120"
"","0.6300","0.1158","1410.1808"
"","0.6890","0.1278","1664.1523"
"","0.7480","0.1398","1916.5544"
"","0.8040","0.1521","2170.1267"
"","0.8810","0.1685","2421.0884"
"","0.9690","0.1865","2671.3401"
"","1.0450","0.2033","2922.0771"
"","1.1270","0.2207","3173.4407"
"","1.2110","0.2379","3424.1960"
"","1.2890","0.2549","3675.9353"
"","1.3770","0.2729","3927.5027"
"","1.4600","0.2906","4179.3750"
"","1.5420","0.3088","4429.6392"
"","1.6350","0.3278","4679.9980"
"","1.7210","0.3464","4930.3750"
"","1.8180","0.3663","5182.8306"
"","1.9090","0.3856","5435.0889"
"","1.9990","0.4056","5687.3018"
"","2.0990","0.4257","5928.5752"
"","2.1900","0.4456","6179.5337"
"","2.2900","0.4661","6419.4897"
"","2.3870","0.4868","6669.9326"
"","2.4870","0.5085","6921.6729"
"","2.5870","0.5292","7158.5635"
"","2.6870","0.5505","7402.8677"
"","2.7870","0.5713","7638.7876"
"","2.8870","0.5934","7889.7773"
"","2.9870","0.6140","8107.7183"
"","3.0870","0.6354","8345.6895"
"","3.1870","0.6565","8565.0752"
"","3.2870","0.6775","8786.8623"
"","3.3870","0.6993","9008.4062"
"","3.4870","0.7194","9205.4668"
"","3.5870","0.7413","9423.6113"
"","3.6870","0.7618","9614.5215"
"","3.7870","0.7835","9821.2666"
"","3.8870","0.8044","10003.5410"
"","3.9870","0.8257","10194.9590"
"","4.0870","0.8468","10369.0107"
"","4.1870","0.8678","10542.0312"
"","4.2870","0.8898","10714.5908"
"","4.3870","0.9101","10859.7783"
"","4.4870","0.9321","11020.2861"
"","4.5870","0.9523","11148.2871"
"","4.6870","0.9741","11292.0273"
"","4.7870","0.9956","11412.2451"
"","4.8870","1.0160","11530.4014"
"","4.9870","1.0374","11640.2637"
"","5.0870","1.0581","11743.9199"
"","5.1870","1.0802","11849.5967"
"","5.2870","1.1006","11933.4365"
"","5.3870","1.1223","12028.0605"
"","5.4870","1.1429","12103.1738"
"","5.5870","1.1644","12186.1514"
"","5.6870","1.1863","12254.6680"
"","5.7870","1.2067","12321.2979"
"","5.8870","1.2281","12382.2148"
"","5.9870","1.2490","12439.8955"
"","6.0870","1.2707","12496.6904"
"","6.1870","1.2915","12540.2959"
"","6.2870","1.3126","12594.6309"
"","6.3870","1.3336","12631.0732"
"","6.4870","1.3547","12678.4268"
"","6.5870","1.3765","12712.7842"
"","6.6870","1.3967","12751.8057"
"","6.7870","1.4187","12787.3584"
"","6.8870","1.4392","12817.5332"
"","6.9870","1.4611","12854.5254"
"","7.0870","1.4822","12874.9463"
"","7.1870","1.5031","12911.8281"
"","7.2870","1.5244","12930.1982"
"","7.3870","1.5450","12960.4209"
"","7.4870","1.5671","12983.4053"
"","7.5870","1.5874","13003.0811"
"","7.6870","1.6092","13029.0508"
"","7.7870","1.6296","13047.4385"
"","7.8870","1.6513","13073.0137"
"","7.9870","1.6728","13084.3047"
"","8.0870","1.6934","13111.7881"
"","8.1870","1.7149","13121.7842"
"","8.2870","1.7354","13143.8975"
"","8.3870","1.7578","13162.7695"
"","8.4870","1.7783","13171.2871"
"","8.5870","1.7996","13195.2764"
"","8.6870","1.8204","13205.5537"
"","8.7870","1.8418","13226.6777"
"","8.8870","1.8634","13233.3379"
"","8.9870","1.8838","13252.6084"
"","9.0870","1.9054","13261.1592"
"","9.1870","1.9260","13276.8672"
"","9.2870","1.9481","13293.5469"
"","9.3870","1.9688","13296.6865"
"","9.4870","1.9900","13320.5537"
"","9.5870","2.0110","13324.1758"
"","9.6870","2.0322","13342.9902"
"","9.7870","2.0542","13349.1475"
"","9.8870","2.0741","13359.7676"
"","9.9870","2.0960","13373.3750"
"","10.0870","2.1165","13380.8672"
"","10.1870","2.1384","13397.4385"
"","10.2870","2.1590","13395.1533"
"","10.3870","2.1802","13420.9443"
"","10.4870","2.2015","13419.1543"
"","10.5870","2.2224","13436.0400"
"","10.6870","2.2447","13444.0186"
"","10.7870","2.2648","13449.5049"
"","10.8870","2.2866","13464.0889"
"","10.9870","2.3073","13468.2637"
"","11.0870","2.3287","13484.2764"
"","11.1870","2.3503","13484.0459"
"","11.2870","2.3709","13501.1895"
"","11.3870","2.3923","13503.3828"
"","11.4870","2.4129","13515.1055"
"","11.5870","2.4351","13525.1660"
"","11.6870","2.4554","13525.3076"
"","11.7870","2.4771","13541.9531"
"","11.8870","2.4976","13542.9863"
"","11.9870","2.5189","13559.1924"
"","12.0870","2.5409","13558.9834"
"","12.1870","2.5611","13571.2314"
"","12.2870","2.5829","13574.4219"
"","12.3870","2.6034","13584.9775"
"","12.4870","2.6256","13593.4424"
"","12.5870","2.6461","13595.2803"
"","12.6870","2.6674","13610.9297"
"","12.7870","2.6883","13610.3330"
"","12.8870","2.7092","13624.7783"
"","12.9870","2.7313","13623.6592"
"","13.0870","2.7511","13630.5068"
"","13.1870","2.7733","13639.5586"
"","13.2870","2.7938","13646.3867"
"","13.3870","2.8157","13658.3584"
"","13.4870","2.8369","13655.4453"
"","13.5870","2.8577","13673.1074"
"","13.6870","2.8789","13669.5967"
"","13.7870","2.8997","13680.8086"
"","13.8870","2.9220","13685.9951"
"","13.9870","2.9421","13686.8555"
"","14.0870","2.9640","13699.8047"
"","14.1870","2.9845","13700.9580"
"","14.2870","3.0061","13716.1289"
"","14.3870","3.0276","13712.3438"
"","14.4870","3.0480","13726.8711"
"","14.5870","3.0696","13725.2598"
"","14.6870","3.0901","13733.5566"
"","14.7870","3.1123","13741.8506"
"","14.8870","3.1328","13738.9824"
"","14.9870","3.1544","13753.8076"
"","15.0870","3.1749","13754.0312"
"","15.1870","3.1965","13767.1455"
"","15.2870","3.2183","13764.3740"
"","15.3870","3.2384","13775.1680"
"","15.4870","3.2601","13775.8623"
"","15.5870","3.2804","13784.6816"
"","15.6870","3.3028","13791.2168"
"","15.7870","3.3235","13788.3623"
"","15.8870","3.3447","13804.5039"
"","15.9870","3.3657","13801.8701"
"","16.0870","3.3868","13814.4346"
"","16.1870","3.4088","13814.9033"
"","16.2870","3.4289","13820.3789"
"","16.3870","3.4504","13825.9258"
"","16.4870","3.4712","13829.5244"
"","16.5870","3.4930","13839.5225"
"","16.6870","3.5143","13835.1475"
"","16.7870","3.5346","13851.6846"
"","16.8870","3.5565","13848.8428"
"","16.9870","3.5771","13857.3691"
"","17.0870","3.5992","13862.6162"
"","17.1870","3.6194","13861.0381"
"","17.2870","3.6413","13872.5625"
"","17.3870","3.6620","13874.3652"
"","17.4870","3.6833","13884.3359"
"","17.5870","3.7049","13880.1426"
"","17.6870","3.7253","13894.0127"
"","17.7870","3.7469","13890.8770"
"","17.8870","3.7675","13900.2158"
"","17.9870","3.7897","13905.3643"
"","18.0870","3.8101","13903.6660"
"","18.1870","3.8317","13917.9473"
"","18.2870","3.8524","13914.0576"
"","18.3870","3.8737","13928.0293"
"","18.4870","3.8955","13922.7822"
"","18.5870","3.9157","13933.2021"
"","18.6870","3.9375","13934.1045"
"","18.7870","3.9578","13940.2480"
"","18.8870","3.9803","13948.4365"
"","18.9870","4.0007","13942.4209"
"","19.0870","4.0221","13960.1963"
"","19.1870","4.0428","13953.9629"
"","19.2870","4.0639","13966.3594"
"","19.3870","4.0862","13967.1895"
"","19.4870","4.1063","13968.3945"
"","19.5870","4.1279","13976.0898"
"","19.6870","4.1485","13979.0283"
"","19.7870","4.1704","13987.8301"
"","19.8870","4.1915","13983.4824"
"","19.9870","4.2124","13998.7363"
"","20.0870","4.2336","13993.9580"
"","20.1870","4.2544","14005.0156"
"","20.2870","4.2766","14006.0264"
"","20.3870","4.2967","14005.1367"
"","20.4870","4.3185","14016.2227"
"","20.5870","4.3392","14014.6689"
"","20.6870","4.3607","14026.4873"
"","20.7870","4.3823","14022.5273"
"","20.8870","4.4028","14034.7305"
"","20.9870","4.4243","14033.1895"
"","21.0870","4.4450","14039.5938"
"","21.1870","4.4670","14044.3057"
"","21.2870","4.4875","14041.9453"
"","21.3870","4.5089","14053.6934"
"","21.4870","4.5295","14051.3506"
"","21.5870","4.5509","14063.4697"
"","21.6870","4.5730","14061.4082"
"","21.7870","4.5930","14066.8926"
"","21.8870","4.6147","14072.2285"
"","21.9870","4.6352","14072.3867"
"","22.0870","4.6573","14083.0879"
"","22.1870","4.6782","14075.5605"
"","22.2870","4.6992","14092.0801"
"","22.3870","4.7205","14087.6055"
"","22.4870","4.7414","14098.9531"
"","22.5870","4.7637","14098.5967"
"","22.6870","4.7837","14099.9199"
"","22.7870","4.8052","14105.0879"
"","22.8870","4.8258","14109.7812"
"","22.9870","4.8476","14117.8818"
"","23.0870","4.8689","14111.4932"
"","23.1870","4.8894","14124.0850"
"","23.2870","4.9109","14125.6631"
"","23.3870","4.9318","14130.1055"
"","23.4870","4.9540","14134.9229"
"","23.5870","4.9743","14133.5605"
"","23.6870","4.9959","14142.9111"
"","23.7870","5.0166","14142.6924"
"","23.8870","5.0382","14152.0293"
"","23.9870","5.0596","14148.3486"
"","24.0870","5.0800","14158.7471"
"","24.1870","5.1016","14157.5498"
"","24.2870","5.1220","14162.5078"
"","24.3870","5.1442","14168.7695"
"","24.4870","5.1648","14164.5312"
"","24.5870","5.1862","14177.0049"
"","24.6870","5.2071","14176.0381"
"","24.7870","5.2282","14186.4170"
"","24.8870","5.2504","14184.4453"
"","24.9870","5.2703","14188.4072"
"","25.0870","5.2922","14191.5996"
"","25.1870","5.3126","14193.7900"
"","25.2870","5.3347","14203.8838"
"","25.3870","5.3558","14194.5703"
"","25.4870","5.3766","14212.6416"
"","25.5870","5.3977","14206.6064"
"","25.6870","5.4187","14218.8955"
"","25.7870","5.4408","14219.0117"
"","25.8870","5.4609","14219.4707"
"","25.9870","5.4825","14224.9346"
"","26.0870","5.5031","14226.6260"
"","26.1870","5.5250","14235.3867"
"","26.2870","5.5464","14228.2441"
"","26.3870","5.5671","14243.8174"
"","26.4870","5.5884","14239.6826"
"","26.5870","5.6091","14249.4160"
"","26.6870","5.6314","14252.0088"
"","26.7870","5.6514","14248.4014"
"","26.8870","5.6730","14257.7246"
"","26.9870","5.6937","14256.8145"
"","27.0870","5.7152","14266.0244"
"","27.1870","5.7368","14262.5811"
"","27.2870","5.7572","14274.8994"
"","27.3870","5.7790","14272.5273"
"","27.4870","5.7996","14279.4062"
"","27.5870","5.8216","14283.6240"
"","27.6870","5.8422","14279.0898"
"","27.7870","5.8637","14290.6006"
"","27.8870","5.8845","14286.4990"
"","27.9870","5.9056","14298.8193"
"","28.0870","5.9276","14295.2842"
"","28.1870","5.9478","14300.7012"
"","28.2870","5.9695","14304.7842"
"","28.3870","5.9901","14307.7607"
"","28.4870","6.0118","14316.0166"
"","28.5870","6.0329","14307.5879"
"","28.6870","6.0540","14323.0557"
"","28.7870","6.0750","14317.0830"
"","28.8870","6.0959","14327.5146"
"","28.9870","6.1183","14328.1357"
"","29.0870","6.1384","14327.1787"
"","29.1870","6.1602","14336.4814"
"","29.2870","6.1804","14335.3779"
"","29.3870","6.2023","14346.7422"
"","29.4870","6.2235","14338.2539"
"","29.5870","6.2442","14352.3945"
"","29.6870","6.2652","14346.9307"
"","29.7870","6.2864","14356.8535"
"","29.8870","6.3085","14358.8711"
"","29.9870","6.3288","14356.2910"
"","30.0870","6.3504","14366.6924"
"","30.1870","6.3711","14365.0127"
"","30.2870","6.3927","14375.6074"
"","30.3870","6.4144","14368.6533"
"","30.4870","6.4348","14379.5967"
"","30.5870","6.4564","14378.3066"
"","30.6870","6.4768","14383.3730"
"","30.7870","6.4990","14390.7158"
"","30.8870","6.5196","14382.5918"
"","30.9870","6.5410","14398.3516"
"","31.0870","6.5617","14392.9482"
"","31.1870","6.5829","14403.8584"
"","31.2870","6.6049","14401.9512"
"","31.3870","6.6251","14405.6855"
"","31.4870","6.6469","14409.0205"
"","31.5870","6.6673","14410.9209"
"","31.6870","6.6893","14419.0596"
"","31.7870","6.7105","14411.9863"
"","31.8870","6.7314","14425.1738"
"","31.9870","6.7524","14421.8398"
"","32.0870","6.7733","14432.0830"
"","32.1870","6.7954","14430.8643"
"","32.2870","6.8156","14433.1123"
"","32.3870","6.8373","14437.1777"
"","32.4870","6.8576","14439.8330"
"","32.5870","6.8795","14447.7607"
"","32.6870","6.9009","14439.3740"
"","32.7870","6.9215","14453.5156"
"","32.8870","6.9430","14448.8262"
"","32.9870","6.9637","14457.7637"
"","33.0870","6.9859","14461.8496"
"","33.1870","7.0062","14457.4971"
"","33.2870","7.0279","14469.3691"
"","33.3870","7.0485","14465.9463"
"","33.4870","7.0700","14477.4590"
"","33.5870","7.0916","14470.0635"
"","33.6870","7.1119","14482.2363"
"","33.7870","7.1337","14482.1885"
"","33.8870","7.1542","14487.5039"
"","33.9870","7.1763","14493.3613"
"","34.0870","7.1967","14487.5469"
"","34.1870","7.2184","14502.0498"
"","34.2870","7.2391","14494.9678"
"","34.3870","7.2603","14506.0850"
"","34.4870","7.2823","14503.6133"
"","34.5870","7.3025","14507.8135"
"","34.6870","7.3242","14506.7646"
"","34.7870","7.3447","14508.7881"
"","34.8870","7.3666","14511.4375"
"","34.9870","7.3875","14507.2227"
"","35.0870","7.4087","14520.2461"
"","35.1870","7.4297","14515.9023"
"","35.2870","7.4505","14530.5039"
"","35.3870","7.4728","14531.9326"
"","35.4870","7.4930","14536.5908"
"","35.5870","7.5147","14543.8154"
"","35.6870","7.5352","14547.7178"
"","35.7870","7.5568","14561.0186"
"","35.8870","7.5783","14555.0176"
"","35.9870","7.5990","14570.9756"
"","36.0870","7.6204","14564.2158"
"","36.1870","7.6406","14577.9492"
"","36.2870","7.6634","14574.1064"
"","36.3870","7.6835","14571.0078"
"","36.4870","7.7055","14581.8096"
"","36.5870","7.7256","14576.7529"
"","36.6870","7.7473","14587.9268"
"","36.7870","7.7692","14576.4053"
"","36.8870","7.7893","14587.2578"
"","36.9870","7.8110","14582.9980"
"","37.0870","7.8316","14593.3584"
"","37.1870","7.8538","14599.3350"
"","37.2870","7.8742","14597.5186"
"","37.3870","7.8956","14609.5547"
"","37.4870","7.9166","14606.4414"
"","37.5870","7.9377","14617.1494"
"","37.6870","7.9596","14613.6270"
"","37.7870","7.9797","14619.1133"
"","37.8870","8.0013","14620.0625"
"","37.9870","8.0220","14624.1631"
"","38.0870","8.0438","14627.5293"
"","38.1870","8.0649","14623.0947"
"","38.2870","8.0860","14629.5322"
"","38.3870","8.1070","14619.7842"
"","38.4870","8.1280","14615.3496"
"","38.5870","8.1502","14604.3467"
"","38.6870","8.1704","14626.5898"
"","38.7870","8.1920","14653.9033"
"","38.8870","8.2125","14669.4766"
"","38.9870","8.2341","14691.4229"
"","39.0870","8.2555","14694.2676"
"","39.1870","8.2762","14712.6631"
"","39.2870","8.2978","14710.2178"
"","39.3870","8.3184","14715.5342"
"","39.4870","8.3405","14726.6719"
"","39.5870","8.3610","14733.8779"
"","39.6870","8.3826","14747.9014"
"","39.7870","8.4030","14744.8438"
"","39.8870","8.4246","14749.7383"
"","39.9870","8.4463","14740.1543"
"","40.0870","8.4667","14746.7656"
"","40.1870","8.4883","14741.5400"
"","40.2870","8.5089","14733.3281"
"","40.3870","8.5310","14706.3047"
"","40.4870","8.5517","14688.6025"
"","40.5870","8.5729","14694.0742"
"","40.6870","8.5937","14690.8760"
"","40.7870","8.6148","14701.1104"
"","40.8870","8.6368","14701.5820"
"","40.9870","8.6571","14706.3477"
"","41.0870","8.6789","14709.0557"
"","41.1870","8.6994","14712.2588"
"","41.2870","8.7212","14719.4062"
"","41.3870","8.7422","14713.8701"
"","41.4870","8.7633","14725.0410"
"","41.5870","8.7844","14718.4248"
"","41.6870","8.8051","14726.3359"
"","41.7870","8.8276","14725.2393"
"","41.8870","8.8477","14722.9297"
"","41.9870","8.8694","14728.4072"
"","42.0870","8.8898","14728.7979"
"","42.1870","8.9114","14733.8809"
"","42.2870","8.9330","14727.4854"
"","42.3870","8.9536","14738.3359"
"","42.4870","8.9750","14731.1064"
"","42.5870","8.9952","14734.6182"
"","42.6870","9.0180","14737.4492"
"","42.7870","9.0383","14727.4492"
"","42.8870","9.0599","14728.9023"
"","42.9870","9.0806","14717.1240"
"","43.0870","9.1020","14715.5625"
"","43.1870","9.1239","14714.5674"
"","43.2870","9.1440","14735.7002"
"","43.3870","9.1656","14751.0449"
"","43.4870","9.1862","14765.2432"
"","43.5870","9.2083","14774.0352"
"","43.6870","9.2289","14772.0576"
"","43.7870","9.2502","14787.7412"
"","43.8870","9.2710","14789.5293"
"","43.9870","9.2922","14806.2451"
"","44.0870","9.3143","14810.8721"
"","44.1870","9.3342","14821.0029"
"","44.2870","9.3562","14829.0459"
"","44.3870","9.3767","14834.0215"
"","44.4870","9.3986","14843.9258"
"","44.5870","9.4196","14838.3379"
"","44.6870","9.4407","14854.3389"
"","44.7870","9.4618","14844.9180"
"","44.8870","9.4826","14856.6826"
"","44.9870","9.5047","14852.1777"
"","45.0870","9.5249","14850.0234"
"","45.1870","9.5468","14856.9209"
"","45.2870","9.5673","14855.0869"
"","45.3870","9.5887","14863.9287"
"","45.4870","9.6104","14857.6680"
"","45.5870","9.6310","14869.7705"
"","45.6870","9.6525","14863.7295"
"","45.7870","9.6730","14869.6406"
"","45.8870","9.6952","14871.5957"
"","45.9870","9.7157","14865.8574"
"","46.0870","9.7372","14872.4736"
"","46.1870","9.7578","14868.4307"
"","46.2870","9.7790","14875.7861"
"","46.3870","9.8010","14870.8301"
"","46.4870","9.8212","14877.7637"
"","46.5870","9.8429","14874.6113"
"","46.6870","9.8634","14877.5117"
"","46.7870","9.8855","14879.6006"
"","46.8870","9.9065","14870.6826"
"","46.9870","9.9275","14880.1670"
"","47.0870","9.9485","14871.1699"
"","47.1870","9.9695","14870.9268"
"","47.2870","9.9917","14855.4521"
"","47.3870","10.0117","14831.9229"
"","47.4870","10.0336","14835.9668"
"","47.5870","10.0539","14860.4746"
"","47.6870","10.0757","14887.6113"
"","47.7870","10.0970","14897.2051"
"","47.8870","10.1178","14924.3828"
"","47.9870","10.1391","14917.3242"
"","48.0870","10.1600","14912.4395"
"","48.1870","10.1823","14899.0273"
"","48.2870","10.2025","14891.9326"
"","48.3870","10.2243","14894.7744"
"","48.4870","10.2447","14892.0996"
"","48.5870","10.2663","14896.4824"
"","48.6870","10.2876","14891.9863"
"","48.7870","10.3082","14899.3711"
"","48.8870","10.3297","14895.7725"
"","48.9870","10.3503","14902.8096"
"","49.0870","10.3722","14911.0391"
"","49.1870","10.3929","14907.7100"
"","49.2870","10.4144","14919.4600"
"","49.3870","10.4352","14920.7744"
"","49.4870","10.4564","14927.8340"
"","49.5870","10.4784","14919.6846"
"","49.6870","10.4988","14919.4424"
"","49.7870","10.5204","14916.4424"
"","49.8870","10.5408","14932.9346"
"","49.9870","10.5630","14967.2773"
"","50.0870","10.5836","14990.7666"
"","50.1870","10.6048","15019.6133"
"","50.2870","10.6257","15026.3105"
"","50.3870","10.6467","15042.2676"
"","50.4870","10.6689","15043.9258"
"","50.5870","10.6890","15048.6621"
"","50.6870","10.7109","15049.0518"
"","50.7870","10.7314","15049.8447"
"","50.8870","10.7533","15047.8779"
"","50.9870","10.7743","15029.4990"
"","51.0870","10.7953","15020.7207"
"","51.1870","10.8168","14996.5479"
"","51.2870","10.8372","14996.0176"
"","51.3870","10.8595","14988.0420"
"","51.4870","10.8796","14997.1191"
"","51.5870","10.9012","15007.5137"
"","51.6870","10.9219","15009.3691"
"","51.7870","10.9434","15012.1494"
"","51.8870","10.9650","15005.1445"
"","51.9870","10.9855","15010.3438"
"","52.0870","11.0071","15002.7109"
"","52.1870","11.0275","15007.2188"
"","52.2870","11.0498","15012.0215"
"","52.3870","11.0703","15013.1475"
"","52.4870","11.0919","15027.1104"
"","52.5870","11.1126","15030.7461"
"","52.6870","11.1338","15044.3496"
"","52.7870","11.1558","15043.7441"
"","52.8870","11.1758","15054.0303"
"","52.9870","11.1977","15051.7773"
"","53.0870","11.2178","15053.3584"
"","53.1870","11.2403","15054.9414"
"","53.2870","11.2610","15047.9775"
"","53.3870","11.2824","15055.1309"
"","53.4870","11.3031","15044.8438"
"","53.5870","11.3241","15050.6826"
"","53.6870","11.3465","15044.5684"
"","53.7870","11.3662","15048.9922"
"","53.8870","11.3883","15053.3496"
"","53.9870","11.4088","15060.0967"
"","54.0870","11.4306","15067.9590"
"","54.1870","11.4518","15062.3496"
"","54.2870","11.4724","15070.9062"
"","54.3870","11.4938","15057.9404"
"","54.4870","11.5147","15058.4082"
"","54.5870","11.5367","15053.1992"
"","54.6870","11.5570","15048.3564"
"","54.7870","11.5786","15049.5430"
"","54.8870","11.5993","15043.8818"
"","54.9870","11.6209","15041.6670"
"","55.0870","11.6423","15024.7959"
"","55.1870","11.6629","15026.4834"
"","55.2870","11.6844","15019.2871"
"","55.3870","11.7050","15023.8184"
"","55.4870","11.7268","15026.0566"
"","55.5870","11.7476","15028.4307"
"","55.6870","11.7691","15034.8398"
"","55.7870","11.7898","15036.3672"
"","55.8870","11.8112","15042.9443"
"","55.9870","11.8329","15040.1387"
"","56.0870","11.8533","15048.1582"
"","56.1870","11.8751","15042.3584"
"","56.2870","11.8955","15046.5029"
"","56.3870","11.9175","15047.2705"
"","56.4870","11.9385","15039.1953"
"","56.5870","11.9597","15042.3350"
"","56.6870","11.9806","15030.8516"
"","56.7870","12.0016","15039.6660"
"","56.8870","12.0236","15037.2314"
"","56.9870","12.0438","15038.8213"
"","57.0870","12.0654","15034.7324"
"","57.1870","12.0860","15046.5430"
"","57.2870","12.1078","15067.1396"
"","57.3870","12.1292","15080.2002"
"","57.4870","12.1498","15107.2441"
"","57.5870","12.1712","15114.9033"
"","57.6870","12.1919","15130.9219"
"","57.7870","12.2141","15141.5439"
"","57.8870","12.2344","15144.1992"
"","57.9870","12.2560","15154.2041"
"","58.0870","12.2766","15156.7529"
"","58.1870","12.2981","15165.6133"
"","58.2870","12.3195","15162.2939"
"","58.3870","12.3401","15176.4766"
"","58.4870","12.3617","15172.9355"
"","58.5870","12.3822","15182.6592"
"","58.6870","12.4045","15185.9941"
"","58.7870","12.4250","15183.6650"
"","58.8870","12.4464","15194.1240"
"","58.9870","12.4671","15190.3467"
"","59.0870","12.4885","15198.7832"
"","59.1870","12.5104","15192.5908"
"","59.2870","12.5306","15197.4033"
"","59.3870","12.5524","15190.3789"
"","59.4870","12.5728","15192.1123"
"","59.5870","12.5949","15193.0312"
"","59.6870","12.6157","15184.4160"
"","59.7870","12.6370","15193.1543"
"","59.8870","12.6579","15186.3574"
"","59.9870","12.6788","15195.9033"
"","60.0870","12.7010","15195.8447"
"","60.1870","12.7211","15198.5674"
"","60.2870","12.7428","15202.6055"
"","60.3870","12.7634","15206.1953"
"","60.4870","12.7852","15217.9346"
"","60.5870","12.8064","15230.1875"
"","60.6870","12.8272","15256.4551"
"","60.7870","12.8485","15258.7559"
"","60.8870","12.8693","15243.8447"
"","60.9870","12.8915","15223.8818"
"","61.0870","12.9116","15217.8164"
"","61.1870","12.9332","15221.3184"
"","61.2870","12.9539","15218.5527"
"","61.3870","12.9755","15223.1279"
"","61.4870","12.9971","15217.0811"
"","61.5870","13.0173","15227.8145"
"","61.6870","13.0391","15221.6689"
"","61.7870","13.0597","15228.6943"
"","61.8870","13.0819","15229.9766"
"","61.9870","13.1021","15229.1973"
"","62.0870","13.1240","15232.6807"
"","62.1870","13.1446","15228.9766"
"","62.2870","13.1659","15234.9932"
"","62.3870","13.1877","15225.6738"
"","62.4870","13.2079","15229.5430"
"","62.5870","13.2298","15221.2139"
"","62.6870","13.2501","15219.5352"
"","62.7870","13.2721","15215.5654"
"","62.8870","13.2931","15204.4102"
"","62.9870","13.3142","15207.9150"
"","63.0870","13.3352","15198.4375"
"","63.1870","13.3561","15201.8096"
"","63.2870","13.3783","15197.4531"
"","63.3870","13.3983","15196.9385"
"","63.4870","13.4202","15195.3418"
"","63.5870","13.4407","15195.3604"
"","63.6870","13.4625","15198.7178"
"","63.7870","13.4839","15190.5967"
"","63.8870","13.5044","15199.4062"
"","63.9870","13.5257","15189.9238"
"","64.0870","13.5466","15192.9316"
"","64.1870","13.5686","15187.9492"
"","64.2870","13.5890","15183.9824"
"","64.3870","13.6106","15184.7051"
"","64.4870","13.6312","15179.5254"
"","64.5870","13.6529","15183.8613"
"","64.6870","13.6745","15177.2080"
"","64.7870","13.6948","15193.1494"
"","64.8870","13.7166","15193.1699"
"","64.9870","13.7370","15204.0361"
"","65.0870","13.7591","15211.1172"
"","65.1870","13.7797","15209.7539"
"","65.2870","13.8011","15220.1055"
"","65.3870","13.8219","15219.7539"
"","65.4870","13.8431","15228.0254"
"","65.5870","13.8651","15224.5078"
"","65.6870","13.8852","15229.9287"
"","65.7870","13.9071","15226.3047"
"","65.8870","13.9275","15226.0186"
"","65.9870","13.9494","15226.2656"
"","66.0870","13.9705","15214.7432"
"","66.1870","13.9915","15220.3799"
"","66.2870","14.0128","15205.9482"
"","66.3870","14.0334","15208.4590"
"","66.4870","14.0557","15203.5879"
"","66.5870","14.0758","15214.3477"
"","66.6870","14.0974","15242.0225"
"","66.7870","14.1179","15270.5879"
"","66.8870","14.1398","15297.1924"
"","66.9870","14.1609","15303.7695"
"","67.0870","14.1818","15326.0127"
"","67.1870","14.2030","15324.7012"
"","67.2870","14.2239","15341.2715"
"","67.3870","14.2462","15344.9463"
"","67.4870","14.2664","15347.7979"
"","67.5870","14.2881","15355.5752"
"","67.6870","14.3087","15354.8350"
"","67.7870","14.3304","15361.6260"
"","67.8870","14.3518","15354.8281"
"","67.9870","14.3720","15362.2295"
"","68.0870","14.3937","15354.7939"
"","68.1870","14.4142","15353.2002"
"","68.2870","14.4364","15348.8975"
"","68.3870","14.4568","15335.0146"
"","68.4870","14.4783","15342.8154"
"","68.5870","14.4993","15329.9824"
"","68.6870","14.5205","15337.1680"
"","68.7870","14.5427","15331.7793"
"","68.8870","14.5626","15338.4912"
"","68.9870","14.5845","15336.0977"
"","69.0870","14.6049","15337.3555"
"","69.1870","14.6268","15343.9941"
"","69.2870","14.6477","15336.6777"
"","69.3870","14.6687","15349.6270"
"","69.4870","14.6898","15341.7500"
"","69.5870","14.7107","15351.5342"
"","69.6870","14.7330","15348.8604"
"","69.7870","14.7530","15349.5176"
"","69.8870","14.7749","15350.6387"
"","69.9870","14.7953","15351.4502"
"","70.0870","14.8170","15357.0234"
"","70.1870","14.8386","15349.2676"
"","70.2870","14.8592","15361.7129"
"","70.3870","14.8807","15355.7480"
"","70.4870","14.9011","15365.8535"
"","70.5870","14.9237","15364.7939"
"","70.6870","14.9436","15367.2129"
"","70.7870","14.9653","15371.4385"
"","70.8870","14.9860","15372.1484"
"","70.9870","15.0074","15379.8447"
"","71.0870","15.0292","15373.2959"
"","71.1870","15.0492","15384.4941"
"","71.2870","15.0712","15380.5361"
"","71.3870","15.0917","15385.5459"
"","71.4870","15.1139","15386.1406"
"","71.5870","15.1344","15381.0547"
"","71.6870","15.1558","15387.6680"
"","71.7870","15.1766","15381.0010"
"","71.8870","15.1978","15388.0684"
"","71.9870","15.2198","15378.9805"
"","72.0870","15.2398","15384.9482"
"","72.1870","15.2618","15379.0225"
"","72.2870","15.2821","15382.0117"
"","72.3870","15.3040","15382.0840"
"","72.4870","15.3250","15375.2070"
"","72.5870","15.3462","15380.4258"
"","72.6870","15.3672","15368.9775"
"","72.7870","15.3881","15365.5859"
"","72.8870","15.4103","15346.9463"
"","72.9870","15.4305","15326.4326"
"","73.0870","15.4523","15323.1143"
"","73.1870","15.4728","15321.9102"
"","73.2870","15.4945","15323.0605"
"","73.3870","15.5158","15314.0430"
"","73.4870","15.5364","15322.3779"
"","73.5870","15.5580","15310.4062"
"","73.6870","15.5783","15316.3594"
"","73.7870","15.6008","15312.3018"
"","73.8870","15.6211","15309.7568"
"","73.9870","15.6426","15315.8203"
"","74.0870","15.6633","15317.3213"
"","74.1870","15.6849","15324.2979"
"","74.2870","15.7067","15321.2939"
"","74.3870","15.7269","15333.3174"
"","74.4870","15.7484","15332.0029"
"","74.5870","15.7689","15339.2197"
"","74.6870","15.7912","15343.9785"
"","74.7870","15.8118","15342.1562"
"","74.8870","15.8327","15351.6104"
"","74.9870","15.8540","15348.4580"
"","75.0870","15.8752","15357.0850"
"","75.1870","15.8970","15355.4287"
"","75.2870","15.9171","15359.9678"
"","75.3870","15.9391","15358.1201"
"","75.4870","15.9596","15361.7246"
"","75.5870","15.9813","15362.5752"
"","75.6870","16.0025","15356.9668"
"","75.7870","16.0235","15365.9570"
"","75.8870","16.0447","15359.3096"
"","75.9870","16.0655","15366.6201"
"","76.0870","16.0877","15362.3652"
"","76.1870","16.1078","15362.3984"
"","76.2870","16.1295","15363.4111"
"","76.3870","16.1501","15362.9688"
"","76.4870","16.1716","15367.1729"
"","76.5870","16.1932","15360.0840"
"","76.6870","16.2138","15371.3955"
"","76.7870","16.2353","15365.3086"
"","76.8870","16.2559","15374.7412"
"","76.9870","16.2783","15379.4531"
"","77.0870","16.2984","15379.4678"
"","77.1870","16.3201","15389.9492"
"","77.2870","16.3406","15390.1533"
"","77.3870","16.3620","15399.5527"
"","77.4870","16.3838","15397.2285"
"","77.5870","16.4041","15406.5820"
"","77.6870","16.4257","15406.4727"
"","77.7870","16.4463","15411.0967"
"","77.8870","16.4685","15413.8711"
"","77.9870","16.4890","15414.0283"
"","78.0870","16.5102","15434.4590"
"","78.1870","16.5311","15452.5625"
"","78.2870","16.5524","15483.6250"
"","78.3870","16.5744","15494.0547"
"","78.4870","16.5947","15505.3584"
"","78.5870","16.6165","15507.4570"
"","78.6870","16.6369","15510.0391"
"","78.7870","16.6588","15509.8643"
"","78.8870","16.6798","15498.8018"
"","78.9870","16.7008","15504.1416"
"","79.0870","16.7219","15489.6260"
"","79.1870","16.7429","15491.1338"
"","79.2870","16.7649","15485.0859"
"","79.3870","16.7851","15483.1064"
"","79.4870","16.8069","15483.1396"
"","79.5870","16.8274","15481.6523"
"","79.6870","16.8491","15485.6729"
"","79.7870","16.8707","15478.6230"
"","79.8870","16.8911","15487.7051"
"","79.9870","16.9126","15480.6289"
"","80.0870","16.9330","15484.5205"
"","80.1870","16.9554","15484.4346"
"","80.2870","16.9758","15479.8057"
"","80.3870","16.9974","15485.1895"
"","80.4870","17.0179","15481.2842"
"","80.5870","17.0394","15484.5391"
"","80.6870","17.0613","15477.1445"
"","80.7870","17.0814","15481.5059"
"","80.8870","17.1029","15471.2881"
"","80.9870","17.1234","15475.2148"
"","81.0870","17.1457","15471.8516"
"","81.1870","17.1665","15462.8721"
"","81.2870","17.1877","15466.5010"
"","81.3870","17.2086","15461.4736"
"","81.4870","17.2298","15460.0801"
"","81.5870","17.2517","15453.0029"
"","81.6870","17.2721","15454.8555"
"","81.7870","17.2936","15450.0771"
"","81.8870","17.3143","15451.0918"
"","81.9870","17.3361","15450.9189"
"","82.0870","17.3572","15446.1387"
"","82.1870","17.3780","15456.2432"
"","82.2870","17.3994","15451.2422"
"","82.3870","17.4201","15458.3428"
"","82.4870","17.4424","15458.2139"
"","82.5870","17.4625","15459.7793"
"","82.6870","17.4843","15463.8438"
"","82.7870","17.5049","15465.5664"
"","82.8870","17.5263","15473.3809"
"","82.9870","17.5478","15470.3438"
"","83.0870","17.5683","15485.3721"
"","83.1870","17.5900","15480.7295"
"","83.2870","17.6104","15491.1045"
"","83.3870","17.6326","15494.4834"
"","83.4870","17.6533","15492.2334"
"","83.5870","17.6746","15502.6553"
"","83.6870","17.6954","15499.2178"
"","83.7870","17.7166","15507.4121"
"","83.8870","17.7385","15499.8135"
"","83.9870","17.7588","15507.1035"
"","84.0870","17.7804","15500.8662"
"","84.1870","17.8009","15506.9590"
"","84.2870","17.8230","15507.4062"
"","84.3870","17.8439","15502.3770"
"","84.4870","17.8651","15511.9746"
"","84.5870","17.8859","15504.6152"
"","84.6870","17.9069","15511.8662"
"","84.7870","17.9291","15506.0557"
"","84.8870","17.9491","15509.3936"
"","84.9870","17.9710","15506.6650"
"","85.0870","17.9915","15508.7051"
"","85.1870","18.0135","15512.4229"
"","85.2870","18.0347","15504.5029"
"","85.3870","18.0554","15514.5000"
"","85.4870","18.0767","15503.4736"
"","85.5870","18.0974","15510.3027"
"","85.6870","18.1198","15503.6836"
"","85.7870","18.1398","15502.7197"
"","85.8870","18.1616","15503.3555"
"","85.9870","18.1820","15501.1338"
"","86.0870","18.2035","15504.2217"
"","86.1870","18.2253","15494.1143"
"","86.2870","18.2456","15502.0508"
"","86.3870","18.2672","15492.7461"
"","86.4870","18.2879","15496.0195"
"","86.5870","18.3098","15494.8828"
"","86.6870","18.3306","15488.0713"
"","86.7870","18.3520","15494.5820"
"","86.8870","18.3728","15488.3770"
"","86.9870","18.3939","15493.2275"
"","87.0870","18.4160","15485.9883"
"","87.1870","18.4362","15491.1592"
"","87.2870","18.4579","15486.5459"
"","87.3870","18.4781","15487.4473"
"","87.4870","18.5001","15490.5576"
"","87.5870","18.5212","15480.6094"
"","87.6870","18.5422","15489.9639"
"","87.7870","18.5630","15480.2812"
"","87.8870","18.5844","15486.9434"
"","87.9870","18.6067","15480.8848"
"","88.0870","18.6266","15481.5020"
"","88.1870","18.6485","15478.8818"
"","88.2870","18.6689","15480.4961"
"","88.3870","18.6910","15482.4961"
"","88.4870","18.7118","15474.3584"
"","88.5870","18.7328","15486.1885"
"","88.6870","18.7538","15476.4902"
"","88.7870","18.7746","15484.0586"
"","88.8870","18.7970","15482.8389"
"","88.9870","18.8171","15483.1250"
"","89.0870","18.8390","15487.8242"
"","89.1870","18.8594","15490.6240"
"","89.2870","18.8811","15495.7686"
"","89.3870","18.9024","15489.9512"
"","89.4870","18.9231","15499.2773"
"","89.5870","18.9445","15491.7051"
"","89.6870","18.9651","15499.0195"
"","89.7870","18.9873","15499.3613"
"","89.8870","19.0080","15497.8154"
"","89.9870","19.0293","15503.5303"
"","90.0870","19.0500","15500.9414"
"","90.1870","19.0713","15504.3633"
"","90.2870","19.0931","15496.5059"
"","90.3870","19.1133","15501.4072"
"","90.4870","19.1353","15494.3613"
"","90.5870","19.1554","15495.6670"
"","90.6870","19.1778","15496.3154"
"","90.7870","19.1987","15485.5420"
"","90.8870","19.2198","15494.1035"
"","90.9870","19.2406","15483.9160"
"","91.0870","19.2617","15489.2598"
"","91.1870","19.2838","15482.9668"
"","91.2870","19.3039","15485.7275"
"","91.3870","19.3257","15495.8467"
"","91.4870","19.3460","15514.7832"
"","91.5870","19.3680","15541.6045"
"","91.6870","19.3892","15556.2793"
"","91.7870","19.4101","15580.2217"
"","91.8870","19.4313","15576.7930"
"","91.9870","19.4520","15586.5771"
"","92.0870","19.4743","15585.4102"
"","92.1870","19.4944","15585.1650"
"","92.2870","19.5162","15590.8252"
"","92.3870","19.5369","15588.9434"
"","92.4870","19.5584","15595.7070"
"","92.5870","19.5799","15588.4531"
"","92.6870","19.6005","15597.9443"
"","92.7870","19.6218","15588.1572"
"","92.8870","19.6423","15592.5078"
"","92.9870","19.6645","15588.1162"
"","93.0870","19.6851","15583.8848"
"","93.1870","19.7067","15587.0928"
"","93.2870","19.7275","15578.9365"
"","93.3870","19.7487","15583.7979"
"","93.4870","19.7707","15573.4971"
"","93.5870","19.7909","15578.2578"
"","93.6870","19.8127","15569.6094"
"","93.7870","19.8330","15570.2920"
"","93.8870","19.8550","15570.8994"
"","93.9870","19.8758","15560.0254"
"","94.0870","19.8971","15569.8613"
"","94.1870","19.9179","15559.1357"
"","94.2870","19.9387","15569.7080"
"","94.3870","19.9612","15559.4688"
"","94.4870","19.9812","15563.8125"
"","94.5870","20.0032","15562.7354"
"","94.6870","20.0235","15564.9346"
"","94.7870","20.0453","15567.8809"
"","94.8870","20.0668","15558.9092"
"","94.9870","20.0873","15571.8428"
"","95.0870","20.1086","15562.2617"
"","95.1870","20.1294","15569.1650"
"","95.2870","20.1516","15565.7197"
"","95.3870","20.1718","15566.0137"
"","95.4870","20.1936","15568.9160"
"","95.5870","20.2140","15568.0176"
"","95.6870","20.2356","15574.2021"
"","95.7870","20.2573","15565.0332"
"","95.8870","20.2777","15577.3135"
"","95.9870","20.2993","15567.1719"
"","96.0870","20.3198","15573.2334"
"","96.1870","20.3421","15572.7637"
"","96.2870","20.3626","15569.7871"
"","96.3870","20.3843","15576.4414"
"","96.4870","20.4047","15573.2031"
"","96.5870","20.4261","15580.1367"
"","96.6870","20.4479","15573.9268"
"","96.7870","20.4680","15579.5527"
"","96.8870","20.4899","15574.2529"
"","96.9870","20.5102","15578.3984"
"","97.0870","20.5322","15581.1016"
"","97.1870","20.5532","15574.7090"
"","97.2870","20.5743","15584.8857"
"","97.3870","20.5953","15577.8066"
"","97.4870","20.6163","15585.5176"
"","97.5870","20.6385","15580.9570"
"","97.6870","20.6587","15582.0938"
"","97.7870","20.6804","15580.7910"
"","97.8870","20.7008","15582.7998"
"","97.9870","20.7225","15585.1797"
"","98.0870","20.7439","15577.6133"
"","98.1870","20.7646","15589.1885"
"","98.2870","20.7859","15578.6348"
"","98.3870","20.8067","15584.5029"
"","98.4870","20.8289","15582.9863"
"","98.5870","20.8491","15578.1748"
"","98.6870","20.8709","15582.9834"
"","98.7870","20.8916","15580.7031"
"","98.8870","20.9130","15584.6445"
"","98.9870","20.9346","15576.8604"
"","99.0870","20.9551","15585.9277"
"","99.1870","20.9767","15576.9111"
"","99.2870","20.9970","15582.4531"
"","99.3870","21.0194","15581.6768"
"","99.4870","21.0397","15576.0664"
"","99.5870","21.0614","15583.2959"
"","99.6870","21.0821","15577.2148"
"","99.7870","21.1033","15583.5879"
"","99.8870","21.1252","15577.3369"
"","99.9870","21.1455","15581.3350"
"","100.0870","21.1674","15575.6533"
"","100.1870","21.1877","15578.3506"
"","100.2870","21.2094","15577.3877"
"","100.3870","21.2306","15570.3340"
"","100.4870","21.2517","15578.8096"
"","100.5870","21.2727","15568.1895"
"","100.6870","21.2932","15570.6553"
"","100.7870","21.3159","15565.6963"
"","100.8870","21.3358","15560.6094"
"","100.9870","21.3576","15560.3350"
"","101.0870","21.3782","15557.2891"
"","101.1870","21.3999","15561.8203"
"","101.2870","21.4215","15552.8428"
"","101.3870","21.4420","15563.3877"
"","101.4870","21.4634","15553.1045"
"","101.5870","21.4839","15557.5771"
"","101.6870","21.5064","15555.0781"
"","101.7870","21.5264","15552.0977"
"","101.8870","21.5483","15556.5859"
"","101.9870","21.5689","15554.4844"
"","102.0870","21.5904","15560.5332"
"","102.1870","21.6121","15552.6367"
"","102.2870","21.6323","15563.9385"
"","102.3870","21.6539","15557.7188"
"","102.4870","21.6743","15563.1855"
"","102.5870","21.6966","15564.1240"
"","102.6870","21.7171","15559.9434"
"","102.7870","21.7387","15570.6172"
"","102.8870","21.7595","15564.2021"
"","102.9870","21.7806","15575.4893"
"","103.0870","21.8025","15569.6553"
"","103.1870","21.8227","15575.7275"
"","103.2870","21.8445","15574.2910"
"","103.3870","21.8650","15575.4473"
"","103.4870","21.8867","15578.2402"
"","103.5870","21.9080","15572.5225"
"","103.6870","21.9289","15583.7764"
"","103.7870","21.9500","15577.2490"
"","103.8870","21.9710","15584.5225"
"","103.9870","21.9930","15583.8955"
"","104.0870","22.0132","15582.0264"
"","104.1870","22.0351","15583.8203"
"","104.2870","22.0557","15584.0293"
"","104.3870","22.0770","15588.1328"
"","104.4870","22.0987","15579.9883"
"","104.5870","22.1193","15590.6426"
"","104.6870","22.1408","15583.3779"
"","104.7870","22.1614","15589.9648"
"","104.8870","22.1837","15587.5234"
"","104.9870","22.2040","15584.6182"
"","105.0870","22.2255","15589.3955"
"","105.1870","22.2461","15587.4033"
"","105.2870","22.2677","15592.9775"
"","105.3870","22.2893","15584.8672"
"","105.4870","22.3096","15595.8906"
"","105.5870","22.3313","15586.4980"
"","105.6870","22.3517","15592.3936"
"","105.7870","22.3738","15594.4688"
"","105.8870","22.3946","15585.9766"
"","105.9870","22.4160","15599.8096"
"","106.0870","22.4368","15591.3145"
"","106.1870","22.4580","15600.6484"
"","106.2870","22.4799","15594.4561"
"","106.3870","22.5000","15601.2793"
"","106.4870","22.5221","15599.1523"
"","106.5870","22.5423","15603.4502"
"","106.6870","22.5642","15607.9932"
"","106.7870","22.5851","15602.5869"
"","106.8870","22.6061","15615.0479"
"","106.9870","22.6273","15608.1592"
"","107.0870","22.6483","15616.7393"
"","107.1870","22.6701","15617.8223"
"","107.2870","22.6908","15615.0107"
"","107.3870","22.7126","15618.9473"
"","107.4870","22.7330","15619.5547"
"","107.5870","22.7546","15626.3662"
"","107.6870","22.7761","15619.2939"
"","107.7870","22.7968","15632.7637"
"","107.8870","22.8180","15625.3438"
"","107.9870","22.8386","15635.2725"
"","108.0870","22.8609","15638.6660"
"","108.1870","22.8812","15640.9248"
"","108.2870","22.9028","15659.7148"
"","108.3870","22.9234","15672.5752"
"","108.4870","22.9449","15696.9277"
"","108.5870","22.9667","15700.5488"
"","108.6870","22.9870","15709.1455"
"","108.7870","23.0087","15700.1074"
"","108.8870","23.0292","15698.7969"
"","108.9870","23.0513","15693.5830"
"","109.0870","23.0718","15680.7842"
"","109.1870","23.0931","15684.3613"
"","109.2870","23.1143","15668.6768"
"","109.3870","23.1351","15671.4062"
"","109.4870","23.1572","15658.1387"
"","109.5870","23.1773","15658.2744"
"","109.6870","23.1992","15647.8252"
"","109.7870","23.2196","15647.0518"
"","109.8870","23.2415","15643.9424"
"","109.9870","23.2625","15634.5605"
"","110.0870","23.2837","15641.7354"
"","110.1870","23.3049","15629.8145"
"","110.2870","23.3256","15637.2725"
"","110.3870","23.3479","15628.6865"
"","110.4870","23.3679","15627.8047"
"","110.5870","23.3898","15626.7549"
"","110.6870","23.4102","15622.3760"
"","110.7870","23.4319","15626.0146"
[...]
"","16.1960","3.4111","15401.8145"
"","16.2960","3.4319","15410.7441"
"","16.3960","3.4533","15402.0146"
"","16.4960","3.4741","15408.0244"
"","16.5960","3.4962","15406.2705"
"","16.6960","3.5165","15404.2676"
"","16.7960","3.5382","15407.2686"
"","16.8960","3.5589","15407.4551"
"","16.9960","3.5802","15410.6426"
"","17.0960","3.6017","15406.1035"
"","17.1960","3.6224","15415.2764"
"","17.2960","3.6438","15409.1816"
"","17.3960","3.6645","15416.9814"
"","17.4960","3.6867","15418.5010"
"","17.5960","3.7072","15415.6123"
"","17.6960","3.7286","15423.8398"
"","17.7960","3.7493","15421.5469"
"","17.8960","3.7708","15428.3154"
"","17.9960","3.7925","15422.8643"
"","18.0960","3.8128","15430.1201"
"","18.1960","3.8345","15428.3779"
"","18.2960","3.8548","15432.2012"
"","18.3960","3.8769","15437.9072"
"","18.4960","3.8979","15431.7451"
"","18.5960","3.9189","15443.9316"
"","18.6960","3.9399","15436.3945"
"","18.7960","3.9609","15445.4053"
"","18.8960","3.9831","15442.4385"
"","18.9960","4.0031","15446.1680"
"","19.0960","4.0251","15446.3008"
"","19.1960","4.0453","15448.2363"
"","19.2960","4.0673","15453.0332"
"","19.3960","4.0885","15444.9131"
"","19.4960","4.1092","15456.8105"
"","19.5960","4.1306","15448.9502"
"","19.6960","4.1514","15456.5352"
"","19.7960","4.1736","15453.5723"
"","19.8960","4.1938","15452.7900"
"","19.9960","4.2156","15457.3594"
"","20.0960","4.2361","15454.7588"
"","20.1960","4.2575","15460.5361"
"","20.2960","4.2793","15452.5664"
"","20.3960","4.2997","15461.9619"
"","20.4960","4.3211","15453.8838"
"","20.5960","4.3418","15459.8398"
"","20.6960","4.3641","15460.4375"
"","20.7960","4.3844","15455.5615"
"","20.8960","4.4060","15462.5225"
"","20.9960","4.4265","15456.1846"
"","21.0960","4.4480","15462.1270"
"","21.1960","4.4699","15451.7744"
"","21.2960","4.4901","15455.7246"
"","21.3960","4.5119","15448.8203"
"","21.4960","4.5323","15447.9814"
"","21.5960","4.5545","15444.2100"
"","21.6960","4.5750","15432.0420"
"","21.7960","4.5960","15432.2373"
"","21.8960","4.6171","15415.3164"
"","21.9960","4.6382","15410.9375"
"","22.0960","4.6604","15404.1533"
"","22.1960","4.6804","15409.2607"
"","22.2960","4.7026","15419.9600"
"","22.3960","4.7228","15428.6172"
"","22.4960","4.7446","15441.8896"
"","22.5960","4.7658","15440.5322"
"","22.6960","4.7867","15461.2363"
"","22.7960","4.8079","15457.0107"
"","22.8960","4.8287","15469.8955"
"","22.9960","4.8509","15473.7432"
"","23.0960","4.8711","15474.9375"
"","23.1960","4.8930","15484.1123"
"","23.2960","4.9134","15484.4492"
"","23.3960","4.9350","15493.7354"
"","23.4960","4.9566","15485.8857"
"","23.5960","4.9769","15496.4268"
"","23.6960","4.9987","15490.4648"
"","23.7960","5.0189","15496.9727"
"","23.8960","5.0414","15501.1299"
"","23.9960","5.0618","15494.4209"
"","24.0960","5.0834","15508.5996"
"","24.1960","5.1039","15501.2715"
"","24.2960","5.1251","15511.8096"
"","24.3960","5.1473","15501.5361"
"","24.4960","5.1671","15508.9121"
"","24.5960","5.1890","15504.9590"
"","24.6960","5.2094","15508.9717"
"","24.7960","5.2316","15515.4033"
"","24.8960","5.2526","15503.2637"
"","24.9960","5.2736","15519.6846"
"","25.0960","5.2947","15509.1123"
"","25.1960","5.3155","15519.2061"
"","25.2960","5.3378","15512.2920"
"","25.3960","5.3578","15512.6230"
"","25.4960","5.3796","15516.3643"
"","25.5960","5.4001","15516.4521"
"","25.6960","5.4220","15522.5068"
"","25.7960","5.4432","15513.2324"
"","25.8960","5.4639","15527.0723"
"","25.9960","5.4852","15517.8486"
"","26.0960","5.5061","15525.9443"
"","26.1960","5.5283","15525.7764"
"","26.2960","5.5485","15522.5859"
"","26.3960","5.5702","15529.2842"
"","26.4960","5.5909","15525.9746"
"","26.5960","5.6123","15533.6621"
"","26.6960","5.6338","15526.8145"
"","26.7960","5.6543","15537.1006"
"","26.8960","5.6759","15531.7393"
"","26.9960","5.6963","15535.8906"
"","27.0960","5.7186","15536.4453"
"","27.1960","5.7389","15526.6885"
"","27.2960","5.7605","15538.8955"
"","27.3960","5.7813","15527.4678"
"","27.4960","5.8025","15538.1826"
"","27.5960","5.8246","15526.8145"
"","27.6960","5.8448","15531.6426"
"","27.7960","5.8666","15527.5254"
"","27.8960","5.8869","15529.4834"
"","27.9960","5.9091","15532.3311"
"","28.0960","5.9298","15522.2568"
"","28.1960","5.9510","15535.8496"
"","28.2960","5.9717","15525.2949"
"","28.3960","5.9929","15533.9512"
"","28.4960","6.0150","15528.7471"
"","28.5960","6.0352","15530.4600"
"","28.6960","6.0568","15530.6221"
"","28.7960","6.0776","15530.8623"
"","28.8960","6.0992","15533.2510"
"","28.9960","6.1207","15525.2520"
"","29.0960","6.1414","15535.2373"
"","29.1960","6.1627","15525.3027"
"","29.2960","6.1834","15532.0020"
"","29.3960","6.2055","15528.5488"
"","29.4960","6.2259","15524.2012"
"","29.5960","6.2474","15528.9707"
"","29.6960","6.2680","15524.4316"
"","29.7960","6.2895","15530.7695"
"","29.8960","6.3112","15520.3506"
"","29.9960","6.3316","15529.1689"
"","30.0960","6.3532","15519.7725"
"","30.1960","6.3736","15522.9883"
"","30.2960","6.3959","15522.3447"
"","30.3960","6.4166","15514.1934"
"","30.4960","6.4379","15522.4932"
"","30.5960","6.4587","15515.1650"
"","30.6960","6.4799","15521.1260"
"","30.7960","6.5021","15512.3428"
"","30.8960","6.5219","15516.0596"
"","30.9960","6.5438","15510.5068"
"","31.0960","6.5642","15512.2520"
"","31.1960","6.5861","15512.0898"
"","31.2960","6.6072","15503.9277"
"","31.3960","6.6282","15513.6426"
"","31.4960","6.6492","15506.0801"
"","31.5960","6.6704","15510.8730"
"","31.6960","6.6926","15506.7031"
"","31.7960","6.7126","15505.2412"
"","31.8960","6.7344","15504.5498"
"","31.9960","6.7548","15505.0918"
"","32.0960","6.7765","15509.4863"
"","32.1960","6.7979","15500.9688"
"","32.2960","6.8186","15513.1172"
"","32.3960","6.8399","15505.4258"
"","32.4960","6.8606","15511.9941"
"","32.5960","6.8827","15510.0508"
"","32.6960","6.9030","15507.2080"
"","32.7960","6.9248","15512.6465"
"","32.8960","6.9454","15511.9834"
"","32.9960","6.9670","15517.2305"
"","33.0960","6.9885","15509.0469"
"","33.1960","7.0090","15518.8027"
"","33.2960","7.0306","15511.4111"
"","33.3960","7.0511","15517.3164"
"","33.4960","7.0732","15516.9932"
"","33.5960","7.0937","15514.2549"
"","33.6960","7.1152","15520.6289"
"","33.7960","7.1360","15516.8008"
"","33.8960","7.1572","15520.5381"
"","33.9960","7.1790","15518.4717"
"","34.0960","7.1995","15519.8604"
"","34.1960","7.2211","15516.5957"
"","34.2960","7.2416","15520.2432"
"","34.3960","7.2636","15521.3057"
"","34.4960","7.2849","15514.1074"
"","34.5960","7.3058","15524.0391"
"","34.6960","7.3265","15515.7354"
"","34.7960","7.3474","15523.0566"
"","34.8960","7.3699","15516.7236"
"","34.9960","7.3898","15516.2900"
"","35.0960","7.4116","15516.5195"
"","35.1960","7.4320","15518.5166"
"","35.2960","7.4538","15521.3984"
"","35.3960","7.4754","15513.8535"
"","35.4960","7.4959","15525.5156"
"","35.5960","7.5173","15516.2246"
"","35.6960","7.5378","15522.7480"
"","35.7960","7.5603","15520.2891"
"","35.8960","7.5804","15517.0127"
"","35.9960","7.6022","15523.5674"
"","36.0960","7.6229","15520.1152"
"","36.1960","7.6443","15530.8604"
"","36.2960","7.6661","15523.3965"
"","36.3960","7.6862","15533.8242"
"","36.4960","7.7077","15526.1416"
"","36.5960","7.7283","15531.9199"
"","36.6960","7.7506","15532.7793"
"","36.7960","7.7711","15526.5107"
"","36.8960","7.7925","15537.9971"
"","36.9960","7.8135","15533.8330"
"","37.0960","7.8347","15542.0840"
"","37.1960","7.8567","15539.8174"
"","37.2960","7.8769","15543.0361"
"","37.3960","7.8984","15544.8975"
"","37.4960","7.9189","15545.5488"
"","37.5960","7.9409","15553.4580"
"","37.6960","7.9618","15548.8564"
"","37.7960","7.9829","15564.2734"
"","37.8960","8.0039","15561.3779"
"","37.9960","8.0248","15576.3613"
"","38.0960","8.0471","15580.4541"
"","38.1960","8.0672","15585.2539"
"","38.2960","8.0891","15596.6523"
"","38.3960","8.1094","15603.6680"
"","38.4960","8.1311","15618.2734"
"","38.5960","8.1526","15614.0742"
"","38.6960","8.1733","15626.8193"
"","38.7960","8.1947","15613.4297"
"","38.8960","8.2153","15613.9092"
"","38.9960","8.2376","15606.1064"
"","39.0960","8.2578","15597.0205"
"","39.1960","8.2794","15598.9365"
"","39.2960","8.2999","15587.3115"
"","39.3960","8.3215","15591.9941"
"","39.4960","8.3433","15578.7314"
"","39.5960","8.3636","15585.5547"
"","39.6960","8.3853","15574.5703"
"","39.7960","8.4058","15576.4971"
"","39.8960","8.4278","15576.1484"
"","39.9960","8.4486","15565.1484"
"","40.0960","8.4699","15573.9541"
"","40.1960","8.4907","15564.4521"
"","40.2960","8.5120","15570.4453"
"","40.3960","8.5338","15562.7666"
"","40.4960","8.5540","15565.2012"
"","40.5960","8.5759","15561.2354"
"","40.6960","8.5963","15561.8369"
"","40.7960","8.6181","15565.2803"
"","40.8960","8.6393","15554.6504"
"","40.9960","8.6603","15566.8135"
"","41.0960","8.6813","15556.8018"
"","41.1960","8.7020","15565.2227"
"","41.2960","8.7244","15560.2100"
"","41.3960","8.7446","15558.3486"
"","41.4960","8.7663","15559.8252"
"","41.5960","8.7863","15558.6396"
"","41.6960","8.8086","15562.6396"
"","41.7960","8.8300","15552.8369"
"","41.8960","8.8505","15565.3848"
"","41.9960","8.8719","15552.9199"
"","42.0960","8.8926","15560.3242"
"","42.1960","8.9149","15558.2051"
"","42.2960","8.9352","15551.2441"
"","42.3960","8.9568","15558.4316"
"","42.4960","8.9775","15553.4268"
"","42.5960","8.9990","15559.7256"
"","42.6960","9.0208","15550.6748"
"","42.7960","9.0410","15559.1562"
"","42.8960","9.0627","15551.7578"
"","42.9960","9.0831","15555.0303"
"","43.0960","9.1053","15554.3652"
"","43.1960","9.1257","15546.4502"
"","43.2960","9.1472","15554.9521"
"","43.3960","9.1680","15547.4727"
"","43.4960","9.1892","15554.6025"
"","43.5960","9.2112","15546.2490"
"","43.6960","9.2313","15551.1777"
"","43.7960","9.2531","15545.5020"
"","43.8960","9.2737","15548.8271"
"","43.9960","9.2955","15549.0293"
"","44.0960","9.3165","15539.0205"
"","44.1960","9.3376","15552.6768"
"","44.2960","9.3587","15540.4746"
"","44.3960","9.3793","15549.5674"
"","44.4960","9.4017","15542.1289"
"","44.5960","9.4218","15542.8018"
"","44.6960","9.4437","15543.9678"
"","44.7960","9.4641","15542.4062"
"","44.8960","9.4858","15547.0312"
"","44.9960","9.5073","15538.9365"
"","45.0960","9.5278","15549.5752"
"","45.1960","9.5494","15539.6973"
"","45.2960","9.5699","15547.2646"
"","45.3960","9.5922","15544.7852"
"","45.4960","9.6126","15539.6270"
"","45.5960","9.6342","15546.7627"
"","45.6960","9.6549","15542.4658"
"","45.7960","9.6762","15549.5869"
"","45.8960","9.6981","15540.6729"
"","45.9960","9.7182","15550.0117"
"","46.0960","9.7400","15543.6543"
"","46.1960","9.7604","15546.9746"
"","46.2960","9.7825","15547.7734"
"","46.3960","9.8032","15541.0732"
"","46.4960","9.8245","15550.9473"
"","46.5960","9.8454","15542.3154"
"","46.6960","9.8665","15552.0977"
"","46.7960","9.8885","15542.6387"
"","46.8960","9.9086","15550.0547"
"","46.9960","9.9306","15544.4727"
"","47.0960","9.9509","15545.7930"
"","47.1960","9.9729","15548.0684"
"","47.2960","9.9940","15539.9482"
"","47.3960","10.0150","15553.0322"
"","47.4960","10.0360","15542.6816"
"","47.5960","10.0568","15550.6406"
"","47.6960","10.0789","15547.8301"
"","47.7960","10.0991","15543.8994"
"","47.8960","10.1209","15545.0283"
"","47.9960","10.1415","15543.6562"
"","48.0960","10.1629","15550.1914"
"","48.1960","10.1848","15538.1602"
"","48.2960","10.2053","15550.6387"
"","48.3960","10.2269","15544.2803"
"","48.4960","10.2474","15548.5215"
"","48.5960","10.2696","15545.9014"
"","48.6960","10.2900","15539.6748"
"","48.7960","10.3114","15547.4932"
"","48.8960","10.3320","15539.7158"
"","48.9960","10.3534","15547.7744"
"","49.0960","10.3754","15537.6855"
"","49.1960","10.3956","15546.4854"
"","49.2960","10.4172","15539.2881"
"","49.3960","10.4377","15543.1777"
"","49.4960","10.4598","15543.8125"
"","49.5960","10.4805","15534.0195"
"","49.6960","10.5019","15545.1475"
"","49.7960","10.5227","15534.1904"
"","49.8960","10.5439","15542.7578"
"","49.9960","10.5659","15534.8896"
"","50.0960","10.5861","15541.5029"
"","50.1960","10.6080","15537.0801"
"","50.2960","10.6281","15541.9141"
"","50.3960","10.6502","15540.0781"
"","50.4960","10.6711","15532.2061"
"","50.5960","10.6920","15542.3643"
"","50.6960","10.7133","15530.2881"
"","50.7960","10.7343","15538.0859"
"","50.8960","10.7564","15532.7920"
"","50.9960","10.7767","15532.3770"
"","51.0960","10.7985","15532.4834"
"","51.1960","10.8189","15527.2363"
"","51.2960","10.8405","15528.0127"
"","51.3960","10.8621","15518.4102"
"","51.4960","10.8826","15530.1631"
"","51.5960","10.9039","15519.7900"
"","51.6960","10.9245","15526.4287"
"","51.7960","10.9468","15525.9561"
"","51.8960","10.9673","15517.8369"
"","51.9960","10.9887","15526.4561"
"","52.0960","11.0094","15518.5674"
"","52.1960","11.0307","15525.0293"
"","52.2960","11.0527","15516.5781"
"","52.3960","11.0730","15521.1133"
"","52.4960","11.0947","15517.0400"
"","52.5960","11.1151","15518.7842"
"","52.6960","11.1372","15521.5518"
"","52.7960","11.1579","15515.7061"
"","52.8960","11.1790","15527.6240"
"","52.9960","11.2001","15520.8828"
"","53.0960","11.2209","15529.6807"
"","53.1960","11.2432","15526.7793"
"","53.2960","11.2632","15529.7090"
"","53.3960","11.2851","15530.2646"
"","53.4960","11.3056","15533.0312"
"","53.5960","11.3275","15538.3096"
"","53.6960","11.3488","15528.5312"
"","53.7960","11.3696","15543.3447"
"","53.8960","11.3910","15533.7559"
"","53.9960","11.4117","15542.8428"
"","54.0960","11.4335","15539.2959"
"","54.1960","11.4540","15537.4531"
"","54.2960","11.4757","15542.3477"
"","54.3960","11.4962","15538.0352"
"","54.4960","11.5174","15543.0107"
"","54.5960","11.5395","15533.5117"
"","54.6960","11.5598","15543.1729"
"","54.7960","11.5813","15532.9873"
"","54.8960","11.6019","15538.2539"
"","54.9960","11.6242","15538.1660"
"","55.0960","11.6448","15528.5879"
"","55.1960","11.6661","15536.0391"
"","55.2960","11.6869","15526.3398"
"","55.3960","11.7081","15531.3564"
"","55.4960","11.7301","15517.9561"
"","55.5960","11.7501","15520.0664"
"","55.6960","11.7719","15513.4941"
"","55.7960","11.7924","15512.5049"
"","55.8960","11.8143","15511.1562"
"","55.9960","11.8353","15499.5469"
"","56.0960","11.8564","15511.7002"
"","56.1960","11.8775","15497.5283"
"","56.2960","11.8984","15507.2744"
"","56.3960","11.9206","15499.0439"
"","56.4960","11.9407","15498.6904"
"","56.5960","11.9627","15500.1807"
"","56.6960","11.9830","15494.5537"
"","56.7960","12.0048","15502.2051"
"","56.8960","12.0260","15486.0752"
"","56.9960","12.0468","15499.5127"
"","57.0960","12.0680","15486.4697"
"","57.1960","12.0888","15492.3682"
"","57.2960","12.1110","15489.3682"
"","57.3960","12.1313","15483.4268"
"","57.4960","12.1530","15489.5977"
"","57.5960","12.1736","15482.2334"
"","57.6960","12.1951","15487.8633"
"","57.7960","12.2168","15475.7012"
"","57.8960","12.2372","15485.9375"
"","57.9960","12.2588","15473.7832"
"","58.0960","12.2792","15478.7422"
"","58.1960","12.3014","15476.2832"
"","58.2960","12.3220","15467.2061"
"","58.3960","12.3433","15474.5410"
"","58.4960","12.3639","15463.5596"
"","58.5960","12.3853","15472.2646"
"","58.6960","12.4073","15458.9873"
"","58.7960","12.4276","15463.0527"
"","58.8960","12.4493","15456.3975"
"","58.9960","12.4698","15456.6553"
"","59.0960","12.4918","15457.0508"
"","59.1960","12.5127","15440.8975"
"","59.2960","12.5338","15454.1631"
"","59.3960","12.5549","15437.3242"
"","59.4960","12.5757","15443.9629"
"","59.5960","12.5980","15435.5635"
"","59.6960","12.6180","15427.9766"
"","59.7960","12.6398","15432.6973"
"","59.8960","12.6603","15424.9414"
"","59.9960","12.6821","15428.1426"
"","60.0960","12.7034","15411.4082"
"","60.1960","12.7241","15423.1982"
"","60.2960","12.7455","15407.0889"
"","60.3960","12.7662","15411.7881"
"","60.4960","12.7884","15406.2061"
"","60.5960","12.8085","15399.8184"
"","60.6960","12.8304","15402.8301"
"","60.7960","12.8509","15393.6699"
"","60.8960","12.8724","15397.2568"
"","60.9960","12.8938","15382.1230"
"","61.0960","12.9144","15386.5938"
"","61.1960","12.9360","15375.5586"
"","61.2960","12.9566","15379.8389"
"","61.3960","12.9787","15376.1699"
"","61.4960","12.9994","15362.7979"
"","61.5960","13.0208","15371.4014"
"","61.6960","13.0414","15356.1582"
"","61.7960","13.0626","15359.9355"
"","61.8960","13.0847","15345.1055"
"","61.9960","13.1048","15344.2070"
"","62.0960","13.1268","15339.7129"
"","62.1960","13.1472","15335.3008"
"","62.2960","13.1692","15337.5430"
"","62.3960","13.1901","15320.2549"
"","62.4960","13.2111","15329.7539"
"","62.5960","13.2321","15310.8643"
"","62.6960","13.2530","15314.3613"
"","62.7960","13.2753","15302.6299"
"","62.8960","13.2953","15295.7930"
"","62.9960","13.3172","15294.8174"
"","63.0960","13.3378","15285.0752"
"","63.1960","13.3594","15287.0645"
"","63.2960","13.3808","15267.8877"
"","63.3960","13.4015","15276.2529"
"","63.4960","13.4226","15256.4775"
"","63.5960","13.4435","15258.9277"
"","63.6960","13.4656","15246.9756"
"","63.7960","13.4859","15236.5625"
"","63.8960","13.5076","15236.8232"
"","63.9960","13.5282","15223.2588"
"","64.0960","13.5498","15225.8320"
"","64.1960","13.5714","15205.8604"
"","64.2960","13.5918","15207.2441"
"","64.3960","13.6133","15191.4580"
"","64.4960","13.6339","15186.7363"
"","64.5960","13.6560","15178.9844"
"","64.6960","13.6766","15159.8799"
"","64.7960","13.6982","15165.8359"
"","64.8960","13.7189","15144.4463"
"","64.9960","13.7400","15145.7236"
"","65.0960","13.7621","15125.4268"
"","65.1960","13.7822","15120.3525"
"","65.2960","13.8040","15107.2920"
"","65.3960","13.8244","15099.2725"
"","65.4960","13.8465","15090.9756"
"","65.5960","13.8674","15066.4180"
"","65.6960","13.8883","15070.0049"
"","65.7960","13.9095","15044.8252"
"","65.8960","13.9304","15042.8652"
"","65.9960","13.9525","15022.5312"
"","66.0960","13.9728","15010.4209"
"","66.1960","13.9945","14998.0742"
"","66.2960","14.0150","14983.1240"
"","66.3960","14.0368","14972.8555"
"","66.4960","14.0580","14944.3398"
"","66.5960","14.0788","14945.0107"
"","66.6960","14.1001","14913.9121"
"","66.7960","14.1209","14907.5791"
"","66.8960","14.1430","14885.8740"
"","66.9960","14.1631","14861.2334"
"","67.0960","14.1850","14853.9561"
"","67.1960","14.2055","14825.6035"
"","67.2960","14.2271","14813.7910"
"","67.3960","14.2485","14776.9775"
"","67.4960","14.2691","14771.7891"
"","67.5960","14.2908","14735.4766"
"","67.6960","14.3112","14719.3623"
"","67.7960","14.3337","14692.7041"
"","67.8960","14.3539","14661.9512"
"","67.9960","14.3755","14646.3584"
"","68.0960","14.3961","14605.8770"
"","68.1960","14.4174","14589.7852"
"","68.2960","14.4395","14545.7920"
"","68.3960","14.4596","14521.2432"
"","68.4960","14.4813","14482.0420"
"","68.5960","14.5018","14452.0732"
"","68.6960","14.5238","14416.4785"
"","68.7960","14.5448","14367.8994"
"","68.8960","14.5659","14343.1875"
"","68.9960","14.5868","14290.3311"
"","69.0960","14.6078","14255.5400"
"","69.1960","14.6298","14200.4346"
"","69.2960","14.6501","14154.7266"
"","69.3960","14.6717","14102.5107"
"","69.4960","14.6924","14053.5225"
"","69.5960","14.7141","13998.1748"
"","69.6960","14.7354","13931.9600"
"","69.7960","14.7560","13882.5459"
"","69.8960","14.7774","13806.8945"
"","69.9960","14.7981","13746.8350"
"","70.0960","14.8203","13669.9785"
"","70.1960","14.8406","13590.8799"
"","70.2960","14.8623","13516.1221"
"","70.3960","14.8830","13429.1455"
"","70.4960","14.9044","13342.9346"
"","70.5960","14.9262","13232.0742"
"","70.6960","14.9464","13143.1113"
"","70.7960","14.9681","13011.6670"
"","70.8960","14.9887","12872.0928"
"","70.9580","15.0023","12600.1895"
"","70.9600","15.0028","12321.9688"
"","70.9620","15.0032","11905.4209"
"","70.9630","15.0034","11655.0000"
"","70.9640","15.0037","11381.4746"
"","70.9650","15.0039","11088.0361"
"","70.9660","15.0041","10777.8027"
"","70.9670","15.0044","10453.4141"
"","70.9680","15.0046","10117.1533"
"","70.9690","15.0048","9771.2588"
"","70.9700","15.0051","9417.8779"
"","70.9710","15.0053","9058.9141"
"","70.9720","15.0055","8696.1504"
"","70.9730","15.0058","8331.3447"
"","70.9740","15.0060","7966.0767"
"","70.9750","15.0063","7601.7202"