File: lab02/data/S1_Steel_11.csv
Results Table 1
,Specimen label,Width,Thickness,Length,Tensile strain (Displacement) at Break (Standard),Maximum Tensile stress
,,(mm),(mm),(mm),(%),(MPa)
"1","Steel-1","12.73","4.06","68.81","44.14","239.24"
"2","Steel-2.1","12.73","3.05","71.09","14.16","311.81"
"3","Steel-2.2","11.76","2.84","76.71","13.13","370.91"
"4","Steel-2.3","10.85","2.72","84.89","11.50","420.57"

1,Time,Displacement,Force
,(s),(mm),(N)
"","0.0000","0.0000","63.5619"
"","0.2000","0.0177","124.3939"
"","0.4000","0.0679","207.0519"
"","0.6000","0.1107","327.9105"
"","0.7890","0.1500","704.2089"
"","0.9240","0.1783","1208.2526"
"","1.0540","0.2064","1715.4930"
"","1.1940","0.2354","2221.6687"
"","1.3360","0.2657","2725.8577"
"","1.4820","0.2968","3226.8972"
"","1.6410","0.3301","3728.9951"
"","1.8020","0.3642","4232.9844"
"","1.9620","0.3987","4736.6167"
"","2.1400","0.4357","5238.1733"
"","2.3230","0.4741","5739.1489"
"","2.5080","0.5140","6241.4067"
"","2.7050","0.5553","6735.0039"
"","2.9050","0.5984","7223.3970"
"","3.1050","0.6405","7652.7275"
"","3.3050","0.6827","8033.6943"
"","3.5050","0.7246","8339.4375"
"","3.7050","0.7667","8574.3652"
"","3.9050","0.8092","8741.4053"
"","4.1050","0.8516","8867.3525"
"","4.3050","0.8949","8964.4971"
"","4.5050","0.9370","9027.8809"
"","4.7050","0.9794","9090.2207"
"","4.9050","1.0211","9123.9219"
"","5.1050","1.0632","9163.2334"
"","5.3050","1.1055","9186.8799"
"","5.5050","1.1479","9223.6992"
"","5.7050","1.1909","9252.4502"
"","5.9050","1.2330","9290.0762"
"","6.1050","1.2758","9329.3350"
"","6.3050","1.3178","9362.3799"
"","6.5050","1.3600","9391.4268"
"","6.7050","1.4019","9413.4639"
"","6.9050","1.4442","9438.6738"
"","7.1050","1.4869","9460.5605"
"","7.3050","1.5292","9491.8574"
"","7.5050","1.5720","9527.3330"
"","7.7050","1.6141","9558.3994"
"","7.9050","1.6566","9597.2236"
"","8.1050","1.6987","9619.6582"
"","8.3050","1.7405","9640.9600"
"","8.5050","1.7830","9656.1631"
"","8.7050","1.8252","9688.0527"
"","8.9050","1.8682","9712.8086"
"","9.1050","1.9101","9740.3457"
"","9.3050","1.9533","9779.7705"
"","9.5050","1.9951","9805.0020"
"","9.7050","2.0375","9832.4883"
"","9.9050","2.0791","9844.8857"
"","10.1050","2.1214","9868.7578"
"","10.3050","2.1636","9882.1533"
"","10.5050","2.2063","9914.3916"
"","10.7050","2.2495","9946.4521"
"","10.9050","2.2916","9974.4502"
"","11.1050","2.3340","10004.7285"
"","11.3050","2.3761","10026.0137"
"","11.5050","2.4180","10043.9883"
"","11.7050","2.4602","10055.2070"
"","11.9050","2.5024","10079.6689"
"","12.1050","2.5456","10104.1787"
"","12.3050","2.5876","10126.5244"
"","12.5050","2.6306","10159.0820"
"","12.7050","2.6725","10182.2656"
"","12.9050","2.7146","10209.5801"
"","13.1050","2.7563","10218.5342"
"","13.3050","2.7986","10238.5732"
"","13.5050","2.8415","10250.4678"
"","13.7050","2.8836","10277.9297"
"","13.9050","2.9269","10303.8564"
"","14.1050","2.9688","10324.8057"
"","14.3050","3.0114","10354.9863"
"","14.5050","3.0533","10372.7920"
"","14.7050","3.0952","10386.9004"
"","14.9050","3.1376","10396.4189"
"","15.1050","3.1798","10419.9971"
"","15.3050","3.2229","10435.3945"
"","15.5050","3.2649","10457.0615"
"","15.7050","3.3080","10489.8604"
"","15.9050","3.3497","10507.5098"
"","16.1050","3.3921","10529.0566"
"","16.3050","3.4339","10539.4697"
"","16.5050","3.4760","10554.0771"
"","16.7050","3.5188","10563.3750"
"","16.9050","3.5613","10587.6855"
"","17.1050","3.6042","10613.6748"
"","17.3050","3.6462","10631.2773"
"","17.5050","3.6885","10655.1943"
"","17.7050","3.7306","10671.8750"
"","17.9050","3.7726","10683.5762"
"","18.1050","3.8149","10689.9668"
"","18.3050","3.8571","10708.3936"
"","18.5050","3.9001","10725.2266"
"","18.7050","3.9422","10743.2568"
"","18.9050","3.9854","10772.1191"
"","19.1050","4.0273","10789.2637"
"","19.3050","4.0692","10807.2070"
"","19.5050","4.1113","10812.1143"
"","19.7050","4.1534","10828.7070"
"","19.9050","4.1962","10836.0908"
"","20.1050","4.2383","10856.1777"
"","20.3050","4.2815","10879.2822"
"","20.5050","4.3235","10894.9922"
"","20.7050","4.3659","10916.9092"
"","20.9050","4.4080","10930.2793"
"","21.1050","4.4501","10942.7617"
"","21.3050","4.4922","10946.0723"
"","21.5050","4.5343","10961.2676"
"","21.7050","4.5777","10979.3994"
"","21.9050","4.6197","10997.3809"
"","22.1050","4.6625","11021.1621"
"","22.3050","4.7044","11031.4326"
"","22.5050","4.7466","11048.2520"
"","22.7050","4.7887","11054.4111"
"","22.9050","4.8307","11067.5498"
"","23.1050","4.8735","11071.6807"
"","23.3050","4.9158","11094.7051"
"","23.5050","4.9589","11112.3271"
"","23.7050","5.0009","11125.8926"
"","23.9050","5.0434","11144.1035"
"","24.1050","5.0852","11156.5459"
"","24.3050","5.1271","11164.9873"
"","24.5050","5.1695","11168.4492"
"","24.7050","5.2119","11184.3984"
"","24.9050","5.2551","11198.2363"
"","25.1050","5.2971","11213.5010"
"","25.3050","5.3400","11236.3408"
"","25.5050","5.3817","11245.4277"
"","25.7050","5.4238","11258.1514"
"","25.9050","5.4660","11264.4180"
"","26.1050","5.5081","11273.4033"
"","26.3050","5.5509","11276.3594"
"","26.5050","5.5931","11293.1963"
"","26.7050","5.6363","11314.1982"
"","26.9050","5.6780","11324.8213"
"","27.1050","5.7203","11339.3213"
"","27.3050","5.7624","11352.6924"
"","27.5050","5.8048","11361.9062"
"","27.7050","5.8471","11362.6553"
"","27.9050","5.8892","11372.9385"
"","28.1050","5.9324","11386.1436"
"","28.3050","5.9744","11399.8662"
"","28.5050","6.0170","11421.6875"
"","28.7050","6.0592","11430.6484"
"","28.9050","6.1012","11441.4980"
"","29.1050","6.1433","11441.8623"
"","29.3050","6.1853","11450.9814"
"","29.5050","6.2282","11456.6094"
"","29.7050","6.2701","11470.9277"
"","29.9050","6.3135","11486.9229"
"","30.1050","6.3554","11498.9688"
"","30.3050","6.3980","11515.8623"
"","30.5050","6.4399","11521.4746"
"","30.7050","6.4818","11525.4521"
"","30.9050","6.5242","11525.0820"
"","31.1050","6.5665","11539.8105"
"","31.3050","6.6097","11551.7793"
"","31.5050","6.6517","11561.7324"
"","31.7050","6.6946","11582.0664"
"","31.9050","6.7364","11585.5889"
"","32.1050","6.7785","11598.7607"
"","32.3050","6.8206","11601.3535"
"","32.5050","6.8626","11610.3408"
"","32.7050","6.9055","11608.7471"
"","32.9050","6.9477","11621.8613"
"","33.1050","6.9909","11639.9375"
"","33.3050","7.0329","11647.8545"
"","33.5050","7.0752","11662.6826"
"","33.7050","7.1171","11666.2705"
"","33.9050","7.1593","11673.1768"
"","34.1050","7.2015","11671.6494"
"","34.3050","7.2440","11681.6436"
"","34.5050","7.2870","11690.5713"
"","34.7050","7.3290","11699.7920"
"","34.9050","7.3717","11716.8203"
"","35.1050","7.4139","11726.3193"
"","35.3050","7.4558","11734.5420"
"","35.5050","7.4980","11735.2109"
"","35.7050","7.5399","11738.6719"
"","35.9050","7.5829","11741.5186"
"","36.1050","7.6249","11746.5107"
"","36.3050","7.6683","11767.6514"
"","36.5050","7.7104","11775.9775"
"","36.7050","7.7526","11791.4346"
"","36.9050","7.7945","11795.0576"
"","37.1050","7.8367","11797.7461"
"","37.3050","7.8790","11796.2998"
"","37.5050","7.9213","11803.8965"
"","37.7050","7.9643","11812.2324"
"","37.9050","8.0062","11821.4482"
"","38.1050","8.0490","11836.4014"
"","38.3050","8.0911","11840.2393"
"","38.5050","8.1330","11847.4629"
"","38.7050","8.1753","11849.1035"
"","38.9050","8.2174","11854.6934"
"","39.1050","8.2602","11856.5059"
"","39.3050","8.3025","11864.9795"
"","39.5050","8.3455","11880.6035"
"","39.7050","8.3876","11886.4375"
"","39.9050","8.4299","11898.8086"
"","40.1050","8.4718","11899.7480"
"","40.3050","8.5139","11901.6641"
"","40.5050","8.5563","11898.6543"
"","40.7050","8.5986","11910.8691"
"","40.9050","8.6416","11918.2910"
"","41.1050","8.6837","11924.1357"
"","41.3050","8.7264","11939.7090"
"","41.5050","8.7685","11946.1748"
"","41.7050","8.8104","11950.5527"
"","41.9050","8.8525","11944.9287"
"","42.1050","8.8947","11951.6270"
"","42.3050","8.9376","11952.5312"
"","42.5050","8.9798","11962.2812"
"","42.7050","9.0231","11978.4619"
"","42.9050","9.0649","11979.5020"
"","43.1050","9.1072","11989.8037"
"","43.3050","9.1491","11990.2441"
"","43.5050","9.1912","11995.2812"
"","43.7050","9.2336","11991.5459"
"","43.9050","9.2759","11999.9756"
"","44.1050","9.3190","12005.2715"
"","44.3050","9.3611","12014.7646"
"","44.5050","9.4038","12027.7393"
"","44.7050","9.4459","12031.8008"
"","44.9050","9.4878","12034.8018"
"","45.1050","9.5298","12029.4951"
"","45.3050","9.5722","12035.2793"
"","45.5050","9.6150","12036.3115"
"","45.7050","9.6573","12043.5176"
"","45.9050","9.7002","12055.7451"
"","46.1050","9.7422","12060.2139"
"","46.3050","9.7843","12070.2832"
"","46.5050","9.8264","12070.8887"
"","46.7050","9.8684","12072.0459"
"","46.9050","9.9111","12067.2627"
"","47.1050","9.9533","12075.1621"
"","47.3050","9.9964","12080.6191"
"","47.5050","10.0385","12087.4141"
"","47.7050","10.0810","12101.8369"
"","47.9050","10.1230","12105.7471"
"","48.1050","10.1652","12106.4951"
"","48.3050","10.2074","12101.9561"
"","48.5050","10.2495","12104.7969"
"","48.7050","10.2922","12107.0762"
"","48.9050","10.3345","12112.3564"
"","49.1050","10.3774","12128.9883"
"","49.3050","10.4195","12128.4580"
"","49.5050","10.4618","12137.4414"
"","49.7050","10.5038","12134.5283"
"","49.9050","10.5459","12136.3027"
"","50.1050","10.5882","12132.2842"
"","50.3050","10.6306","12139.5801"
"","50.5050","10.6737","12145.0986"
"","50.7050","10.7158","12149.1123"
"","50.9050","10.7585","12161.9326"
"","51.1050","10.8006","12166.3359"
"","51.3050","10.8424","12167.5703"
"","51.5050","10.8845","12161.9043"
"","51.7050","10.9268","12166.4160"
"","51.9050","10.9697","12165.8789"
"","52.1050","11.0119","12171.3691"
"","52.3050","11.0549","12182.7871"
"","52.5050","11.0969","12184.8770"
"","52.7050","11.1391","12193.4414"
"","52.9050","11.1811","12193.8691"
"","53.1050","11.2228","12190.4951"
"","53.3050","11.2656","12185.6230"
"","53.5050","11.3078","12189.9043"
"","53.7050","11.3513","12198.3467"
"","53.9050","11.3932","12202.6328"
"","54.1050","11.4358","12213.5137"
"","54.3050","11.4776","12215.3242"
"","54.5050","11.5198","12215.7725"
"","54.7050","11.5619","12212.3848"
"","54.9050","11.6042","12214.9600"
"","55.1050","11.6469","12212.6729"
"","55.3050","11.6893","12220.2090"
"","55.5050","11.7318","12227.9443"
"","55.7050","11.7741","12230.4688"
"","55.9050","11.8164","12237.2578"
"","56.1050","11.8585","12240.0039"
"","56.3050","11.9005","12237.8857"
"","56.5050","11.9432","12232.5293"
"","56.7050","11.9853","12236.9814"
"","56.9050","12.0285","12242.1562"
"","57.1050","12.0703","12245.0635"
"","57.3050","12.1130","12256.0635"
"","57.5050","12.1550","12257.2520"
"","57.7050","12.1970","12257.3506"
"","57.9050","12.2393","12251.5371"
"","58.1050","12.2815","12255.1465"
"","58.3050","12.3242","12254.9590"
"","58.5050","12.3664","12259.0889"
"","58.7050","12.4096","12270.0537"
"","58.9050","12.4514","12270.8760"
"","59.1050","12.4937","12277.0596"
"","59.3050","12.5359","12276.8154"
"","59.5050","12.5778","12273.7266"
"","59.7050","12.6203","12266.8203"
"","59.9050","12.6626","12272.0088"
"","60.1050","12.7059","12279.2402"
"","60.3050","12.7477","12281.9404"
"","60.5050","12.7903","12289.2471"
"","60.7050","12.8323","12289.5859"
"","60.9050","12.8745","12293.5322"
"","61.1050","12.9164","12284.9297"
"","61.3050","12.9588","12289.5596"
"","61.5050","13.0017","12285.4307"
"","61.7050","13.0438","12290.9551"
"","61.9050","13.0869","12300.2266"
"","62.1050","13.1290","12302.1250"
"","62.3050","13.1712","12309.8525"
"","62.5050","13.2131","12306.4814"
"","62.7050","13.2551","12303.4424"
"","62.9050","13.2978","12297.5186"
"","63.1050","13.3400","12302.3564"
"","63.3050","13.3832","12308.1807"
"","63.5050","13.4251","12309.6045"
"","63.7050","13.4677","12317.9277"
"","63.9050","13.5096","12319.3135"
"","64.1050","13.5519","12322.6377"
"","64.3050","13.5939","12313.8252"
"","64.5050","13.6359","12311.6934"
"","64.7050","13.6790","12309.4170"
"","64.9050","13.7214","12317.6035"
"","65.1050","13.7643","12328.5459"
"","65.3050","13.8061","12325.8408"
"","65.5050","13.8483","12329.6221"
"","65.7050","13.8903","12328.1826"
"","65.9050","13.9325","12327.3301"
"","66.1050","13.9751","12319.5420"
"","66.3050","14.0173","12321.5693"
"","66.5050","14.0606","12329.5391"
"","66.7050","14.1023","12332.7295"
"","66.9050","14.1451","12340.6377"
"","67.1050","14.1870","12340.4033"
"","67.3050","14.2291","12340.3672"
"","67.5050","14.2713","12332.0127"
"","67.7050","14.3135","12334.2793"
"","67.9050","14.3564","12331.4570"
"","68.1050","14.3986","12338.2051"
"","68.3050","14.4415","12344.2109"
"","68.5050","14.4835","12347.8701"
"","68.7050","14.5257","12348.7637"
"","68.9050","14.5678","12346.4443"
"","69.1050","14.6097","12341.0332"
"","69.3050","14.6523","12335.1719"
"","69.5050","14.6945","12340.0166"
"","69.7050","14.7379","12347.2256"
"","69.9050","14.7799","12349.2617"
"","70.1050","14.8223","12356.0947"
"","70.3050","14.8645","12355.1953"
"","70.5050","14.9063","12356.3037"
"","70.7050","14.9485","12347.5479"
"","70.9050","14.9908","12347.2686"
"","71.1050","15.0338","12344.7334"
"","71.3050","15.0760","12350.3477"
"","71.5050","15.1190","12358.5498"
"","71.7050","15.1609","12358.1621"
"","71.9050","15.2031","12361.7412"
"","72.1050","15.2449","12359.0908"
"","72.3050","15.2871","12355.7314"
"","72.5050","15.3297","12350.5908"
"","72.7050","15.3720","12352.0752"
"","72.9050","15.4151","12356.9521"
"","73.1050","15.4571","12358.0400"
"","73.3050","15.4997","12366.1914"
"","73.5050","15.5417","12364.9043"
"","73.7050","15.5835","12365.0020"
"","73.9050","15.6260","12355.1455"
"","74.1050","15.6682","12359.1758"
"","74.3050","15.7113","12353.3848"
"","74.5050","15.7531","12358.9385"
"","74.7050","15.7963","12367.8994"
"","74.9050","15.8378","12366.4844"
"","75.1050","15.8803","12367.2715"
"","75.3050","15.9223","12365.8936"
"","75.5050","15.9646","12364.2686"
"","75.7050","16.0072","12357.1211"
"","75.9050","16.0493","12357.2461"
"","76.1050","16.0926","12363.2295"
"","76.3050","16.1344","12365.2363"
"","76.5050","16.1769","12372.4443"
"","76.7050","16.2190","12369.5459"
"","76.9050","16.2610","12367.4092"
"","77.1050","16.3033","12359.3271"
"","77.3050","16.3455","12362.3262"
"","77.5050","16.3885","12359.0977"
"","77.7050","16.4304","12360.0010"
"","77.9050","16.4736","12369.8223"
"","78.1050","16.5154","12370.3369"
"","78.3050","16.5576","12372.0820"
"","78.5050","16.5997","12364.8906"
"","78.7050","16.6419","12365.1289"
"","78.9050","16.6845","12357.9678"
"","79.1050","16.7267","12361.3555"
"","79.3050","16.7698","12364.7031"
"","79.5050","16.8119","12365.0684"
"","79.7050","16.8543","12371.4004"
"","79.9050","16.8963","12368.9570"
"","80.1050","16.9381","12366.1748"
"","80.3050","16.9805","12357.8203"
"","80.5050","17.0227","12360.7266"
"","80.7050","17.0661","12359.8818"
"","80.9050","17.1076","12358.3369"
"","81.1050","17.1508","12369.2715"
"","81.3050","17.1926","12362.5645"
"","81.5050","17.2350","12367.9336"
"","81.7050","17.2771","12365.0049"
"","81.9050","17.3192","12363.0732"
"","82.1050","17.3619","12355.6943"
"","82.3050","17.4042","12357.5703"
"","82.5050","17.4473","12361.9219"
"","82.7050","17.4892","12361.8447"
"","82.9050","17.5316","12367.4404"
"","83.1050","17.5736","12365.8428"
"","83.3050","17.6155","12361.4277"
"","83.5050","17.6580","12352.5117"
"","83.7050","17.7001","12355.8115"
"","83.9050","17.7432","12354.3525"
"","84.1050","17.7852","12353.3613"
"","84.3050","17.8282","12362.7783"
"","84.5050","17.8702","12361.0098"
"","84.7050","17.9122","12363.6025"
"","84.9050","17.9542","12356.6826"
"","85.1050","17.9964","12352.4238"
"","85.3050","18.0393","12347.5898"
"","85.5050","18.0814","12349.9062"
"","85.7050","18.1246","12351.4766"
"","85.9050","18.1665","12352.9961"
"","86.1050","18.2088","12359.3418"
"","86.3050","18.2508","12355.9219"
"","86.5050","18.2930","12352.4424"
"","86.7050","18.3354","12344.3779"
"","86.9050","18.3775","12344.8584"
"","87.1050","18.4207","12344.4648"
"","87.3050","18.4627","12345.4521"
"","87.5050","18.5054","12354.9424"
"","87.7050","18.5474","12351.2822"
"","87.9050","18.5897","12352.9512"
"","88.1050","18.6316","12343.5400"
"","88.3050","18.6738","12341.3213"
"","88.5050","18.7164","12335.0459"
"","88.7050","18.7586","12336.8691"
"","88.9050","18.8018","12341.0215"
"","89.1050","18.8439","12339.8633"
"","89.3050","18.8863","12345.6670"
"","89.5050","18.9285","12344.2676"
"","89.7050","18.9702","12338.9971"
"","89.9050","19.0127","12330.1475"
"","90.1050","19.0549","12333.7676"
"","90.3050","19.0978","12329.9502"
"","90.5050","19.1400","12328.5479"
"","90.7050","19.1830","12337.7832"
"","90.9050","19.2249","12334.9297"
"","91.1050","19.2670","12336.5020"
"","91.3050","19.3089","12327.7529"
"","91.5050","19.3509","12325.0918"
"","91.7050","19.3938","12317.3916"
"","91.9050","19.4361","12320.9287"
"","92.1050","19.4793","12324.6748"
"","92.3050","19.5212","12323.8604"
"","92.5050","19.5636","12325.8799"
"","92.7050","19.6057","12324.5967"
"","92.9050","19.6475","12322.4375"
"","93.1050","19.6899","12313.7529"
"","93.3050","19.7322","12312.1113"
"","93.5050","19.7754","12310.1650"
"","93.7050","19.8175","12309.6299"
"","93.9050","19.8602","12318.1846"
"","94.1050","19.9022","12315.3623"
"","94.3050","19.9441","12318.3105"
"","94.5050","19.9862","12307.9863"
"","94.7050","20.0284","12303.8730"
"","94.9050","20.0713","12296.6064"
"","95.1050","20.1133","12299.2188"
"","95.3050","20.1565","12301.5430"
"","95.5050","20.1984","12299.8096"
"","95.7050","20.2409","12306.1250"
"","95.9050","20.2829","12303.3057"
"","96.1050","20.3249","12297.3535"
"","96.3050","20.3674","12287.8896"
"","96.5050","20.4095","12287.6201"
"","96.7050","20.4526","12286.9209"
"","96.9050","20.4947","12285.4238"
"","97.1050","20.5374","12291.6963"
"","97.3050","20.5794","12288.1729"
"","97.5050","20.6216","12289.2949"
"","97.7050","20.6637","12280.6738"
"","97.9050","20.7057","12277.0254"
"","98.1050","20.7486","12270.9629"
"","98.3050","20.7907","12271.7705"
"","98.5050","20.8340","12275.9111"
"","98.7050","20.8758","12273.0557"
"","98.9050","20.9183","12276.1328"
"","99.1050","20.9603","12273.0195"
"","99.3050","21.0021","12267.1250"
"","99.5050","21.0444","12257.0693"
"","99.7050","21.0869","12256.6533"
"","99.9050","21.1299","12255.7549"
"","100.1050","21.1721","12253.6338"
"","100.3050","21.2145","12258.9502"
"","100.5050","21.2568","12256.6582"
"","100.7050","21.2984","12254.4912"
"","100.9050","21.3407","12245.0410"
"","101.1050","21.3830","12240.6465"
"","101.3050","21.4260","12235.4941"
"","101.5050","21.4682","12237.5908"
"","101.7050","21.5114","12240.1475"
"","101.9050","21.5533","12237.2188"
"","102.1050","21.5956","12239.6611"
"","102.3050","21.6375","12234.9395"
"","102.5050","21.6795","12230.4258"
"","102.7050","21.7218","12218.2402"
"","102.9050","21.7641","12216.4424"
"","103.1050","21.8073","12216.8574"
"","103.3050","21.8495","12217.9092"
"","103.5050","21.8919","12219.9365"
"","103.7050","21.9339","12213.3008"
"","103.9050","21.9760","12210.9297"
"","104.1050","22.0182","12204.8076"
"","104.3050","22.0605","12199.5967"
"","104.5050","22.1033","12192.1572"
"","104.7050","22.1455","12191.7402"
"","104.9050","22.1887","12194.0850"
"","105.1050","22.2304","12189.9727"
"","105.3050","22.2729","12192.9180"
"","105.5050","22.3148","12189.1807"
"","105.7050","22.3567","12179.3105"
"","105.9050","22.3993","12167.2344"
"","106.1050","22.4416","12167.3770"
"","106.3050","22.4846","12164.3301"
"","106.5050","22.5269","12163.5156"
"","106.7050","22.5694","12165.8945"
"","106.9050","22.6113","12162.7256"
"","107.1050","22.6535","12158.3740"
"","107.3050","22.6957","12148.2510"
"","107.5050","22.7378","12142.6367"
"","107.7050","22.7807","12134.2119"
"","107.9050","22.8227","12131.2969"
"","108.1050","22.8660","12135.4395"
"","108.3050","22.9078","12130.4092"
"","108.5050","22.9501","12128.7979"
"","108.7050","22.9922","12121.5908"
"","108.9050","23.0342","12115.8564"
"","109.1050","23.0765","12101.6836"
"","109.3050","23.1191","12098.6113"
"","109.5050","23.1620","12096.1680"
"","109.7050","23.2039","12091.7129"
"","109.9050","23.2467","12093.1426"
"","110.1050","23.2889","12086.9736"
"","110.3050","23.3309","12082.5820"
"","110.5050","23.3729","12070.4111"
"","110.7050","23.4151","12062.6289"
"","110.9050","23.4579","12051.4746"
"","111.1050","23.5001","12046.8350"
"","111.3050","23.5433","12048.2812"
"","111.5050","23.5853","12040.5449"
"","111.7050","23.6275","12039.6816"
"","111.9050","23.6693","12028.7646"
"","112.1050","23.7114","12020.1387"
"","112.3050","23.7540","12004.6934"
"","112.5050","23.7962","11998.5342"
"","112.7050","23.8395","11990.7080"
"","112.9050","23.8815","11985.0215"
"","113.1050","23.9243","11985.0488"
"","113.3050","23.9661","11975.5840"
"","113.5050","24.0082","11966.4873"
"","113.7050","24.0503","11953.8877"
"","113.9050","24.0925","11941.0098"
"","114.1050","24.1353","11925.4717"
"","114.3050","24.1776","11916.9873"
"","114.5050","24.2207","11916.2051"
"","114.7050","24.2623","11905.1582"
"","114.9050","24.3046","11897.0107"
"","115.1050","24.3468","11883.5020"
"","115.3050","24.3890","11872.3486"
"","115.5050","24.4314","11853.5352"
"","115.7050","24.4737","11841.2549"
"","115.9050","24.5167","11828.1172"
"","116.1050","24.5587","11816.6270"
"","116.3050","24.6014","11811.8154"
"","116.5050","24.6434","11798.4277"
"","116.7050","24.6854","11782.5273"
"","116.9050","24.7276","11760.7559"
"","117.1050","24.7699","11745.6436"
"","117.3050","24.8127","11728.5918"
"","117.5050","24.8547","11712.0732"
"","117.7050","24.8980","11705.7373"
"","117.9050","24.9399","11687.5146"
"","118.1050","24.9821","11674.8174"
"","118.3050","25.0241","11653.4131"
"","118.5050","25.0661","11633.1113"
"","118.7050","25.1086","11606.8867"
"","118.9050","25.1508","11590.9404"
"","119.1050","25.1942","11571.1182"
"","119.3050","25.2360","11553.2334"
"","119.5050","25.2789","11539.7695"
"","119.7050","25.3205","11516.7061"
"","119.9050","25.3628","11496.4795"
"","120.1050","25.4047","11469.9277"
"","120.3050","25.4471","11445.6416"
"","120.5050","25.4900","11416.9980"
"","120.7050","25.5323","11395.9795"
"","120.9050","25.5752","11378.7549"
"","121.1050","25.6172","11353.5342"
"","121.3050","25.6594","11329.0352"
"","121.5050","25.7015","11302.5635"
"","121.7050","25.7435","11273.2773"
"","121.9050","25.7861","11238.7422"
"","122.1050","25.8283","11213.9678"
"","122.3050","25.8714","11183.5986"
"","122.5050","25.9134","11155.7334"
"","122.7050","25.9560","11133.4180"
"","122.9050","25.9979","11102.2715"
"","123.1050","26.0400","11067.5811"
"","123.3050","26.0821","11028.8047"
"","123.5050","26.1243","10994.4385"
"","123.7050","26.1674","10954.5947"
"","123.9050","26.2096","10921.7822"
"","124.1050","26.2526","10890.9453"
"","124.3050","26.2946","10855.2832"
"","124.5050","26.3367","10819.6230"
"","124.7050","26.3788","10777.7324"
"","124.9050","26.4208","10734.8496"
"","125.1050","26.4633","10686.0176"
"","125.3050","26.5055","10644.5254"
"","125.5050","26.5488","10600.3047"
"","125.7050","26.5909","10558.2051"
"","125.9050","26.6336","10517.5234"
"","126.1050","26.6751","10467.9336"
"","126.3050","26.7172","10417.7100"
"","126.5050","26.7593","10358.3057"
"","126.7050","26.8018","10308.6758"
"","126.9050","26.8447","10250.3936"
"","127.1050","26.8869","10196.0498"
"","127.3050","26.9299","10143.4443"
"","127.5050","26.9720","10083.7852"
"","127.7050","27.0142","10026.4365"
"","127.9050","27.0561","9960.7314"
"","128.1050","27.0980","9890.4404"
"","128.3050","27.1407","9817.0283"
"","128.5050","27.1829","9750.2676"
"","128.7050","27.2263","9676.6201"
"","128.9050","27.2680","9600.9336"
"","129.1050","27.3107","9530.6592"
"","129.3050","27.3527","9449.0869"
"","129.5050","27.3947","9365.0293"
"","129.7050","27.4369","9269.7832"
"","129.9050","27.4791","9178.3633"
"","130.1050","27.5221","9076.5645"
"","130.3050","27.5642","8979.3750"
"","130.5050","27.6073","8877.7158"
"","130.7050","27.6492","8766.1182"
"","130.9050","27.6914","8651.5615"
"","131.1050","27.7334","8527.3252"
"","131.3050","27.7754","8395.3945"
"","131.5050","27.8179","8247.1934"
"","131.7050","27.8602","8098.8311"
"","131.9050","27.9035","7936.8823"
"","132.1050","27.9456","7765.2588"
"","132.3050","27.9882","7579.2314"
"","132.5050","28.0302","7370.1240"
"","132.7050","28.0720","7074.4956"
"","132.7740","28.0875","6559.5239"
"","132.8120","28.0957","6048.8701"
"","132.8680","28.1070","5542.0049"
"","132.9280","28.1196","5039.3716"
"","133.0100","28.1371","4532.9546"
"","133.1550","28.1674","4028.6516"
"","133.3540","28.2096","3542.8584"
"","133.5540","28.2518","3115.7610"
"","133.7540","28.2948","2645.5518"
"","133.9540","28.3367","2257.8169"
"","134.1540","28.3795","1817.0148"
"","134.3540","28.4215","1491.9091"
"","134.5540","28.4636","1121.9398"
"","134.7540","28.5058","814.6357"
"","134.9410","28.5451","385.1432"
"","135.0920","28.5784","29.5388"
"","135.2920","28.6200","-11.4316"
"","135.4920","28.6624","-11.5527"
"","135.6920","28.7044","-11.0829"
"","135.8920","28.7466","-11.0193"
"","136.0920","28.7889","-10.9003"
"","136.2920","28.8311","-10.7219"
"","136.4920","28.8744","-10.8881"
"","136.6920","28.9162","-10.6449"
"","136.8920","28.9589","-10.3727"
"","137.0920","29.0010","-10.4372"
"","137.2920","29.0432","-10.7520"
"","137.4920","29.0853","-10.5990"
"","137.6920","29.1273","-10.1514"
"","137.8920","29.1700","-10.1814"
"","138.0920","29.2123","-10.3759"
"","138.2920","29.2552","-10.3928"
"","138.4920","29.2974","-10.3513"
"","138.6920","29.3398","-9.9866"
"","138.8920","29.3820","-10.0451"
"","139.0920","29.4236","-10.0888"
"","139.2920","29.4661","-9.9180"
"","139.4920","29.5082","-9.9608"
"","139.6920","29.5517","-9.8337"
"","139.8920","29.5937","-9.8094"
"","140.0920","29.6366","-10.1304"
"","140.2920","29.6784","-9.7229"
"","140.4920","29.7204","-9.6472"
"","140.6920","29.7624","-9.7083"
"","140.8920","29.8046","-9.9902"
"","141.0920","29.8474","-9.6398"
"","141.2920","29.8898","-9.8113"
"","141.4920","29.9330","-9.6601"
"","141.6920","29.9747","-9.8104"
"","141.8920","30.0171","-9.7316"
"","142.0920","30.0591","-9.8286"
"","142.2920","30.1010","-9.5722"
"","142.4920","30.1435","-9.8744"
"","142.6920","30.1857","-9.5644"
"","142.8920","30.2290","-9.5163"
"","143.0920","30.2709","-9.3619"
"","143.2920","30.3137","-9.7825"
"","143.4920","30.3557","-9.5775"
"","143.5760","30.3731","-9.4054"
2,Time,Displacement,Force
,(s),(mm),(N)
"","0.0000","0.0000","124.0740"
"","0.1000","0.0047","151.8590"
"","0.2000","0.0188","172.5312"
"","0.3000","0.0478","224.4474"
"","0.4000","0.0683","302.1273"
"","0.5000","0.0894","458.2172"
"","0.5720","0.1052","712.2818"
"","0.6270","0.1171","965.8426"
"","0.6810","0.1277","1216.2631"
"","0.7490","0.1422","1467.6643"
"","0.8190","0.1574","1719.7551"
"","0.9020","0.1742","1971.6605"
"","0.9770","0.1904","2224.0923"
"","1.0520","0.2070","2476.4731"
"","1.1380","0.2245","2726.6057"
"","1.2170","0.2413","2979.2112"
"","1.3020","0.2592","3230.3650"
"","1.3900","0.2774","3481.1165"
"","1.4730","0.2957","3733.8032"
"","1.5670","0.3155","3984.0593"
"","1.6570","0.3344","4234.2983"
"","1.7500","0.3544","4484.6074"
"","1.8500","0.3748","4737.1050"
"","1.9400","0.3946","4987.6992"
"","2.0400","0.4155","5225.0078"
"","2.1360","0.4360","5476.8574"
"","2.2360","0.4569","5706.8145"
"","2.3360","0.4778","5950.7559"
"","2.4360","0.4999","6196.5273"
"","2.5360","0.5199","6398.2749"
"","2.6360","0.5417","6640.9438"
"","2.7360","0.5623","6842.6133"
"","2.8360","0.5839","7071.1167"
"","2.9360","0.6054","7267.2671"
"","3.0360","0.6261","7467.2622"
"","3.1360","0.6475","7655.0337"
"","3.2360","0.6680","7827.6182"
"","3.3360","0.6905","8014.8647"
"","3.4360","0.7107","8136.8276"
"","3.5360","0.7324","8291.6572"
"","3.6360","0.7529","8395.4619"
"","3.7360","0.7744","8524.5273"
"","3.8360","0.7962","8614.6953"
"","3.9360","0.8165","8692.8379"
"","4.0360","0.8382","8770.4043"
"","4.1360","0.8586","8826.6152"
"","4.2360","0.8808","8898.9404"
"","4.3360","0.9015","8919.9639"
"","4.4360","0.9227","8977.9160"
"","4.5360","0.9437","9000.9814"
"","4.6360","0.9649","9043.3027"
"","4.7360","0.9868","9068.6406"
"","4.8360","1.0070","9085.6582"
"","4.9360","1.0288","9118.4238"
"","5.0360","1.0492","9127.5898"
"","5.1360","1.0712","9167.5762"
"","5.2360","1.0919","9160.5586"
"","5.3360","1.1131","9200.2705"
"","5.4360","1.1343","9203.0723"
"","5.5360","1.1552","9229.2383"
"","5.6360","1.1773","9251.6719"
"","5.7360","1.1975","9249.3271"
"","5.8360","1.2195","9284.7451"
"","5.9360","1.2398","9282.2461"
"","6.0360","1.2613","9311.4072"
"","6.1360","1.2827","9316.7383"
"","6.2360","1.3035","9337.8369"
"","6.3360","1.3250","9348.4248"
"","6.4360","1.3454","9360.0742"
"","6.5360","1.3678","9395.7197"
"","6.6360","1.3879","9381.8721"
"","6.7360","1.4097","9418.2949"
"","6.8360","1.4304","9418.0938"
"","6.9360","1.4517","9448.3447"
"","7.0360","1.4735","9452.9805"
"","7.1360","1.4939","9463.9707"
"","7.2360","1.5156","9481.6387"
"","7.3360","1.5360","9489.4688"
"","7.4360","1.5582","9519.9824"
"","7.5360","1.5788","9510.6992"
"","7.6360","1.6002","9546.5234"
"","7.7360","1.6210","9544.7461"
"","7.8360","1.6421","9571.3350"
"","7.9360","1.6643","9584.4512"
"","8.0360","1.6842","9584.0176"
"","8.1360","1.7061","9610.9346"
"","8.2360","1.7265","9613.1582"
"","8.3360","1.7484","9643.3584"
"","8.4360","1.7695","9636.5605"
"","8.5360","1.7904","9667.2412"
"","8.6360","1.8118","9668.9521"
"","8.7360","1.8324","9689.3359"
"","8.8360","1.8547","9708.5293"
"","8.9360","1.8748","9704.4092"
"","9.0360","1.8965","9733.5469"
"","9.1360","1.9170","9730.0830"
"","9.2360","1.9388","9761.7148"
"","9.3360","1.9602","9759.0791"
"","9.4360","1.9808","9783.2939"
"","9.5360","2.0022","9789.1279"
"","9.6360","2.0229","9804.5596"
"","9.7360","2.0451","9826.9150"
"","9.8360","2.0653","9816.1309"
"","9.9360","2.0871","9850.0850"
"","10.0360","2.1077","9845.5078"
"","10.1360","2.1292","9874.0645"
"","10.2360","2.1509","9877.0586"
"","10.3360","2.1713","9890.4209"
"","10.4360","2.1929","9904.8984"
"","10.5360","2.2134","9913.5781"
"","10.6360","2.2356","9937.7520"
"","10.7360","2.2562","9928.3311"
"","10.8360","2.2773","9956.5664"
"","10.9360","2.2983","9956.7725"
"","11.0360","2.3195","9981.4619"
"","11.1360","2.3414","9989.4854"
"","11.2360","2.3615","9993.9404"
"","11.3360","2.3835","10016.0137"
"","11.4360","2.4039","10017.2656"
"","11.5360","2.4257","10044.5771"
"","11.6360","2.4468","10035.3467"
"","11.7360","2.4676","10065.1846"
"","11.8360","2.4891","10063.6279"
"","11.9360","2.5098","10082.8115"
"","12.0360","2.5320","10097.7412"
"","12.1360","2.5521","10092.6104"
"","12.2360","2.5740","10119.8574"
"","12.3360","2.5945","10117.2549"
"","12.4360","2.6161","10146.3438"
"","12.5360","2.6372","10138.8018"
"","12.6360","2.6582","10163.9482"
"","12.7360","2.6796","10166.9922"
"","12.8360","2.7002","10181.0811"
"","12.9360","2.7222","10198.7920"
"","13.0360","2.7429","10193.4248"
"","13.1360","2.7645","10219.6914"
"","13.2360","2.7851","10215.8047"
"","13.3360","2.8064","10239.5469"
"","13.4360","2.8283","10243.2217"
"","13.5360","2.8486","10252.6025"
"","13.6360","2.8701","10264.9014"
"","13.7360","2.8907","10274.1982"
"","13.8360","2.9127","10296.4219"
"","13.9360","2.9336","10286.7100"
"","14.0360","2.9547","10313.3213"
"","14.1360","2.9756","10311.4795"
"","14.2360","2.9968","10333.2344"
"","14.3360","3.0189","10341.7627"
"","14.4360","3.0390","10342.1367"
"","14.5360","3.0607","10362.9785"
"","14.6360","3.0812","10361.9023"
"","14.7360","3.1031","10387.8799"
"","14.8360","3.1242","10378.4229"
"","14.9360","3.1450","10402.1836"
"","15.0360","3.1664","10403.7080"
"","15.1360","3.1871","10418.2139"
"","15.2360","3.2094","10436.4209"
"","15.3360","3.2294","10428.0166"
"","15.4360","3.2511","10451.3301"
"","15.5360","3.2719","10452.7305"
"","15.6360","3.2934","10472.2344"
"","15.7360","3.3149","10471.5352"
"","15.8360","3.3355","10486.7617"
"","15.9360","3.3571","10492.9473"
"","16.0360","3.3776","10501.4121"
"","16.1360","3.3998","10521.5439"
"","16.2360","3.4201","10512.5938"
"","16.3360","3.4416","10539.0625"
"","16.4360","3.4624","10534.0254"
"","16.5360","3.4837","10556.7354"
"","16.6360","3.5054","10559.5898"
"","16.7360","3.5258","10565.6504"
"","16.8360","3.5476","10578.3145"
"","16.9360","3.5680","10584.4561"
"","17.0360","3.5901","10606.7578"
"","17.1360","3.6108","10596.6709"
"","17.2360","3.6322","10621.0996"
"","17.3360","3.6530","10613.3242"
"","17.4360","3.6741","10636.2109"
"","17.5360","3.6961","10639.1396"
"","17.6360","3.7162","10641.3857"
"","17.7360","3.7381","10660.5996"
"","17.8360","3.7585","10664.5586"
"","17.9360","3.7803","10683.6680"
"","18.0360","3.8015","10679.0234"
"","18.1360","3.8224","10695.4619"
"","18.2360","3.8434","10695.9990"
"","18.3360","3.8645","10711.4590"
"","18.4360","3.8867","10722.3652"
"","18.5360","3.9070","10717.5264"
"","18.6360","3.9287","10739.1338"
"","18.7360","3.9493","10738.1855"
"","18.8360","3.9709","10759.0352"
"","18.9360","3.9922","10752.0039"
"","19.0360","4.0127","10770.5918"
"","19.1360","4.0343","10775.2051"
"","19.2360","4.0548","10781.4258"
"","19.3360","4.0769","10798.6748"
"","19.4360","4.0973","10791.7051"
"","19.5360","4.1188","10814.3945"
"","19.6360","4.1397","10811.5156"
"","19.7360","4.1612","10832.6064"
"","19.8360","4.1830","10833.9961"
"","19.9360","4.2032","10837.9160"
"","20.0360","4.2250","10848.8057"
"","20.1360","4.2452","10850.3926"
"","20.2360","4.2675","10873.7754"
"","20.3360","4.2883","10860.9600"
"","20.4360","4.3093","10884.8525"
"","20.5360","4.3303","10882.7490"
"","20.6360","4.3513","10898.8975"
"","20.7360","4.3734","10907.6523"
"","20.8360","4.3935","10904.3242"
"","20.9360","4.4154","10920.6680"
"","21.0360","4.4359","10921.6592"
"","21.1360","4.4577","10940.6709"
"","21.2360","4.4791","10932.9961"
"","21.3360","4.4999","10950.7344"
"","21.4360","4.5211","10953.8037"
"","21.5360","4.5420","10962.9170"
"","21.6360","4.5639","10976.7754"
"","21.7360","4.5842","10967.4795"
"","21.8360","4.6059","10992.5967"
"","21.9360","4.6265","10985.5576"
"","22.0360","4.6481","11007.1543"
"","22.1360","4.6694","11000.2188"
"","22.2360","4.6899","11014.9229"
"","22.3360","4.7116","11019.3291"
"","22.4360","4.7322","11025.6396"
"","22.5360","4.7544","11043.9580"
"","22.6360","4.7749","11032.1143"
"","22.7360","4.7964","11057.0469"
"","22.8360","4.8172","11049.7119"
"","22.9360","4.8383","11068.7676"
"","23.0360","4.8601","11068.4697"
"","23.1360","4.8804","11074.0195"
"","23.2360","4.9022","11084.5547"
"","23.3360","4.9225","11087.6289"
"","23.4360","4.9447","11108.8906"
"","23.5360","4.9655","11093.5996"
"","23.6360","4.9867","11118.1904"
"","23.7360","5.0077","11111.5527"
"","23.8360","5.0286","11127.0684"
"","23.9360","5.0510","11135.6484"
"","24.0360","5.0711","11129.6465"
"","24.1360","5.0927","11147.0576"
"","24.2360","5.1133","11147.1611"
"","24.3360","5.1351","11167.4707"
"","24.4360","5.1562","11156.9785"
"","24.5360","5.1771","11176.1328"
"","24.6360","5.1982","11171.6836"
"","24.7360","5.2191","11183.1865"
"","24.8360","5.2414","11196.3369"
"","24.9360","5.2615","11184.5654"
"","25.0360","5.2832","11208.9131"
"","25.1360","5.3039","11203.2012"
"","25.2360","5.3255","11223.1768"
"","25.3360","5.3471","11217.2852"
"","25.4360","5.3672","11227.1660"
"","25.5360","5.3890","11233.8174"
"","25.6360","5.4095","11237.2363"
"","25.7360","5.4318","11254.3281"
"","25.8360","5.4517","11238.7861"
"","25.9360","5.4736","11267.7236"
"","26.0360","5.4943","11257.0684"
"","26.1360","5.5156","11275.7012"
"","26.2360","5.5376","11276.2197"
"","26.3360","5.5578","11278.7773"
"","26.4360","5.5796","11290.7383"
"","26.5360","5.6001","11289.2471"
"","26.6360","5.6221","11308.8906"
"","26.7360","5.6430","11297.3730"
"","26.8360","5.6642","11318.3975"
"","26.9360","5.6852","11313.1611"
"","27.0360","5.7061","11326.5303"
"","27.1360","5.7282","11333.3301"
"","27.2360","5.7483","11327.9883"
"","27.3360","5.7702","11343.2227"
"","27.4360","5.7905","11340.3145"
"","27.5360","5.8123","11361.4961"
"","27.6360","5.8336","11352.0723"
"","27.7360","5.8544","11368.5752"
"","27.8360","5.8756","11362.3584"
"","27.9360","5.8964","11375.7910"
"","28.0360","5.9186","11383.2725"
"","28.1360","5.9390","11378.3623"
"","28.2360","5.9607","11396.9893"
"","28.3360","5.9811","11390.9717"
"","28.4360","6.0027","11412.8125"
"","28.5360","6.0242","11403.4678"
"","28.6360","6.0445","11411.5938"
"","28.7360","6.0661","11413.6494"
"","28.8360","6.0867","11421.0088"
"","28.9360","6.1090","11437.0879"
"","29.0360","6.1296","11424.0889"
"","29.1360","6.1512","11449.3018"
"","29.2360","6.1717","11440.8115"
"","29.3360","6.1931","11457.2783"
"","29.4360","6.2150","11455.7959"
"","29.5360","6.2351","11455.4248"
"","29.6360","6.2569","11464.8398"
"","29.7360","6.2773","11463.9609"
"","29.8360","6.2995","11484.2773"
"","29.9360","6.3203","11473.3936"
"","30.0360","6.3414","11494.2168"
"","30.1360","6.3625","11486.8457"
"","30.2360","6.3833","11498.6260"
"","30.3360","6.4055","11506.3076"
"","30.4360","6.4257","11498.7725"
"","30.5360","6.4474","11511.3555"
"","30.6360","6.4678","11511.2002"
"","30.7360","6.4897","11529.7412"
"","30.8360","6.5110","11518.6084"
"","30.9360","6.5318","11536.4883"
"","31.0360","6.5530","11529.4932"
"","31.1360","6.5737","11543.4404"
"","31.2360","6.5960","11550.8945"
"","31.3360","6.6162","11539.0420"
"","31.4360","6.6379","11558.3086"
"","31.5360","6.6585","11553.2178"
"","31.6360","6.6802","11571.9346"
"","31.7360","6.7017","11565.5781"
"","31.8360","6.7220","11574.5000"
"","31.9360","6.7434","11577.6445"
"","32.0360","6.7641","11580.4102"
"","32.1360","6.7864","11594.7441"
"","32.2360","6.8070","11581.6484"
"","32.3360","6.8281","11603.3789"
"","32.4360","6.8493","11595.6426"
"","32.5360","6.8704","11610.6172"
"","32.6360","6.8924","11611.9580"
"","32.7360","6.9125","11609.9639"
"","32.8360","6.9343","11619.5391"
"","32.9360","6.9549","11619.9541"
"","33.0360","6.9767","11636.8467"
"","33.1360","6.9976","11622.6260"
"","33.2360","7.0187","11643.3086"
"","33.3360","7.0398","11634.2764"
"","33.4360","7.0607","11647.8857"
"","33.5360","7.0828","11652.1387"
"","33.6360","7.1030","11646.2881"
"","33.7360","7.1249","11662.2773"
"","33.8360","7.1452","11655.8818"
"","33.9360","7.1671","11676.2256"
"","34.0360","7.1882","11662.9658"
"","34.1360","7.2091","11680.5361"
"","34.2360","7.2303","11674.2041"
"","34.3360","7.2510","11683.9307"
"","34.4360","7.2734","11692.7500"
"","34.5360","7.2934","11681.7256"
"","34.6360","7.3154","11701.1514"
"","34.7360","7.3357","11694.2998"
"","34.8360","7.3573","11711.0264"
"","34.9360","7.3791","11706.2998"
"","35.0360","7.3995","11711.1650"
"","35.1360","7.4209","11712.3193"
"","35.2360","7.4414","11717.3232"
"","35.3360","7.4637","11730.5781"
"","35.4360","7.4843","11717.9219"
"","35.5360","7.5057","11737.6338"
"","35.6360","7.5264","11729.6133"
"","35.7360","7.5477","11746.3467"
"","35.8360","7.5696","11743.5361"
"","35.9360","7.5897","11743.5205"
"","36.0360","7.6116","11752.1543"
"","36.1360","7.6321","11749.2012"
"","36.2360","7.6540","11765.1123"
"","36.3360","7.6750","11753.2500"
"","36.4360","7.6961","11771.5361"
"","36.5360","7.7171","11766.1064"
"","36.6360","7.7382","11777.3438"
"","36.7360","7.7601","11780.0928"
"","36.8360","7.7803","11773.5137"
"","36.9360","7.8020","11786.3047"
"","37.0360","7.8224","11782.4326"
"","37.1360","7.8442","11799.0303"
"","37.2360","7.8657","11790.9219"
"","37.3360","7.8862","11800.7471"
"","37.4360","7.9077","11800.7363"
"","37.5360","7.9282","11805.4922"
"","37.6360","7.9506","11817.0186"
"","37.7360","7.9710","11803.2393"
"","37.8360","7.9926","11822.2314"
"","37.9360","8.0133","11813.2803"
"","38.0360","8.0347","11830.9355"
"","38.1360","8.0566","11825.2480"
"","38.2360","8.0768","11830.3438"
"","38.3360","8.0982","11831.0078"
"","38.4360","8.1188","11836.0059"
"","38.5360","8.1410","11848.6191"
"","38.6360","8.1616","11833.7354"
"","38.7360","8.1827","11850.1699"
"","38.8360","8.2039","11848.0215"
"","38.9360","8.2249","11858.6953"
"","39.0360","8.2470","11858.9434"
"","39.1360","8.2672","11856.3594"
"","39.2360","8.2889","11864.5430"
[...]
"","37.5430","7.9286","12394.8994"
"","37.6430","7.9491","12404.4453"
"","37.7430","7.9706","12397.3701"
"","37.8430","7.9912","12400.6934"
"","37.9430","8.0134","12406.5723"
"","38.0430","8.0337","12390.5361"
"","38.1430","8.0554","12404.9258"
"","38.2430","8.0760","12393.6602"
"","38.3430","8.0974","12406.6104"
"","38.4430","8.1194","12398.7188"
"","38.5430","8.1397","12399.3477"
"","38.6430","8.1614","12398.7842"
"","38.7430","8.1816","12395.5312"
"","38.8430","8.2040","12406.9053"
"","38.9430","8.2244","12389.4434"
"","39.0430","8.2458","12402.2461"
"","39.1430","8.2667","12393.6992"
"","39.2430","8.2877","12401.6904"
"","39.3430","8.3100","12400.2246"
"","39.4430","8.3299","12392.9844"
"","39.5430","8.3518","12400.9658"
"","39.6430","8.3723","12393.7842"
"","39.7430","8.3943","12403.0508"
"","39.8430","8.4152","12388.9980"
"","39.9430","8.4361","12400.6670"
"","40.0430","8.4573","12391.3945"
"","40.1430","8.4781","12399.5850"
"","40.2430","8.5005","12399.3975"
"","40.3430","8.5204","12388.2529"
"","40.4430","8.5423","12398.6426"
"","40.5430","8.5628","12390.3359"
"","40.6430","8.5844","12400.3184"
"","40.7430","8.6058","12389.9053"
"","40.8430","8.6266","12397.2256"
"","40.9430","8.6479","12389.6436"
"","41.0430","8.6686","12393.3916"
"","41.1430","8.6907","12398.9912"
"","41.2430","8.7112","12385.9453"
"","41.3430","8.7328","12396.6123"
"","41.4430","8.7534","12386.8291"
"","41.5430","8.7749","12397.5684"
"","41.6430","8.7966","12388.7744"
"","41.7430","8.8168","12390.5908"
"","41.8430","8.8388","12392.0742"
"","41.9430","8.8588","12387.5264"
"","42.0430","8.8811","12397.2812"
"","42.1430","8.9020","12381.5137"
"","42.2430","8.9232","12393.2812"
"","42.3430","8.9440","12384.1445"
"","42.4430","8.9652","12392.2178"
"","42.5430","8.9874","12390.2207"
"","42.6430","9.0075","12383.9424"
"","42.7430","9.0290","12388.1631"
"","42.8430","9.0495","12383.0361"
"","42.9430","9.0715","12393.5107"
"","43.0430","9.0926","12378.4980"
"","43.1430","9.1133","12387.4463"
"","43.2430","9.1347","12383.5762"
"","43.3430","9.1556","12387.3018"
"","43.4430","9.1776","12389.4268"
"","43.5430","9.1977","12376.9658"
"","43.6430","9.2195","12386.4336"
"","43.7430","9.2402","12378.5020"
"","43.8430","9.2618","12385.4707"
"","43.9430","9.2833","12378.5488"
"","44.0430","9.3040","12383.5703"
"","44.1430","9.3254","12380.9834"
"","44.2430","9.3459","12380.9365"
"","44.3430","9.3682","12386.7520"
"","44.4430","9.3885","12372.5537"
"","44.5430","9.4100","12382.4375"
"","44.6430","9.4307","12372.6729"
"","44.7430","9.4520","12381.2119"
"","44.8430","9.4739","12376.6338"
"","44.9430","9.4942","12375.0742"
"","45.0430","9.5160","12375.9092"
"","45.1430","9.5364","12373.2676"
"","45.2430","9.5586","12383.8301"
"","45.3430","9.5792","12365.0723"
"","45.4430","9.6005","12379.5215"
"","45.5430","9.6213","12365.8848"
"","45.6430","9.6425","12375.7256"
"","45.7430","9.6645","12373.7764"
"","45.8430","9.6847","12366.6367"
"","45.9430","9.7064","12373.7158"
"","46.0430","9.7268","12368.3721"
"","46.1430","9.7488","12376.7549"
"","46.2430","9.7697","12361.9385"
"","46.3430","9.7906","12370.3164"
"","46.4430","9.8119","12362.3076"
"","46.5430","9.8328","12368.0371"
"","46.6430","9.8550","12370.4531"
"","46.7430","9.8754","12360.4072"
"","46.8430","9.8971","12369.7510"
"","46.9430","9.9175","12360.8750"
"","47.0430","9.9391","12369.2744"
"","47.1430","9.9606","12358.8350"
"","47.2430","9.9812","12364.1934"
"","47.3430","10.0026","12358.3643"
"","47.4430","10.0233","12360.3018"
"","47.5430","10.0454","12364.5742"
"","47.6430","10.0659","12351.4639"
"","47.6800","10.0735","12356.2412"
4,Time,Displacement,Force
,(s),(mm),(N)
"","0.0000","0.0000","40.3766"
"","0.1000","0.0036","40.6731"
"","0.2000","0.0168","41.1484"
"","0.3000","0.0462","41.7676"
"","0.4000","0.0670","42.5046"
"","0.5000","0.0879","43.6832"
"","0.6000","0.1092","44.5928"
"","0.7000","0.1302","50.4129"
"","0.8000","0.1515","59.7459"
"","0.9000","0.1732","177.5233"
"","0.9760","0.1885","428.1584"
"","1.0450","0.2032","680.4917"
"","1.1310","0.2215","932.0881"
"","1.2180","0.2393","1183.8243"
"","1.2990","0.2574","1435.6587"
"","1.3970","0.2779","1687.3665"
"","1.4940","0.2981","1938.2285"
"","1.5940","0.3194","2189.1140"
"","1.6940","0.3401","2436.3162"
"","1.7910","0.3617","2687.3010"
"","1.8910","0.3820","2910.5635"
"","1.9910","0.4036","3161.1067"
"","2.0910","0.4243","3384.7749"
"","2.1910","0.4457","3624.8042"
"","2.2910","0.4675","3854.1174"
"","2.3910","0.4878","4069.2839"
"","2.4910","0.5094","4296.9810"
"","2.5910","0.5300","4512.1851"
"","2.6910","0.5521","4748.8955"
"","2.7910","0.5727","4953.5054"
"","2.8910","0.5939","5180.6680"
"","2.9910","0.6148","5390.8530"
"","3.0910","0.6360","5618.1533"
"","3.1910","0.6580","5844.2202"
"","3.2910","0.6782","6050.4878"
"","3.3910","0.6999","6282.2378"
"","3.4910","0.7204","6489.6152"
"","3.5910","0.7425","6724.7769"
"","3.6910","0.7634","6915.0640"
"","3.7910","0.7845","7122.3931"
"","3.8910","0.8054","7314.2588"
"","3.9910","0.8264","7518.8770"
"","4.0910","0.8485","7730.4893"
"","4.1910","0.8687","7911.9473"
"","4.2910","0.8906","8119.4297"
"","4.3910","0.9111","8296.6123"
"","4.4910","0.9329","8500.3379"
"","4.5910","0.9540","8682.4453"
"","4.6910","0.9749","8873.7871"
"","4.7910","0.9962","9063.5928"
"","4.8910","1.0168","9250.1719"
"","4.9910","1.0391","9462.9033"
"","5.0910","1.0595","9631.8232"
"","5.1910","1.0810","9839.0703"
"","5.2910","1.1017","10019.6084"
"","5.3910","1.1229","10218.0967"
"","5.4910","1.1449","10414.0283"
"","5.5910","1.1651","10586.6553"
"","5.6910","1.1867","10778.3389"
"","5.7910","1.2072","10949.4180"
"","5.8910","1.2294","11141.7529"
"","5.9910","1.2502","11292.1406"
"","6.0910","1.2713","11460.4102"
"","6.1910","1.2919","11594.9688"
"","6.2910","1.3133","11742.9072"
"","6.3910","1.3355","11870.9551"
"","6.4910","1.3557","11967.3271"
"","6.5910","1.3771","12066.3682"
"","6.6910","1.3979","12146.4648"
"","6.7910","1.4199","12225.7334"
"","6.8910","1.4408","12267.8389"
"","6.9910","1.4618","12318.5244"
"","7.0910","1.4829","12344.0566"
"","7.1910","1.5040","12370.9570"
"","7.2910","1.5260","12383.8213"
"","7.3910","1.5462","12380.3184"
"","7.4910","1.5678","12392.2676"
"","7.5910","1.5886","12386.6846"
"","7.6910","1.6101","12395.4160"
"","7.7910","1.6316","12384.8164"
"","7.8910","1.6522","12390.6963"
"","7.9910","1.6737","12385.9746"
"","8.0910","1.6943","12386.5586"
"","8.1910","1.7164","12394.2832"
"","8.2910","1.7367","12378.1455"
"","8.3910","1.7584","12392.1533"
"","8.4910","1.7790","12380.2539"
"","8.5910","1.8003","12390.0762"
"","8.6910","1.8223","12385.6904"
"","8.7910","1.8425","12382.2227"
"","8.8910","1.8641","12385.1533"
"","8.9910","1.8846","12382.9414"
"","9.0910","1.9068","12392.3545"
"","9.1910","1.9274","12378.9688"
"","9.2910","1.9488","12391.1943"
"","9.3910","1.9696","12381.1611"
"","9.4910","1.9908","12390.0820"
"","9.5910","2.0128","12387.2588"
"","9.6910","2.0330","12381.4395"
"","9.7910","2.0547","12386.3867"
"","9.8910","2.0751","12383.7852"
"","9.9910","2.0970","12395.2666"
"","10.0910","2.1182","12380.9932"
"","10.1910","2.1392","12392.3340"
"","10.2910","2.1602","12383.6768"
"","10.3910","2.1811","12389.0273"
"","10.4910","2.2034","12392.9541"
"","10.5910","2.2235","12379.9141"
"","10.6910","2.2453","12393.1992"
"","10.7910","2.2658","12384.0547"
"","10.8910","2.2877","12397.0771"
"","10.9910","2.3089","12382.1680"
"","11.0910","2.3294","12391.5879"
"","11.1910","2.3509","12385.0615"
"","11.2910","2.3714","12386.7676"
"","11.3910","2.3937","12396.1270"
"","11.4910","2.4141","12379.9707"
"","11.5910","2.4356","12394.4287"
"","11.6910","2.4563","12383.8770"
"","11.7910","2.4777","12393.6562"
"","11.8910","2.4996","12389.7676"
"","11.9910","2.5199","12387.0996"
"","12.0910","2.5416","12388.0166"
"","12.1910","2.5620","12385.5977"
"","12.2910","2.5841","12396.8076"
"","12.3910","2.6050","12382.3906"
"","12.4910","2.6261","12392.9131"
"","12.5910","2.6471","12382.6514"
"","12.6910","2.6678","12390.7100"
"","12.7910","2.6901","12391.2256"
"","12.8910","2.7102","12382.1055"
"","12.9910","2.7320","12388.2236"
"","13.0910","2.7525","12384.2617"
"","13.1910","2.7747","12394.9287"
"","13.2910","2.7956","12379.3555"
"","13.3910","2.8165","12391.6133"
"","13.4910","2.8377","12381.8164"
"","13.5910","2.8585","12387.0312"
"","13.6910","2.8808","12387.8018"
"","13.7910","2.9007","12376.7041"
"","13.8910","2.9226","12386.5107"
"","13.9910","2.9430","12378.8252"
"","14.0910","2.9647","12390.7275"
"","14.1910","2.9862","12377.9453"
"","14.2910","3.0068","12385.2402"
"","14.3910","3.0282","12376.0449"
"","14.4910","3.0489","12381.2744"
"","14.5910","3.0710","12385.0439"
"","14.6910","3.0915","12375.0273"
"","14.7910","3.1132","12384.4336"
"","14.8910","3.1337","12374.3223"
"","14.9910","3.1551","12384.6289"
"","15.0910","3.1768","12375.3662"
"","15.1910","3.1973","12374.8086"
"","15.2910","3.2187","12373.6465"
"","15.3910","3.2394","12374.2793"
"","15.4910","3.2615","12380.9512"
"","15.5910","3.2821","12366.0557"
"","15.6910","3.3035","12380.0420"
"","15.7910","3.3243","12366.5205"
"","15.8910","3.3453","12375.5156"
"","15.9910","3.3677","12373.3584"
"","16.0910","3.3877","12364.1885"
"","16.1910","3.4095","12369.4990"
"","16.2910","3.4298","12363.2275"
"","16.3910","3.4518","12373.8486"
"","16.4910","3.4730","12360.6943"
"","16.5910","3.4938","12369.6777"
"","16.6910","3.5148","12360.0664"
"","16.7910","3.5357","12365.2705"
"","16.8910","3.5580","12366.1777"
"","16.9910","3.5781","12353.8672"
"","17.0910","3.5999","12362.7725"
"","17.1910","3.6205","12354.3184"
"","17.2910","3.6423","12364.7656"
"","17.3910","3.6636","12352.2373"
"","17.4910","3.6840","12359.2920"
"","17.5910","3.7056","12352.5098"
"","17.6910","3.7262","12352.7324"
"","17.7910","3.7483","12356.8740"
"","17.8910","3.7688","12343.3975"
"","17.9910","3.7904","12352.8281"
"","18.0910","3.8109","12343.2510"
"","18.1910","3.8324","12353.7119"
"","18.2910","3.8540","12343.9404"
"","18.3910","3.8746","12345.2695"
"","18.4910","3.8963","12342.9814"
"","18.5910","3.9168","12339.3438"
"","18.6910","3.9388","12347.0566"
"","18.7910","3.9596","12331.2178"
"","18.8910","3.9810","12342.9316"
"","18.9910","4.0018","12330.5947"
"","19.0910","4.0226","12336.8135"
"","19.1910","4.0448","12334.6934"
"","19.2910","4.0649","12326.6328"
"","19.3910","4.0867","12330.7197"
"","19.4910","4.1069","12322.3359"
"","19.5910","4.1291","12337.1631"
"","19.6910","4.1502","12318.0225"
"","19.7910","4.1711","12328.4238"
"","19.8910","4.1923","12315.8477"
"","19.9910","4.2130","12321.3135"
"","20.0910","4.2354","12322.8867"
"","20.1910","4.2555","12308.4668"
"","20.2910","4.2772","12317.8516"
"","20.3910","4.2977","12309.0771"
"","20.4910","4.3195","12318.6592"
"","20.5910","4.3409","12305.0557"
"","20.6910","4.3615","12309.0293"
"","20.7910","4.3829","12302.0137"
"","20.8910","4.4034","12301.5811"
"","20.9910","4.4257","12306.8711"
"","21.0910","4.4461","12290.0605"
"","21.1910","4.4677","12302.1875"
"","21.2910","4.4884","12290.7441"
"","21.3910","4.5098","12298.7266"
"","21.4910","4.5317","12287.8447"
"","21.5910","4.5520","12287.2383"
"","21.6910","4.5736","12282.6699"
"","21.7910","4.5940","12280.3613"
"","21.8910","4.6162","12286.2393"
"","21.9910","4.6369","12270.1045"
"","22.0910","4.6581","12282.4189"
"","22.1910","4.6790","12268.3262"
"","22.2910","4.7000","12275.0664"
"","22.3910","4.7221","12270.4033"
"","22.4910","4.7422","12261.5088"
"","22.5910","4.7640","12264.9600"
"","22.6910","4.7845","12256.6973"
"","22.7910","4.8064","12263.1113"
"","22.8910","4.8275","12249.6689"
"","22.9910","4.8485","12255.4082"
"","23.0910","4.8695","12244.6963"
"","23.1910","4.8904","12247.8467"
"","23.2910","4.9126","12247.9785"
"","23.3910","4.9328","12231.9453"
"","23.4910","4.9545","12240.4795"
"","23.5910","4.9751","12230.7676"
"","23.6910","4.9967","12236.1406"
"","23.7910","5.0183","12224.7529"
"","23.8910","5.0387","12225.1436"
"","23.9910","5.0603","12218.7178"
"","24.0910","5.0810","12216.1562"
"","24.1910","5.1031","12218.9033"
"","24.2910","5.1235","12202.7920"
"","24.3910","5.1452","12210.9629"
"","24.4910","5.1658","12196.9756"
"","24.5910","5.1870","12205.1953"
"","24.6910","5.2089","12192.7549"
"","24.7910","5.2291","12190.5479"
"","24.8910","5.2510","12187.1328"
"","24.9910","5.2714","12180.1982"
"","25.0910","5.2933","12185.1826"
"","25.1910","5.3142","12167.5439"
"","25.2910","5.3355","12176.8369"
"","25.3910","5.3564","12160.3799"
"","25.4910","5.3773","12164.4209"
"","25.5910","5.3993","12159.8223"
"","25.6910","5.4196","12147.1104"
"","25.7910","5.4414","12148.4678"
"","25.8910","5.4619","12138.6875"
"","25.9910","5.4836","12146.9189"
"","26.0910","5.5051","12127.9873"
"","26.1910","5.5257","12133.4053"
"","26.2910","5.5470","12121.1572"
"","26.3910","5.5675","12117.3809"
"","26.4910","5.5899","12117.1650"
"","26.5910","5.6102","12097.8330"
"","26.6910","5.6319","12104.9580"
"","26.7910","5.6525","12091.8525"
"","26.8910","5.6741","12099.2217"
"","26.9910","5.6958","12080.6992"
"","27.0910","5.7161","12081.4990"
"","27.1910","5.7377","12071.2627"
"","27.2910","5.7582","12064.8262"
"","27.3910","5.7805","12067.2324"
"","27.4910","5.8008","12045.0947"
"","27.5910","5.8223","12052.6836"
"","27.6910","5.8430","12036.3096"
"","27.7910","5.8644","12041.6621"
"","27.8910","5.8863","12027.7080"
"","27.9910","5.9063","12020.5439"
"","28.0910","5.9283","12015.9346"
"","28.1910","5.9486","12003.5527"
"","28.2910","5.9707","12005.4639"
"","28.3910","5.9915","11985.0420"
"","28.4910","6.0126","11989.7646"
"","28.5910","6.0339","11974.9707"
"","28.6910","6.0548","11975.7354"
"","28.7910","6.0768","11967.1934"
"","28.8910","6.0970","11950.0000"
"","28.9910","6.1186","11948.2881"
"","29.0910","6.1392","11935.0791"
"","29.1910","6.1607","11933.7734"
"","29.2910","6.1822","11916.8555"
"","29.3910","6.2031","11918.8291"
"","29.4910","6.2244","11902.0684"
"","29.5910","6.2451","11895.8076"
"","29.6910","6.2672","11895.4971"
"","29.7910","6.2877","11872.8057"
"","29.8910","6.3092","11873.1152"
"","29.9910","6.3299","11856.1924"
"","30.0910","6.3515","11858.3018"
"","30.1910","6.3731","11839.1436"
"","30.2910","6.3935","11832.6533"
"","30.3910","6.4149","11821.7441"
"","30.4910","6.4355","11812.7871"
"","30.5910","6.4578","11809.0996"
"","30.6910","6.4780","11783.0645"
"","30.7910","6.4997","11789.9707"
"","30.8910","6.5204","11768.3145"
"","30.9910","6.5415","11766.8018"
"","31.0910","6.5638","11752.0615"
"","31.1910","6.5837","11736.6689"
"","31.2910","6.6057","11730.4814"
"","31.3910","6.6260","11716.0791"
"","31.4910","6.6481","11714.2832"
"","31.5910","6.6689","11689.4072"
"","31.6910","6.6901","11691.9160"
"","31.7910","6.7111","11666.9121"
"","31.8910","6.7320","11664.8096"
"","31.9910","6.7540","11650.7725"
"","32.0910","6.7741","11633.3311"
"","32.1910","6.7960","11628.9482"
"","32.2910","6.8165","11610.7617"
"","32.3910","6.8382","11604.8799"
"","32.4910","6.8597","11585.4287"
"","32.5910","6.8805","11579.9346"
"","32.6910","6.9019","11559.3594"
"","32.7910","6.9224","11549.7100"
"","32.8910","6.9448","11541.8457"
"","32.9910","6.9650","11515.4316"
"","33.0910","6.9866","11512.2148"
"","33.1910","7.0070","11490.5479"
"","33.2910","7.0287","11488.2227"
"","33.3910","7.0504","11464.5596"
"","33.4910","7.0707","11455.8350"
"","33.5910","7.0923","11438.1738"
"","33.6910","7.1128","11424.6016"
"","33.7910","7.1350","11415.5254"
"","33.8910","7.1557","11387.0244"
"","33.9910","7.1769","11384.0547"
"","34.0910","7.1978","11359.3555"
"","34.1910","7.2190","11354.8076"
"","34.2910","7.2409","11331.6943"
"","34.3910","7.2610","11315.1094"
"","34.4910","7.2829","11303.5283"
"","34.5910","7.3034","11280.3457"
"","34.6910","7.3252","11275.2432"
"","34.7910","7.3462","11243.2178"
"","34.8910","7.3674","11240.2832"
"","34.9910","7.3883","11214.2119"
"","35.0910","7.4093","11203.7979"
"","35.1910","7.4314","11185.4033"
"","35.2910","7.4517","11161.6064"
"","35.3910","7.4735","11149.1348"
"","35.4910","7.4939","11122.4150"
"","35.5910","7.5158","11114.8281"
"","35.6910","7.5369","11083.7939"
"","35.7910","7.5577","11076.0420"
"","35.8910","7.5792","11049.8223"
"","35.9910","7.5998","11035.1074"
"","36.0910","7.6219","11017.2402"
"","36.1910","7.6422","10987.8701"
"","36.2910","7.6640","10975.8633"
"","36.3910","7.6844","10947.2998"
"","36.4910","7.7060","10937.4600"
"","36.5910","7.7277","10906.0029"
"","36.6910","7.7482","10889.9414"
"","36.7910","7.7697","10863.5303"
"","36.8910","7.7901","10843.7012"
"","36.9910","7.8124","10827.4600"
"","37.0910","7.8329","10791.5488"
"","37.1910","7.8542","10781.0117"
"","37.2910","7.8750","10748.6924"
"","37.3910","7.8962","10733.7441"
"","37.4910","7.9182","10706.5732"
"","37.5910","7.9385","10679.5049"
"","37.6910","7.9602","10658.1064"
"","37.7910","7.9807","10628.8027"
"","37.8910","8.0028","10611.2393"
"","37.9910","8.0237","10571.5439"
"","38.0910","8.0448","10558.6553"
"","38.1910","8.0658","10522.7656"
"","38.2910","8.0868","10503.7559"
"","38.3910","8.1090","10473.0869"
"","38.4910","8.1288","10441.2393"
"","38.5910","8.1507","10418.6885"
"","38.6910","8.1712","10385.5830"
"","38.7910","8.1931","10365.4678"
"","38.8910","8.2140","10324.3340"
"","38.9910","8.2352","10304.6279"
"","39.0910","8.2563","10265.3828"
"","39.1910","8.2772","10240.9268"
"","39.2910","8.2993","10210.3037"
"","39.3910","8.3196","10169.8428"
"","39.4910","8.3412","10144.5439"
"","39.5910","8.3618","10103.1484"
"","39.6910","8.3834","10079.8213"
"","39.7910","8.4050","10036.5752"
"","39.8910","8.4255","10008.4033"
"","39.9910","8.4470","9971.7949"
"","40.0910","8.4675","9937.0645"
"","40.1910","8.4896","9904.7695"
"","40.2910","8.5101","9855.6533"
"","40.3910","8.5315","9826.4375"
"","40.4910","8.5524","9778.9561"
"","40.5910","8.5737","9748.7773"
"","40.6910","8.5957","9704.4092"
"","40.7910","8.6160","9664.7539"
"","40.8910","8.6377","9624.0811"
"","40.9910","8.6582","9581.0283"
"","41.0910","8.6800","9541.6787"
"","41.1910","8.7010","9487.7773"
"","41.2910","8.7220","9451.8740"
"","41.3910","8.7429","9396.4209"
"","41.4910","8.7640","9358.4082"
"","41.5910","8.7861","9307.8965"
"","41.6910","8.8063","9256.1436"
"","41.7910","8.8282","9210.4658"
"","41.8910","8.8487","9156.4609"
"","41.9910","8.8704","9110.1543"
"","42.0910","8.8917","9046.1787"
"","42.1910","8.9123","8998.8369"
"","42.2910","8.9338","8936.9658"
"","42.3910","8.9544","8882.3926"
"","42.4910","8.9765","8824.6807"
"","42.5910","8.9970","8757.1172"
"","42.6910","9.0186","8702.0713"
"","42.7910","9.0391","8632.2021"
"","42.8910","9.0604","8572.9600"
"","42.9910","9.0825","8495.8408"
"","43.0910","9.1027","8429.6602"
"","43.1910","9.1244","8353.0127"
"","43.2910","9.1448","8279.5801"
"","43.3910","9.1671","8205.1035"
"","43.4910","9.1878","8114.1646"
"","43.5910","9.2089","8039.3149"
"","43.6910","9.2298","7946.1763"
"","43.7910","9.2510","7863.2632"
"","43.8910","9.2730","7758.3872"
"","43.9910","9.2931","7664.1812"
"","44.0910","9.3148","7556.3535"
"","44.1910","9.3353","7448.9644"
"","44.2910","9.3575","7326.4204"
"","44.3910","9.3784","7092.2456"
"","44.4250","9.3852","6836.6421"
"","44.4470","9.3899","6581.5776"
"","44.4620","9.3932","6319.6284"
"","44.4740","9.3959","6060.9048"
"","44.4860","9.3986","5803.8452"
"","44.5020","9.4022","5541.5054"
"","44.5330","9.4090","5288.5288"
"","44.5960","9.4216","5036.6147"
"","44.6650","9.4359","4782.8252"
"","44.7220","9.4486","4531.8242"
"","44.7880","9.4632","4280.1235"
"","44.8640","9.4784","4029.2661"
"","44.9410","9.4944","3778.4226"
"","45.0250","9.5126","3527.5032"
"","45.1250","9.5332","3340.3645"
"","45.2190","9.5539","3089.1057"
"","45.3190","9.5744","2873.4241"
"","45.4190","9.5958","2653.3142"
"","45.5190","9.6168","2445.5393"
"","45.6190","9.6379","2255.8215"
"","45.7190","9.6599","2071.3362"
"","45.8190","9.6801","1900.5137"
"","45.9190","9.7019","1679.8621"
"","46.0190","9.7224","1465.9503"
"","46.1190","9.7443","1214.7759"
"","46.1830","9.7581","961.9037"
"","46.2380","9.7691","708.3375"
"","46.2460","9.7707","672.1154"